Workbook

Sheet 集計
A1: 原価センター | B1: 組織名 | C1: TYPE | D1: KEY | F1: 4 | G1: 5 | H1: 6 | I1: 7 | J1: 8 | K1: 9 | L1: 10 | M1: 11 | N1: 12 | O1: 1 | P1: 2 | Q1: 3
A2: 1412000004 | B2: 機器製造1課 | E2: 人員
A3: 1412000004 | B3: 機器製造1課 | E3: 出向社員 | F3: 2 | G3: 2 | H3: 2 | I3: 2 | J3: 2 | K3: 2 | L3: 2 | M3: 2 | N3: 2 | O3: 2 | P3: 2 | Q3: 2
A4: 1412000004 | B4: 機器製造1課 | E4: G5以上 | F4: 77 | G4: 77 | H4: 77 | I4: 85 | J4: 85 | K4: 85 | L4: 85 | M4: 85 | N4: 85 | O4: 93 | P4: 93 | Q4: 93
A5: 1412000004 | B5: 機器製造1課 | E5: G7,G6 | F5: 928 | G5: 965 | H5: 961 | I5: 1105 | J5: 1185 | K5: 1450 | L5: 1751 | M5: 1757 | N5: 1752 | O5: 1772 | P5: 1962 | Q5: 1789
A6: 1412000004 | B6: 機器製造1課 | E6: ローカル社員 | F6: 1005 | G6: 1042 | H6: 1038 | I6: 1190 | J6: 1270 | K6: 1535 | L6: 1836 | M6: 1842 | N6: 1837 | O6: 1865 | P6: 2055 | Q6: 1882
A7: 1412000004 | B7: 機器製造1課 | E7: 人員合計 | F7: 1007 | G7: 1044 | H7: 1040 | I7: 1192 | J7: 1272 | K7: 1537 | L7: 1838 | M7: 1844 | N7: 1839 | O7: 1867 | P7: 2057 | Q7: 1884
A8: 1412000004 | B8: 機器製造1課
A9: 1412000004 | B9: 機器製造1課 | E9: 定時間
A10: 1412000004 | B10: 機器製造1課 | E10: 出向社員 | F10: 340 | G10: 323 | H10: 357 | I10: 391 | J10: 340 | K10: 323 | L10: 391 | M10: 340 | N10: 374 | O10: 340 | P10: 255 | Q10: 340
A11: 1412000004 | B11: 機器製造1課 | E11: G5以上 | F11: 13430 | G11: 12759 | H11: 14102 | I11: 17009 | J11: 14790 | K11: 14051 | L11: 17009 | M11: 14790 | N11: 16269 | O11: 16150 | P11: 12113 | Q11: 16150
A12: 1412000004 | B12: 機器製造1課 | E12: G7,G6 | F12: 77074 | G12: 76933 | H12: 89856 | I12: 118502 | J12: 112189 | K12: 145429 | L12: 249945 | M12: 161958 | N12: 177584 | O12: 173898 | P12: 141193 | Q12: 168487
A13: 1412000004 | B13: 機器製造1課 | E13: ローカル社員 | F13: 90504 | G13: 89692 | H13: 103958 | I13: 135511 | J13: 126979 | K13: 159480 | L13: 266954 | M13: 176748 | N13: 193853 | O13: 190048 | P13: 153306 | Q13: 184637
A14: 1412000004 | B14: 機器製造1課 | E14: 定時間合計 | F14: 90844 | G14: 90015 | H14: 104315 | I14: 135902 | J14: 127319 | K14: 159803 | L14: 267345 | M14: 177088 | N14: 194227 | O14: 190388 | P14: 153561 | Q14: 184977
A15: 1412000004 | B15: 機器製造1課
A16: 1412000004 | B16: 機器製造1課 | E16: 残業時間
A17: 1412000004 | B17: 機器製造1課 | E17: 出向社員 | F17: 80 | G17: 76 | H17: 84 | I17: 92 | J17: 80 | K17: 76 | L17: 92 | M17: 80 | N17: 88 | O17: 80 | P17: 60 | Q17: 80
A18: 1412000004 | B18: 機器製造1課 | E18: G5以上 | F18: 189 | G18: 221 | H18: 189 | I18: 216 | J18: 300 | K18: 570 | L18: 271 | M18: 281 | N18: 345 | O18: 503 | P18: 1053 | Q18: 423
A19: 1412000004 | B19: 機器製造1課 | E19: G7,G6 | F19: 721 | G19: 732 | H19: 709 | I19: 667 | J19: 1081 | K19: 647 | L19: 615 | M19: 665 | N19: 555 | O19: 449 | P19: 3057 | Q19: 769
A20: 1412000004 | B20: 機器製造1課 | E20: ローカル社員 | F20: 910 | G20: 953 | H20: 898 | I20: 883 | J20: 1381 | K20: 1217 | L20: 886 | M20: 946 | N20: 900 | O20: 952 | P20: 4110 | Q20: 1192
A21: 1412000004 | B21: 機器製造1課 | E21: 残業時間合計 | F21: 990 | G21: 1029 | H21: 982 | I21: 975 | J21: 1461 | K21: 1293 | L21: 978 | M21: 1026 | N21: 988 | O21: 1032 | P21: 4170 | Q21: 1272
A22: 1412000005 | B22: 機器製造2課 | E22: 人員
A23: 1412000005 | B23: 機器製造2課 | E23: 出向社員 | F23: 0 | G23: 0 | H23: 0 | I23: 0 | J23: 0 | K23: 0 | L23: 0 | M23: 0 | N23: 0 | O23: 0 | P23: 0 | Q23: 0
A24: 1412000005 | B24: 機器製造2課 | E24: G5以上 | F24: 100 | G24: 100 | H24: 100 | I24: 116 | J24: 116 | K24: 116 | L24: 116 | M24: 116 | N24: 116 | O24: 132 | P24: 132 | Q24: 132
A25: 1412000005 | B25: 機器製造2課 | E25: G7,G6 | F25: 1514 | G25: 1454 | H25: 1418 | I25: 1637 | J25: 1688 | K25: 1616 | L25: 1660 | M25: 1761 | N25: 1714 | O25: 1862 | P25: 2010 | Q25: 1761
A26: 1412000005 | B26: 機器製造2課 | E26: ローカル社員 | F26: 1614 | G26: 1554 | H26: 1518 | I26: 1753 | J26: 1804 | K26: 1732 | L26: 1776 | M26: 1877 | N26: 1830 | O26: 1994 | P26: 2142 | Q26: 1893
A27: 1412000005 | B27: 機器製造2課 | E27: 人員合計 | F27: 1614 | G27: 1554 | H27: 1518 | I27: 1753 | J27: 1804 | K27: 1732 | L27: 1776 | M27: 1877 | N27: 1830 | O27: 1994 | P27: 2142 | Q27: 1893
A28: 1412000005 | B28: 機器製造2課
A29: 1412000005 | B29: 機器製造2課 | E29: 定時間
A30: 1412000005 | B30: 機器製造2課 | E30: 出向社員 | F30: 0 | G30: 0 | H30: 0 | I30: 0 | J30: 0 | K30: 0 | L30: 0 | M30: 0 | N30: 0 | O30: 0 | P30: 0 | Q30: 0
A31: 1412000005 | B31: 機器製造2課 | E31: G5以上 | F31: 17680 | G31: 16796 | H31: 18564 | I31: 23460 | J31: 20400 | K31: 19380 | L31: 23460 | M31: 20400 | N31: 22440 | O31: 23120 | P31: 17340 | Q31: 23120
A32: 1412000005 | B32: 機器製造2課 | E32: G7,G6 | F32: 298714 | G32: 275654 | H32: 293133 | I32: 380903 | J32: 332664 | K32: 304855 | L32: 371226 | M32: 345745 | N32: 367426 | O32: 361894 | P32: 293047 | Q32: 342991
A33: 1412000005 | B33: 機器製造2課 | E33: ローカル社員 | F33: 316394 | G33: 292450 | H33: 311697 | I33: 404363 | J33: 353064 | K33: 324235 | L33: 394686 | M33: 366145 | N33: 389866 | O33: 385014 | P33: 310387 | Q33: 366111
A34: 1412000005 | B34: 機器製造2課 | E34: 定時間合計 | F34: 316394 | G34: 292450 | H34: 311697 | I34: 404363 | J34: 353064 | K34: 324235 | L34: 394686 | M34: 366145 | N34: 389866 | O34: 385014 | P34: 310387 | Q34: 366111
A35: 1412000005 | B35: 機器製造2課
A36: 1412000005 | B36: 機器製造2課 | E36: 残業時間
A37: 1412000005 | B37: 機器製造2課 | E37: 出向社員 | F37: 0 | G37: 0 | H37: 0 | I37: 0 | J37: 0 | K37: 0 | L37: 0 | M37: 0 | N37: 0 | O37: 0 | P37: 0 | Q37: 0
A38: 1412000005 | B38: 機器製造2課 | E38: G5以上 | F38: 263 | G38: 259 | H38: 267 | I38: 283 | J38: 356 | K38: 939 | L38: 328 | M38: 628 | N38: 288 | O38: 372 | P38: 1323 | Q38: 360
A39: 1412000005 | B39: 機器製造2課 | E39: G7,G6 | F39: 2323 | G39: 2947 | H39: 2207 | I39: 2210 | J39: 4741 | K39: 17785 | L39: 3215 | M39: 8836 | N39: 3250 | O39: 7764 | P39: 28373 | Q39: 5748
A40: 1412000005 | B40: 機器製造2課 | E40: ローカル社員 | F40: 2586 | G40: 3206 | H40: 2474 | I40: 2493 | J40: 5097 | K40: 18724 | L40: 3543 | M40: 9464 | N40: 3538 | O40: 8136 | P40: 29696 | Q40: 6108
...

Sheet DATA
A1: 原価センタ | B1: 名称 | C1: Tên phòng ban | E1: ◆FY2025マスタープラン人員・時間計画表
A2: 1412000004 | B2: 機器製造1課 | E2: → １＝日本語(tiếng nhật)、２＝ベトナム語(tiếng việt)
A3: 1412000005 | B3: 機器製造2課 | E3: 原価センター | F3: 組織名
A4: 1412000081 | B4: 機器製造3課 | E4: 14120000ZZ | F4: =VLOOKUP(E4,A:B,2,0) -> #N/A
A5: 1412000066 | B5: RPS製造課 | E5: 人員 | F5: Số người
A6: 1412000062 | B6: 機器製造管理課 | E6: 出向社員 | F6: Nhân viên công tác
E7: G5以上 | F7: G5 trở lên
A8: 1412000034 | B8: トナー製造課 | E8: G7,G6 | F8: G7,G6 | R8: 0
A9: 1412000048 | B9: トナー生産技術課 | E9: ローカル社員 | F9: Nhân viên địa phương
A10: 1412000063 | B10: トナー製造管理課 | E10: 人員合計 | F10: Tổng số người
A11: 1412000055 | B11: トナー品質管理課
E12: 定時間 | F12: Thời gian cố định | R12: 0
A13: 1412000056 | B13: 部品製造課 | E13: 出向社員 | F13: Nhân viên công tác
A14: 1412000044 | B14: 金型技術課 | E14: G5以上 | F14: G5 trở lên
A15: 1412000087 | B15: 部品製造管理課 | E15: G7,G6 | F15: G7,G6
A16: 1412000088 | B16: 品質管理課 | E16: ローカル社員 | F16: Nhân viên địa phương | R16: 0
E17: 定時間合計 | F17: Tổng thời gian cố định
A18: 1412000098 | B18: 電工製造課
E19: 残業時間 | F19: Thời gian thêm giờ
A20: 1412000008 | B20: 生産管理課 | E20: 出向社員 | F20: Nhân viên công tác
A21: 1412000010 | B21: 採算管理課 | E21: G5以上 | F21: G5 trở lên
A22: 1412000054 | B22: マスター管理課 | E22: G7,G6 | F22: G7,G6
A23: 1412000094 | B23: 部品在庫管理課 | E23: ローカル社員 | F23: Nhân viên địa phương
E24: 残業時間合計 | F24: Tổng thời gian thêm giờ
A25: 1412000036 | B25: 部品管理1課
A26: 1412000103 | B26: 部品管理2課
A27: 1412000072 | B27: 製品管理課
A28: 1412000073 | B28: 物流管理課
A30: 1412000053 | B30: 工程品質管理1課
A31: 1412000104 | B31: 工程品質管理2課
A32: 1412000105 | B32: 工程品質管理3課
A33: 1412000075 | B33: 工程品質管理4課
A35: 1412000013 | B35: 部品検査1課
A36: 1412000092 | B36: 部品検査2課
A37: 1412000035 | B37: 部品品質管理課
A39: 1412000006 | B39: メカ製造技術1課
... A101: 1412000001 | B101: 取締役共通
A102: 1412A00004 | B102: 調整
A103: 1412C00001 | B103: 労働組合

Sheet 人員計画
B1: FY2024_MP
D2: 機器製造1課 | E2: 機器製造2課 | F2: 機器製造3課 | G2: RPS製造課 | H2: 機器製造管理課 | I2: 機器製造部 | J2: トナー製造課 | K2: トナー生産技術課 | L2: トナー製造管理課 | M2: トナー品質管理課 | N2: トナー製造部計 | O2: 部品製造課 | P2: 金型技術課 | Q2: 部品製造管理課 | R2: 品質管理課 | S2: 部品技術課 | T2: 部品製造部 | U2: 生産管理課 | V2: 採算管理課 | W2: マスター管理課 | X2: 生産管理部 | Y2: 部品管理課 | Z2: 製品管理課 | AA2: 物流管理課 | AB2: 物流部 | AC2: 製造本 | AD2: メカ製造技術1課 | AE2: メカ製造技術2課 | AF2: メカ製造技術3課 | AG2: 電気製造技術課 | AH2: 製造技術部 | AI2: 生産技術1課 | AJ2: 生産技術2課 | AK2: 生産技術3課 | AL2: 生産技術部 | AM2: 工程品質管理1課 | AN2: 工程品質管理2課 | AO2: 工程品質管理部 | AP2: 部品検査1課 | AQ2: 部品検査2課 | AR2: 外製管理課 | AS2: 外製品質管理部 | AT2: 生産技術本部 | AU2: MD1課 | AV2: MD2課 | AW2: MD3課 | AX2: EI1課 | AY2: ESD1課 | AZ2: 製品開発部 | BA2: 製品開発本部 | BB2: 品質保証課 | BC2: 製品保証課 | BD2: 品質保証部 | BE2: 第1資材課 | BF2: 第2資材課 | BG2: 第3資材課 | BH2: 第4資材課 | BI2: 資材管理課 | BJ2: 資材管理部 | BK2: 総務課 | BL2: 人事課 | BM2: 人材開発課 | BN2: 施設課 | BO2: リスクマネジメント課 | BP2: 保安課 | BQ2: 総務人事部 | BR2: 会計課 | BS2: 経営管理課 | BT2: 貿易管理課 | BU2: 経営管理部 | BV2: 情報システム課 | BW2: ITソリューション推進部 | BX2: KDTVN合計
B3: 4 | C3: 人員
A4: 人員 | B4: 4 | C4: 出向社員 | D4: =VLOOKUP(D$2&$C4&$A4,集計!$D:$R,$B4,0) -> #N/A | E4: =VLOOKUP(E$2&$C4&$A4,集計!$D:$R,$B4,0) -> #N/A | F4: =VLOOKUP(F$2&$C4&$A4,集計!$D:$R,$B4,0) -> #N/A | G4: =VLOOKUP(G$2&$C4&$A4,集計!$D:$R,$B4,0) -> #N/A | H4: =VLOOKUP(H$2&$C4&$A4,集計!$D:$R,$B4,0) -> #N/A | I4: =D4+E4+F4+G4+H4 -> #N/A | J4: =VLOOKUP(J$2&$C4&$A4,集計!$D:$R,$B4,0) -> #N/A | K4: =VLOOKUP(K$2&$C4&$A4,集計!$D:$R,$B4,0) -> #N/A | L4: =VLOOKUP(L$2&$C4&$A4,集計!$D:$R,$B4,0) -> #N/A | M4: =VLOOKUP(M$2&$C4&$A4,集計!$D:$R,$B4,0) -> #N/A | N4: =J4+K4+L4+M4 -> #N/A | O4: =VLOOKUP(O$2&$C4&$A4,集計!$D:$R,$B4,0) -> #N/A | P4: =VLOOKUP(P$2&$C4&$A4,集計!$D:$R,$B4,0) -> #N/A | Q4: =VLOOKUP(Q$2&$C4&$A4,集計!$D:$R,$B4,0) -> #N/A | R4: =VLOOKUP(R$2&$C4&$A4,集計!$D:$R,$B4,0) -> #N/A | S4: =VLOOKUP(S$2&$C4&$A4,集計!$D:$R,$B4,0) -> #N/A | T4: =O4+P4+Q4+R4+S4 -> #N/A | U4: =VLOOKUP(U$2&$C4&$A4,集計!$D:$R,$B4,0) -> #N/A | V4: =VLOOKUP(V$2&$C4&$A4,集計!$D:$R,$B4,0) -> #N/A | W4: =VLOOKUP(W$2&$C4&$A4,集計!$D:$R,$B4,0) -> #N/A | X4: =U4+V4+W4 -> #N/A | Y4: =VLOOKUP(Y$2&$C4&$A4,集計!$D:$R,$B4,0) -> #N/A | Z4: =VLOOKUP(Z$2&$C4&$A4,集計!$D:$R,$B4,0) -> #N/A | AA4: =VLOOKUP(AA$2&$C4&$A4,集計!$D:$R,$B4,0) -> #N/A | AB4: =Y4+Z4+AA4 -> #N/A | AC4: =I4+N4+T4+X4+AB4 -> #N/A | AD4: =VLOOKUP(AD$2&$C4&$A4,集計!$D:$R,$B4,0) -> #N/A | AE4: =VLOOKUP(AE$2&$C4&$A4,集計!$D:$R,$B4,0) -> #N/A | AF4: =VLOOKUP(AF$2&$C4&$A4,集計!$D:$R,$B4,0) -> #N/A | AG4: =VLOOKUP(AG$2&$C4&$A4,集計!$D:$R,$B4,0) -> #N/A | AH4: =AD4+AE4+AF4+AG4 -> #N/A | AI4: =VLOOKUP(AI$2&$C4&$A4,集計!$D:$R,$B4,0) -> #N/A | AJ4: =VLOOKUP(AJ$2&$C4&$A4,集計!$D:$R,$B4,0) -> #N/A | AK4: =VLOOKUP(AK$2&$C4&$A4,集計!$D:$R,$B4,0) -> #N/A | AL4: =AI4+AJ4+AK4 -> #N/A | AM4: =VLOOKUP(AM$2&$C4&$A4,集計!$D:$R,$B4,0) -> #N/A | AN4: =VLOOKUP(AN$2&$C4&$A4,集計!$D:$R,$B4,0) -> #N/A | AO4: =AM4+AN4 -> #N/A | AP4: =VLOOKUP(AP$2&$C4&$A4,集計!$D:$R,$B4,0) -> #N/A | AQ4: =VLOOKUP(AQ$2&$C4&$A4,集計!$D:$R,$B4,0) -> #N/A | AR4: =VLOOKUP(AR$2&$C4&$A4,集計!$D:$R,$B4,0) -> #N/A | AS4: =AP4+AQ4+AR4 -> #N/A | AT4: =AH4+AL4+AO4+AS4 -> #N/A | AU4: =VLOOKUP(AU$2&$C4&$A4,集計!$D:$R,$B4,0) -> #N/A | AV4: =VLOOKUP(AV$2&$C4&$A4,集計!$D:$R,$B4,0) -> #N/A | AW4: =VLOOKUP(AW$2&$C4&$A4,集計!$D:$R,$B4,0) -> #N/A | AX4: =VLOOKUP(AX$2&$C4&$A4,集計!$D:$R,$B4,0) -> #N/A | AY4: =VLOOKUP(AY$2&$C4&$A4,集計!$D:$R,$B4,0) -> #N/A | AZ4: =AU4+AV4+AW4+AX4+AY4 -> #N/A | BA4: =AZ4 -> #N/A | BB4: =VLOOKUP(BB$2&$C4&$A4,集計!$D:$R,$B4,0) -> #N/A | BC4: =VLOOKUP(BC$2&$C4&$A4,集計!$D:$R,$B4,0) -> #N/A | BD4: =BB4+BC4 -> #N/A | BE4: =VLOOKUP(BE$2&$C4&$A4,集計!$D:$R,$B4,0) -> #N/A | BF4: =VLOOKUP(BF$2&$C4&$A4,集計!$D:$R,$B4,0) -> #N/A | BG4: =VLOOKUP(BG$2&$C4&$A4,集計!$D:$R,$B4,0) -> #N/A | BH4: =VLOOKUP(BH$2&$C4&$A4,集計!$D:$R,$B4,0) -> #N/A | BI4: =VLOOKUP(BI$2&$C4&$A4,集計!$D:$R,$B4,0) -> #N/A | BJ4: =BE4+BF4+BG4+BH4+BI4 -> #N/A | BK4: =VLOOKUP(BK$2&$C4&$A4,集計!$D:$R,$B4,0) -> #N/A | BL4: =VLOOKUP(BL$2&$C4&$A4,集計!$D:$R,$B4,0) -> #N/A | BM4: =VLOOKUP(BM$2&$C4&$A4,集計!$D:$R,$B4,0) -> #N/A | BN4: =VLOOKUP(BN$2&$C4&$A4,集計!$D:$R,$B4,0) -> #N/A | BO4: =VLOOKUP(BO$2&$C4&$A4,集計!$D:$R,$B4,0) -> #N/A | BP4: =VLOOKUP(BP$2&$C4&$A4,集計!$D:$R,$B4,0) -> #N/A | BQ4: =BK4+BL4+BM4+BN4+BO4+BP4 -> #N/A | BR4: =VLOOKUP(BR$2&$C4&$A4,集計!$D:$R,$B4,0) -> #N/A | BS4: =VLOOKUP(BS$2&$C4&$A4,集計!$D:$R,$B4,0) -> #N/A | BT4: =VLOOKUP(BT$2&$C4&$A4,集計!$D:$R,$B4,0) -> #N/A | BU4: =BR4+BS4+BT4 -> #N/A | BV4: =VLOOKUP(BV$2&$C4&$A4,集計!$D:$R,$B4,0) -> #N/A | BW4: =BV4 -> #N/A | BX4: =AC4+AT4+BA4+BD4+BJ4+BQ4+BU4+BW4 -> #N/A
A5: 人員 | B5: 4 | C5: G5以上 | D5: =VLOOKUP(D$2&$C5&$A5,集計!$D:$R,$B5,0) -> #N/A | E5: =VLOOKUP(E$2&$C5&$A5,集計!$D:$R,$B5,0) -> #N/A | F5: =VLOOKUP(F$2&$C5&$A5,集計!$D:$R,$B5,0) -> #N/A | G5: =VLOOKUP(G$2&$C5&$A5,集計!$D:$R,$B5,0) -> #N/A | H5: =VLOOKUP(H$2&$C5&$A5,集計!$D:$R,$B5,0) -> #N/A | I5: =D5+E5+F5+G5+H5 -> #N/A | J5: =VLOOKUP(J$2&$C5&$A5,集計!$D:$R,$B5,0) -> #N/A | K5: =VLOOKUP(K$2&$C5&$A5,集計!$D:$R,$B5,0) -> #N/A | L5: =VLOOKUP(L$2&$C5&$A5,集計!$D:$R,$B5,0) -> #N/A | M5: =VLOOKUP(M$2&$C5&$A5,集計!$D:$R,$B5,0) -> #N/A | N5: =J5+K5+L5+M5 -> #N/A | O5: =VLOOKUP(O$2&$C5&$A5,集計!$D:$R,$B5,0) -> #N/A | P5: =VLOOKUP(P$2&$C5&$A5,集計!$D:$R,$B5,0) -> #N/A | Q5: =VLOOKUP(Q$2&$C5&$A5,集計!$D:$R,$B5,0) -> #N/A | R5: =VLOOKUP(R$2&$C5&$A5,集計!$D:$R,$B5,0) -> #N/A | S5: =VLOOKUP(S$2&$C5&$A5,集計!$D:$R,$B5,0) -> #N/A | T5: =O5+P5+Q5+R5+S5 -> #N/A | U5: =VLOOKUP(U$2&$C5&$A5,集計!$D:$R,$B5,0) -> #N/A | V5: =VLOOKUP(V$2&$C5&$A5,集計!$D:$R,$B5,0) -> #N/A | W5: =VLOOKUP(W$2&$C5&$A5,集計!$D:$R,$B5,0) -> #N/A | X5: =U5+V5+W5 -> #N/A | Y5: =VLOOKUP(Y$2&$C5&$A5,集計!$D:$R,$B5,0) -> #N/A | Z5: =VLOOKUP(Z$2&$C5&$A5,集計!$D:$R,$B5,0) -> #N/A | AA5: =VLOOKUP(AA$2&$C5&$A5,集計!$D:$R,$B5,0) -> #N/A | AB5: =Y5+Z5+AA5 -> #N/A | AC5: =I5+N5+T5+X5+AB5 -> #N/A | AD5: =VLOOKUP(AD$2&$C5&$A5,集計!$D:$R,$B5,0) -> #N/A | AE5: =VLOOKUP(AE$2&$C5&$A5,集計!$D:$R,$B5,0) -> #N/A | AF5: =VLOOKUP(AF$2&$C5&$A5,集計!$D:$R,$B5,0) -> #N/A | AG5: =VLOOKUP(AG$2&$C5&$A5,集計!$D:$R,$B5,0) -> #N/A | AH5: =AD5+AE5+AF5+AG5 -> #N/A | AI5: =VLOOKUP(AI$2&$C5&$A5,集計!$D:$R,$B5,0) -> #N/A | AJ5: =VLOOKUP(AJ$2&$C5&$A5,集計!$D:$R,$B5,0) -> #N/A | AK5: =VLOOKUP(AK$2&$C5&$A5,集計!$D:$R,$B5,0) -> #N/A | AL5: =AI5+AJ5+AK5 -> #N/A | AM5: =VLOOKUP(AM$2&$C5&$A5,集計!$D:$R,$B5,0) -> #N/A | AN5: =VLOOKUP(AN$2&$C5&$A5,集計!$D:$R,$B5,0) -> #N/A | AO5: =AM5+AN5 -> #N/A | AP5: =VLOOKUP(AP$2&$C5&$A5,集計!$D:$R,$B5,0) -> #N/A | AQ5: =VLOOKUP(AQ$2&$C5&$A5,集計!$D:$R,$B5,0) -> #N/A | AR5: =VLOOKUP(AR$2&$C5&$A5,集計!$D:$R,$B5,0) -> #N/A | AS5: =AP5+AQ5+AR5 -> #N/A | AT5: =AH5+AL5+AO5+AS5 -> #N/A | AU5: =VLOOKUP(AU$2&$C5&$A5,集計!$D:$R,$B5,0) -> #N/A | AV5: =VLOOKUP(AV$2&$C5&$A5,集計!$D:$R,$B5,0) -> #N/A | AW5: =VLOOKUP(AW$2&$C5&$A5,集計!$D:$R,$B5,0) -> #N/A | AX5: =VLOOKUP(AX$2&$C5&$A5,集計!$D:$R,$B5,0) -> #N/A | AY5: =VLOOKUP(AY$2&$C5&$A5,集計!$D:$R,$B5,0) -> #N/A | AZ5: =AU5+AV5+AW5+AX5+AY5 -> #N/A | BA5: =AZ5 -> #N/A | BB5: =VLOOKUP(BB$2&$C5&$A5,集計!$D:$R,$B5,0) -> #N/A | BC5: =VLOOKUP(BC$2&$C5&$A5,集計!$D:$R,$B5,0) -> #N/A | BD5: =BB5+BC5 -> #N/A | BE5: =VLOOKUP(BE$2&$C5&$A5,集計!$D:$R,$B5,0) -> #N/A | BF5: =VLOOKUP(BF$2&$C5&$A5,集計!$D:$R,$B5,0) -> #N/A | BG5: =VLOOKUP(BG$2&$C5&$A5,集計!$D:$R,$B5,0) -> #N/A | BH5: =VLOOKUP(BH$2&$C5&$A5,集計!$D:$R,$B5,0) -> #N/A | BI5: =VLOOKUP(BI$2&$C5&$A5,集計!$D:$R,$B5,0) -> #N/A | BJ5: =BE5+BF5+BG5+BH5+BI5 -> #N/A | BK5: =VLOOKUP(BK$2&$C5&$A5,集計!$D:$R,$B5,0) -> #N/A | BL5: =VLOOKUP(BL$2&$C5&$A5,集計!$D:$R,$B5,0) -> #N/A | BM5: =VLOOKUP(BM$2&$C5&$A5,集計!$D:$R,$B5,0) -> #N/A | BN5: =VLOOKUP(BN$2&$C5&$A5,集計!$D:$R,$B5,0) -> #N/A | BO5: =VLOOKUP(BO$2&$C5&$A5,集計!$D:$R,$B5,0) -> #N/A | BP5: =VLOOKUP(BP$2&$C5&$A5,集計!$D:$R,$B5,0) -> #N/A | BQ5: =BK5+BL5+BM5+BN5+BO5+BP5 -> #N/A | BR5: =VLOOKUP(BR$2&$C5&$A5,集計!$D:$R,$B5,0) -> #N/A | BS5: =VLOOKUP(BS$2&$C5&$A5,集計!$D:$R,$B5,0) -> #N/A | BT5: =VLOOKUP(BT$2&$C5&$A5,集計!$D:$R,$B5,0) -> #N/A | BU5: =BR5+BS5+BT5 -> #N/A | BV5: =VLOOKUP(BV$2&$C5&$A5,集計!$D:$R,$B5,0) -> #N/A | BW5: =BV5 -> #N/A | BX5: =AC5+AT5+BA5+BD5+BJ5+BQ5+BU5+BW5 -> #N/A
A6: 人員 | B6: 4 | C6: G7, G6 | D6: =VLOOKUP(D$2&$C6&$A6,集計!$D:$R,$B6,0) -> #N/A | E6: =VLOOKUP(E$2&$C6&$A6,集計!$D:$R,$B6,0) -> #N/A | F6: =VLOOKUP(F$2&$C6&$A6,集計!$D:$R,$B6,0) -> #N/A | G6: =VLOOKUP(G$2&$C6&$A6,集計!$D:$R,$B6,0) -> #N/A | H6: =VLOOKUP(H$2&$C6&$A6,集計!$D:$R,$B6,0) -> #N/A | I6: =D6+E6+F6+G6+H6 -> #N/A | J6: =VLOOKUP(J$2&$C6&$A6,集計!$D:$R,$B6,0) -> #N/A | K6: =VLOOKUP(K$2&$C6&$A6,集計!$D:$R,$B6,0) -> #N/A | L6: =VLOOKUP(L$2&$C6&$A6,集計!$D:$R,$B6,0) -> #N/A | M6: =VLOOKUP(M$2&$C6&$A6,集計!$D:$R,$B6,0) -> #N/A | N6: =J6+K6+L6+M6 -> #N/A | O6: =VLOOKUP(O$2&$C6&$A6,集計!$D:$R,$B6,0) -> #N/A | P6: =VLOOKUP(P$2&$C6&$A6,集計!$D:$R,$B6,0) -> #N/A | Q6: =VLOOKUP(Q$2&$C6&$A6,集計!$D:$R,$B6,0) -> #N/A | R6: =VLOOKUP(R$2&$C6&$A6,集計!$D:$R,$B6,0) -> #N/A | S6: =VLOOKUP(S$2&$C6&$A6,集計!$D:$R,$B6,0) -> #N/A | T6: =O6+P6+Q6+R6+S6 -> #N/A | U6: =VLOOKUP(U$2&$C6&$A6,集計!$D:$R,$B6,0) -> #N/A | V6: =VLOOKUP(V$2&$C6&$A6,集計!$D:$R,$B6,0) -> #N/A | W6: =VLOOKUP(W$2&$C6&$A6,集計!$D:$R,$B6,0) -> #N/A | X6: =U6+V6+W6 -> #N/A | Y6: =VLOOKUP(Y$2&$C6&$A6,集計!$D:$R,$B6,0) -> #N/A | Z6: =VLOOKUP(Z$2&$C6&$A6,集計!$D:$R,$B6,0) -> #N/A | AA6: =VLOOKUP(AA$2&$C6&$A6,集計!$D:$R,$B6,0) -> #N/A | AB6: =Y6+Z6+AA6 -> #N/A | AC6: =I6+N6+T6+X6+AB6 -> #N/A | AD6: =VLOOKUP(AD$2&$C6&$A6,集計!$D:$R,$B6,0) -> #N/A | AE6: =VLOOKUP(AE$2&$C6&$A6,集計!$D:$R,$B6,0) -> #N/A | AF6: =VLOOKUP(AF$2&$C6&$A6,集計!$D:$R,$B6,0) -> #N/A | AG6: =VLOOKUP(AG$2&$C6&$A6,集計!$D:$R,$B6,0) -> #N/A | AH6: =AD6+AE6+AF6+AG6 -> #N/A | AI6: =VLOOKUP(AI$2&$C6&$A6,集計!$D:$R,$B6,0) -> #N/A | AJ6: =VLOOKUP(AJ$2&$C6&$A6,集計!$D:$R,$B6,0) -> #N/A | AK6: =VLOOKUP(AK$2&$C6&$A6,集計!$D:$R,$B6,0) -> #N/A | AL6: =AI6+AJ6+AK6 -> #N/A | AM6: =VLOOKUP(AM$2&$C6&$A6,集計!$D:$R,$B6,0) -> #N/A | AN6: =VLOOKUP(AN$2&$C6&$A6,集計!$D:$R,$B6,0) -> #N/A | AO6: =AM6+AN6 -> #N/A | AP6: =VLOOKUP(AP$2&$C6&$A6,集計!$D:$R,$B6,0) -> #N/A | AQ6: =VLOOKUP(AQ$2&$C6&$A6,集計!$D:$R,$B6,0) -> #N/A | AR6: =VLOOKUP(AR$2&$C6&$A6,集計!$D:$R,$B6,0) -> #N/A | AS6: =AP6+AQ6+AR6 -> #N/A | AT6: =AH6+AL6+AO6+AS6 -> #N/A | AU6: =VLOOKUP(AU$2&$C6&$A6,集計!$D:$R,$B6,0) -> #N/A | AV6: =VLOOKUP(AV$2&$C6&$A6,集計!$D:$R,$B6,0) -> #N/A | AW6: =VLOOKUP(AW$2&$C6&$A6,集計!$D:$R,$B6,0) -> #N/A | AX6: =VLOOKUP(AX$2&$C6&$A6,集計!$D:$R,$B6,0) -> #N/A | AY6: =VLOOKUP(AY$2&$C6&$A6,集計!$D:$R,$B6,0) -> #N/A | AZ6: =AU6+AV6+AW6+AX6+AY6 -> #N/A | BA6: =AZ6 -> #N/A | BB6: =VLOOKUP(BB$2&$C6&$A6,集計!$D:$R,$B6,0) -> #N/A | BC6: =VLOOKUP(BC$2&$C6&$A6,集計!$D:$R,$B6,0) -> #N/A | BD6: =BB6+BC6 -> #N/A | BE6: =VLOOKUP(BE$2&$C6&$A6,集計!$D:$R,$B6,0) -> #N/A | BF6: =VLOOKUP(BF$2&$C6&$A6,集計!$D:$R,$B6,0) -> #N/A | BG6: =VLOOKUP(BG$2&$C6&$A6,集計!$D:$R,$B6,0) -> #N/A | BH6: =VLOOKUP(BH$2&$C6&$A6,集計!$D:$R,$B6,0) -> #N/A | BI6: =VLOOKUP(BI$2&$C6&$A6,集計!$D:$R,$B6,0) -> #N/A | BJ6: =BE6+BF6+BG6+BH6+BI6 -> #N/A | BK6: =VLOOKUP(BK$2&$C6&$A6,集計!$D:$R,$B6,0) -> #N/A | BL6: =VLOOKUP(BL$2&$C6&$A6,集計!$D:$R,$B6,0) -> #N/A | BM6: =VLOOKUP(BM$2&$C6&$A6,集計!$D:$R,$B6,0) -> #N/A | BN6: =VLOOKUP(BN$2&$C6&$A6,集計!$D:$R,$B6,0) -> #N/A | BO6: =VLOOKUP(BO$2&$C6&$A6,集計!$D:$R,$B6,0) -> #N/A | BP6: =VLOOKUP(BP$2&$C6&$A6,集計!$D:$R,$B6,0) -> #N/A | BQ6: =BK6+BL6+BM6+BN6+BO6+BP6 -> #N/A | BR6: =VLOOKUP(BR$2&$C6&$A6,集計!$D:$R,$B6,0) -> #N/A | BS6: =VLOOKUP(BS$2&$C6&$A6,集計!$D:$R,$B6,0) -> #N/A | BT6: =VLOOKUP(BT$2&$C6&$A6,集計!$D:$R,$B6,0) -> #N/A | BU6: =BR6+BS6+BT6 -> #N/A | BV6: =VLOOKUP(BV$2&$C6&$A6,集計!$D:$R,$B6,0) -> #N/A | BW6: =BV6 -> #N/A | BX6: =AC6+AT6+BA6+BD6+BJ6+BQ6+BU6+BW6 -> #N/A
A7: 人員 | B7: 4 | C7: ローカル社員 | D7: =IF(VLOOKUP(D$2&$C7&$A7,集計!$D:$R,$B7,0)<>SUM(D5:D6),"NG",SUM(D5:D6)) -> #N/A | E7: =IF(VLOOKUP(E$2&$C7&$A7,集計!$D:$R,$B7,0)<>SUM(E5:E6),"NG",SUM(E5:E6)) -> #N/A | F7: =IF(VLOOKUP(F$2&$C7&$A7,集計!$D:$R,$B7,0)<>SUM(F5:F6),"NG",SUM(F5:F6)) -> #N/A | G7: =IF(VLOOKUP(G$2&$C7&$A7,集計!$D:$R,$B7,0)<>SUM(G5:G6),"NG",SUM(G5:G6)) -> #N/A | H7: =IF(VLOOKUP(H$2&$C7&$A7,集計!$D:$R,$B7,0)<>SUM(H5:H6),"NG",SUM(H5:H6)) -> #N/A | I7: =I5+I6 -> #N/A | J7: =IF(VLOOKUP(J$2&$C7&$A7,集計!$D:$R,$B7,0)<>SUM(J5:J6),"NG",SUM(J5:J6)) -> #N/A | K7: =IF(VLOOKUP(K$2&$C7&$A7,集計!$D:$R,$B7,0)<>SUM(K5:K6),"NG",SUM(K5:K6)) -> #N/A | L7: =IF(VLOOKUP(L$2&$C7&$A7,集計!$D:$R,$B7,0)<>SUM(L5:L6),"NG",SUM(L5:L6)) -> #N/A | M7: =IF(VLOOKUP(M$2&$C7&$A7,集計!$D:$R,$B7,0)<>SUM(M5:M6),"NG",SUM(M5:M6)) -> #N/A | N7: =N5+N6 -> #N/A | O7: =IF(VLOOKUP(O$2&$C7&$A7,集計!$D:$R,$B7,0)<>SUM(O5:O6),"NG",SUM(O5:O6)) -> #N/A | P7: =IF(VLOOKUP(P$2&$C7&$A7,集計!$D:$R,$B7,0)<>SUM(P5:P6),"NG",SUM(P5:P6)) -> #N/A | Q7: =IF(VLOOKUP(Q$2&$C7&$A7,集計!$D:$R,$B7,0)<>SUM(Q5:Q6),"NG",SUM(Q5:Q6)) -> #N/A | R7: =IF(VLOOKUP(R$2&$C7&$A7,集計!$D:$R,$B7,0)<>SUM(R5:R6),"NG",SUM(R5:R6)) -> #N/A | S7: =IF(VLOOKUP(S$2&$C7&$A7,集計!$D:$R,$B7,0)<>SUM(S5:S6),"NG",SUM(S5:S6)) -> #N/A | T7: =T5+T6 -> #N/A | U7: =IF(VLOOKUP(U$2&$C7&$A7,集計!$D:$R,$B7,0)<>SUM(U5:U6),"NG",SUM(U5:U6)) -> #N/A | V7: =IF(VLOOKUP(V$2&$C7&$A7,集計!$D:$R,$B7,0)<>SUM(V5:V6),"NG",SUM(V5:V6)) -> #N/A | W7: =IF(VLOOKUP(W$2&$C7&$A7,集計!$D:$R,$B7,0)<>SUM(W5:W6),"NG",SUM(W5:W6)) -> #N/A | X7: =SUM(X5:X6) -> #N/A | Y7: =IF(VLOOKUP(Y$2&$C7&$A7,集計!$D:$R,$B7,0)<>SUM(Y5:Y6),"NG",SUM(Y5:Y6)) -> #N/A | Z7: =IF(VLOOKUP(Z$2&$C7&$A7,集計!$D:$R,$B7,0)<>SUM(Z5:Z6),"NG",SUM(Z5:Z6)) -> #N/A | AA7: =IF(VLOOKUP(AA$2&$C7&$A7,集計!$D:$R,$B7,0)<>SUM(AA5:AA6),"NG",SUM(AA5:AA6)) -> #N/A | AB7: =SUM(AB5:AB6) -> #N/A | AC7: =SUM(AC5:AC6) -> #N/A | AD7: =IF(VLOOKUP(AD$2&$C7&$A7,集計!$D:$R,$B7,0)<>SUM(AD5:AD6),"NG",SUM(AD5:AD6)) -> #N/A | AE7: =IF(VLOOKUP(AE$2&$C7&$A7,集計!$D:$R,$B7,0)<>SUM(AE5:AE6),"NG",SUM(AE5:AE6)) -> #N/A | AF7: =IF(VLOOKUP(AF$2&$C7&$A7,集計!$D:$R,$B7,0)<>SUM(AF5:AF6),"NG",SUM(AF5:AF6)) -> #N/A | AG7: =IF(VLOOKUP(AG$2&$C7&$A7,集計!$D:$R,$B7,0)<>SUM(AG5:AG6),"NG",SUM(AG5:AG6)) -> #N/A | AH7: =SUM(AH5:AH6) -> #N/A | AI7: =IF(VLOOKUP(AI$2&$C7&$A7,集計!$D:$R,$B7,0)<>SUM(AI5:AI6),"NG",SUM(AI5:AI6)) -> #N/A | AJ7: =IF(VLOOKUP(AJ$2&$C7&$A7,集計!$D:$R,$B7,0)<>SUM(AJ5:AJ6),"NG",SUM(AJ5:AJ6)) -> #N/A | AK7: =IF(VLOOKUP(AK$2&$C7&$A7,集計!$D:$R,$B7,0)<>SUM(AK5:AK6),"NG",SUM(AK5:AK6)) -> #N/A | AL7: =SUM(AL5:AL6) -> #N/A | AM7: =IF(VLOOKUP(AM$2&$C7&$A7,集計!$D:$R,$B7,0)<>SUM(AM5:AM6),"NG",SUM(AM5:AM6)) -> #N/A | AN7: =IF(VLOOKUP(AN$2&$C7&$A7,集計!$D:$R,$B7,0)<>SUM(AN5:AN6),"NG",SUM(AN5:AN6)) -> #N/A | AO7: =SUM(AO5:AO6) -> #N/A | AP7: =IF(VLOOKUP(AP$2&$C7&$A7,集計!$D:$R,$B7,0)<>SUM(AP5:AP6),"NG",SUM(AP5:AP6)) -> #N/A | AQ7: =IF(VLOOKUP(AQ$2&$C7&$A7,集計!$D:$R,$B7,0)<>SUM(AQ5:AQ6),"NG",SUM(AQ5:AQ6)) -> #N/A | AR7: =IF(VLOOKUP(AR$2&$C7&$A7,集計!$D:$R,$B7,0)<>SUM(AR5:AR6),"NG",SUM(AR5:AR6)) -> #N/A | AS7: =SUM(AS5:AS6) -> #N/A | AT7: =SUM(AT5:AT6) -> #N/A | AU7: =IF(VLOOKUP(AU$2&$C7&$A7,集計!$D:$R,$B7,0)<>SUM(AU5:AU6),"NG",SUM(AU5:AU6)) -> #N/A | AV7: =IF(VLOOKUP(AV$2&$C7&$A7,集計!$D:$R,$B7,0)<>SUM(AV5:AV6),"NG",SUM(AV5:AV6)) -> #N/A | AW7: =IF(VLOOKUP(AW$2&$C7&$A7,集計!$D:$R,$B7,0)<>SUM(AW5:AW6),"NG",SUM(AW5:AW6)) -> #N/A | AX7: =IF(VLOOKUP(AX$2&$C7&$A7,集計!$D:$R,$B7,0)<>SUM(AX5:AX6),"NG",SUM(AX5:AX6)) -> #N/A | AY7: =IF(VLOOKUP(AY$2&$C7&$A7,集計!$D:$R,$B7,0)<>SUM(AY5:AY6),"NG",SUM(AY5:AY6)) -> #N/A | AZ7: =AZ5+AZ6 -> #N/A | BA7: =BA5+BA6 -> #N/A | BB7: =IF(VLOOKUP(BB$2&$C7&$A7,集計!$D:$R,$B7,0)<>SUM(BB5:BB6),"NG",SUM(BB5:BB6)) -> #N/A | BC7: =IF(VLOOKUP(BC$2&$C7&$A7,集計!$D:$R,$B7,0)<>SUM(BC5:BC6),"NG",SUM(BC5:BC6)) -> #N/A | BD7: =SUM(BD5:BD6) -> #N/A | BE7: =IF(VLOOKUP(BE$2&$C7&$A7,集計!$D:$R,$B7,0)<>SUM(BE5:BE6),"NG",SUM(BE5:BE6)) -> #N/A | BF7: =IF(VLOOKUP(BF$2&$C7&$A7,集計!$D:$R,$B7,0)<>SUM(BF5:BF6),"NG",SUM(BF5:BF6)) -> #N/A | BG7: =IF(VLOOKUP(BG$2&$C7&$A7,集計!$D:$R,$B7,0)<>SUM(BG5:BG6),"NG",SUM(BG5:BG6)) -> #N/A | BH7: =IF(VLOOKUP(BH$2&$C7&$A7,集計!$D:$R,$B7,0)<>SUM(BH5:BH6),"NG",SUM(BH5:BH6)) -> #N/A | BI7: =IF(VLOOKUP(BI$2&$C7&$A7,集計!$D:$R,$B7,0)<>SUM(BI5:BI6),"NG",SUM(BI5:BI6)) -> #N/A | BJ7: =BJ5+BJ6 -> #N/A | BK7: =IF(VLOOKUP(BK$2&$C7&$A7,集計!$D:$R,$B7,0)<>SUM(BK5:BK6),"NG",SUM(BK5:BK6)) -> #N/A | BL7: =IF(VLOOKUP(BL$2&$C7&$A7,集計!$D:$R,$B7,0)<>SUM(BL5:BL6),"NG",SUM(BL5:BL6)) -> #N/A | BM7: =IF(VLOOKUP(BM$2&$C7&$A7,集計!$D:$R,$B7,0)<>SUM(BM5:BM6),"NG",SUM(BM5:BM6)) -> #N/A | BN7: =IF(VLOOKUP(BN$2&$C7&$A7,集計!$D:$R,$B7,0)<>SUM(BN5:BN6),"NG",SUM(BN5:BN6)) -> #N/A | BO7: =IF(VLOOKUP(BO$2&$C7&$A7,集計!$D:$R,$B7,0)<>SUM(BO5:BO6),"NG",SUM(BO5:BO6)) -> #N/A | BP7: =IF(VLOOKUP(BP$2&$C7&$A7,集計!$D:$R,$B7,0)<>SUM(BP5:BP6),"NG",SUM(BP5:BP6)) -> #N/A | BQ7: =BQ5+BQ6 -> #N/A | BR7: =IF(VLOOKUP(BR$2&$C7&$A7,集計!$D:$R,$B7,0)<>SUM(BR5:BR6),"NG",SUM(BR5:BR6)) -> #N/A | BS7: =IF(VLOOKUP(BS$2&$C7&$A7,集計!$D:$R,$B7,0)<>SUM(BS5:BS6),"NG",SUM(BS5:BS6)) -> #N/A | BT7: =IF(VLOOKUP(BT$2&$C7&$A7,集計!$D:$R,$B7,0)<>SUM(BT5:BT6),"NG",SUM(BT5:BT6)) -> #N/A | BU7: =BU5+BU6 -> #N/A | BV7: =IF(VLOOKUP(BV$2&$C7&$A7,集計!$D:$R,$B7,0)<>SUM(BV5:BV6),"NG",SUM(BV5:BV6)) -> #N/A | BW7: =SUM(BW5:BW6) -> #N/A | BX7: =SUM(BX5:BX6) -> #N/A
A8: 人員 | B8: 4 | C8: 人員合計 | D8: =IF(VLOOKUP(D$2&$C8&$A8,集計!$D:$R,$B8,0)<>SUM(D4,D7),"NG",SUM(D4,D7)) -> #N/A | E8: =IF(VLOOKUP(E$2&$C8&$A8,集計!$D:$R,$B8,0)<>SUM(E4,E7),"NG",SUM(E4,E7)) -> #N/A | F8: =IF(VLOOKUP(F$2&$C8&$A8,集計!$D:$R,$B8,0)<>SUM(F4,F7),"NG",SUM(F4,F7)) -> #N/A | G8: =IF(VLOOKUP(G$2&$C8&$A8,集計!$D:$R,$B8,0)<>SUM(G4,G7),"NG",SUM(G4,G7)) -> #N/A | H8: =IF(VLOOKUP(H$2&$C8&$A8,集計!$D:$R,$B8,0)<>SUM(H4,H7),"NG",SUM(H4,H7)) -> #N/A | I8: =I4+I7 -> #N/A | J8: =IF(VLOOKUP(J$2&$C8&$A8,集計!$D:$R,$B8,0)<>SUM(J4,J7),"NG",SUM(J4,J7)) -> #N/A | K8: =IF(VLOOKUP(K$2&$C8&$A8,集計!$D:$R,$B8,0)<>SUM(K4,K7),"NG",SUM(K4,K7)) -> #N/A | L8: =IF(VLOOKUP(L$2&$C8&$A8,集計!$D:$R,$B8,0)<>SUM(L4,L7),"NG",SUM(L4,L7)) -> #N/A | M8: =IF(VLOOKUP(M$2&$C8&$A8,集計!$D:$R,$B8,0)<>SUM(M4,M7),"NG",SUM(M4,M7)) -> #N/A | N8: =N4+N7 -> #N/A | O8: =IF(VLOOKUP(O$2&$C8&$A8,集計!$D:$R,$B8,0)<>SUM(O4,O7),"NG",SUM(O4,O7)) -> #N/A | P8: =IF(VLOOKUP(P$2&$C8&$A8,集計!$D:$R,$B8,0)<>SUM(P4,P7),"NG",SUM(P4,P7)) -> #N/A | Q8: =IF(VLOOKUP(Q$2&$C8&$A8,集計!$D:$R,$B8,0)<>SUM(Q4,Q7),"NG",SUM(Q4,Q7)) -> #N/A | R8: =IF(VLOOKUP(R$2&$C8&$A8,集計!$D:$R,$B8,0)<>SUM(R4,R7),"NG",SUM(R4,R7)) -> #N/A | S8: =IF(VLOOKUP(S$2&$C8&$A8,集計!$D:$R,$B8,0)<>SUM(S4,S7),"NG",SUM(S4,S7)) -> #N/A | T8: =T4+T7 -> #N/A | U8: =IF(VLOOKUP(U$2&$C8&$A8,集計!$D:$R,$B8,0)<>SUM(U4,U7),"NG",SUM(U4,U7)) -> #N/A | V8: =IF(VLOOKUP(V$2&$C8&$A8,集計!$D:$R,$B8,0)<>SUM(V4,V7),"NG",SUM(V4,V7)) -> #N/A | W8: =IF(VLOOKUP(W$2&$C8&$A8,集計!$D:$R,$B8,0)<>SUM(W4,W7),"NG",SUM(W4,W7)) -> #N/A | X8: =X4+X7 -> #N/A | Y8: =IF(VLOOKUP(Y$2&$C8&$A8,集計!$D:$R,$B8,0)<>SUM(Y4,Y7),"NG",SUM(Y4,Y7)) -> #N/A | Z8: =IF(VLOOKUP(Z$2&$C8&$A8,集計!$D:$R,$B8,0)<>SUM(Z4,Z7),"NG",SUM(Z4,Z7)) -> #N/A | AA8: =IF(VLOOKUP(AA$2&$C8&$A8,集計!$D:$R,$B8,0)<>SUM(AA4,AA7),"NG",SUM(AA4,AA7)) -> #N/A | AB8: =AB4+AB7 -> #N/A | AC8: =AC4+AC7 -> #N/A | AD8: =IF(VLOOKUP(AD$2&$C8&$A8,集計!$D:$R,$B8,0)<>SUM(AD4,AD7),"NG",SUM(AD4,AD7)) -> #N/A | AE8: =IF(VLOOKUP(AE$2&$C8&$A8,集計!$D:$R,$B8,0)<>SUM(AE4,AE7),"NG",SUM(AE4,AE7)) -> #N/A | AF8: =IF(VLOOKUP(AF$2&$C8&$A8,集計!$D:$R,$B8,0)<>SUM(AF4,AF7),"NG",SUM(AF4,AF7)) -> #N/A | AG8: =IF(VLOOKUP(AG$2&$C8&$A8,集計!$D:$R,$B8,0)<>SUM(AG4,AG7),"NG",SUM(AG4,AG7)) -> #N/A | AH8: =AH4+AH7 -> #N/A | AI8: =IF(VLOOKUP(AI$2&$C8&$A8,集計!$D:$R,$B8,0)<>SUM(AI4,AI7),"NG",SUM(AI4,AI7)) -> #N/A | AJ8: =IF(VLOOKUP(AJ$2&$C8&$A8,集計!$D:$R,$B8,0)<>SUM(AJ4,AJ7),"NG",SUM(AJ4,AJ7)) -> #N/A | AK8: =IF(VLOOKUP(AK$2&$C8&$A8,集計!$D:$R,$B8,0)<>SUM(AK4,AK7),"NG",SUM(AK4,AK7)) -> #N/A | AL8: =AL4+AL7 -> #N/A | AM8: =IF(VLOOKUP(AM$2&$C8&$A8,集計!$D:$R,$B8,0)<>SUM(AM4,AM7),"NG",SUM(AM4,AM7)) -> #N/A | AN8: =IF(VLOOKUP(AN$2&$C8&$A8,集計!$D:$R,$B8,0)<>SUM(AN4,AN7),"NG",SUM(AN4,AN7)) -> #N/A | AO8: =AO4+AO7 -> #N/A | AP8: =IF(VLOOKUP(AP$2&$C8&$A8,集計!$D:$R,$B8,0)<>SUM(AP4,AP7),"NG",SUM(AP4,AP7)) -> #N/A | AQ8: =IF(VLOOKUP(AQ$2&$C8&$A8,集計!$D:$R,$B8,0)<>SUM(AQ4,AQ7),"NG",SUM(AQ4,AQ7)) -> #N/A | AR8: =IF(VLOOKUP(AR$2&$C8&$A8,集計!$D:$R,$B8,0)<>SUM(AR4,AR7),"NG",SUM(AR4,AR7)) -> #N/A | AS8: =AS4+AS7 -> #N/A | AT8: =AT4+AT7 -> #N/A | AU8: =IF(VLOOKUP(AU$2&$C8&$A8,集計!$D:$R,$B8,0)<>SUM(AU4,AU7),"NG",SUM(AU4,AU7)) -> #N/A | AV8: =IF(VLOOKUP(AV$2&$C8&$A8,集計!$D:$R,$B8,0)<>SUM(AV4,AV7),"NG",SUM(AV4,AV7)) -> #N/A | AW8: =IF(VLOOKUP(AW$2&$C8&$A8,集計!$D:$R,$B8,0)<>SUM(AW4,AW7),"NG",SUM(AW4,AW7)) -> #N/A | AX8: =IF(VLOOKUP(AX$2&$C8&$A8,集計!$D:$R,$B8,0)<>SUM(AX4,AX7),"NG",SUM(AX4,AX7)) -> #N/A | AY8: =IF(VLOOKUP(AY$2&$C8&$A8,集計!$D:$R,$B8,0)<>SUM(AY4,AY7),"NG",SUM(AY4,AY7)) -> #N/A | AZ8: =AZ4+AZ7 -> #N/A | BA8: =BA4+BA7 -> #N/A | BB8: =IF(VLOOKUP(BB$2&$C8&$A8,集計!$D:$R,$B8,0)<>SUM(BB4,BB7),"NG",SUM(BB4,BB7)) -> #N/A | BC8: =IF(VLOOKUP(BC$2&$C8&$A8,集計!$D:$R,$B8,0)<>SUM(BC4,BC7),"NG",SUM(BC4,BC7)) -> #N/A | BD8: =BD4+BD7 -> #N/A | BE8: =IF(VLOOKUP(BE$2&$C8&$A8,集計!$D:$R,$B8,0)<>SUM(BE4,BE7),"NG",SUM(BE4,BE7)) -> #N/A | BF8: =IF(VLOOKUP(BF$2&$C8&$A8,集計!$D:$R,$B8,0)<>SUM(BF4,BF7),"NG",SUM(BF4,BF7)) -> #N/A | BG8: =IF(VLOOKUP(BG$2&$C8&$A8,集計!$D:$R,$B8,0)<>SUM(BG4,BG7),"NG",SUM(BG4,BG7)) -> #N/A | BH8: =IF(VLOOKUP(BH$2&$C8&$A8,集計!$D:$R,$B8,0)<>SUM(BH4,BH7),"NG",SUM(BH4,BH7)) -> #N/A | BI8: =IF(VLOOKUP(BI$2&$C8&$A8,集計!$D:$R,$B8,0)<>SUM(BI4,BI7),"NG",SUM(BI4,BI7)) -> #N/A | BJ8: =BJ4+BJ7 -> #N/A | BK8: =IF(VLOOKUP(BK$2&$C8&$A8,集計!$D:$R,$B8,0)<>SUM(BK4,BK7),"NG",SUM(BK4,BK7)) -> #N/A | BL8: =IF(VLOOKUP(BL$2&$C8&$A8,集計!$D:$R,$B8,0)<>SUM(BL4,BL7),"NG",SUM(BL4,BL7)) -> #N/A | BM8: =IF(VLOOKUP(BM$2&$C8&$A8,集計!$D:$R,$B8,0)<>SUM(BM4,BM7),"NG",SUM(BM4,BM7)) -> #N/A | BN8: =IF(VLOOKUP(BN$2&$C8&$A8,集計!$D:$R,$B8,0)<>SUM(BN4,BN7),"NG",SUM(BN4,BN7)) -> #N/A | BO8: =IF(VLOOKUP(BO$2&$C8&$A8,集計!$D:$R,$B8,0)<>SUM(BO4,BO7),"NG",SUM(BO4,BO7)) -> #N/A | BP8: =IF(VLOOKUP(BP$2&$C8&$A8,集計!$D:$R,$B8,0)<>SUM(BP4,BP7),"NG",SUM(BP4,BP7)) -> #N/A | BQ8: =BQ4+BQ7 -> #N/A | BR8: =IF(VLOOKUP(BR$2&$C8&$A8,集計!$D:$R,$B8,0)<>SUM(BR4,BR7),"NG",SUM(BR4,BR7)) -> #N/A | BS8: =IF(VLOOKUP(BS$2&$C8&$A8,集計!$D:$R,$B8,0)<>SUM(BS4,BS7),"NG",SUM(BS4,BS7)) -> #N/A | BT8: =IF(VLOOKUP(BT$2&$C8&$A8,集計!$D:$R,$B8,0)<>SUM(BT4,BT7),"NG",SUM(BT4,BT7)) -> #N/A | BU8: =BU4+BU7 -> #N/A | BV8: =IF(VLOOKUP(BV$2&$C8&$A8,集計!$D:$R,$B8,0)<>SUM(BV4,BV7),"NG",SUM(BV4,BV7)) -> #N/A | BW8: =BW4+BW7 -> #N/A | BX8: =BX4+BX7 -> #N/A
B10: 5 | C10: 人員
A11: 人員 | B11: 5 | C11: 出向社員 | D11: =VLOOKUP(D$2&$C11&$A11,集計!$D:$R,$B11,0) -> #N/A | E11: =VLOOKUP(E$2&$C11&$A11,集計!$D:$R,$B11,0) -> #N/A | F11: =VLOOKUP(F$2&$C11&$A11,集計!$D:$R,$B11,0) -> #N/A | G11: =VLOOKUP(G$2&$C11&$A11,集計!$D:$R,$B11,0) -> #N/A | H11: =VLOOKUP(H$2&$C11&$A11,集計!$D:$R,$B11,0) -> #N/A | I11: =D11+E11+F11+G11+H11 -> #N/A | J11: =VLOOKUP(J$2&$C11&$A11,集計!$D:$R,$B11,0) -> #N/A | K11: =VLOOKUP(K$2&$C11&$A11,集計!$D:$R,$B11,0) -> #N/A | L11: =VLOOKUP(L$2&$C11&$A11,集計!$D:$R,$B11,0) -> #N/A | M11: =VLOOKUP(M$2&$C11&$A11,集計!$D:$R,$B11,0) -> #N/A | N11: =J11+K11+L11+M11 -> #N/A | O11: =VLOOKUP(O$2&$C11&$A11,集計!$D:$R,$B11,0) -> #N/A | P11: =VLOOKUP(P$2&$C11&$A11,集計!$D:$R,$B11,0) -> #N/A | Q11: =VLOOKUP(Q$2&$C11&$A11,集計!$D:$R,$B11,0) -> #N/A | R11: =VLOOKUP(R$2&$C11&$A11,集計!$D:$R,$B11,0) -> #N/A | S11: =VLOOKUP(S$2&$C11&$A11,集計!$D:$R,$B11,0) -> #N/A | T11: =O11+P11+Q11+R11+S11 -> #N/A | U11: =VLOOKUP(U$2&$C11&$A11,集計!$D:$R,$B11,0) -> #N/A | V11: =VLOOKUP(V$2&$C11&$A11,集計!$D:$R,$B11,0) -> #N/A | W11: =VLOOKUP(W$2&$C11&$A11,集計!$D:$R,$B11,0) -> #N/A | X11: =U11+V11+W11 -> #N/A | Y11: =VLOOKUP(Y$2&$C11&$A11,集計!$D:$R,$B11,0) -> #N/A | Z11: =VLOOKUP(Z$2&$C11&$A11,集計!$D:$R,$B11,0) -> #N/A | AA11: =VLOOKUP(AA$2&$C11&$A11,集計!$D:$R,$B11,0) -> #N/A | AB11: =Y11+Z11+AA11 -> #N/A | AC11: =I11+N11+T11+X11+AB11 -> #N/A | AD11: =VLOOKUP(AD$2&$C11&$A11,集計!$D:$R,$B11,0) -> #N/A | AE11: =VLOOKUP(AE$2&$C11&$A11,集計!$D:$R,$B11,0) -> #N/A | AF11: =VLOOKUP(AF$2&$C11&$A11,集計!$D:$R,$B11,0) -> #N/A | AG11: =VLOOKUP(AG$2&$C11&$A11,集計!$D:$R,$B11,0) -> #N/A | AH11: =AD11+AE11+AF11+AG11 -> #N/A | AI11: =VLOOKUP(AI$2&$C11&$A11,集計!$D:$R,$B11,0) -> #N/A | AJ11: =VLOOKUP(AJ$2&$C11&$A11,集計!$D:$R,$B11,0) -> #N/A | AK11: =VLOOKUP(AK$2&$C11&$A11,集計!$D:$R,$B11,0) -> #N/A | AL11: =AI11+AJ11+AK11 -> #N/A | AM11: =VLOOKUP(AM$2&$C11&$A11,集計!$D:$R,$B11,0) -> #N/A | AN11: =VLOOKUP(AN$2&$C11&$A11,集計!$D:$R,$B11,0) -> #N/A | AO11: =AM11+AN11 -> #N/A | AP11: =VLOOKUP(AP$2&$C11&$A11,集計!$D:$R,$B11,0) -> #N/A | AQ11: =VLOOKUP(AQ$2&$C11&$A11,集計!$D:$R,$B11,0) -> #N/A | AR11: =VLOOKUP(AR$2&$C11&$A11,集計!$D:$R,$B11,0) -> #N/A | AS11: =AP11+AQ11+AR11 -> #N/A | AT11: =AH11+AL11+AO11+AS11 -> #N/A | AU11: =VLOOKUP(AU$2&$C11&$A11,集計!$D:$R,$B11,0) -> #N/A | AV11: =VLOOKUP(AV$2&$C11&$A11,集計!$D:$R,$B11,0) -> #N/A | AW11: =VLOOKUP(AW$2&$C11&$A11,集計!$D:$R,$B11,0) -> #N/A | AX11: =VLOOKUP(AX$2&$C11&$A11,集計!$D:$R,$B11,0) -> #N/A | AY11: =VLOOKUP(AY$2&$C11&$A11,集計!$D:$R,$B11,0) -> #N/A | AZ11: =AU11+AV11+AW11+AX11+AY11 -> #N/A | BA11: =AZ11 -> #N/A | BB11: =VLOOKUP(BB$2&$C11&$A11,集計!$D:$R,$B11,0) -> #N/A | BC11: =VLOOKUP(BC$2&$C11&$A11,集計!$D:$R,$B11,0) -> #N/A | BD11: =BB11+BC11 -> #N/A | BE11: =VLOOKUP(BE$2&$C11&$A11,集計!$D:$R,$B11,0) -> #N/A | BF11: =VLOOKUP(BF$2&$C11&$A11,集計!$D:$R,$B11,0) -> #N/A | BG11: =VLOOKUP(BG$2&$C11&$A11,集計!$D:$R,$B11,0) -> #N/A | BH11: =VLOOKUP(BH$2&$C11&$A11,集計!$D:$R,$B11,0) -> #N/A | BI11: =VLOOKUP(BI$2&$C11&$A11,集計!$D:$R,$B11,0) -> #N/A | BJ11: =BE11+BF11+BG11+BH11+BI11 -> #N/A | BK11: =VLOOKUP(BK$2&$C11&$A11,集計!$D:$R,$B11,0) -> #N/A | BL11: =VLOOKUP(BL$2&$C11&$A11,集計!$D:$R,$B11,0) -> #N/A | BM11: =VLOOKUP(BM$2&$C11&$A11,集計!$D:$R,$B11,0) -> #N/A | BN11: =VLOOKUP(BN$2&$C11&$A11,集計!$D:$R,$B11,0) -> #N/A | BO11: =VLOOKUP(BO$2&$C11&$A11,集計!$D:$R,$B11,0) -> #N/A | BP11: =VLOOKUP(BP$2&$C11&$A11,集計!$D:$R,$B11,0) -> #N/A | BQ11: =BK11+BL11+BM11+BN11+BO11+BP11 -> #N/A | BR11: =VLOOKUP(BR$2&$C11&$A11,集計!$D:$R,$B11,0) -> #N/A | BS11: =VLOOKUP(BS$2&$C11&$A11,集計!$D:$R,$B11,0) -> #N/A | BT11: =VLOOKUP(BT$2&$C11&$A11,集計!$D:$R,$B11,0) -> #N/A | BU11: =BR11+BS11+BT11 -> #N/A | BV11: =VLOOKUP(BV$2&$C11&$A11,集計!$D:$R,$B11,0) -> #N/A | BW11: =BV11 -> #N/A | BX11: =AC11+AT11+BA11+BD11+BJ11+BQ11+BU11+BW11 -> #N/A
A12: 人員 | B12: 5 | C12: G5以上 | D12: =VLOOKUP(D$2&$C12&$A12,集計!$D:$R,$B12,0) -> #N/A | E12: =VLOOKUP(E$2&$C12&$A12,集計!$D:$R,$B12,0) -> #N/A | F12: =VLOOKUP(F$2&$C12&$A12,集計!$D:$R,$B12,0) -> #N/A | G12: =VLOOKUP(G$2&$C12&$A12,集計!$D:$R,$B12,0) -> #N/A | H12: =VLOOKUP(H$2&$C12&$A12,集計!$D:$R,$B12,0) -> #N/A | I12: =D12+E12+F12+G12+H12 -> #N/A | J12: =VLOOKUP(J$2&$C12&$A12,集計!$D:$R,$B12,0) -> #N/A | K12: =VLOOKUP(K$2&$C12&$A12,集計!$D:$R,$B12,0) -> #N/A | L12: =VLOOKUP(L$2&$C12&$A12,集計!$D:$R,$B12,0) -> #N/A | M12: =VLOOKUP(M$2&$C12&$A12,集計!$D:$R,$B12,0) -> #N/A | N12: =J12+K12+L12+M12 -> #N/A | O12: =VLOOKUP(O$2&$C12&$A12,集計!$D:$R,$B12,0) -> #N/A | P12: =VLOOKUP(P$2&$C12&$A12,集計!$D:$R,$B12,0) -> #N/A | Q12: =VLOOKUP(Q$2&$C12&$A12,集計!$D:$R,$B12,0) -> #N/A | R12: =VLOOKUP(R$2&$C12&$A12,集計!$D:$R,$B12,0) -> #N/A | S12: =VLOOKUP(S$2&$C12&$A12,集計!$D:$R,$B12,0) -> #N/A | T12: =O12+P12+Q12+R12+S12 -> #N/A | U12: =VLOOKUP(U$2&$C12&$A12,集計!$D:$R,$B12,0) -> #N/A | V12: =VLOOKUP(V$2&$C12&$A12,集計!$D:$R,$B12,0) -> #N/A | W12: =VLOOKUP(W$2&$C12&$A12,集計!$D:$R,$B12,0) -> #N/A | X12: =U12+V12+W12 -> #N/A | Y12: =VLOOKUP(Y$2&$C12&$A12,集計!$D:$R,$B12,0) -> #N/A | Z12: =VLOOKUP(Z$2&$C12&$A12,集計!$D:$R,$B12,0) -> #N/A | AA12: =VLOOKUP(AA$2&$C12&$A12,集計!$D:$R,$B12,0) -> #N/A | AB12: =Y12+Z12+AA12 -> #N/A | AC12: =I12+N12+T12+X12+AB12 -> #N/A | AD12: =VLOOKUP(AD$2&$C12&$A12,集計!$D:$R,$B12,0) -> #N/A | AE12: =VLOOKUP(AE$2&$C12&$A12,集計!$D:$R,$B12,0) -> #N/A | AF12: =VLOOKUP(AF$2&$C12&$A12,集計!$D:$R,$B12,0) -> #N/A | AG12: =VLOOKUP(AG$2&$C12&$A12,集計!$D:$R,$B12,0) -> #N/A | AH12: =AD12+AE12+AF12+AG12 -> #N/A | AI12: =VLOOKUP(AI$2&$C12&$A12,集計!$D:$R,$B12,0) -> #N/A | AJ12: =VLOOKUP(AJ$2&$C12&$A12,集計!$D:$R,$B12,0) -> #N/A | AK12: =VLOOKUP(AK$2&$C12&$A12,集計!$D:$R,$B12,0) -> #N/A | AL12: =AI12+AJ12+AK12 -> #N/A | AM12: =VLOOKUP(AM$2&$C12&$A12,集計!$D:$R,$B12,0) -> #N/A | AN12: =VLOOKUP(AN$2&$C12&$A12,集計!$D:$R,$B12,0) -> #N/A | AO12: =AM12+AN12 -> #N/A | AP12: =VLOOKUP(AP$2&$C12&$A12,集計!$D:$R,$B12,0) -> #N/A | AQ12: =VLOOKUP(AQ$2&$C12&$A12,集計!$D:$R,$B12,0) -> #N/A | AR12: =VLOOKUP(AR$2&$C12&$A12,集計!$D:$R,$B12,0) -> #N/A | AS12: =AP12+AQ12+AR12 -> #N/A | AT12: =AH12+AL12+AO12+AS12 -> #N/A | AU12: =VLOOKUP(AU$2&$C12&$A12,集計!$D:$R,$B12,0) -> #N/A | AV12: =VLOOKUP(AV$2&$C12&$A12,集計!$D:$R,$B12,0) -> #N/A | AW12: =VLOOKUP(AW$2&$C12&$A12,集計!$D:$R,$B12,0) -> #N/A | AX12: =VLOOKUP(AX$2&$C12&$A12,集計!$D:$R,$B12,0) -> #N/A | AY12: =VLOOKUP(AY$2&$C12&$A12,集計!$D:$R,$B12,0) -> #N/A | AZ12: =AU12+AV12+AW12+AX12+AY12 -> #N/A | BA12: =AZ12 -> #N/A | BB12: =VLOOKUP(BB$2&$C12&$A12,集計!$D:$R,$B12,0) -> #N/A | BC12: =VLOOKUP(BC$2&$C12&$A12,集計!$D:$R,$B12,0) -> #N/A | BD12: =BB12+BC12 -> #N/A | BE12: =VLOOKUP(BE$2&$C12&$A12,集計!$D:$R,$B12,0) -> #N/A | BF12: =VLOOKUP(BF$2&$C12&$A12,集計!$D:$R,$B12,0) -> #N/A | BG12: =VLOOKUP(BG$2&$C12&$A12,集計!$D:$R,$B12,0) -> #N/A | BH12: =VLOOKUP(BH$2&$C12&$A12,集計!$D:$R,$B12,0) -> #N/A | BI12: =VLOOKUP(BI$2&$C12&$A12,集計!$D:$R,$B12,0) -> #N/A | BJ12: =BE12+BF12+BG12+BH12+BI12 -> #N/A | BK12: =VLOOKUP(BK$2&$C12&$A12,集計!$D:$R,$B12,0) -> #N/A | BL12: =VLOOKUP(BL$2&$C12&$A12,集計!$D:$R,$B12,0) -> #N/A | BM12: =VLOOKUP(BM$2&$C12&$A12,集計!$D:$R,$B12,0) -> #N/A | BN12: =VLOOKUP(BN$2&$C12&$A12,集計!$D:$R,$B12,0) -> #N/A | BO12: =VLOOKUP(BO$2&$C12&$A12,集計!$D:$R,$B12,0) -> #N/A | BP12: =VLOOKUP(BP$2&$C12&$A12,集計!$D:$R,$B12,0) -> #N/A | BQ12: =BK12+BL12+BM12+BN12+BO12+BP12 -> #N/A | BR12: =VLOOKUP(BR$2&$C12&$A12,集計!$D:$R,$B12,0) -> #N/A | BS12: =VLOOKUP(BS$2&$C12&$A12,集計!$D:$R,$B12,0) -> #N/A | BT12: =VLOOKUP(BT$2&$C12&$A12,集計!$D:$R,$B12,0) -> #N/A | BU12: =BR12+BS12+BT12 -> #N/A | BV12: =VLOOKUP(BV$2&$C12&$A12,集計!$D:$R,$B12,0) -> #N/A | BW12: =BV12 -> #N/A | BX12: =AC12+AT12+BA12+BD12+BJ12+BQ12+BU12+BW12 -> #N/A
A13: 人員 | B13: 5 | C13: G7, G6 | D13: =VLOOKUP(D$2&$C13&$A13,集計!$D:$R,$B13,0) -> #N/A | E13: =VLOOKUP(E$2&$C13&$A13,集計!$D:$R,$B13,0) -> #N/A | F13: =VLOOKUP(F$2&$C13&$A13,集計!$D:$R,$B13,0) -> #N/A | G13: =VLOOKUP(G$2&$C13&$A13,集計!$D:$R,$B13,0) -> #N/A | H13: =VLOOKUP(H$2&$C13&$A13,集計!$D:$R,$B13,0) -> #N/A | I13: =D13+E13+F13+G13+H13 -> #N/A | J13: =VLOOKUP(J$2&$C13&$A13,集計!$D:$R,$B13,0) -> #N/A | K13: =VLOOKUP(K$2&$C13&$A13,集計!$D:$R,$B13,0) -> #N/A | L13: =VLOOKUP(L$2&$C13&$A13,集計!$D:$R,$B13,0) -> #N/A | M13: =VLOOKUP(M$2&$C13&$A13,集計!$D:$R,$B13,0) -> #N/A | N13: =J13+K13+L13+M13 -> #N/A | O13: =VLOOKUP(O$2&$C13&$A13,集計!$D:$R,$B13,0) -> #N/A | P13: =VLOOKUP(P$2&$C13&$A13,集計!$D:$R,$B13,0) -> #N/A | Q13: =VLOOKUP(Q$2&$C13&$A13,集計!$D:$R,$B13,0) -> #N/A | R13: =VLOOKUP(R$2&$C13&$A13,集計!$D:$R,$B13,0) -> #N/A | S13: =VLOOKUP(S$2&$C13&$A13,集計!$D:$R,$B13,0) -> #N/A | T13: =O13+P13+Q13+R13+S13 -> #N/A | U13: =VLOOKUP(U$2&$C13&$A13,集計!$D:$R,$B13,0) -> #N/A | V13: =VLOOKUP(V$2&$C13&$A13,集計!$D:$R,$B13,0) -> #N/A | W13: =VLOOKUP(W$2&$C13&$A13,集計!$D:$R,$B13,0) -> #N/A | X13: =U13+V13+W13 -> #N/A | Y13: =VLOOKUP(Y$2&$C13&$A13,集計!$D:$R,$B13,0) -> #N/A | Z13: =VLOOKUP(Z$2&$C13&$A13,集計!$D:$R,$B13,0) -> #N/A | AA13: =VLOOKUP(AA$2&$C13&$A13,集計!$D:$R,$B13,0) -> #N/A | AB13: =Y13+Z13+AA13 -> #N/A | AC13: =I13+N13+T13+X13+AB13 -> #N/A | AD13: =VLOOKUP(AD$2&$C13&$A13,集計!$D:$R,$B13,0) -> #N/A | AE13: =VLOOKUP(AE$2&$C13&$A13,集計!$D:$R,$B13,0) -> #N/A | AF13: =VLOOKUP(AF$2&$C13&$A13,集計!$D:$R,$B13,0) -> #N/A | AG13: =VLOOKUP(AG$2&$C13&$A13,集計!$D:$R,$B13,0) -> #N/A | AH13: =AD13+AE13+AF13+AG13 -> #N/A | AI13: =VLOOKUP(AI$2&$C13&$A13,集計!$D:$R,$B13,0) -> #N/A | AJ13: =VLOOKUP(AJ$2&$C13&$A13,集計!$D:$R,$B13,0) -> #N/A | AK13: =VLOOKUP(AK$2&$C13&$A13,集計!$D:$R,$B13,0) -> #N/A | AL13: =AI13+AJ13+AK13 -> #N/A | AM13: =VLOOKUP(AM$2&$C13&$A13,集計!$D:$R,$B13,0) -> #N/A | AN13: =VLOOKUP(AN$2&$C13&$A13,集計!$D:$R,$B13,0) -> #N/A | AO13: =AM13+AN13 -> #N/A | AP13: =VLOOKUP(AP$2&$C13&$A13,集計!$D:$R,$B13,0) -> #N/A | AQ13: =VLOOKUP(AQ$2&$C13&$A13,集計!$D:$R,$B13,0) -> #N/A | AR13: =VLOOKUP(AR$2&$C13&$A13,集計!$D:$R,$B13,0) -> #N/A | AS13: =AP13+AQ13+AR13 -> #N/A | AT13: =AH13+AL13+AO13+AS13 -> #N/A | AU13: =VLOOKUP(AU$2&$C13&$A13,集計!$D:$R,$B13,0) -> #N/A | AV13: =VLOOKUP(AV$2&$C13&$A13,集計!$D:$R,$B13,0) -> #N/A | AW13: =VLOOKUP(AW$2&$C13&$A13,集計!$D:$R,$B13,0) -> #N/A | AX13: =VLOOKUP(AX$2&$C13&$A13,集計!$D:$R,$B13,0) -> #N/A | AY13: =VLOOKUP(AY$2&$C13&$A13,集計!$D:$R,$B13,0) -> #N/A | AZ13: =AU13+AV13+AW13+AX13+AY13 -> #N/A | BA13: =AZ13 -> #N/A | BB13: =VLOOKUP(BB$2&$C13&$A13,集計!$D:$R,$B13,0) -> #N/A | BC13: =VLOOKUP(BC$2&$C13&$A13,集計!$D:$R,$B13,0) -> #N/A | BD13: =BB13+BC13 -> #N/A | BE13: =VLOOKUP(BE$2&$C13&$A13,集計!$D:$R,$B13,0) -> #N/A | BF13: =VLOOKUP(BF$2&$C13&$A13,集計!$D:$R,$B13,0) -> #N/A | BG13: =VLOOKUP(BG$2&$C13&$A13,集計!$D:$R,$B13,0) -> #N/A | BH13: =VLOOKUP(BH$2&$C13&$A13,集計!$D:$R,$B13,0) -> #N/A | BI13: =VLOOKUP(BI$2&$C13&$A13,集計!$D:$R,$B13,0) -> #N/A | BJ13: =BE13+BF13+BG13+BH13+BI13 -> #N/A | BK13: =VLOOKUP(BK$2&$C13&$A13,集計!$D:$R,$B13,0) -> #N/A | BL13: =VLOOKUP(BL$2&$C13&$A13,集計!$D:$R,$B13,0) -> #N/A | BM13: =VLOOKUP(BM$2&$C13&$A13,集計!$D:$R,$B13,0) -> #N/A | BN13: =VLOOKUP(BN$2&$C13&$A13,集計!$D:$R,$B13,0) -> #N/A | BO13: =VLOOKUP(BO$2&$C13&$A13,集計!$D:$R,$B13,0) -> #N/A | BP13: =VLOOKUP(BP$2&$C13&$A13,集計!$D:$R,$B13,0) -> #N/A | BQ13: =BK13+BL13+BM13+BN13+BO13+BP13 -> #N/A | BR13: =VLOOKUP(BR$2&$C13&$A13,集計!$D:$R,$B13,0) -> #N/A | BS13: =VLOOKUP(BS$2&$C13&$A13,集計!$D:$R,$B13,0) -> #N/A | BT13: =VLOOKUP(BT$2&$C13&$A13,集計!$D:$R,$B13,0) -> #N/A | BU13: =BR13+BS13+BT13 -> #N/A | BV13: =VLOOKUP(BV$2&$C13&$A13,集計!$D:$R,$B13,0) -> #N/A | BW13: =BV13 -> #N/A | BX13: =AC13+AT13+BA13+BD13+BJ13+BQ13+BU13+BW13 -> #N/A
A14: 人員 | B14: 5 | C14: ローカル社員 | D14: =IF(VLOOKUP(D$2&$C14&$A14,集計!$D:$R,$B14,0)<>SUM(D12:D13),"NG",SUM(D12:D13)) -> #N/A | E14: =IF(VLOOKUP(E$2&$C14&$A14,集計!$D:$R,$B14,0)<>SUM(E12:E13),"NG",SUM(E12:E13)) -> #N/A | F14: =IF(VLOOKUP(F$2&$C14&$A14,集計!$D:$R,$B14,0)<>SUM(F12:F13),"NG",SUM(F12:F13)) -> #N/A | G14: =IF(VLOOKUP(G$2&$C14&$A14,集計!$D:$R,$B14,0)<>SUM(G12:G13),"NG",SUM(G12:G13)) -> #N/A | H14: =IF(VLOOKUP(H$2&$C14&$A14,集計!$D:$R,$B14,0)<>SUM(H12:H13),"NG",SUM(H12:H13)) -> #N/A | I14: =I12+I13 -> #N/A | J14: =IF(VLOOKUP(J$2&$C14&$A14,集計!$D:$R,$B14,0)<>SUM(J12:J13),"NG",SUM(J12:J13)) -> #N/A | K14: =IF(VLOOKUP(K$2&$C14&$A14,集計!$D:$R,$B14,0)<>SUM(K12:K13),"NG",SUM(K12:K13)) -> #N/A | L14: =IF(VLOOKUP(L$2&$C14&$A14,集計!$D:$R,$B14,0)<>SUM(L12:L13),"NG",SUM(L12:L13)) -> #N/A | M14: =IF(VLOOKUP(M$2&$C14&$A14,集計!$D:$R,$B14,0)<>SUM(M12:M13),"NG",SUM(M12:M13)) -> #N/A | N14: =N12+N13 -> #N/A | O14: =IF(VLOOKUP(O$2&$C14&$A14,集計!$D:$R,$B14,0)<>SUM(O12:O13),"NG",SUM(O12:O13)) -> #N/A | P14: =IF(VLOOKUP(P$2&$C14&$A14,集計!$D:$R,$B14,0)<>SUM(P12:P13),"NG",SUM(P12:P13)) -> #N/A | Q14: =IF(VLOOKUP(Q$2&$C14&$A14,集計!$D:$R,$B14,0)<>SUM(Q12:Q13),"NG",SUM(Q12:Q13)) -> #N/A | R14: =IF(VLOOKUP(R$2&$C14&$A14,集計!$D:$R,$B14,0)<>SUM(R12:R13),"NG",SUM(R12:R13)) -> #N/A | S14: =IF(VLOOKUP(S$2&$C14&$A14,集計!$D:$R,$B14,0)<>SUM(S12:S13),"NG",SUM(S12:S13)) -> #N/A | T14: =T12+T13 -> #N/A | U14: =IF(VLOOKUP(U$2&$C14&$A14,集計!$D:$R,$B14,0)<>SUM(U12:U13),"NG",SUM(U12:U13)) -> #N/A | V14: =IF(VLOOKUP(V$2&$C14&$A14,集計!$D:$R,$B14,0)<>SUM(V12:V13),"NG",SUM(V12:V13)) -> #N/A | W14: =IF(VLOOKUP(W$2&$C14&$A14,集計!$D:$R,$B14,0)<>SUM(W12:W13),"NG",SUM(W12:W13)) -> #N/A | X14: =SUM(X12:X13) -> #N/A | Y14: =IF(VLOOKUP(Y$2&$C14&$A14,集計!$D:$R,$B14,0)<>SUM(Y12:Y13),"NG",SUM(Y12:Y13)) -> #N/A | Z14: =IF(VLOOKUP(Z$2&$C14&$A14,集計!$D:$R,$B14,0)<>SUM(Z12:Z13),"NG",SUM(Z12:Z13)) -> #N/A | AA14: =IF(VLOOKUP(AA$2&$C14&$A14,集計!$D:$R,$B14,0)<>SUM(AA12:AA13),"NG",SUM(AA12:AA13)) -> #N/A | AB14: =SUM(AB12:AB13) -> #N/A | AC14: =SUM(AC12:AC13) -> #N/A | AD14: =IF(VLOOKUP(AD$2&$C14&$A14,集計!$D:$R,$B14,0)<>SUM(AD12:AD13),"NG",SUM(AD12:AD13)) -> #N/A | AE14: =IF(VLOOKUP(AE$2&$C14&$A14,集計!$D:$R,$B14,0)<>SUM(AE12:AE13),"NG",SUM(AE12:AE13)) -> #N/A | AF14: =IF(VLOOKUP(AF$2&$C14&$A14,集計!$D:$R,$B14,0)<>SUM(AF12:AF13),"NG",SUM(AF12:AF13)) -> #N/A | AG14: =IF(VLOOKUP(AG$2&$C14&$A14,集計!$D:$R,$B14,0)<>SUM(AG12:AG13),"NG",SUM(AG12:AG13)) -> #N/A | AH14: =SUM(AH12:AH13) -> #N/A | AI14: =IF(VLOOKUP(AI$2&$C14&$A14,集計!$D:$R,$B14,0)<>SUM(AI12:AI13),"NG",SUM(AI12:AI13)) -> #N/A | AJ14: =IF(VLOOKUP(AJ$2&$C14&$A14,集計!$D:$R,$B14,0)<>SUM(AJ12:AJ13),"NG",SUM(AJ12:AJ13)) -> #N/A | AK14: =IF(VLOOKUP(AK$2&$C14&$A14,集計!$D:$R,$B14,0)<>SUM(AK12:AK13),"NG",SUM(AK12:AK13)) -> #N/A | AL14: =SUM(AL12:AL13) -> #N/A | AM14: =IF(VLOOKUP(AM$2&$C14&$A14,集計!$D:$R,$B14,0)<>SUM(AM12:AM13),"NG",SUM(AM12:AM13)) -> #N/A | AN14: =IF(VLOOKUP(AN$2&$C14&$A14,集計!$D:$R,$B14,0)<>SUM(AN12:AN13),"NG",SUM(AN12:AN13)) -> #N/A | AO14: =SUM(AO12:AO13) -> #N/A | AP14: =IF(VLOOKUP(AP$2&$C14&$A14,集計!$D:$R,$B14,0)<>SUM(AP12:AP13),"NG",SUM(AP12:AP13)) -> #N/A | AQ14: =IF(VLOOKUP(AQ$2&$C14&$A14,集計!$D:$R,$B14,0)<>SUM(AQ12:AQ13),"NG",SUM(AQ12:AQ13)) -> #N/A | AR14: =IF(VLOOKUP(AR$2&$C14&$A14,集計!$D:$R,$B14,0)<>SUM(AR12:AR13),"NG",SUM(AR12:AR13)) -> #N/A | AS14: =SUM(AS12:AS13) -> #N/A | AT14: =SUM(AT12:AT13) -> #N/A | AU14: =IF(VLOOKUP(AU$2&$C14&$A14,集計!$D:$R,$B14,0)<>SUM(AU12:AU13),"NG",SUM(AU12:AU13)) -> #N/A | AV14: =IF(VLOOKUP(AV$2&$C14&$A14,集計!$D:$R,$B14,0)<>SUM(AV12:AV13),"NG",SUM(AV12:AV13)) -> #N/A | AW14: =IF(VLOOKUP(AW$2&$C14&$A14,集計!$D:$R,$B14,0)<>SUM(AW12:AW13),"NG",SUM(AW12:AW13)) -> #N/A | AX14: =IF(VLOOKUP(AX$2&$C14&$A14,集計!$D:$R,$B14,0)<>SUM(AX12:AX13),"NG",SUM(AX12:AX13)) -> #N/A | AY14: =IF(VLOOKUP(AY$2&$C14&$A14,集計!$D:$R,$B14,0)<>SUM(AY12:AY13),"NG",SUM(AY12:AY13)) -> #N/A | AZ14: =AZ12+AZ13 -> #N/A | BA14: =BA12+BA13 -> #N/A | BB14: =IF(VLOOKUP(BB$2&$C14&$A14,集計!$D:$R,$B14,0)<>SUM(BB12:BB13),"NG",SUM(BB12:BB13)) -> #N/A | BC14: =IF(VLOOKUP(BC$2&$C14&$A14,集計!$D:$R,$B14,0)<>SUM(BC12:BC13),"NG",SUM(BC12:BC13)) -> #N/A | BD14: =SUM(BD12:BD13) -> #N/A | BE14: =IF(VLOOKUP(BE$2&$C14&$A14,集計!$D:$R,$B14,0)<>SUM(BE12:BE13),"NG",SUM(BE12:BE13)) -> #N/A | BF14: =IF(VLOOKUP(BF$2&$C14&$A14,集計!$D:$R,$B14,0)<>SUM(BF12:BF13),"NG",SUM(BF12:BF13)) -> #N/A | BG14: =IF(VLOOKUP(BG$2&$C14&$A14,集計!$D:$R,$B14,0)<>SUM(BG12:BG13),"NG",SUM(BG12:BG13)) -> #N/A | BH14: =IF(VLOOKUP(BH$2&$C14&$A14,集計!$D:$R,$B14,0)<>SUM(BH12:BH13),"NG",SUM(BH12:BH13)) -> #N/A | BI14: =IF(VLOOKUP(BI$2&$C14&$A14,集計!$D:$R,$B14,0)<>SUM(BI12:BI13),"NG",SUM(BI12:BI13)) -> #N/A | BJ14: =BJ12+BJ13 -> #N/A | BK14: =IF(VLOOKUP(BK$2&$C14&$A14,集計!$D:$R,$B14,0)<>SUM(BK12:BK13),"NG",SUM(BK12:BK13)) -> #N/A | BL14: =IF(VLOOKUP(BL$2&$C14&$A14,集計!$D:$R,$B14,0)<>SUM(BL12:BL13),"NG",SUM(BL12:BL13)) -> #N/A | BM14: =IF(VLOOKUP(BM$2&$C14&$A14,集計!$D:$R,$B14,0)<>SUM(BM12:BM13),"NG",SUM(BM12:BM13)) -> #N/A | BN14: =IF(VLOOKUP(BN$2&$C14&$A14,集計!$D:$R,$B14,0)<>SUM(BN12:BN13),"NG",SUM(BN12:BN13)) -> #N/A | BO14: =IF(VLOOKUP(BO$2&$C14&$A14,集計!$D:$R,$B14,0)<>SUM(BO12:BO13),"NG",SUM(BO12:BO13)) -> #N/A | BP14: =IF(VLOOKUP(BP$2&$C14&$A14,集計!$D:$R,$B14,0)<>SUM(BP12:BP13),"NG",SUM(BP12:BP13)) -> #N/A | BQ14: =BQ12+BQ13 -> #N/A | BR14: =IF(VLOOKUP(BR$2&$C14&$A14,集計!$D:$R,$B14,0)<>SUM(BR12:BR13),"NG",SUM(BR12:BR13)) -> #N/A | BS14: =IF(VLOOKUP(BS$2&$C14&$A14,集計!$D:$R,$B14,0)<>SUM(BS12:BS13),"NG",SUM(BS12:BS13)) -> #N/A | BT14: =IF(VLOOKUP(BT$2&$C14&$A14,集計!$D:$R,$B14,0)<>SUM(BT12:BT13),"NG",SUM(BT12:BT13)) -> #N/A | BU14: =BU12+BU13 -> #N/A | BV14: =IF(VLOOKUP(BV$2&$C14&$A14,集計!$D:$R,$B14,0)<>SUM(BV12:BV13),"NG",SUM(BV12:BV13)) -> #N/A | BW14: =SUM(BW12:BW13) -> #N/A | BX14: =SUM(BX12:BX13) -> #N/A
A15: 人員 | B15: 5 | C15: 人員合計 | D15: =IF(VLOOKUP(D$2&$C15&$A15,集計!$D:$R,$B15,0)<>SUM(D11,D14),"NG",SUM(D11,D14)) -> #N/A | E15: =IF(VLOOKUP(E$2&$C15&$A15,集計!$D:$R,$B15,0)<>SUM(E11,E14),"NG",SUM(E11,E14)) -> #N/A | F15: =IF(VLOOKUP(F$2&$C15&$A15,集計!$D:$R,$B15,0)<>SUM(F11,F14),"NG",SUM(F11,F14)) -> #N/A | G15: =IF(VLOOKUP(G$2&$C15&$A15,集計!$D:$R,$B15,0)<>SUM(G11,G14),"NG",SUM(G11,G14)) -> #N/A | H15: =IF(VLOOKUP(H$2&$C15&$A15,集計!$D:$R,$B15,0)<>SUM(H11,H14),"NG",SUM(H11,H14)) -> #N/A | I15: =I11+I14 -> #N/A | J15: =IF(VLOOKUP(J$2&$C15&$A15,集計!$D:$R,$B15,0)<>SUM(J11,J14),"NG",SUM(J11,J14)) -> #N/A | K15: =IF(VLOOKUP(K$2&$C15&$A15,集計!$D:$R,$B15,0)<>SUM(K11,K14),"NG",SUM(K11,K14)) -> #N/A | L15: =IF(VLOOKUP(L$2&$C15&$A15,集計!$D:$R,$B15,0)<>SUM(L11,L14),"NG",SUM(L11,L14)) -> #N/A | M15: =IF(VLOOKUP(M$2&$C15&$A15,集計!$D:$R,$B15,0)<>SUM(M11,M14),"NG",SUM(M11,M14)) -> #N/A | N15: =N11+N14 -> #N/A | O15: =IF(VLOOKUP(O$2&$C15&$A15,集計!$D:$R,$B15,0)<>SUM(O11,O14),"NG",SUM(O11,O14)) -> #N/A | P15: =IF(VLOOKUP(P$2&$C15&$A15,集計!$D:$R,$B15,0)<>SUM(P11,P14),"NG",SUM(P11,P14)) -> #N/A | Q15: =IF(VLOOKUP(Q$2&$C15&$A15,集計!$D:$R,$B15,0)<>SUM(Q11,Q14),"NG",SUM(Q11,Q14)) -> #N/A | R15: =IF(VLOOKUP(R$2&$C15&$A15,集計!$D:$R,$B15,0)<>SUM(R11,R14),"NG",SUM(R11,R14)) -> #N/A | S15: =IF(VLOOKUP(S$2&$C15&$A15,集計!$D:$R,$B15,0)<>SUM(S11,S14),"NG",SUM(S11,S14)) -> #N/A | T15: =T11+T14 -> #N/A | U15: =IF(VLOOKUP(U$2&$C15&$A15,集計!$D:$R,$B15,0)<>SUM(U11,U14),"NG",SUM(U11,U14)) -> #N/A | V15: =IF(VLOOKUP(V$2&$C15&$A15,集計!$D:$R,$B15,0)<>SUM(V11,V14),"NG",SUM(V11,V14)) -> #N/A | W15: =IF(VLOOKUP(W$2&$C15&$A15,集計!$D:$R,$B15,0)<>SUM(W11,W14),"NG",SUM(W11,W14)) -> #N/A | X15: =X11+X14 -> #N/A | Y15: =IF(VLOOKUP(Y$2&$C15&$A15,集計!$D:$R,$B15,0)<>SUM(Y11,Y14),"NG",SUM(Y11,Y14)) -> #N/A | Z15: =IF(VLOOKUP(Z$2&$C15&$A15,集計!$D:$R,$B15,0)<>SUM(Z11,Z14),"NG",SUM(Z11,Z14)) -> #N/A | AA15: =IF(VLOOKUP(AA$2&$C15&$A15,集計!$D:$R,$B15,0)<>SUM(AA11,AA14),"NG",SUM(AA11,AA14)) -> #N/A | AB15: =AB11+AB14 -> #N/A | AC15: =AC11+AC14 -> #N/A | AD15: =IF(VLOOKUP(AD$2&$C15&$A15,集計!$D:$R,$B15,0)<>SUM(AD11,AD14),"NG",SUM(AD11,AD14)) -> #N/A | AE15: =IF(VLOOKUP(AE$2&$C15&$A15,集計!$D:$R,$B15,0)<>SUM(AE11,AE14),"NG",SUM(AE11,AE14)) -> #N/A | AF15: =IF(VLOOKUP(AF$2&$C15&$A15,集計!$D:$R,$B15,0)<>SUM(AF11,AF14),"NG",SUM(AF11,AF14)) -> #N/A | AG15: =IF(VLOOKUP(AG$2&$C15&$A15,集計!$D:$R,$B15,0)<>SUM(AG11,AG14),"NG",SUM(AG11,AG14)) -> #N/A | AH15: =AH11+AH14 -> #N/A | AI15: =IF(VLOOKUP(AI$2&$C15&$A15,集計!$D:$R,$B15,0)<>SUM(AI11,AI14),"NG",SUM(AI11,AI14)) -> #N/A | AJ15: =IF(VLOOKUP(AJ$2&$C15&$A15,集計!$D:$R,$B15,0)<>SUM(AJ11,AJ14),"NG",SUM(AJ11,AJ14)) -> #N/A | AK15: =IF(VLOOKUP(AK$2&$C15&$A15,集計!$D:$R,$B15,0)<>SUM(AK11,AK14),"NG",SUM(AK11,AK14)) -> #N/A | AL15: =AL11+AL14 -> #N/A | AM15: =IF(VLOOKUP(AM$2&$C15&$A15,集計!$D:$R,$B15,0)<>SUM(AM11,AM14),"NG",SUM(AM11,AM14)) -> #N/A | AN15: =IF(VLOOKUP(AN$2&$C15&$A15,集計!$D:$R,$B15,0)<>SUM(AN11,AN14),"NG",SUM(AN11,AN14)) -> #N/A | AO15: =AO11+AO14 -> #N/A | AP15: =IF(VLOOKUP(AP$2&$C15&$A15,集計!$D:$R,$B15,0)<>SUM(AP11,AP14),"NG",SUM(AP11,AP14)) -> #N/A | AQ15: =IF(VLOOKUP(AQ$2&$C15&$A15,集計!$D:$R,$B15,0)<>SUM(AQ11,AQ14),"NG",SUM(AQ11,AQ14)) -> #N/A | AR15: =IF(VLOOKUP(AR$2&$C15&$A15,集計!$D:$R,$B15,0)<>SUM(AR11,AR14),"NG",SUM(AR11,AR14)) -> #N/A | AS15: =AS11+AS14 -> #N/A | AT15: =AT11+AT14 -> #N/A | AU15: =IF(VLOOKUP(AU$2&$C15&$A15,集計!$D:$R,$B15,0)<>SUM(AU11,AU14),"NG",SUM(AU11,AU14)) -> #N/A | AV15: =IF(VLOOKUP(AV$2&$C15&$A15,集計!$D:$R,$B15,0)<>SUM(AV11,AV14),"NG",SUM(AV11,AV14)) -> #N/A | AW15: =IF(VLOOKUP(AW$2&$C15&$A15,集計!$D:$R,$B15,0)<>SUM(AW11,AW14),"NG",SUM(AW11,AW14)) -> #N/A | AX15: =IF(VLOOKUP(AX$2&$C15&$A15,集計!$D:$R,$B15,0)<>SUM(AX11,AX14),"NG",SUM(AX11,AX14)) -> #N/A | AY15: =IF(VLOOKUP(AY$2&$C15&$A15,集計!$D:$R,$B15,0)<>SUM(AY11,AY14),"NG",SUM(AY11,AY14)) -> #N/A | AZ15: =AZ11+AZ14 -> #N/A | BA15: =BA11+BA14 -> #N/A | BB15: =IF(VLOOKUP(BB$2&$C15&$A15,集計!$D:$R,$B15,0)<>SUM(BB11,BB14),"NG",SUM(BB11,BB14)) -> #N/A | BC15: =IF(VLOOKUP(BC$2&$C15&$A15,集計!$D:$R,$B15,0)<>SUM(BC11,BC14),"NG",SUM(BC11,BC14)) -> #N/A | BD15: =BD11+BD14 -> #N/A | BE15: =IF(VLOOKUP(BE$2&$C15&$A15,集計!$D:$R,$B15,0)<>SUM(BE11,BE14),"NG",SUM(BE11,BE14)) -> #N/A | BF15: =IF(VLOOKUP(BF$2&$C15&$A15,集計!$D:$R,$B15,0)<>SUM(BF11,BF14),"NG",SUM(BF11,BF14)) -> #N/A | BG15: =IF(VLOOKUP(BG$2&$C15&$A15,集計!$D:$R,$B15,0)<>SUM(BG11,BG14),"NG",SUM(BG11,BG14)) -> #N/A | BH15: =IF(VLOOKUP(BH$2&$C15&$A15,集計!$D:$R,$B15,0)<>SUM(BH11,BH14),"NG",SUM(BH11,BH14)) -> #N/A | BI15: =IF(VLOOKUP(BI$2&$C15&$A15,集計!$D:$R,$B15,0)<>SUM(BI11,BI14),"NG",SUM(BI11,BI14)) -> #N/A | BJ15: =BJ11+BJ14 -> #N/A | BK15: =IF(VLOOKUP(BK$2&$C15&$A15,集計!$D:$R,$B15,0)<>SUM(BK11,BK14),"NG",SUM(BK11,BK14)) -> #N/A | BL15: =IF(VLOOKUP(BL$2&$C15&$A15,集計!$D:$R,$B15,0)<>SUM(BL11,BL14),"NG",SUM(BL11,BL14)) -> #N/A | BM15: =IF(VLOOKUP(BM$2&$C15&$A15,集計!$D:$R,$B15,0)<>SUM(BM11,BM14),"NG",SUM(BM11,BM14)) -> #N/A | BN15: =IF(VLOOKUP(BN$2&$C15&$A15,集計!$D:$R,$B15,0)<>SUM(BN11,BN14),"NG",SUM(BN11,BN14)) -> #N/A | BO15: =IF(VLOOKUP(BO$2&$C15&$A15,集計!$D:$R,$B15,0)<>SUM(BO11,BO14),"NG",SUM(BO11,BO14)) -> #N/A | BP15: =IF(VLOOKUP(BP$2&$C15&$A15,集計!$D:$R,$B15,0)<>SUM(BP11,BP14),"NG",SUM(BP11,BP14)) -> #N/A | BQ15: =BQ11+BQ14 -> #N/A | BR15: =IF(VLOOKUP(BR$2&$C15&$A15,集計!$D:$R,$B15,0)<>SUM(BR11,BR14),"NG",SUM(BR11,BR14)) -> #N/A | BS15: =IF(VLOOKUP(BS$2&$C15&$A15,集計!$D:$R,$B15,0)<>SUM(BS11,BS14),"NG",SUM(BS11,BS14)) -> #N/A | BT15: =IF(VLOOKUP(BT$2&$C15&$A15,集計!$D:$R,$B15,0)<>SUM(BT11,BT14),"NG",SUM(BT11,BT14)) -> #N/A | BU15: =BU11+BU14 -> #N/A | BV15: =IF(VLOOKUP(BV$2&$C15&$A15,集計!$D:$R,$B15,0)<>SUM(BV11,BV14),"NG",SUM(BV11,BV14)) -> #N/A | BW15: =BW11+BW14 -> #N/A | BX15: =BX11+BX14 -> #N/A
B17: 6 | C17: 人員
A18: 人員 | B18: 6 | C18: 出向社員 | D18: =VLOOKUP(D$2&$C18&$A18,集計!$D:$R,$B18,0) -> #N/A | E18: =VLOOKUP(E$2&$C18&$A18,集計!$D:$R,$B18,0) -> #N/A | F18: =VLOOKUP(F$2&$C18&$A18,集計!$D:$R,$B18,0) -> #N/A | G18: =VLOOKUP(G$2&$C18&$A18,集計!$D:$R,$B18,0) -> #N/A | H18: =VLOOKUP(H$2&$C18&$A18,集計!$D:$R,$B18,0) -> #N/A | I18: =D18+E18+F18+G18+H18 -> #N/A | J18: =VLOOKUP(J$2&$C18&$A18,集計!$D:$R,$B18,0) -> #N/A | K18: =VLOOKUP(K$2&$C18&$A18,集計!$D:$R,$B18,0) -> #N/A | L18: =VLOOKUP(L$2&$C18&$A18,集計!$D:$R,$B18,0) -> #N/A | M18: =VLOOKUP(M$2&$C18&$A18,集計!$D:$R,$B18,0) -> #N/A | N18: =J18+K18+L18+M18 -> #N/A | O18: =VLOOKUP(O$2&$C18&$A18,集計!$D:$R,$B18,0) -> #N/A | P18: =VLOOKUP(P$2&$C18&$A18,集計!$D:$R,$B18,0) -> #N/A | Q18: =VLOOKUP(Q$2&$C18&$A18,集計!$D:$R,$B18,0) -> #N/A | R18: =VLOOKUP(R$2&$C18&$A18,集計!$D:$R,$B18,0) -> #N/A | S18: =VLOOKUP(S$2&$C18&$A18,集計!$D:$R,$B18,0) -> #N/A | T18: =O18+P18+Q18+R18+S18 -> #N/A | U18: =VLOOKUP(U$2&$C18&$A18,集計!$D:$R,$B18,0) -> #N/A | V18: =VLOOKUP(V$2&$C18&$A18,集計!$D:$R,$B18,0) -> #N/A | W18: =VLOOKUP(W$2&$C18&$A18,集計!$D:$R,$B18,0) -> #N/A | X18: =U18+V18+W18 -> #N/A | Y18: =VLOOKUP(Y$2&$C18&$A18,集計!$D:$R,$B18,0) -> #N/A | Z18: =VLOOKUP(Z$2&$C18&$A18,集計!$D:$R,$B18,0) -> #N/A | AA18: =VLOOKUP(AA$2&$C18&$A18,集計!$D:$R,$B18,0) -> #N/A | AB18: =Y18+Z18+AA18 -> #N/A | AC18: =I18+N18+T18+X18+AB18 -> #N/A | AD18: =VLOOKUP(AD$2&$C18&$A18,集計!$D:$R,$B18,0) -> #N/A | AE18: =VLOOKUP(AE$2&$C18&$A18,集計!$D:$R,$B18,0) -> #N/A | AF18: =VLOOKUP(AF$2&$C18&$A18,集計!$D:$R,$B18,0) -> #N/A | AG18: =VLOOKUP(AG$2&$C18&$A18,集計!$D:$R,$B18,0) -> #N/A | AH18: =AD18+AE18+AF18+AG18 -> #N/A | AI18: =VLOOKUP(AI$2&$C18&$A18,集計!$D:$R,$B18,0) -> #N/A | AJ18: =VLOOKUP(AJ$2&$C18&$A18,集計!$D:$R,$B18,0) -> #N/A | AK18: =VLOOKUP(AK$2&$C18&$A18,集計!$D:$R,$B18,0) -> #N/A | AL18: =AI18+AJ18+AK18 -> #N/A | AM18: =VLOOKUP(AM$2&$C18&$A18,集計!$D:$R,$B18,0) -> #N/A | AN18: =VLOOKUP(AN$2&$C18&$A18,集計!$D:$R,$B18,0) -> #N/A | AO18: =AM18+AN18 -> #N/A | AP18: =VLOOKUP(AP$2&$C18&$A18,集計!$D:$R,$B18,0) -> #N/A | AQ18: =VLOOKUP(AQ$2&$C18&$A18,集計!$D:$R,$B18,0) -> #N/A | AR18: =VLOOKUP(AR$2&$C18&$A18,集計!$D:$R,$B18,0) -> #N/A | AS18: =AP18+AQ18+AR18 -> #N/A | AT18: =AH18+AL18+AO18+AS18 -> #N/A | AU18: =VLOOKUP(AU$2&$C18&$A18,集計!$D:$R,$B18,0) -> #N/A | AV18: =VLOOKUP(AV$2&$C18&$A18,集計!$D:$R,$B18,0) -> #N/A | AW18: =VLOOKUP(AW$2&$C18&$A18,集計!$D:$R,$B18,0) -> #N/A | AX18: =VLOOKUP(AX$2&$C18&$A18,集計!$D:$R,$B18,0) -> #N/A | AY18: =VLOOKUP(AY$2&$C18&$A18,集計!$D:$R,$B18,0) -> #N/A | AZ18: =AU18+AV18+AW18+AX18+AY18 -> #N/A | BA18: =AZ18 -> #N/A | BB18: =VLOOKUP(BB$2&$C18&$A18,集計!$D:$R,$B18,0) -> #N/A | BC18: =VLOOKUP(BC$2&$C18&$A18,集計!$D:$R,$B18,0) -> #N/A | BD18: =BB18+BC18 -> #N/A | BE18: =VLOOKUP(BE$2&$C18&$A18,集計!$D:$R,$B18,0) -> #N/A | BF18: =VLOOKUP(BF$2&$C18&$A18,集計!$D:$R,$B18,0) -> #N/A | BG18: =VLOOKUP(BG$2&$C18&$A18,集計!$D:$R,$B18,0) -> #N/A | BH18: =VLOOKUP(BH$2&$C18&$A18,集計!$D:$R,$B18,0) -> #N/A | BI18: =VLOOKUP(BI$2&$C18&$A18,集計!$D:$R,$B18,0) -> #N/A | BJ18: =BE18+BF18+BG18+BH18+BI18 -> #N/A | BK18: =VLOOKUP(BK$2&$C18&$A18,集計!$D:$R,$B18,0) -> #N/A | BL18: =VLOOKUP(BL$2&$C18&$A18,集計!$D:$R,$B18,0) -> #N/A | BM18: =VLOOKUP(BM$2&$C18&$A18,集計!$D:$R,$B18,0) -> #N/A | BN18: =VLOOKUP(BN$2&$C18&$A18,集計!$D:$R,$B18,0) -> #N/A | BO18: =VLOOKUP(BO$2&$C18&$A18,集計!$D:$R,$B18,0) -> #N/A | BP18: =VLOOKUP(BP$2&$C18&$A18,集計!$D:$R,$B18,0) -> #N/A | BQ18: =BK18+BL18+BM18+BN18+BO18+BP18 -> #N/A | BR18: =VLOOKUP(BR$2&$C18&$A18,集計!$D:$R,$B18,0) -> #N/A | BS18: =VLOOKUP(BS$2&$C18&$A18,集計!$D:$R,$B18,0) -> #N/A | BT18: =VLOOKUP(BT$2&$C18&$A18,集計!$D:$R,$B18,0) -> #N/A | BU18: =BR18+BS18+BT18 -> #N/A | BV18: =VLOOKUP(BV$2&$C18&$A18,集計!$D:$R,$B18,0) -> #N/A | BW18: =BV18 -> #N/A | BX18: =AC18+AT18+BA18+BD18+BJ18+BQ18+BU18+BW18 -> #N/A
A19: 人員 | B19: 6 | C19: G5以上 | D19: =VLOOKUP(D$2&$C19&$A19,集計!$D:$R,$B19,0) -> #N/A | E19: =VLOOKUP(E$2&$C19&$A19,集計!$D:$R,$B19,0) -> #N/A | F19: =VLOOKUP(F$2&$C19&$A19,集計!$D:$R,$B19,0) -> #N/A | G19: =VLOOKUP(G$2&$C19&$A19,集計!$D:$R,$B19,0) -> #N/A | H19: =VLOOKUP(H$2&$C19&$A19,集計!$D:$R,$B19,0) -> #N/A | I19: =D19+E19+F19+G19+H19 -> #N/A | J19: =VLOOKUP(J$2&$C19&$A19,集計!$D:$R,$B19,0) -> #N/A | K19: =VLOOKUP(K$2&$C19&$A19,集計!$D:$R,$B19,0) -> #N/A | L19: =VLOOKUP(L$2&$C19&$A19,集計!$D:$R,$B19,0) -> #N/A | M19: =VLOOKUP(M$2&$C19&$A19,集計!$D:$R,$B19,0) -> #N/A | N19: =J19+K19+L19+M19 -> #N/A | O19: =VLOOKUP(O$2&$C19&$A19,集計!$D:$R,$B19,0) -> #N/A | P19: =VLOOKUP(P$2&$C19&$A19,集計!$D:$R,$B19,0) -> #N/A | Q19: =VLOOKUP(Q$2&$C19&$A19,集計!$D:$R,$B19,0) -> #N/A | R19: =VLOOKUP(R$2&$C19&$A19,集計!$D:$R,$B19,0) -> #N/A | S19: =VLOOKUP(S$2&$C19&$A19,集計!$D:$R,$B19,0) -> #N/A | T19: =O19+P19+Q19+R19+S19 -> #N/A | U19: =VLOOKUP(U$2&$C19&$A19,集計!$D:$R,$B19,0) -> #N/A | V19: =VLOOKUP(V$2&$C19&$A19,集計!$D:$R,$B19,0) -> #N/A | W19: =VLOOKUP(W$2&$C19&$A19,集計!$D:$R,$B19,0) -> #N/A | X19: =U19+V19+W19 -> #N/A | Y19: =VLOOKUP(Y$2&$C19&$A19,集計!$D:$R,$B19,0) -> #N/A | Z19: =VLOOKUP(Z$2&$C19&$A19,集計!$D:$R,$B19,0) -> #N/A | AA19: =VLOOKUP(AA$2&$C19&$A19,集計!$D:$R,$B19,0) -> #N/A | AB19: =Y19+Z19+AA19 -> #N/A | AC19: =I19+N19+T19+X19+AB19 -> #N/A | AD19: =VLOOKUP(AD$2&$C19&$A19,集計!$D:$R,$B19,0) -> #N/A | AE19: =VLOOKUP(AE$2&$C19&$A19,集計!$D:$R,$B19,0) -> #N/A | AF19: =VLOOKUP(AF$2&$C19&$A19,集計!$D:$R,$B19,0) -> #N/A | AG19: =VLOOKUP(AG$2&$C19&$A19,集計!$D:$R,$B19,0) -> #N/A | AH19: =AD19+AE19+AF19+AG19 -> #N/A | AI19: =VLOOKUP(AI$2&$C19&$A19,集計!$D:$R,$B19,0) -> #N/A | AJ19: =VLOOKUP(AJ$2&$C19&$A19,集計!$D:$R,$B19,0) -> #N/A | AK19: =VLOOKUP(AK$2&$C19&$A19,集計!$D:$R,$B19,0) -> #N/A | AL19: =AI19+AJ19+AK19 -> #N/A | AM19: =VLOOKUP(AM$2&$C19&$A19,集計!$D:$R,$B19,0) -> #N/A | AN19: =VLOOKUP(AN$2&$C19&$A19,集計!$D:$R,$B19,0) -> #N/A | AO19: =AM19+AN19 -> #N/A | AP19: =VLOOKUP(AP$2&$C19&$A19,集計!$D:$R,$B19,0) -> #N/A | AQ19: =VLOOKUP(AQ$2&$C19&$A19,集計!$D:$R,$B19,0) -> #N/A | AR19: =VLOOKUP(AR$2&$C19&$A19,集計!$D:$R,$B19,0) -> #N/A | AS19: =AP19+AQ19+AR19 -> #N/A | AT19: =AH19+AL19+AO19+AS19 -> #N/A | AU19: =VLOOKUP(AU$2&$C19&$A19,集計!$D:$R,$B19,0) -> #N/A | AV19: =VLOOKUP(AV$2&$C19&$A19,集計!$D:$R,$B19,0) -> #N/A | AW19: =VLOOKUP(AW$2&$C19&$A19,集計!$D:$R,$B19,0) -> #N/A | AX19: =VLOOKUP(AX$2&$C19&$A19,集計!$D:$R,$B19,0) -> #N/A | AY19: =VLOOKUP(AY$2&$C19&$A19,集計!$D:$R,$B19,0) -> #N/A | AZ19: =AU19+AV19+AW19+AX19+AY19 -> #N/A | BA19: =AZ19 -> #N/A | BB19: =VLOOKUP(BB$2&$C19&$A19,集計!$D:$R,$B19,0) -> #N/A | BC19: =VLOOKUP(BC$2&$C19&$A19,集計!$D:$R,$B19,0) -> #N/A | BD19: =BB19+BC19 -> #N/A | BE19: =VLOOKUP(BE$2&$C19&$A19,集計!$D:$R,$B19,0) -> #N/A | BF19: =VLOOKUP(BF$2&$C19&$A19,集計!$D:$R,$B19,0) -> #N/A | BG19: =VLOOKUP(BG$2&$C19&$A19,集計!$D:$R,$B19,0) -> #N/A | BH19: =VLOOKUP(BH$2&$C19&$A19,集計!$D:$R,$B19,0) -> #N/A | BI19: =VLOOKUP(BI$2&$C19&$A19,集計!$D:$R,$B19,0) -> #N/A | BJ19: =BE19+BF19+BG19+BH19+BI19 -> #N/A | BK19: =VLOOKUP(BK$2&$C19&$A19,集計!$D:$R,$B19,0) -> #N/A | BL19: =VLOOKUP(BL$2&$C19&$A19,集計!$D:$R,$B19,0) -> #N/A | BM19: =VLOOKUP(BM$2&$C19&$A19,集計!$D:$R,$B19,0) -> #N/A | BN19: =VLOOKUP(BN$2&$C19&$A19,集計!$D:$R,$B19,0) -> #N/A | BO19: =VLOOKUP(BO$2&$C19&$A19,集計!$D:$R,$B19,0) -> #N/A | BP19: =VLOOKUP(BP$2&$C19&$A19,集計!$D:$R,$B19,0) -> #N/A | BQ19: =BK19+BL19+BM19+BN19+BO19+BP19 -> #N/A | BR19: =VLOOKUP(BR$2&$C19&$A19,集計!$D:$R,$B19,0) -> #N/A | BS19: =VLOOKUP(BS$2&$C19&$A19,集計!$D:$R,$B19,0) -> #N/A | BT19: =VLOOKUP(BT$2&$C19&$A19,集計!$D:$R,$B19,0) -> #N/A | BU19: =BR19+BS19+BT19 -> #N/A | BV19: =VLOOKUP(BV$2&$C19&$A19,集計!$D:$R,$B19,0) -> #N/A | BW19: =BV19 -> #N/A | BX19: =AC19+AT19+BA19+BD19+BJ19+BQ19+BU19+BW19 -> #N/A
