Workbook
Name _DAT1: #REF!
Name _DAT10: #REF!
Name _DAT11: #REF!
Name _DAT12: #REF!
Name _DAT2: #REF!
Name _DAT3: #REF!
Name _DAT4: #REF!
Name _DAT5: #REF!
Name _DAT6: #REF!
Name _DAT7: #REF!
Name _DAT8: #REF!
Name _DAT9: #REF!
Name Print_Tiles: #REF!
Name Q_ﾄﾞﾗﾑ社内売_塗工出荷_製品_: #REF!
Name Q_ドラム総_梱包出荷額_製品_: #REF!
Name Q_塗工出荷額_製品当り_ﾄﾞﾗﾑ_: #REF!
Name TEST0: #REF!
Name TEST1: #REF!
Name TESTKEYS: #REF!
Name TESTVKEY: #REF!
Name クエリー4: #REF!
Name 採算表累積表: #REF!
Name 採算表累積表1: #REF!
Name 採算表累積表2: #REF!
Name 採算表累積表3: #REF!
Name 支給率Ａ: 4.3
Name 支給率Ｂ: 6.3
Name 実績予定表: #REF!
Name 実績予定表1: #REF!
Name 実績予定表2: #REF!
Name 消費税: -INT(#REF!/1.05*0.05)
Name 消費税率Ａ: 1.03
Name 消費税率Ｂ: 1.05
Name 生産5: #REF!
Name 生産6: #REF!
Name 生産７: #REF!
Name 売上5: #REF!
Name 売上6: #REF!
Name 売上7: #REF!

Sheet 6221
A1: 1 | B1: → １＝日本語(tiếng nhật)、２＝ベトナム語(tiếng việt) | F1: 4 | J1: =F1+1 -> 5 | N1: =J1+1 -> 6 | R1: =N1+1 -> 7 | V1: =R1+1 -> 8 | Z1: =V1+1 -> 9 | AD1: =Z1+1 -> 10 | AH1: =AD1+1 -> 11 | AL1: =AH1+1 -> 12 | AP1: 1 | AT1: =AP1+1 -> 2 | AX1: =AT1+1 -> 3
F2: Dự tính Thời gian làm thêm (người Việt ) 残業時間（ローカル社員） (1/4/2023 ~ 30/4/2023) | H2: Dự tính Số người Việt 人員合計 (1/4/2023 ~ 30/4/2023) | J2: Dự tính Thời gian làm thêm (người Việt ) 残業時間（ローカル社員） (1/5/2023 ~ 31/5/2023) | L2: Dự tính Số người Việt 人員合計 (1/5/2023 ~ 31/5/2023) | N2: Dự tính Thời gian làm thêm (người Việt ) 残業時間（ローカル社員） (1/6/2023 ~ 30/6/2023) | P2: Dự tính Số người Việt 人員合計 (1/6/2023 ~ 30/6/2023) | R2: Dự tính Thời gian làm thêm (người Việt ) 残業時間（ローカル社員） (1/7/2023 ~ 31/7/2023) | T2: Dự tính Số người Việt 人員合計 (1/7/2023 ~ 31/7/2023) | V2: Dự tính Thời gian làm thêm (người Việt ) 残業時間（ローカル社員） (1/8/2023 ~ 31/8/2023) | X2: Dự tính Số người Việt 人員合計 (1/8/2023 ~ 31/8/2023) | Z2: Dự tính Thời gian làm thêm (người Việt ) 残業時間（ローカル社員） (1/9/2023 ~ 30/9/2023) | AB2: Dự tính Số người Việt 人員合計 (1/9/2023 ~ 30/9/2023) | AD2: Dự tính Thời gian làm thêm(người Việt ) 残業時間（ローカル社員） (1/10/2023 ~ 31/10/2023) | AF2: Dự tính Số người Việt 人員合計 (1/10/2023 ~ 31/10/2023) | AH2: Dự tính Thời gian làm thêm (người Việt ) 残業時間（ローカル社員） (1/11/2023 ~ 30/11/2023) | AJ2: Dự tính Số người Việt 人員合計 (1/11/2023 ~ 30/11/2023) | AL2: Dự tính Thời gian làm thêm (người Việt ) 残業時間（ローカル社員） (1/12/2023 ~ 31/12/2023) | AN2: Dự tính Số người Việt 人員合計 (1/12/2023 ~ 31/12/2023) | AP2: Dự tính Thời gian làm thêm (người Việt ) 残業時間（ローカル社員） (1/1/2024 ~ 31/1/2024) | AR2: Dự tính Số người Việt 人員合計 (1/1/2024 ~ 31/1/2024) | AT2: Dự tính Thời gian làm thêm (người Việt ) 残業時間（ローカル社員） (1/2/2024 ~ 28/2/2024) | AV2: Dự tính Số người Việt 人員合計 (1/2/2024~ 28/2/2024) | AX2: Dự tính Thời gian làm thêm (người Việt ) 残業時間（ローカル社員） (1/3/2024 ~ 31/3/2024) | AZ2: Dự tính Số người Việt 人員合計 (1/3/2024~ 31/3/2024)
F3: 4 | G3: 4 | H3: 4 | I3: 4 | J3: 5 | K3: 5 | L3: 5 | M3: 5 | N3: 6 | O3: 6 | P3: 6 | Q3: 6 | R3: 7 | S3: 7 | T3: 7 | U3: 7 | V3: 8 | W3: 8 | X3: 8 | Y3: 8 | Z3: 9 | AA3: 9 | AB3: 9 | AC3: 9 | AD3: 10 | AE3: 10 | AF3: 10 | AG3: 10 | AH3: 11 | AI3: 11 | AJ3: 11 | AK3: 11 | AL3: 12 | AM3: 12 | AN3: 12 | AO3: 12 | AP3: 1 | AQ3: 1 | AR3: 1 | AS3: 1 | AT3: 2 | AU3: 2 | AV3: 2 | AW3: 2 | AX3: 3 | AY3: 3 | AZ3: 3 | BA3: 3
F4: 残業時間 | G4: 残業時間 | H4: 人員 | I4: 人員 | J4: 残業時間 | K4: 残業時間 | L4: 人員 | M4: 人員 | N4: 残業時間 | O4: 残業時間 | P4: 人員 | Q4: 人員 | R4: 残業時間 | S4: 残業時間 | T4: 人員 | U4: 人員 | V4: 残業時間 | W4: 残業時間 | X4: 人員 | Y4: 人員 | Z4: 残業時間 | AA4: 残業時間 | AB4: 人員 | AC4: 人員 | AD4: 残業時間 | AE4: 残業時間 | AF4: 人員 | AG4: 人員 | AH4: 残業時間 | AI4: 残業時間 | AJ4: 人員 | AK4: 人員 | AL4: 残業時間 | AM4: 残業時間 | AN4: 人員 | AO4: 人員 | AP4: 残業時間 | AQ4: 残業時間 | AR4: 人員 | AS4: 人員 | AT4: 残業時間 | AU4: 残業時間 | AV4: 人員 | AW4: 人員 | AX4: 残業時間 | AY4: 残業時間 | AZ4: 人員 | BA4: 人員
F5: G5以上 | G5: G7, G6 | H5: G5以上 | I5: G7, G6 | J5: G5以上 | K5: G7, G6 | L5: G5以上 | M5: G7, G6 | N5: G5以上 | O5: G7, G6 | P5: G5以上 | Q5: G7, G6 | R5: G5以上 | S5: G7, G6 | T5: G5以上 | U5: G7, G6 | V5: G5以上 | W5: G7, G6 | X5: G5以上 | Y5: G7, G6 | Z5: G5以上 | AA5: G7, G6 | AB5: G5以上 | AC5: G7, G6 | AD5: G5以上 | AE5: G7, G6 | AF5: G5以上 | AG5: G7, G6 | AH5: G5以上 | AI5: G7, G6 | AJ5: G5以上 | AK5: G7, G6 | AL5: G5以上 | AM5: G7, G6 | AN5: G5以上 | AO5: G7, G6 | AP5: G5以上 | AQ5: G7, G6 | AR5: G5以上 | AS5: G7, G6 | AT5: G5以上 | AU5: G7, G6 | AV5: G5以上 | AW5: G7, G6 | AX5: G5以上 | AY5: G7, G6 | AZ5: G5以上 | BA5: G7, G6
B6: Mã TK コード | C6: Tên bộ phận 名前部 | D6: Tên phòng 名前課 | E6: 原価センター | F6: Nhân viên スタップ | G6: Công nhân ワーカー | H6: Nhân viên スタップ | I6: Công nhân ワーカー | J6: Nhân viên スタップ | K6: Công nhân ワーカー | L6: Nhân viên スタップ | M6: Công nhân ワーカー | N6: Nhân viên スタップ | O6: Công nhân ワーカー | P6: Nhân viên スタップ | Q6: Công nhân ワーカー | R6: Nhân viên スタップ | S6: Công nhân ワーカー | T6: Nhân viên スタップ | U6: Công nhân ワーカー | V6: Nhân viên スタップ | W6: Công nhân ワーカー | X6: Nhân viên スタップ | Y6: Công nhân ワーカー | Z6: Nhân viên スタップ | AA6: Công nhân ワーカー | AB6: Nhân viên スタップ | AC6: Công nhân ワーカー | AD6: Nhân viên スタップ | AE6: Công nhân ワーカー | AF6: Nhân viên スタップ | AG6: Công nhân ワーカー | AH6: Nhân viên スタップ | AI6: Công nhân ワーカー | AJ6: Nhân viên スタップ | AK6: Công nhân ワーカー | AL6: Nhân viên スタップ | AM6: Công nhân ワーカー | AN6: Nhân viên スタップ | AO6: Công nhân ワーカー | AP6: Nhân viên スタップ | AQ6: Công nhân ワーカー | AR6: Nhân viên スタップ | AS6: Công nhân ワーカー | AT6: Nhân viên スタップ | AU6: Công nhân ワーカー | AV6: Nhân viên スタップ | AW6: Công nhân ワーカー | AX6: Nhân viên スタップ | AY6: Công nhân ワーカー | AZ6: Nhân viên スタップ | BA6: Công nhân ワーカー
B7: 6221 | C7: =IF($A$1=1,Sheet1!D3,Sheet1!A3) -> 機器製造部
D8: =IF($A$1=1,Sheet1!C4,Sheet1!B4) -> 機器製造1課 | E8: 1412000004 | F8: =[1]人員・時間計画!$C$25 -> 189 | G8: =[1]人員・時間計画!$C$26 -> 721 | H8: =[1]人員・時間計画!$C$11 -> 77 | I8: =[1]人員・時間計画!$C$12 -> 928 | J8: =[1]人員・時間計画!$D$25 -> 221 | K8: =[1]人員・時間計画!$D$26 -> 732 | L8: =[1]人員・時間計画!$D$11 -> 77 | M8: =[1]人員・時間計画!$D$12 -> 965 | N8: =[1]人員・時間計画!$E$25 -> 189 | O8: =[1]人員・時間計画!$E$26 -> 709 | P8: =[1]人員・時間計画!$E$11 -> 77 | Q8: =[1]人員・時間計画!$E$12 -> 961 | R8: =[1]人員・時間計画!$F$25 -> 216 | S8: =[1]人員・時間計画!$F$26 -> 667 | T8: =[1]人員・時間計画!$F$11 -> 85 | U8: =[1]人員・時間計画!$F$12 -> 1105 | V8: =[1]人員・時間計画!$G$25 -> 300 | W8: =[1]人員・時間計画!$G$26 -> 1081 | X8: =[1]人員・時間計画!$G$11 -> 85 | Y8: =[1]人員・時間計画!$G$12 -> 1185 | Z8: =[1]人員・時間計画!$H$25 -> 570 | AA8: =[1]人員・時間計画!$H$26 -> 647 | AB8: =[1]人員・時間計画!$H$11 -> 85 | AC8: =[1]人員・時間計画!$H$12 -> 1450 | AD8: =[1]人員・時間計画!$I$25 -> 271 | AE8: =[1]人員・時間計画!$I$26 -> 615 | AF8: =[1]人員・時間計画!$I$11 -> 85 | AG8: =[1]人員・時間計画!$I$12 -> 1751 | AH8: =[1]人員・時間計画!$J$25 -> 281 | AI8: =[1]人員・時間計画!$J$26 -> 665 | AJ8: =[1]人員・時間計画!$J$11 -> 85 | AK8: =[1]人員・時間計画!$J$12 -> 1757 | AL8: =[1]人員・時間計画!$K$25 -> 345 | AM8: =[1]人員・時間計画!$K$26 -> 555 | AN8: =[1]人員・時間計画!$K$11 -> 85 | AO8: =[1]人員・時間計画!$K$12 -> 1752 | AP8: =[1]人員・時間計画!$L$25 -> 503 | AQ8: =[1]人員・時間計画!$L$26 -> 449 | AR8: =[1]人員・時間計画!$L$11 -> 93 | AS8: =[1]人員・時間計画!$L$12 -> 1772 | AT8: =[1]人員・時間計画!$M$25 -> 1053 | AU8: =[1]人員・時間計画!$M$26 -> 3057 | AV8: =[1]人員・時間計画!$M$11 -> 93 | AW8: =[1]人員・時間計画!$M$12 -> 1962 | AX8: =[1]人員・時間計画!$N$25 -> 423 | AY8: =[1]人員・時間計画!$N$26 -> 769 | AZ8: =[1]人員・時間計画!$N$11 -> 93 | BA8: =[1]人員・時間計画!$N$12 -> 1789
D9: =IF($A$1=1,Sheet1!C5,Sheet1!B5) -> 機器製造2課 | E9: 1412000005 | F9: =[2]人員・時間計画!$C$25 -> 263 | G9: =[2]人員・時間計画!$C$26 -> 2323 | H9: =[2]人員・時間計画!$C$11 -> 100 | I9: =[2]人員・時間計画!$C$12 -> 1514 | J9: =[2]人員・時間計画!$D$25 -> 259 | K9: =[2]人員・時間計画!$D$26 -> 2947 | L9: =[2]人員・時間計画!$D$11 -> 100 | M9: =[2]人員・時間計画!$D$12 -> 1454 | N9: =[2]人員・時間計画!$E$25 -> 267 | O9: =[2]人員・時間計画!$E$26 -> 2207 | P9: =[2]人員・時間計画!$E$11 -> 100 | Q9: =[2]人員・時間計画!$E$12 -> 1418 | R9: =[2]人員・時間計画!$F$25 -> 283 | S9: =[2]人員・時間計画!$F$26 -> 2210 | T9: =[2]人員・時間計画!$F$11 -> 116 | U9: =[2]人員・時間計画!$F$12 -> 1637 | V9: =[2]人員・時間計画!$G$25 -> 356 | W9: =[2]人員・時間計画!$G$26 -> 4741 | X9: =[2]人員・時間計画!$G$11 -> 116 | Y9: =[2]人員・時間計画!$G$12 -> 1688 | Z9: =[2]人員・時間計画!$H$25 -> 939 | AA9: =[2]人員・時間計画!$H$26 -> 17785 | AB9: =[2]人員・時間計画!$H$11 -> 116 | AC9: =[2]人員・時間計画!$H$12 -> 1616 | AD9: =[2]人員・時間計画!$I$25 -> 328 | AE9: =[2]人員・時間計画!$I$26 -> 3215 | AF9: =[2]人員・時間計画!$I$11 -> 116 | AG9: =[2]人員・時間計画!$I$12 -> 1660 | AH9: =[2]人員・時間計画!$J$25 -> 628 | AI9: =[2]人員・時間計画!$J$26 -> 8836 | AJ9: =[2]人員・時間計画!$J$11 -> 116 | AK9: =[2]人員・時間計画!$J$12 -> 1761 | AL9: =[2]人員・時間計画!$K$25 -> 288 | AM9: =[2]人員・時間計画!$K$26 -> 3250 | AN9: =[2]人員・時間計画!$K$11 -> 116 | AO9: =[2]人員・時間計画!$K$12 -> 1714 | AP9: =[2]人員・時間計画!$L$25 -> 372 | AQ9: =[2]人員・時間計画!$L$26 -> 7764 | AR9: =[2]人員・時間計画!$L$11 -> 132 | AS9: =[2]人員・時間計画!$L$12 -> 1862 | AT9: =[2]人員・時間計画!$M$25 -> 1323 | AU9: =[2]人員・時間計画!$M$26 -> 28373 | AV9: =[2]人員・時間計画!$M$11 -> 132 | AW9: =[2]人員・時間計画!$M$12 -> 2010 | AX9: =[2]人員・時間計画!$N$25 -> 360 | AY9: =[2]人員・時間計画!$N$26 -> 5748 | AZ9: =[2]人員・時間計画!$N$11 -> 132 | BA9: =[2]人員・時間計画!$N$12 -> 1761
D10: =IF('6221'!$A$1=1,Sheet1!C7,Sheet1!B7) -> 機器製造3課 | E10: 1412000081 | F10: =[3]人員・時間計画!$C$25 -> 143 | G10: =[3]人員・時間計画!$C$26 -> 391 | H10: =[3]人員・時間計画!$C$11 -> 81 | I10: =[3]人員・時間計画!$C12 -> 1024 | J10: =[3]人員・時間計画!$D$25 -> 137 | K10: =[3]人員・時間計画!$D$26 -> 391 | L10: =[3]人員・時間計画!$D$11 -> 81 | M10: =[3]人員・時間計画!$D12 -> 1000 | N10: =[3]人員・時間計画!$E$25 -> 149 | O10: =[3]人員・時間計画!$E$26 -> 391 | P10: =[3]人員・時間計画!$E$11 -> 81 | Q10: =[3]人員・時間計画!$E12 -> 905 | R10: =[3]人員・時間計画!$F$25 -> 161 | S10: =[3]人員・時間計画!$F$26 -> 690 | T10: =[3]人員・時間計画!$F$11 -> 90 | U10: =[3]人員・時間計画!$F12 -> 1014 | V10: =[3]人員・時間計画!$G$25 -> 427 | W10: =[3]人員・時間計画!$G$26 -> 5273 | X10: =[3]人員・時間計画!$G$11 -> 90 | Y10: =[3]人員・時間計画!$G$12 -> 1058 | Z10: =[3]人員・時間計画!$H$25 -> 1095 | AA10: =[3]人員・時間計画!$H$26 -> 16775 | AB10: =[3]人員・時間計画!$H$11 -> 90 | AC10: =[3]人員・時間計画!$H$12 -> 1070 | AD10: =[3]人員・時間計画!$I$25 -> 258 | AE10: =[3]人員・時間計画!$I$26 -> 2817 | AF10: =[3]人員・時間計画!$I$11 -> 90 | AG10: =[3]人員・時間計画!$I$12 -> 1067 | AH10: =[3]人員・時間計画!$J$25 -> 529 | AI10: =[3]人員・時間計画!$J$26 -> 7150 | AJ10: =[3]人員・時間計画!$J$11 -> 90 | AK10: =[3]人員・時間計画!$J$12 -> 1068 | AL10: =[3]人員・時間計画!$K$25 -> 745 | AM10: =[3]人員・時間計画!$K$26 -> 11318 | AN10: =[3]人員・時間計画!$K$11 -> 90 | AO10: =[3]人員・時間計画!$K$12 -> 1061 | AP10: =[3]人員・時間計画!$L$25 -> 1013 | AQ10: =[3]人員・時間計画!$L$26 -> 15487 | AR10: =[3]人員・時間計画!$L$11 -> 99 | AS10: =[3]人員・時間計画!$L$12 -> 1095 | AT10: =[3]人員・時間計画!$M$25 -> 1952 | AU10: =[3]人員・時間計画!$M$26 -> 31974 | AV10: =[3]人員・時間計画!$M$11 -> 99 | AW10: =[3]人員・時間計画!$M$12 -> 1168 | AX10: =[3]人員・時間計画!$N$25 -> 1669 | AY10: =[3]人員・時間計画!$N$26 -> 26021 | AZ10: =[3]人員・時間計画!$N$11 -> 99 | BA10: =[3]人員・時間計画!$N$12 -> 1123
D11: =IF($A$1=1,Sheet1!C8,Sheet1!B8) -> RPS製造課 | E11: 1412000066 | F11: =[4]人員・時間計画!$C$25 -> 0 | G11: =[4]人員・時間計画!$C$26 -> 0 | H11: =[4]人員・時間計画!$C$11 -> 0 | I11: =[4]人員・時間計画!$C$12 -> 0 | J11: =[4]人員・時間計画!$D$25 -> 0 | K11: =[4]人員・時間計画!$D$26 -> 0 | L11: =[4]人員・時間計画!$D$11 -> 0 | M11: =[4]人員・時間計画!$D$12 -> 0 | N11: =[4]人員・時間計画!$E$25 -> 0 | O11: =[4]人員・時間計画!$E$26 -> 0 | P11: =[4]人員・時間計画!$E$11 -> 0 | Q11: =[4]人員・時間計画!$E$12 -> 0 | R11: =[4]人員・時間計画!$F$25 -> 0 | S11: =[4]人員・時間計画!$F$26 -> 0 | T11: =[4]人員・時間計画!$F$11 -> 0 | U11: =[4]人員・時間計画!$F$12 -> 0 | V11: =[4]人員・時間計画!$G$25 -> 0 | W11: =[4]人員・時間計画!$G$26 -> 0 | X11: =[4]人員・時間計画!$G$11 -> 0 | Y11: =[4]人員・時間計画!$G$12 -> 0 | Z11: =[4]人員・時間計画!$H$25 -> 0 | AA11: =[4]人員・時間計画!$H$26 -> 0 | AB11: =[4]人員・時間計画!$H$11 -> 0 | AC11: =[4]人員・時間計画!$H$12 -> 0 | AD11: =[4]人員・時間計画!$I$25 -> 0 | AE11: =[4]人員・時間計画!$I$26 -> 0 | AF11: =[4]人員・時間計画!$I$11 -> 0 | AG11: =[4]人員・時間計画!$I$12 -> 0 | AH11: =[4]人員・時間計画!$J$25 -> 0 | AI11: =[4]人員・時間計画!$J$26 -> 0 | AJ11: =[4]人員・時間計画!$J$11 -> 0 | AK11: =[4]人員・時間計画!$J$12 -> 0 | AL11: =[4]人員・時間計画!$K$25 -> 0 | AM11: =[4]人員・時間計画!$K$26 -> 0 | AN11: =[4]人員・時間計画!$K$11 -> 0 | AO11: =[4]人員・時間計画!$K$12 -> 0 | AP11: =[4]人員・時間計画!$L$25 -> 0 | AQ11: =[4]人員・時間計画!$L$26 -> 0 | AR11: =[4]人員・時間計画!$L$11 -> 0 | AS11: =[4]人員・時間計画!$L$12 -> 0 | AT11: =[4]人員・時間計画!$M$25 -> 0 | AU11: =[4]人員・時間計画!$M$26 -> 0 | AV11: =[4]人員・時間計画!$M$11 -> 0 | AW11: =[4]人員・時間計画!$M$12 -> 0 | AX11: =[4]人員・時間計画!$N$25 -> 0 | AY11: =[4]人員・時間計画!$N$26 -> 0 | AZ11: =[4]人員・時間計画!$N$11 -> 0 | BA11: =[4]人員・時間計画!$N$12 -> 0
B12: 6221 | C12: =IF($A$1=1,Sheet1!D13,Sheet1!A13) -> トナー製造部
D13: =IF($A$1=1,Sheet1!C14,Sheet1!B14) -> トナー製造課 | E13: 1412000034 | F13: =[5]人員・時間計画!$C$25 -> 76 | G13: =[5]人員・時間計画!$C$26 -> 0 | H13: =[5]人員・時間計画!$C$11 -> 22 | I13: =[5]人員・時間計画!$C$12 -> 297 | J13: =[5]人員・時間計画!$D$25 -> 104 | K13: =[5]人員・時間計画!$D$26 -> 720 | L13: =[5]人員・時間計画!$D$11 -> 22 | M13: =[5]人員・時間計画!$D$12 -> 297 | N13: =[5]人員・時間計画!$E$25 -> 112 | O13: =[5]人員・時間計画!$E$26 -> 304 | P13: =[5]人員・時間計画!$E$11 -> 22 | Q13: =[5]人員・時間計画!$E$12 -> 298 | R13: =[5]人員・時間計画!$F$25 -> 184 | S13: =[5]人員・時間計画!$F$26 -> 2384 | T13: =[5]人員・時間計画!$F$11 -> 22 | U13: =[5]人員・時間計画!$F$12 -> 298 | V13: =[5]人員・時間計画!$G$25 -> 132 | W13: =[5]人員・時間計画!$G$26 -> 1240 | X13: =[5]人員・時間計画!$G$11 -> 22 | Y13: =[5]人員・時間計画!$G$12 -> 306 | Z13: =[5]人員・時間計画!$H$25 -> 136 | AA13: =[5]人員・時間計画!$H$26 -> 2064 | AB13: =[5]人員・時間計画!$H$11 -> 22 | AC13: =[5]人員・時間計画!$H$12 -> 314 | AD13: =[5]人員・時間計画!$I$25 -> 160 | AE13: =[5]人員・時間計画!$I$26 -> 1656 | AF13: =[5]人員・時間計画!$I$11 -> 22 | AG13: =[5]人員・時間計画!$I$12 -> 314 | AH13: =[5]人員・時間計画!$J$25 -> 164 | AI13: =[5]人員・時間計画!$J$26 -> 1352 | AJ13: =[5]人員・時間計画!$J$11 -> 22 | AK13: =[5]人員・時間計画!$J$12 -> 314 | AL13: =[5]人員・時間計画!$K$25 -> 132 | AM13: =[5]人員・時間計画!$K$26 -> 1248 | AN13: =[5]人員・時間計画!$K$11 -> 22 | AO13: =[5]人員・時間計画!$K$12 -> 314 | AP13: =[5]人員・時間計画!$L$25 -> 180 | AQ13: =[5]人員・時間計画!$L$26 -> 2376 | AR13: =[5]人員・時間計画!$L$11 -> 22 | AS13: =[5]人員・時間計画!$L$12 -> 314 | AT13: =[5]人員・時間計画!$M$25 -> 136 | AU13: =[5]人員・時間計画!$M$26 -> 1968 | AV13: =[5]人員・時間計画!$M$11 -> 22 | AW13: =[5]人員・時間計画!$M$12 -> 324 | AX13: =[5]人員・時間計画!$N$25 -> 124 | AY13: =[5]人員・時間計画!$N$26 -> 936 | AZ13: =[5]人員・時間計画!$N$11 -> 22 | BA13: =[5]人員・時間計画!$N$12 -> 324
B14: 6221 | C14: =IF($A$1=1,Sheet1!D18,Sheet1!A18) -> 部品製造部
D15: =IF($A$1=1,Sheet1!C19,Sheet1!B19) -> 部品製造課 | E15: 1412000056 | F15: =[6]人員・時間計画!$C$25 -> 56 | G15: =[6]人員・時間計画!$C$26 -> 1300 | H15: =[6]人員・時間計画!$C$11 -> 16 | I15: =[6]人員・時間計画!$C$12 -> 125 | J15: =[6]人員・時間計画!$D$25 -> 56 | K15: =[6]人員・時間計画!$D$26 -> 1300 | L15: =[6]人員・時間計画!$D$11 -> 16 | M15: =[6]人員・時間計画!$D$12 -> 125 | N15: =[6]人員・時間計画!$E$25 -> 56 | O15: =[6]人員・時間計画!$E$26 -> 1300 | P15: =[6]人員・時間計画!$E$11 -> 16 | Q15: =[6]人員・時間計画!$E$12 -> 125 | R15: =[6]人員・時間計画!$F$25 -> 172 | S15: =[6]人員・時間計画!$F$26 -> 1300 | T15: =[6]人員・時間計画!$F$11 -> 16 | U15: =[6]人員・時間計画!$F$12 -> 125 | V15: =[6]人員・時間計画!$G$25 -> 112 | W15: =[6]人員・時間計画!$G$26 -> 1400 | X15: =[6]人員・時間計画!$G$11 -> 16 | Y15: =[6]人員・時間計画!$G$12 -> 125 | Z15: =[6]人員・時間計画!$H$25 -> 112 | AA15: =[6]人員・時間計画!$H$26 -> 1400 | AB15: =[6]人員・時間計画!$H$11 -> 16 | AC15: =[6]人員・時間計画!$H$12 -> 125 | AD15: =[6]人員・時間計画!$I$25 -> 116 | AE15: =[6]人員・時間計画!$I$26 -> 1300 | AF15: =[6]人員・時間計画!$I$11 -> 16 | AG15: =[6]人員・時間計画!$I$12 -> 125 | AH15: =[6]人員・時間計画!$J$25 -> 116 | AI15: =[6]人員・時間計画!$J$26 -> 1400 | AJ15: =[6]人員・時間計画!$J$11 -> 16 | AK15: =[6]人員・時間計画!$J$12 -> 125 | AL15: =[6]人員・時間計画!$K$25 -> 112 | AM15: =[6]人員・時間計画!$K$26 -> 1300 | AN15: =[6]人員・時間計画!$K$11 -> 16 | AO15: =[6]人員・時間計画!$K$12 -> 125 | AP15: =[6]人員・時間計画!$L$25 -> 56 | AQ15: =[6]人員・時間計画!$L$26 -> 1300 | AR15: =[6]人員・時間計画!$L$11 -> 16 | AS15: =[6]人員・時間計画!$L$12 -> 125 | AT15: =[6]人員・時間計画!$M$25 -> 172 | AU15: =[6]人員・時間計画!$M$26 -> 1400 | AV15: =[6]人員・時間計画!$M$11 -> 16 | AW15: =[6]人員・時間計画!$M$12 -> 125 | AX15: =[6]人員・時間計画!$N$25 -> 172 | AY15: =[6]人員・時間計画!$N$26 -> 1400 | AZ15: =[6]人員・時間計画!$N$11 -> 16 | BA15: =[6]人員・時間計画!$N$12 -> 125
B16: 6221 | C16: 電工製造部
D17: 電工製造課 | E17: 1412000098 | F17: ='[7]人員・時間計画 '!$C$25 -> 147 | G17: ='[7]人員・時間計画 '!$C$26 -> 107 | H17: ='[7]人員・時間計画 '!$C$11 -> 15 | I17: ='[7]人員・時間計画 '!$C$12 -> 14 | J17: ='[7]人員・時間計画 '!$D$25 -> 245 | K17: ='[7]人員・時間計画 '!$D$26 -> 207 | L17: ='[7]人員・時間計画 '!$D$11 -> 15 | M17: ='[7]人員・時間計画 '!$D$12 -> 14 | N17: ='[7]人員・時間計画 '!$E$25 -> 234 | O17: ='[7]人員・時間計画 '!$E$26 -> 192 | P17: ='[7]人員・時間計画 '!$E$11 -> 15 | Q17: ='[7]人員・時間計画 '!$E$12 -> 14 | R17: ='[7]人員・時間計画 '!$F$25 -> 467 | S17: ='[7]人員・時間計画 '!$F$26 -> 421 | T17: ='[7]人員・時間計画 '!$F$11 -> 15 | U17: ='[7]人員・時間計画 '!$F$12 -> 29 | V17: ='[7]人員・時間計画 '!$G$25 -> 352 | W17: ='[7]人員・時間計画 '!$G$26 -> 312 | X17: ='[7]人員・時間計画 '!$G$11 -> 15 | Y17: ='[7]人員・時間計画 '!$G$12 -> 29 | Z17: ='[7]人員・時間計画 '!$H$25 -> 38 | AA17: ='[7]人員・時間計画 '!$H$26 -> 0 | AB17: ='[7]人員・時間計画 '!$H$11 -> 15 | AC17: ='[7]人員・時間計画 '!$H$12 -> 29 | AD17: ='[7]人員・時間計画 '!$I$25 -> 46 | AE17: ='[7]人員・時間計画 '!$I$26 -> 0 | AF17: ='[7]人員・時間計画 '!$I$11 -> 15 | AG17: ='[7]人員・時間計画 '!$I$12 -> 30 | AH17: ='[7]人員・時間計画 '!$J$25 -> 40 | AI17: ='[7]人員・時間計画 '!$J$26 -> 0 | AJ17: ='[7]人員・時間計画 '!$J$11 -> 15 | AK17: ='[7]人員・時間計画 '!$J$12 -> 30 | AL17: ='[7]人員・時間計画 '!$K$25 -> 42 | AM17: ='[7]人員・時間計画 '!$K$26 -> 0 | AN17: ='[7]人員・時間計画 '!$K$11 -> 15 | AO17: ='[7]人員・時間計画 '!$K$12 -> 30 | AP17: ='[7]人員・時間計画 '!$L$25 -> 40 | AQ17: ='[7]人員・時間計画 '!$L$26 -> 0 | AR17: ='[7]人員・時間計画 '!$L$11 -> 15 | AS17: ='[7]人員・時間計画 '!$L$12 -> 43 | AT17: ='[7]人員・時間計画 '!$M$25 -> 419 | AU17: ='[7]人員・時間計画 '!$M$26 -> 389 | AV17: ='[7]人員・時間計画 '!$M$11 -> 15 | AW17: ='[7]人員・時間計画 '!$M$12 -> 43 | AX17: ='[7]人員・時間計画 '!$N$25 -> 40 | AY17: ='[7]人員・時間計画 '!$N$26 -> 0 | AZ17: ='[7]人員・時間計画 '!$N$11 -> 15 | BA17: ='[7]人員・時間計画 '!$N$12 -> 43
B18: 6221 | C18: =IF($A$1=1,Sheet1!D50,Sheet1!A50) -> 製品開発部
D19: =IF($A$1=1,Sheet1!C51,Sheet1!B51) -> MD1課 | E19: 1412000050 | F19: =[8]人員・時間計画!$C$25 -> 170 | G19: =[8]人員・時間計画!$C$26 -> 0 | H19: =[8]人員・時間計画!$C$11 -> 8 | I19: =[8]人員・時間計画!$C$12 -> 0 | J19: =[8]人員・時間計画!$D$25 -> 166 | K19: =[8]人員・時間計画!$D$26 -> 0 | L19: =[8]人員・時間計画!$D$11 -> 8 | M19: =[8]人員・時間計画!$D$12 -> 0 | N19: =[8]人員・時間計画!$E$25 -> 174 | O19: =[8]人員・時間計画!$E$26 -> 0 | P19: =[8]人員・時間計画!$E$11 -> 8 | Q19: =[8]人員・時間計画!$E$12 -> 0 | R19: =[8]人員・時間計画!$F$25 -> 182 | S19: =[8]人員・時間計画!$F$26 -> 0 | T19: =[8]人員・時間計画!$F$11 -> 8 | U19: =[8]人員・時間計画!$F$12 -> 0 | V19: =[8]人員・時間計画!$G$25 -> 170 | W19: =[8]人員・時間計画!$G$26 -> 0 | X19: =[8]人員・時間計画!$G$11 -> 8 | Y19: =[8]人員・時間計画!$G$12 -> 0 | Z19: =[8]人員・時間計画!$H$25 -> 166 | AA19: =[8]人員・時間計画!$H$26 -> 0 | AB19: =[8]人員・時間計画!$H$11 -> 9 | AC19: =[8]人員・時間計画!$H$12 -> 0 | AD19: =[8]人員・時間計画!$I$25 -> 182 | AE19: =[8]人員・時間計画!$I$26 -> 0 | AF19: =[8]人員・時間計画!$I$11 -> 9 | AG19: =[8]人員・時間計画!$I$12 -> 0 | AH19: =[8]人員・時間計画!$J$25 -> 170 | AI19: =[8]人員・時間計画!$J$26 -> 0 | AJ19: =[8]人員・時間計画!$J$11 -> 9 | AK19: =[8]人員・時間計画!$J$12 -> 0 | AL19: =[8]人員・時間計画!$K$25 -> 178 | AM19: =[8]人員・時間計画!$K$26 -> 0 | AN19: =[8]人員・時間計画!$K$11 -> 9 | AO19: =[8]人員・時間計画!$K$12 -> 0 | AP19: =[8]人員・時間計画!$L$25 -> 170 | AQ19: =[8]人員・時間計画!$L$26 -> 0 | AR19: =[8]人員・時間計画!$L$11 -> 9 | AS19: =[8]人員・時間計画!$L$12 -> 0 | AT19: =[8]人員・時間計画!$M$25 -> 150 | AU19: =[8]人員・時間計画!$M$26 -> 0 | AV19: =[8]人員・時間計画!$M$11 -> 9 | AW19: =[8]人員・時間計画!$M$12 -> 0 | AX19: =[8]人員・時間計画!$N$25 -> 170 | AY19: =[8]人員・時間計画!$N$26 -> 0 | AZ19: =[8]人員・時間計画!$N$11 -> 9 | BA19: =[8]人員・時間計画!$N$12 -> 0
D20: =IF($A$1=1,Sheet1!C52,Sheet1!B52) -> MD2課 | E20: 1412000077 | F20: =[9]人員・時間計画!$C$25 -> 144 | G20: =[9]人員・時間計画!$C$26 -> 0 | H20: =[9]人員・時間計画!$C$11 -> 9 | I20: =[9]人員・時間計画!$C$12 -> 0 | J20: =[9]人員・時間計画!$D$25 -> 142 | K20: =[9]人員・時間計画!$D$26 -> 0 | L20: =[9]人員・時間計画!$D$11 -> 9 | M20: =[9]人員・時間計画!$D$12 -> 0 | N20: =[9]人員・時間計画!$E$25 -> 146 | O20: =[9]人員・時間計画!$E$26 -> 0 | P20: =[9]人員・時間計画!$E$11 -> 9 | Q20: =[9]人員・時間計画!$E$12 -> 0 | R20: =[9]人員・時間計画!$F$25 -> 150 | S20: =[9]人員・時間計画!$F$26 -> 0 | T20: =[9]人員・時間計画!$F$11 -> 9 | U20: =[9]人員・時間計画!$F$12 -> 0 | V20: =[9]人員・時間計画!$G$25 -> 144 | W20: =[9]人員・時間計画!$G$26 -> 0 | X20: =[9]人員・時間計画!$G$11 -> 9 | Y20: =[9]人員・時間計画!$G$12 -> 0 | Z20: =[9]人員・時間計画!$H$25 -> 142 | AA20: =[9]人員・時間計画!$H$26 -> 0 | AB20: =[9]人員・時間計画!$H$11 -> 9 | AC20: =[9]人員・時間計画!$H$12 -> 0 | AD20: =[9]人員・時間計画!$I$25 -> 150 | AE20: =[9]人員・時間計画!$I$26 -> 0 | AF20: =[9]人員・時間計画!$I$11 -> 9 | AG20: =[9]人員・時間計画!$I$12 -> 0 | AH20: =[9]人員・時間計画!$J$25 -> 144 | AI20: =[9]人員・時間計画!$J$26 -> 0 | AJ20: =[9]人員・時間計画!$J$11 -> 9 | AK20: =[9]人員・時間計画!$J$12 -> 0 | AL20: =[9]人員・時間計画!$K$25 -> 148 | AM20: =[9]人員・時間計画!$K$26 -> 0 | AN20: =[9]人員・時間計画!$K$11 -> 9 | AO20: =[9]人員・時間計画!$K$12 -> 0 | AP20: =[9]人員・時間計画!$L$25 -> 144 | AQ20: =[9]人員・時間計画!$L$26 -> 0 | AR20: =[9]人員・時間計画!$L$11 -> 9 | AS20: =[9]人員・時間計画!$L$12 -> 0 | AT20: =[9]人員・時間計画!$M$25 -> 134 | AU20: =[9]人員・時間計画!$M$26 -> 0 | AV20: =[9]人員・時間計画!$M$11 -> 9 | AW20: =[9]人員・時間計画!$M$12 -> 0 | AX20: =[9]人員・時間計画!$N$25 -> 144 | AY20: =[9]人員・時間計画!$N$26 -> 0 | AZ20: =[9]人員・時間計画!$N$11 -> 9 | BA20: =[9]人員・時間計画!$N$12 -> 0
D21: =IF($A$1=1,Sheet1!C53,Sheet1!B53) -> MD3課 | E21: 1412000083 | F21: =[10]人員・時間計画!$C$25 -> 130 | G21: =[10]人員・時間計画!$C$26 -> 0 | H21: =[10]人員・時間計画!$C$11 -> 11 | I21: =[10]人員・時間計画!$C$12 -> 0 | J21: =[10]人員・時間計画!$D$25 -> 128 | K21: =[10]人員・時間計画!$D$26 -> 0 | L21: =[10]人員・時間計画!$D$11 -> 11 | M21: =[10]人員・時間計画!$D$12 -> 0 | N21: =[10]人員・時間計画!$E$25 -> 132 | O21: =[10]人員・時間計画!$E$26 -> 0 | P21: =[10]人員・時間計画!$E$11 -> 11 | Q21: =[10]人員・時間計画!$E$12 -> 0 | R21: =[10]人員・時間計画!$F$25 -> 136 | S21: =[10]人員・時間計画!$F$26 -> 0 | T21: =[10]人員・時間計画!$F$11 -> 11 | U21: =[10]人員・時間計画!$F$12 -> 0 | V21: =[10]人員・時間計画!$G$25 -> 140 | W21: =[10]人員・時間計画!$G$26 -> 0 | X21: =[10]人員・時間計画!$G$11 -> 11 | Y21: =[10]人員・時間計画!$G$12 -> 0 | Z21: =[10]人員・時間計画!$H$25 -> 138 | AA21: =[10]人員・時間計画!$H$26 -> 0 | AB21: =[10]人員・時間計画!$H$11 -> 11 | AC21: =[10]人員・時間計画!$H$12 -> 0 | AD21: =[10]人員・時間計画!$I$25 -> 146 | AE21: =[10]人員・時間計画!$I$26 -> 0 | AF21: =[10]人員・時間計画!$I$11 -> 11 | AG21: =[10]人員・時間計画!$I$12 -> 0 | AH21: =[10]人員・時間計画!$J$25 -> 140 | AI21: =[10]人員・時間計画!$J$26 -> 0 | AJ21: =[10]人員・時間計画!$J$11 -> 11 | AK21: =[10]人員・時間計画!$J$12 -> 0 | AL21: =[10]人員・時間計画!$K$25 -> 144 | AM21: =[10]人員・時間計画!$K$26 -> 0 | AN21: =[10]人員・時間計画!$K$11 -> 11 | AO21: =[10]人員・時間計画!$K$12 -> 0 | AP21: =[10]人員・時間計画!$L$25 -> 140 | AQ21: =[10]人員・時間計画!$L$26 -> 0 | AR21: =[10]人員・時間計画!$L$11 -> 11 | AS21: =[10]人員・時間計画!$L$12 -> 0 | AT21: =[10]人員・時間計画!$M$25 -> 130 | AU21: =[10]人員・時間計画!$M$26 -> 0 | AV21: =[10]人員・時間計画!$M$11 -> 11 | AW21: =[10]人員・時間計画!$M$12 -> 0 | AX21: =[10]人員・時間計画!$N$25 -> 140 | AY21: =[10]人員・時間計画!$N$26 -> 0 | AZ21: =[10]人員・時間計画!$N$11 -> 11 | BA21: =[10]人員・時間計画!$N$12 -> 0
D22: =IF($A$1=1,Sheet1!C54,Sheet1!B54) -> MD4課 | E22: 1412000099 | F22: =[11]人員・時間計画!$C25 -> 124 | G22: =[11]人員・時間計画!$C26 -> 0 | H22: =[11]人員・時間計画!$C11 -> 15 | I22: =[11]人員・時間計画!$C12 -> 0 | J22: =[11]人員・時間計画!$D25 -> 122 | K22: =[11]人員・時間計画!$D$26 -> 0 | L22: =[11]人員・時間計画!$D$11 -> 15 | M22: =[11]人員・時間計画!$D$12 -> 0 | N22: =[11]人員・時間計画!E25 -> 114 | O22: =[11]人員・時間計画!$E26 -> 0 | P22: =[11]人員・時間計画!$E$11 -> 15 | Q22: =[11]人員・時間計画!$E$12 -> 0 | R22: =[11]人員・時間計画!$F25 -> 118 | S22: =[11]人員・時間計画!$F26 -> 0 | T22: =[11]人員・時間計画!$F$11 -> 15 | U22: =[11]人員・時間計画!$F$12 -> 0 | V22: =[11]人員・時間計画!G25 -> 112 | W22: =[11]人員・時間計画!$G26 -> 0 | X22: =[11]人員・時間計画!$G$11 -> 15 | Y22: =[11]人員・時間計画!$G$12 -> 0 | Z22: =[11]人員・時間計画!H25 -> 110 | AA22: =[11]人員・時間計画!$H26 -> 0 | AB22: =[11]人員・時間計画!$H$11 -> 15 | AC22: =[11]人員・時間計画!$H$12 -> 0 | AD22: =[11]人員・時間計画!$I25 -> 118 | AE22: =[11]人員・時間計画!$I26 -> 0 | AF22: =[11]人員・時間計画!$I$11 -> 15 | AG22: =[11]人員・時間計画!$I$12 -> 0 | AH22: =[11]人員・時間計画!$J25 -> 112 | AI22: =[11]人員・時間計画!$J26 -> 0 | AJ22: =[11]人員・時間計画!$J$11 -> 15 | AK22: =[11]人員・時間計画!$J$12 -> 0 | AL22: =[11]人員・時間計画!$K25 -> 116 | AM22: =[11]人員・時間計画!$K26 -> 0 | AN22: =[11]人員・時間計画!$K$11 -> 15 | AO22: =[11]人員・時間計画!$K$12 -> 0 | AP22: =[11]人員・時間計画!$L25 -> 112 | AQ22: =[11]人員・時間計画!$L26 -> 0 | AR22: =[11]人員・時間計画!$L$11 -> 15 | AS22: =[11]人員・時間計画!$L$12 -> 0 | AT22: =[11]人員・時間計画!$M25 -> 102 | AU22: =[11]人員・時間計画!$M26 -> 0 | AV22: =[11]人員・時間計画!$M$11 -> 15 | AW22: =[11]人員・時間計画!$M$12 -> 0 | AX22: =[11]人員・時間計画!$N25 -> 112 | AY22: =[11]人員・時間計画!$N26 -> 0 | AZ22: =[11]人員・時間計画!$N$11 -> 15 | BA22: =[11]人員・時間計画!$N$12 -> 0
D23: =IF($A$1=1,Sheet1!C55,Sheet1!B55) -> MD5課 | F23: =[12]人員・時間計画!$C$25 -> 180 | G23: =[12]人員・時間計画!$C$26 -> 0 | H23: =[12]人員・時間計画!$C$11 -> 7 | I23: =[12]人員・時間計画!$C$12 -> 0 | J23: =[12]人員・時間計画!$D$25 -> 171 | K23: =[12]人員・時間計画!$D$26 -> 0 | L23: =[12]人員・時間計画!$D$11 -> 7 | M23: =[12]人員・時間計画!$D$12 -> 0 | N23: =[12]人員・時間計画!$E$25 -> 189 | O23: =[12]人員・時間計画!$E$26 -> 0 | P23: =[12]人員・時間計画!$E$11 -> 7 | Q23: =[12]人員・時間計画!$E$12 -> 0 | R23: =[12]人員・時間計画!$F$25 -> 207 | S23: =[12]人員・時間計画!$F$26 -> 0 | T23: =[12]人員・時間計画!$F$11 -> 7 | U23: =[12]人員・時間計画!$F$12 -> 0 | V23: =[12]人員・時間計画!$G$25 -> 180 | W23: =[12]人員・時間計画!$G$26 -> 0 | X23: =[12]人員・時間計画!$G$11 -> 7 | Y23: =[12]人員・時間計画!$G$12 -> 0 | Z23: =[12]人員・時間計画!$H$25 -> 171 | AA23: =[12]人員・時間計画!$H$26 -> 0 | AB23: =[12]人員・時間計画!$H$11 -> 7 | AC23: =[12]人員・時間計画!$H$12 -> 0 | AD23: =[12]人員・時間計画!$I$25 -> 207 | AE23: =[12]人員・時間計画!$I$26 -> 0 | AF23: =[12]人員・時間計画!$I$11 -> 7 | AG23: =[12]人員・時間計画!$I$12 -> 0 | AH23: =[12]人員・時間計画!$J$25 -> 180 | AI23: =[12]人員・時間計画!$J$26 -> 0 | AJ23: =[12]人員・時間計画!$J$11 -> 7 | AK23: =[12]人員・時間計画!$J$12 -> 0 | AL23: =[12]人員・時間計画!$K$25 -> 198 | AM23: =[12]人員・時間計画!$K$26 -> 0 | AN23: =[12]人員・時間計画!$K$11 -> 7 | AO23: =[12]人員・時間計画!$K$12 -> 0 | AP23: =[12]人員・時間計画!$L$25 -> 180 | AQ23: =[12]人員・時間計画!$L$26 -> 0 | AR23: =[12]人員・時間計画!$L$11 -> 7 | AS23: =[12]人員・時間計画!$L$12 -> 0 | AT23: =[12]人員・時間計画!$M$25 -> 135 | AU23: =[12]人員・時間計画!$M$26 -> 0 | AV23: =[12]人員・時間計画!$M$11 -> 7 | AW23: =[12]人員・時間計画!$M$12 -> 0 | AX23: =[12]人員・時間計画!$N$25 -> 180 | AY23: =[12]人員・時間計画!$N$26 -> 0 | AZ23: =[12]人員・時間計画!$N$11 -> 7 | BA23: =[12]人員・時間計画!$N$12 -> 0
D24: =IF($A$1=1,Sheet1!C56,Sheet1!B56) -> EI1課 | E24: 1412000057 | F24: =[13]人員・時間計画!$C$25 -> 180 | G24: =[13]人員・時間計画!$C$26 -> 0 | H24: =[13]人員・時間計画!$C$11 -> 9 | I24: =[13]人員・時間計画!$C$12 -> 0 | J24: =[13]人員・時間計画!$D$25 -> 178 | K24: =[13]人員・時間計画!$D$26 -> 0 | L24: =[13]人員・時間計画!$D$11 -> 9 | M24: =[13]人員・時間計画!$D$12 -> 0 | N24: =[13]人員・時間計画!$E$25 -> 182 | O24: =[13]人員・時間計画!$E$26 -> 0 | P24: =[13]人員・時間計画!$E$11 -> 9 | Q24: =[13]人員・時間計画!$E$12 -> 0 | R24: =[13]人員・時間計画!$F$25 -> 186 | S24: =[13]人員・時間計画!$F$26 -> 0 | T24: =[13]人員・時間計画!$F$11 -> 9 | U24: =[13]人員・時間計画!$F$12 -> 0 | V24: =[13]人員・時間計画!$G$25 -> 180 | W24: =[13]人員・時間計画!$G$26 -> 0 | X24: =[13]人員・時間計画!$G$11 -> 9 | Y24: =[13]人員・時間計画!$G$12 -> 0 | Z24: =[13]人員・時間計画!$H$25 -> 178 | AA24: =[13]人員・時間計画!$H$26 -> 0 | AB24: =[13]人員・時間計画!$H$11 -> 10 | AC24: =[13]人員・時間計画!$H$12 -> 0 | AD24: =[13]人員・時間計画!$I$25 -> 186 | AE24: =[13]人員・時間計画!$I$26 -> 0 | AF24: =[13]人員・時間計画!$I$11 -> 10 | AG24: =[13]人員・時間計画!$I$12 -> 0 | AH24: =[13]人員・時間計画!$J$25 -> 180 | AI24: =[13]人員・時間計画!$J$26 -> 0 | AJ24: =[13]人員・時間計画!$J$11 -> 10 | AK24: =[13]人員・時間計画!$J$12 -> 0 | AL24: =[13]人員・時間計画!$K$25 -> 184 | AM24: =[13]人員・時間計画!$K$26 -> 0 | AN24: =[13]人員・時間計画!$K$11 -> 10 | AO24: =[13]人員・時間計画!$K$12 -> 0 | AP24: =[13]人員・時間計画!$L$25 -> 180 | AQ24: =[13]人員・時間計画!$L$26 -> 0 | AR24: =[13]人員・時間計画!$L$11 -> 10 | AS24: =[13]人員・時間計画!$L$12 -> 0 | AT24: =[13]人員・時間計画!$M$25 -> 170 | AU24: =[13]人員・時間計画!$M$26 -> 0 | AV24: =[13]人員・時間計画!$M$11 -> 10 | AW24: =[13]人員・時間計画!$M$12 -> 0 | AX24: =[13]人員・時間計画!$N$25 -> 180 | AY24: =[13]人員・時間計画!$N$26 -> 0 | AZ24: =[13]人員・時間計画!$N$11 -> 10 | BA24: =[13]人員・時間計画!$N$12 -> 0
D25: =IF($A$1=1,Sheet1!C57,Sheet1!B57) -> EI2課 | F25: =[14]人員・時間計画!$C$25 -> 100 | G25: =[14]人員・時間計画!$C$26 -> 0 | H25: =[14]人員・時間計画!$C$11 -> 7 | I25: =[14]人員・時間計画!$C$12 -> 0 | J25: =[14]人員・時間計画!$D$25 -> 100 | K25: =[14]人員・時間計画!$D$26 -> 0 | L25: =[14]人員・時間計画!$D$11 -> 7 | M25: =[14]人員・時間計画!$D$12 -> 0 | N25: =[14]人員・時間計画!$E$25 -> 100 | O25: =[14]人員・時間計画!$E$26 -> 0 | P25: =[14]人員・時間計画!$E$11 -> 7 | Q25: =[14]人員・時間計画!$E$12 -> 0 | R25: =[14]人員・時間計画!$F$25 -> 100 | S25: =[14]人員・時間計画!$F$26 -> 0 | T25: =[14]人員・時間計画!$F$11 -> 7 | U25: =[14]人員・時間計画!$F$12 -> 0 | V25: =[14]人員・時間計画!$G$25 -> 100 | W25: =[14]人員・時間計画!$G$26 -> 0 | X25: =[14]人員・時間計画!$G$11 -> 7 | Y25: =[14]人員・時間計画!$G$12 -> 0 | Z25: =[14]人員・時間計画!$H$25 -> 100 | AA25: =[14]人員・時間計画!$H$26 -> 0 | AB25: =[14]人員・時間計画!$H$11 -> 8 | AC25: =[14]人員・時間計画!$H$12 -> 0 | AD25: =[14]人員・時間計画!$I$25 -> 100 | AE25: =[14]人員・時間計画!$I$26 -> 0 | AF25: =[14]人員・時間計画!$I$11 -> 8 | AG25: =[14]人員・時間計画!$I$12 -> 0 | AH25: =[14]人員・時間計画!$J$25 -> 100 | AI25: =[14]人員・時間計画!$J$26 -> 0 | AJ25: =[14]人員・時間計画!$J$11 -> 8 | AK25: =[14]人員・時間計画!$J$12 -> 0 | AL25: =[14]人員・時間計画!$K$25 -> 100 | AM25: =[14]人員・時間計画!$K$26 -> 0 | AN25: =[14]人員・時間計画!$K$11 -> 8 | AO25: =[14]人員・時間計画!$K$12 -> 0 | AP25: =[14]人員・時間計画!$L$25 -> 100 | AQ25: =[14]人員・時間計画!$L$26 -> 0 | AR25: =[14]人員・時間計画!$L$11 -> 8 | AS25: =[14]人員・時間計画!$L$12 -> 0 | AT25: =[14]人員・時間計画!$M$25 -> 100 | AU25: =[14]人員・時間計画!$M$26 -> 0 | AV25: =[14]人員・時間計画!$M$11 -> 8 | AW25: =[14]人員・時間計画!$M$12 -> 0 | AX25: =[14]人員・時間計画!$N$25 -> 100 | AY25: =[14]人員・時間計画!$N$26 -> 0 | AZ25: =[14]人員・時間計画!$N$11 -> 8 | BA25: =[14]人員・時間計画!$N$12 -> 0
D26: =IF($A$1=1,Sheet1!C58,Sheet1!B58) -> ESD1課 | E26: 1412000078 | F26: =[15]人員・時間計画!$C$25 -> 148 | G26: =[15]人員・時間計画!$C$26 -> 0 | H26: =[15]人員・時間計画!$C$11 -> 11 | I26: =[15]人員・時間計画!$C$12 -> 0 | J26: =[15]人員・時間計画!$D$25 -> 146 | K26: =[15]人員・時間計画!$D$26 -> 0 | L26: =[15]人員・時間計画!$D$11 -> 11 | M26: =[15]人員・時間計画!$D$12 -> 0 | N26: =[15]人員・時間計画!$E$25 -> 150 | O26: =[15]人員・時間計画!$E$26 -> 0 | P26: =[15]人員・時間計画!$E$11 -> 11 | Q26: =[15]人員・時間計画!$E$12 -> 0 | R26: =[15]人員・時間計画!$F$25 -> 154 | S26: =[15]人員・時間計画!$F$26 -> 0 | T26: =[15]人員・時間計画!$F$11 -> 11 | U26: =[15]人員・時間計画!$F$12 -> 0 | V26: =[15]人員・時間計画!$G$25 -> 148 | W26: =[15]人員・時間計画!$G$26 -> 0 | X26: =[15]人員・時間計画!$G$11 -> 11 | Y26: =[15]人員・時間計画!$G$12 -> 0 | Z26: =[15]人員・時間計画!$H$25 -> 146 | AA26: =[15]人員・時間計画!$H$26 -> 0 | AB26: =[15]人員・時間計画!$H$11 -> 13 | AC26: =[15]人員・時間計画!$H$12 -> 0 | AD26: =[15]人員・時間計画!$I$25 -> 181 | AE26: =[15]人員・時間計画!$I$26 -> 0 | AF26: =[15]人員・時間計画!$I$11 -> 13 | AG26: =[15]人員・時間計画!$I$12 -> 0 | AH26: =[15]人員・時間計画!$J$25 -> 175 | AI26: =[15]人員・時間計画!$J$26 -> 0 | AJ26: =[15]人員・時間計画!$J$11 -> 13 | AK26: =[15]人員・時間計画!$J$12 -> 0 | AL26: =[15]人員・時間計画!$K$25 -> 179 | AM26: =[15]人員・時間計画!$K$26 -> 0 | AN26: =[15]人員・時間計画!$K$11 -> 13 | AO26: =[15]人員・時間計画!$K$12 -> 0 | AP26: =[15]人員・時間計画!$L$25 -> 175 | AQ26: =[15]人員・時間計画!$L$26 -> 0 | AR26: =[15]人員・時間計画!$L$11 -> 13 | AS26: =[15]人員・時間計画!$L$12 -> 0 | AT26: =[15]人員・時間計画!$M$25 -> 165 | AU26: =[15]人員・時間計画!$M$26 -> 0 | AV26: =[15]人員・時間計画!$M$11 -> 13 | AW26: =[15]人員・時間計画!$M$12 -> 0 | AX26: =[15]人員・時間計画!$N$25 -> 175 | AY26: =[15]人員・時間計画!$N$26 -> 0 | AZ26: =[15]人員・時間計画!$N$11 -> 13 | BA26: =[15]人員・時間計画!$N$12 -> 0
D27: =IF($A$1=1,Sheet1!C59,Sheet1!B59) -> ESD2課 | E27: 1412000096 | F27: =[16]人員・時間計画!$C$25 -> 160 | G27: =[16]人員・時間計画!$C$26 -> 0 | H27: =[16]人員・時間計画!$C$11 -> 10 | I27: =[16]人員・時間計画!$C$12 -> 0 | J27: =[16]人員・時間計画!$D$25 -> 158 | K27: =[16]人員・時間計画!$D$26 -> 0 | L27: =[16]人員・時間計画!$D$11 -> 10 | M27: =[16]人員・時間計画!$D$12 -> 0 | N27: =[16]人員・時間計画!$E$25 -> 162 | O27: =[16]人員・時間計画!$E$26 -> 0 | P27: =[16]人員・時間計画!$E$11 -> 10 | Q27: =[16]人員・時間計画!$E$12 -> 0 | R27: =[16]人員・時間計画!$F$25 -> 166 | S27: =[16]人員・時間計画!$F$26 -> 0 | T27: =[16]人員・時間計画!$F$11 -> 10 | U27: =[16]人員・時間計画!$F$12 -> 0 | V27: =[16]人員・時間計画!$G$25 -> 160 | W27: =[16]人員・時間計画!$G$26 -> 0 | X27: =[16]人員・時間計画!$G$11 -> 10 | Y27: =[16]人員・時間計画!$G$12 -> 0 | Z27: =[16]人員・時間計画!$H$25 -> 158 | AA27: =[16]人員・時間計画!$H$26 -> 0 | AB27: =[16]人員・時間計画!$H$11 -> 12 | AC27: =[16]人員・時間計画!$H$12 -> 0 | AD27: =[16]人員・時間計画!$I$25 -> 166 | AE27: =[16]人員・時間計画!$I$26 -> 0 | AF27: =[16]人員・時間計画!$I$11 -> 12 | AG27: =[16]人員・時間計画!$I$12 -> 0 | AH27: =[16]人員・時間計画!$J$25 -> 160 | AI27: =[16]人員・時間計画!$J$26 -> 0 | AJ27: =[16]人員・時間計画!$J$11 -> 12 | AK27: =[16]人員・時間計画!$J$12 -> 0 | AL27: =[16]人員・時間計画!$K$25 -> 164 | AM27: =[16]人員・時間計画!$K$26 -> 0 | AN27: =[16]人員・時間計画!$K$11 -> 12 | AO27: =[16]人員・時間計画!$K$12 -> 0 | AP27: =[16]人員・時間計画!$L$25 -> 160 | AQ27: =[16]人員・時間計画!$L$26 -> 0 | AR27: =[16]人員・時間計画!$L$11 -> 12 | AS27: =[16]人員・時間計画!$L$12 -> 0 | AT27: =[16]人員・時間計画!$M$25 -> 150 | AU27: =[16]人員・時間計画!$M$26 -> 0 | AV27: =[16]人員・時間計画!$M$11 -> 12 | AW27: =[16]人員・時間計画!$M$12 -> 0 | AX27: =[16]人員・時間計画!$N$25 -> 160 | AY27: =[16]人員・時間計画!$N$26 -> 0 | AZ27: =[16]人員・時間計画!$N$11 -> 12 | BA27: =[16]人員・時間計画!$N$12 -> 0
B29: TOTAL | F29: =SUM(F8:F27) -> 2210 | G29: =SUM(G8:G27) -> 4842 | H29: =SUM(H8:H27) -> 398 | I29: =SUM(I8:I27) -> 3902 | J29: =SUM(J8:J27) -> 2333 | K29: =SUM(K8:K27) -> 6297 | L29: =SUM(L8:L27) -> 398 | M29: =SUM(M8:M27) -> 3855 | ... BA29: =SUM(BA8:BA27) -> 5165
F31: 2210 | G31: 4842 | H31: 398 | I31: 3902 | J31: 2333 | K31: 6297 | L31: 398 | M31: 3855 | N31: 2356 | O31: 5103 | P31: 398 | Q31: 3721 | R31: 2882 | S31: 7672 | T31: 431 | U31: 4208 | V31: 3013 | W31: 14047 | X31: 431 | Y31: 4391 | Z31: 4199 | AA31: 38671 | AB31: 438 | AC31: 4604 | AD31: 2615 | AE31: 9603 | AF31: 438 | AG31: 4947 | AH31: 3119 | AI31: 19403 | AJ31: 438 | AK31: 5055 | AL31: 3075 | AM31: 17671 | AN31: 438 | AO31: 4996 | AP31: 3525 | AQ31: 27376 | AR31: 471 | AS31: 5211 | AT31: 3851 | AU31: 27457 | AV31: 471 | AW31: 5632 | AX31: 4149 | AY31: 34874 | AZ31: 471 | BA31: 5165
F33: =F29-F31 -> 0 | G33: =G29-G31 -> 0 | H33: =H29-H31 -> 0 | I33: =I29-I31 -> 0 | J33: =J29-J31 -> 0 | K33: =K29-K31 -> 0 | L33: =L29-L31 -> 0 | M33: =M29-M31 -> 0 | ... BA33: =BA29-BA31 -> 0

Sheet 6371
A1: 1 | B1: → １＝日本語(tiếng nhật)、２＝ベトナム語(tiếng việt) | F1: 4 | J1: 5 | N1: 6 | R1: 7 | V1: 8 | Z1: 9 | AD1: 10 | AH1: 11 | AL1: 12 | AP1: 1 | AT1: 2 | AX1: 3
F2: Dự tính Thời gian làm thêm (người Việt ) 残業時間（ローカル社員） (1/4/2023 ~ 30/4/2023) | H2: Dự tính Số người Việt 人員合計 (1/4/2023 ~ 30/4/2023) | J2: Dự tính Thời gian làm thêm (người Việt ) 残業時間（ローカル社員） (1/5/2023 ~ 31/5/2023) | L2: Dự tính Số người Việt 人員合計 (1/5/2023 ~ 31/5/2023) | N2: Dự tính Thời gian làm thêm (người Việt ) 残業時間（ローカル社員） (1/6/2023 ~ 30/6/2023) | P2: Dự tính Số người Việt 人員合計 (1/6/2023 ~ 30/6/2023) | R2: Dự tính Thời gian làm thêm (người Việt ) 残業時間（ローカル社員） (1/7/2023 ~ 31/7/2023) | T2: Dự tính Số người Việt 人員合計 (1/7/2023 ~ 31/7/2023) | V2: Dự tính Thời gian làm thêm (người Việt ) 残業時間（ローカル社員） (1/8/2023 ~ 31/8/2023) | X2: Dự tính Số người Việt 人員合計 (1/8/2023 ~ 31/8/2023) | Z2: Dự tính Thời gian làm thêm (người Việt ) 残業時間（ローカル社員） (1/9/2023 ~ 30/9/2023) | AB2: Dự tính Số người Việt 人員合計 (1/9/2023 ~ 30/9/2023) | AD2: Dự tính Thời gian làm thêm(người Việt ) 残業時間（ローカル社員） (1/10/2023 ~ 31/10/2023) | AF2: Dự tính Số người Việt 人員合計 (1/10/2023 ~ 31/10/2023) | AH2: Dự tính Thời gian làm thêm (người Việt ) 残業時間（ローカル社員） (1/11/2023 ~ 30/11/2023) | AJ2: Dự tính Số người Việt 人員合計 (1/11/2023 ~ 30/11/2023) | AL2: Dự tính Thời gian làm thêm (người Việt ) 残業時間（ローカル社員） (1/12/2023 ~ 31/12/2023) | AN2: Dự tính Số người Việt 人員合計 (1/12/2023 ~ 31/12/2023) | AP2: Dự tính Thời gian làm thêm (người Việt ) 残業時間（ローカル社員） (1/1/2024 ~ 31/1/2024) | AR2: Dự tính Số người Việt 人員合計 (1/1/2024 ~ 31/1/2024) | AT2: Dự tính Thời gian làm thêm (người Việt ) 残業時間（ローカル社員） (1/2/2024 ~ 28/2/2024) | AV2: Dự tính Số người Việt 人員合計 (1/2/2024~ 28/2/2024) | AX2: Dự tính Thời gian làm thêm (người Việt ) 残業時間（ローカル社員） (1/3/2024 ~ 31/3/2024) | AZ2: Dự tính Số người Việt 人員合計 (1/3/2024~ 31/3/2024)
F3: 4 | G3: 4 | H3: 4 | I3: 4 | J3: 5 | K3: 5 | L3: 5 | M3: 5 | N3: 6 | O3: 6 | P3: 6 | Q3: 6 | R3: 7 | S3: 7 | T3: 7 | U3: 7 | V3: 8 | W3: 8 | X3: 8 | Y3: 8 | Z3: 9 | AA3: 9 | AB3: 9 | AC3: 9 | AD3: 10 | AE3: 10 | AF3: 10 | AG3: 10 | AH3: 11 | AI3: 11 | AJ3: 11 | AK3: 11 | AL3: 12 | AM3: 12 | AN3: 12 | AO3: 12 | AP3: 1 | AQ3: 1 | AR3: 1 | AS3: 1 | AT3: 2 | AU3: 2 | AV3: 2 | AW3: 2 | AX3: 3 | AY3: 3 | AZ3: 3 | BA3: 3
F4: 残業時間 | G4: 残業時間 | H4: 人員 | I4: 人員 | J4: 残業時間 | K4: 残業時間 | L4: 人員 | M4: 人員 | N4: 残業時間 | O4: 残業時間 | P4: 人員 | Q4: 人員 | R4: 残業時間 | S4: 残業時間 | T4: 人員 | U4: 人員 | V4: 残業時間 | W4: 残業時間 | X4: 人員 | Y4: 人員 | Z4: 残業時間 | AA4: 残業時間 | AB4: 人員 | AC4: 人員 | AD4: 残業時間 | AE4: 残業時間 | AF4: 人員 | AG4: 人員 | AH4: 残業時間 | AI4: 残業時間 | AJ4: 人員 | AK4: 人員 | AL4: 残業時間 | AM4: 残業時間 | AN4: 人員 | AO4: 人員 | AP4: 残業時間 | AQ4: 残業時間 | AR4: 人員 | AS4: 人員 | AT4: 残業時間 | AU4: 残業時間 | AV4: 人員 | AW4: 人員 | AX4: 残業時間 | AY4: 残業時間 | AZ4: 人員 | BA4: 人員
F5: G5以上 | G5: G7, G6 | H5: G5以上 | I5: G7, G6 | J5: G5以上 | K5: G7, G6 | L5: G5以上 | M5: G7, G6 | N5: G5以上 | O5: G7, G6 | P5: G5以上 | Q5: G7, G6 | R5: G5以上 | S5: G7, G6 | T5: G5以上 | U5: G7, G6 | V5: G5以上 | W5: G7, G6 | X5: G5以上 | Y5: G7, G6 | Z5: G5以上 | AA5: G7, G6 | AB5: G5以上 | AC5: G7, G6 | AD5: G5以上 | AE5: G7, G6 | AF5: G5以上 | AG5: G7, G6 | AH5: G5以上 | AI5: G7, G6 | AJ5: G5以上 | AK5: G7, G6 | AL5: G5以上 | AM5: G7, G6 | AN5: G5以上 | AO5: G7, G6 | AP5: G5以上 | AQ5: G7, G6 | AR5: G5以上 | AS5: G7, G6 | AT5: G5以上 | AU5: G7, G6 | AV5: G5以上 | AW5: G7, G6 | AX5: G5以上 | AY5: G7, G6 | AZ5: G5以上 | BA5: G7, G6
B6: Mã TK コード | C6: Tên bộ phận 名前部 | D6: Tên phòng 名前課 | E6: 原価センター | F6: Nhân viên スタップ | G6: Công nhân ワーカー | H6: Nhân viên スタップ | I6: Công nhân ワーカー | J6: Nhân viên スタップ | K6: Công nhân ワーカー | L6: Nhân viên スタップ | M6: Công nhân ワーカー | N6: Nhân viên スタップ | O6: Công nhân ワーカー | P6: Nhân viên スタップ | Q6: Công nhân ワーカー | R6: Nhân viên スタップ | S6: Công nhân ワーカー | T6: Nhân viên スタップ | U6: Công nhân ワーカー | V6: Nhân viên スタップ | W6: Công nhân ワーカー | X6: Nhân viên スタップ | Y6: Công nhân ワーカー | Z6: Nhân viên スタップ | AA6: Công nhân ワーカー | AB6: Nhân viên スタップ | AC6: Công nhân ワーカー | AD6: Nhân viên スタップ | AE6: Công nhân ワーカー | AF6: Nhân viên スタップ | AG6: Công nhân ワーカー | AH6: Nhân viên スタップ | AI6: Công nhân ワーカー | AJ6: Nhân viên スタップ | AK6: Công nhân ワーカー | AL6: Nhân viên スタップ | AM6: Công nhân ワーカー | AN6: Nhân viên スタップ | AO6: Công nhân ワーカー | AP6: Nhân viên スタップ | AQ6: Công nhân ワーカー | AR6: Nhân viên スタップ | AS6: Công nhân ワーカー | AT6: Nhân viên スタップ | AU6: Công nhân ワーカー | AV6: Nhân viên スタップ | AW6: Công nhân ワーカー | AX6: Nhân viên スタップ | AY6: Công nhân ワーカー | AZ6: Nhân viên スタップ | BA6: Công nhân ワーカー
B7: 6221 | C7: 機器製造部
D8: =IF('6221'!$A$1=1,Sheet1!C6,Sheet1!B6) -> 機器製造管理課 | E8: 1412000062 | F8: =[17]人員・時間計画!$C$25 -> 200 | G8: =[17]人員・時間計画!$C$26 -> 100 | H8: =[17]人員・時間計画!$C$11 -> 21 | I8: =[17]人員・時間計画!$C$12 -> 7 | J8: =[17]人員・時間計画!$D$25 -> 200 | K8: =[17]人員・時間計画!$D$26 -> 100 | L8: =[17]人員・時間計画!$D$11 -> 21 | M8: =[17]人員・時間計画!$D$12 -> 7 | N8: =[17]人員・時間計画!$E$25 -> 200 | O8: =[17]人員・時間計画!$E$26 -> 100 | P8: =[17]人員・時間計画!$E$11 -> 21 | Q8: =[17]人員・時間計画!$E$12 -> 7 | R8: =[17]人員・時間計画!$F$25 -> 200 | S8: =[17]人員・時間計画!$F$26 -> 100 | T8: =[17]人員・時間計画!$F$11 -> 21 | U8: =[17]人員・時間計画!$F$12 -> 7 | V8: =[17]人員・時間計画!$G$25 -> 200 | W8: =[17]人員・時間計画!$G$26 -> 100 | X8: =[17]人員・時間計画!$G$11 -> 21 | Y8: =[17]人員・時間計画!$G$12 -> 7 | Z8: =[17]人員・時間計画!$H$25 -> 200 | AA8: =[17]人員・時間計画!$H$26 -> 100 | AB8: =[17]人員・時間計画!$H$11 -> 21 | AC8: =[17]人員・時間計画!$H$12 -> 7 | AD8: =[17]人員・時間計画!$I$25 -> 200 | AE8: =[17]人員・時間計画!$I$26 -> 100 | AF8: =[17]人員・時間計画!$I$11 -> 21 | AG8: =[17]人員・時間計画!$I$12 -> 7 | AH8: =[17]人員・時間計画!$J$25 -> 200 | AI8: =[17]人員・時間計画!$J$26 -> 100 | AJ8: =[17]人員・時間計画!$J$11 -> 21 | AK8: =[17]人員・時間計画!$J$12 -> 7 | AL8: =[17]人員・時間計画!$K$25 -> 200 | AM8: =[17]人員・時間計画!$K$26 -> 100 | AN8: =[17]人員・時間計画!$K$11 -> 21 | AO8: =[17]人員・時間計画!$K$12 -> 7 | AP8: =[17]人員・時間計画!$L$25 -> 200 | AQ8: =[17]人員・時間計画!$L$26 -> 100 | AR8: =[17]人員・時間計画!$L$11 -> 21 | AS8: =[17]人員・時間計画!$L$12 -> 7 | AT8: =[17]人員・時間計画!$M$25 -> 100 | AU8: =[17]人員・時間計画!$M$26 -> 80 | AV8: =[17]人員・時間計画!$M$11 -> 21 | AW8: =[17]人員・時間計画!$M$12 -> 7 | AX8: =[17]人員・時間計画!$N$25 -> 200 | AY8: =[17]人員・時間計画!$N$26 -> 100 | AZ8: =[17]人員・時間計画!$N$11 -> 21 | BA8: =[17]人員・時間計画!$N$12 -> 7
B9: 6221 | C9: トナー製造部
D10: =IF('6221'!$A$1=1,Sheet1!C15,Sheet1!B15) -> トナー生産技術課 | E10: 1412000048 | F10: =[18]人員・時間計画!$C$25 -> 38 | G10: =[18]人員・時間計画!$C$26 -> 0 | H10: =[18]人員・時間計画!$C$11 -> 14 | I10: =[18]人員・時間計画!$C$12 -> 10 | J10: =[18]人員・時間計画!$D$25 -> 52 | K10: =[18]人員・時間計画!$D$26 -> 24 | L10: =[18]人員・時間計画!$D$11 -> 14 | M10: =[18]人員・時間計画!$D$12 -> 10 | N10: =[18]人員・時間計画!$E$25 -> 40 | O10: =[18]人員・時間計画!$E$26 -> 0 | P10: =[18]人員・時間計画!$E$11 -> 14 | Q10: =[18]人員・時間計画!$E$12 -> 11 | R10: =[18]人員・時間計画!$F$25 -> 60 | S10: =[18]人員・時間計画!$F$26 -> 16 | T10: =[18]人員・時間計画!$F$11 -> 14 | U10: =[18]人員・時間計画!$F$12 -> 11 | V10: =[18]人員・時間計画!$G$25 -> 54 | W10: =[18]人員・時間計画!$G$26 -> 16 | X10: =[18]人員・時間計画!$G$11 -> 14 | Y10: =[18]人員・時間計画!$G$12 -> 11 | Z10: =[18]人員・時間計画!$H$25 -> 60 | AA10: =[18]人員・時間計画!$H$26 -> 24 | AB10: =[18]人員・時間計画!$H$11 -> 14 | AC10: =[18]人員・時間計画!$H$12 -> 11 | AD10: =[18]人員・時間計画!$I$25 -> 68 | AE10: =[18]人員・時間計画!$I$26 -> 24 | AF10: =[18]人員・時間計画!$I$11 -> 14 | AG10: =[18]人員・時間計画!$I$12 -> 11 | AH10: =[18]人員・時間計画!$J$25 -> 54 | AI10: =[18]人員・時間計画!$J$26 -> 16 | AJ10: =[18]人員・時間計画!$J$11 -> 14 | AK10: =[18]人員・時間計画!$J$12 -> 11 | AL10: =[18]人員・時間計画!$K$25 -> 58 | AM10: =[18]人員・時間計画!$K$26 -> 16 | AN10: =[18]人員・時間計画!$K$11 -> 14 | AO10: =[18]人員・時間計画!$K$12 -> 11 | AP10: =[18]人員・時間計画!$L$25 -> 54 | AQ10: =[18]人員・時間計画!$L$26 -> 16 | AR10: =[18]人員・時間計画!$L$11 -> 14 | AS10: =[18]人員・時間計画!$L$12 -> 11 | AT10: =[18]人員・時間計画!$M$25 -> 44 | AU10: =[18]人員・時間計画!$M26 -> 16 | AV10: =[18]人員・時間計画!$M$11 -> 14 | AW10: =[18]人員・時間計画!$M$12 -> 11 | AX10: =[18]人員・時間計画!$N$25 -> 54 | AY10: =[18]人員・時間計画!$N26 -> 16 | AZ10: =[18]人員・時間計画!$N$11 -> 14 | BA10: =[18]人員・時間計画!$N$12 -> 11
D11: =IF('6221'!$A$1=1,Sheet1!C16,Sheet1!B16) -> トナー製造管理課 | E11: 1412000063 | F11: =[19]人員・時間計画!$C$25 -> 0 | G11: =[19]人員・時間計画!$C$26 -> 0 | H11: =[19]人員・時間計画!$C$11 -> 7 | I11: =[19]人員・時間計画!$C$12 -> 6 | J11: =[19]人員・時間計画!$D$25 -> 0 | K11: =[19]人員・時間計画!$D$26 -> 0 | L11: =[19]人員・時間計画!$D$11 -> 6 | M11: =[19]人員・時間計画!$D$12 -> 6 | N11: =[19]人員・時間計画!$E$25 -> 0 | O11: =[19]人員・時間計画!$E$26 -> 0 | P11: =[19]人員・時間計画!$E$11 -> 5 | Q11: =[19]人員・時間計画!$E$12 -> 4 | R11: =[19]人員・時間計画!$F$25 -> 0 | S11: =[19]人員・時間計画!$F$26 -> 0 | T11: =[19]人員・時間計画!$F$11 -> 6 | U11: =[19]人員・時間計画!$F$12 -> 3 | V11: =[19]人員・時間計画!$G$25 -> 0 | W11: =[19]人員・時間計画!$G$26 -> 0 | X11: =[19]人員・時間計画!$G$11 -> 6 | Y11: =[19]人員・時間計画!$G$12 -> 3 | Z11: =[19]人員・時間計画!$H$25 -> 0 | AA11: =[19]人員・時間計画!$H$26 -> 0 | AB11: =[19]人員・時間計画!$H$11 -> 6 | AC11: =[19]人員・時間計画!$H$12 -> 3 | AD11: =[19]人員・時間計画!$I$25 -> 0 | AE11: =[19]人員・時間計画!$I$26 -> 0 | AF11: =[19]人員・時間計画!$I$11 -> 6 | AG11: =[19]人員・時間計画!$I$12 -> 3 | AH11: =[19]人員・時間計画!$J$25 -> 0 | AI11: =[19]人員・時間計画!$J$26 -> 0 | AJ11: =[19]人員・時間計画!$J$11 -> 6 | AK11: =[19]人員・時間計画!$J$12 -> 3 | AL11: =[19]人員・時間計画!$K$25 -> 0 | AM11: =[19]人員・時間計画!$K$26 -> 0 | AN11: =[19]人員・時間計画!$K$11 -> 5 | AO11: =[19]人員・時間計画!$K$12 -> 3 | AP11: =[19]人員・時間計画!$L$25 -> 0 | AQ11: =[19]人員・時間計画!$L$26 -> 0 | AR11: =[19]人員・時間計画!$L$11 -> 5 | AS11: =[19]人員・時間計画!$L$12 -> 3 | AT11: =[19]人員・時間計画!$M$25 -> 0 | AU11: =[19]人員・時間計画!$M$26 -> 0 | AV11: =[19]人員・時間計画!$M$11 -> 5 | AW11: =[19]人員・時間計画!$M$12 -> 3 | AX11: =[19]人員・時間計画!$N$25 -> 0 | AY11: =[19]人員・時間計画!$N$26 -> 0 | AZ11: =[19]人員・時間計画!$N$11 -> 5 | BA11: =[19]人員・時間計画!$N$12 -> 3
D12: =IF('6221'!$A$1=1,Sheet1!C17,Sheet1!B17) -> トナー品質管理課 | E12: 1412000055 | F12: =[20]人員・時間計画!$C$25 -> 38 | G12: =[20]人員・時間計画!$C$26 -> 0 | H12: =[20]人員・時間計画!$C$11 -> 11 | I12: =[20]人員・時間計画!$C$12 -> 14 | J12: =[20]人員・時間計画!$D$25 -> 60 | K12: =[20]人員・時間計画!$D$26 -> 24 | L12: =[20]人員・時間計画!$D$11 -> 11 | M12: =[20]人員・時間計画!$D$12 -> 14 | N12: =[20]人員・時間計画!$E$25 -> 40 | O12: =[20]人員・時間計画!$E$26 -> 24 | P12: =[20]人員・時間計画!$E$11 -> 11 | Q12: =[20]人員・時間計画!$E$12 -> 14 | R12: =[20]人員・時間計画!$F$25 -> 68 | S12: =[20]人員・時間計画!$F$26 -> 176 | T12: =[20]人員・時間計画!$F$11 -> 10 | U12: =[20]人員・時間計画!$F$12 -> 14 | V12: =[20]人員・時間計画!$G$25 -> 62 | W12: =[20]人員・時間計画!$G$26 -> 24 | X12: =[20]人員・時間計画!$G$11 -> 10 | Y12: =[20]人員・時間計画!$G$12 -> 15 | Z12: =[20]人員・時間計画!$H$25 -> 60 | AA12: =[20]人員・時間計画!$H$26 -> 48 | AB12: =[20]人員・時間計画!$H$11 -> 10 | AC12: =[20]人員・時間計画!$H$12 -> 17 | AD12: =[20]人員・時間計画!$I$25 -> 68 | AE12: =[20]人員・時間計画!$I$26 -> 48 | AF12: =[20]人員・時間計画!$I$11 -> 10 | AG12: =[20]人員・時間計画!$I$12 -> 17 | AH12: =[20]人員・時間計画!$J$25 -> 62 | AI12: =[20]人員・時間計画!$J$26 -> 24 | AJ12: =[20]人員・時間計画!$J$11 -> 10 | AK12: =[20]人員・時間計画!$J$12 -> 17 | AL12: =[20]人員・時間計画!$K$25 -> 66 | AM12: =[20]人員・時間計画!$K$26 -> 24 | AN12: =[20]人員・時間計画!$K$11 -> 11 | AO12: =[20]人員・時間計画!$K$12 -> 17 | AP12: =[20]人員・時間計画!$L$25 -> 62 | AQ12: =[20]人員・時間計画!$L$26 -> 176 | AR12: =[20]人員・時間計画!$L$11 -> 11 | AS12: =[20]人員・時間計画!$L$12 -> 17 | AT12: =[20]人員・時間計画!$M$25 -> 52 | AU12: =[20]人員・時間計画!$M$26 -> 152 | AV12: =[20]人員・時間計画!$M$11 -> 11 | AW12: =[20]人員・時間計画!$M$12 -> 17 | AX12: =[20]人員・時間計画!$N$25 -> 38 | AY12: =[20]人員・時間計画!$N$26 -> 72 | AZ12: =[20]人員・時間計画!$N$11 -> 11 | BA12: =[20]人員・時間計画!$N$12 -> 19
B13: 6221 | C13: 部品製造部
D14: =IF($A$1=1,Sheet1!C20,Sheet1!B20) -> 金型技術課 | E14: 1412000044 | F14: ='[21]Kế hoạch số người - thời gian'!$C$25 -> 230 | G14: ='[21]Kế hoạch số người - thời gian'!$C$26 -> 100 | H14: ='[21]Kế hoạch số người - thời gian'!$C$11 -> 23 | I14: ='[21]Kế hoạch số người - thời gian'!$C$12 -> 9 | J14: ='[21]Kế hoạch số người - thời gian'!$D$25 -> 226 | K14: ='[21]Kế hoạch số người - thời gian'!$D$26 -> 100 | L14: ='[21]Kế hoạch số người - thời gian'!$D$11 -> 23 | M14: ='[21]Kế hoạch số người - thời gian'!$D$12 -> 9 | N14: ='[21]Kế hoạch số người - thời gian'!$E$25 -> 234 | O14: ='[21]Kế hoạch số người - thời gian'!$E$26 -> 100 | P14: ='[21]Kế hoạch số người - thời gian'!$E$11 -> 23 | Q14: ='[21]Kế hoạch số người - thời gian'!$E$12 -> 9 | R14: ='[21]Kế hoạch số người - thời gian'!$F$25 -> 392 | S14: ='[21]Kế hoạch số người - thời gian'!$F$26 -> 100 | T14: ='[21]Kế hoạch số người - thời gian'!$F$11 -> 23 | U14: ='[21]Kế hoạch số người - thời gian'!$F$12 -> 9 | V14: ='[21]Kế hoạch số người - thời gian'!$G$25 -> 230 | W14: ='[21]Kế hoạch số người - thời gian'!$G$26 -> 100 | X14: ='[21]Kế hoạch số người - thời gian'!$G$11 -> 23 | Y14: ='[21]Kế hoạch số người - thời gian'!$G$12 -> 9 | Z14: ='[21]Kế hoạch số người - thời gian'!$H$25 -> 226 | AA14: ='[21]Kế hoạch số người - thời gian'!$H$26 -> 100 | AB14: ='[21]Kế hoạch số người - thời gian'!$H$11 -> 23 | AC14: ='[21]Kế hoạch số người - thời gian'!$H$12 -> 9 | AD14: ='[21]Kế hoạch số người - thời gian'!$I$25 -> 392 | AE14: ='[21]Kế hoạch số người - thời gian'!$I$26 -> 100 | AF14: ='[21]Kế hoạch số người - thời gian'!$I$11 -> 23 | AG14: ='[21]Kế hoạch số người - thời gian'!$I$12 -> 9 | AH14: ='[21]Kế hoạch số người - thời gian'!$J$25 -> 404 | AI14: ='[21]Kế hoạch số người - thời gian'!$J$26 -> 114 | AJ14: ='[21]Kế hoạch số người - thời gian'!$J$11 -> 23 | AK14: ='[21]Kế hoạch số người - thời gian'!$J$12 -> 9 | AL14: ='[21]Kế hoạch số người - thời gian'!$K$25 -> 238 | AM14: ='[21]Kế hoạch số người - thời gian'!$K$26 -> 106 | AN14: ='[21]Kế hoạch số người - thời gian'!$K$11 -> 23 | AO14: ='[21]Kế hoạch số người - thời gian'!$K$12 -> 9 | AP14: ='[21]Kế hoạch số người - thời gian'!$L$25 -> 230 | AQ14: ='[21]Kế hoạch số người - thời gian'!$L$26 -> 100 | AR14: ='[21]Kế hoạch số người - thời gian'!$L$11 -> 23 | AS14: ='[21]Kế hoạch số người - thời gian'!$L$12 -> 9 | AT14: ='[21]Kế hoạch số người - thời gian'!$M$25 -> 360 | AU14: ='[21]Kế hoạch số người - thời gian'!$M$26 -> 100 | AV14: ='[21]Kế hoạch số người - thời gian'!$M$11 -> 23 | AW14: ='[21]Kế hoạch số người - thời gian'!$M$12 -> 9 | AX14: ='[21]Kế hoạch số người - thời gian'!$N$25 -> 380 | AY14: ='[21]Kế hoạch số người - thời gian'!$N$26 -> 100 | AZ14: ='[21]Kế hoạch số người - thời gian'!$N$11 -> 23 | BA14: ='[21]Kế hoạch số người - thời gian'!$N$12 -> 9
D15: =IF($A$1=1,Sheet1!C21,Sheet1!B21) -> 部品製造管理課 | E15: 1412000087 | F15: =[22]人員・時間計画!$C$25 -> 0 | G15: =[22]人員・時間計画!$C$26 -> 0 | H15: =[22]人員・時間計画!$C$11 -> 9 | I15: =[22]人員・時間計画!$C$12 -> 0 | J15: =[22]人員・時間計画!$D$25 -> 0 | K15: =[22]人員・時間計画!$D$26 -> 0 | L15: =[22]人員・時間計画!$D$11 -> 9 | M15: =[22]人員・時間計画!$D$12 -> 0 | N15: =[22]人員・時間計画!$E$25 -> 0 | O15: =[22]人員・時間計画!$E$26 -> 0 | P15: =[22]人員・時間計画!$E$11 -> 9 | Q15: =[22]人員・時間計画!$E$12 -> 0 | R15: =[22]人員・時間計画!$F$25 -> 0 | S15: =[22]人員・時間計画!$F$26 -> 0 | T15: =[22]人員・時間計画!$F$11 -> 9 | U15: =[22]人員・時間計画!$F$12 -> 0 | V15: =[22]人員・時間計画!$G$25 -> 0 | W15: =[22]人員・時間計画!$G$26 -> 0 | X15: =[22]人員・時間計画!$G$11 -> 9 | Y15: =[22]人員・時間計画!$G$12 -> 0 | Z15: =[22]人員・時間計画!$H$25 -> 0 | AA15: =[22]人員・時間計画!$H$26 -> 0 | AB15: =[22]人員・時間計画!$H$11 -> 9 | AC15: =[22]人員・時間計画!$H$12 -> 0 | AD15: =[22]人員・時間計画!$I$25 -> 0 | AE15: =[22]人員・時間計画!$I$26 -> 0 | AF15: =[22]人員・時間計画!$I$11 -> 9 | AG15: =[22]人員・時間計画!$I$12 -> 0 | AH15: =[22]人員・時間計画!$J$25 -> 0 | AI15: =[22]人員・時間計画!$J$26 -> 0 | AJ15: =[22]人員・時間計画!$J$11 -> 9 | AK15: =[22]人員・時間計画!$J$12 -> 0 | AL15: =[22]人員・時間計画!$K$25 -> 0 | AM15: =[22]人員・時間計画!$K$26 -> 0 | AN15: =[22]人員・時間計画!$K$11 -> 9 | AO15: =[22]人員・時間計画!$K$12 -> 0 | AP15: =[22]人員・時間計画!$L$25 -> 0 | AQ15: =[22]人員・時間計画!$L$26 -> 0 | AR15: =[22]人員・時間計画!$L$11 -> 9 | AS15: =[22]人員・時間計画!$L$12 -> 0 | AT15: =[22]人員・時間計画!$M$25 -> 0 | AU15: =[22]人員・時間計画!$M$26 -> 0 | AV15: =[22]人員・時間計画!$M$11 -> 9 | AW15: =[22]人員・時間計画!$M$12 -> 0 | AX15: =[22]人員・時間計画!$N$25 -> 0 | AY15: =[22]人員・時間計画!$N$26 -> 0 | AZ15: =[22]人員・時間計画!$N$11 -> 9 | BA15: =[22]人員・時間計画!$N$12 -> 0
D16: =IF($A$1=1,Sheet1!C22,Sheet1!B22) -> 品質管理課 | E16: 1412000088 | F16: =[23]人員・時間計画!$C$25 -> 36 | G16: =[23]人員・時間計画!$C$26 -> 48 | H16: =[23]人員・時間計画!$C$11 -> 12 | I16: =[23]人員・時間計画!$C$12 -> 13 | J16: =[23]人員・時間計画!$D$25 -> 34 | K16: =[23]人員・時間計画!$D$26 -> 48 | L16: =[23]人員・時間計画!$D$11 -> 12 | M16: =[23]人員・時間計画!$D$12 -> 13 | N16: =[23]人員・時間計画!$E$25 -> 38 | O16: =[23]人員・時間計画!$E$26 -> 48 | P16: =[23]人員・時間計画!$E$11 -> 12 | Q16: =[23]人員・時間計画!$E$12 -> 13 | R16: =[23]人員・時間計画!$F$25 -> 42 | S16: =[23]人員・時間計画!$F$26 -> 48 | T16: =[23]人員・時間計画!$F$11 -> 12 | U16: =[23]人員・時間計画!$F$12 -> 13 | V16: =[23]人員・時間計画!$G$25 -> 36 | W16: =[23]人員・時間計画!$G$26 -> 48 | X16: =[23]人員・時間計画!$G$11 -> 12 | Y16: =[23]人員・時間計画!$G$12 -> 13 | Z16: =[23]人員・時間計画!$H$25 -> 34 | AA16: =[23]人員・時間計画!$H$26 -> 48 | AB16: =[23]人員・時間計画!$H$11 -> 12 | AC16: =[23]人員・時間計画!$H$12 -> 13 | AD16: =[23]人員・時間計画!$I$25 -> 42 | AE16: =[23]人員・時間計画!$I$26 -> 48 | AF16: =[23]人員・時間計画!$I$11 -> 12 | AG16: =[23]人員・時間計画!$I$12 -> 13 | AH16: =[23]人員・時間計画!$J$25 -> 36 | AI16: =[23]人員・時間計画!$J$26 -> 48 | AJ16: =[23]人員・時間計画!$J$11 -> 12 | AK16: =[23]人員・時間計画!$J$12 -> 13 | AL16: =[23]人員・時間計画!$K$25 -> 40 | AM16: =[23]人員・時間計画!$K$26 -> 48 | AN16: =[23]人員・時間計画!$K$11 -> 12 | AO16: =[23]人員・時間計画!$K$12 -> 13 | AP16: =[23]人員・時間計画!$L$25 -> 36 | AQ16: =[23]人員・時間計画!$L$26 -> 48 | AR16: =[23]人員・時間計画!$L$11 -> 12 | AS16: =[23]人員・時間計画!$L$12 -> 13 | AT16: =[23]人員・時間計画!$M$25 -> 26 | AU16: =[23]人員・時間計画!$M$26 -> 48 | AV16: =[23]人員・時間計画!$M$11 -> 12 | AW16: =[23]人員・時間計画!$M$12 -> 13 | AX16: =[23]人員・時間計画!$N$25 -> 36 | AY16: =[23]人員・時間計画!$N$26 -> 48 | AZ16: =[23]人員・時間計画!$N$11 -> 12 | BA16: =[23]人員・時間計画!$N$12 -> 13
B17: 6371 | C17: =IF($A$1=1,Sheet1!D9,Sheet1!A9) -> 工程品質管理部
D18: =IF($A$1=1,Sheet1!C10,Sheet1!B10) -> 工程品質管理1課 | E18: 1412000053 | F18: =[24]人員・時間計画!$C$25 -> 2395 | G18: =[24]人員・時間計画!$C$26 -> 2550 | H18: =[24]人員・時間計画!$C$11 -> 94 | I18: =[24]人員・時間計画!$C$12 -> 102 | J18: =[24]人員・時間計画!$D$25 -> 2389 | K18: =[24]人員・時間計画!$D$26 -> 2550 | L18: =[24]人員・時間計画!$D$11 -> 94 | M18: =[24]人員・時間計画!$D$12 -> 102 | N18: =[24]人員・時間計画!$E$25 -> 2401 | O18: =[24]人員・時間計画!$E$26 -> 2550 | P18: =[24]人員・時間計画!$E$11 -> 94 | Q18: =[24]人員・時間計画!$E$12 -> 102 | R18: =[24]人員・時間計画!$F$25 -> 2613 | S18: =[24]人員・時間計画!$F$26 -> 2350 | T18: =[24]人員・時間計画!$F$11 -> 102 | U18: =[24]人員・時間計画!$F$12 -> 94 | V18: =[24]人員・時間計画!$G$25 -> 2595 | W18: =[24]人員・時間計画!$G$26 -> 2350 | X18: =[24]人員・時間計画!$G$11 -> 102 | Y18: =[24]人員・時間計画!$G$12 -> 94 | Z18: =[24]人員・時間計画!$H$25 -> 2589 | AA18: =[24]人員・時間計画!$H$26 -> 2350 | AB18: =[24]人員・時間計画!$H$11 -> 102 | AC18: =[24]人員・時間計画!$H$12 -> 94 | AD18: =[24]人員・時間計画!$I$25 -> 2638 | AE18: =[24]人員・時間計画!$I$26 -> 2425 | AF18: =[24]人員・時間計画!$I$11 -> 103 | AG18: =[24]人員・時間計画!$I$12 -> 97 | AH18: =[24]人員・時間計画!$J$25 -> 2620 | AI18: =[24]人員・時間計画!$J$26 -> 2425 | AJ18: =[24]人員・時間計画!$J$11 -> 103 | AK18: =[24]人員・時間計画!$J$12 -> 97 | AL18: =[24]人員・時間計画!$K$25 -> 2632 | AM18: =[24]人員・時間計画!$K$26 -> 2425 | AN18: =[24]人員・時間計画!$K$11 -> 103 | AO18: =[24]人員・時間計画!$K$12 -> 97 | AP18: =[24]人員・時間計画!$L$25 -> 2795 | AQ18: =[24]人員・時間計画!$L$26 -> 2275 | AR18: =[24]人員・時間計画!$L$11 -> 110 | AS18: =[24]人員・時間計画!$L$12 -> 91 | AT18: =[24]人員・時間計画!$M$25 -> 2765 | AU18: =[24]人員・時間計画!$M$26 -> 2700 | AV18: =[24]人員・時間計画!$M$11 -> 110 | AW18: =[24]人員・時間計画!$M$12 -> 108 | AX18: =[24]人員・時間計画!$N$25 -> 2795 | AY18: =[24]人員・時間計画!$N$26 -> 2700 | AZ18: =[24]人員・時間計画!$N$11 -> 110 | BA18: =[24]人員・時間計画!$N$12 -> 108
D19: =IF($A$1=1,Sheet1!C11,Sheet1!B11) -> 工程品質管理2課 | E19: 1412000075 | F19: =[25]人員・時間計画!$C$25 -> 48 | G19: =[25]人員・時間計画!$C$26 -> 0 | H19: =[25]人員・時間計画!$C$11 -> 7 | I19: =[25]人員・時間計画!$C$12 -> 1 | J19: =[25]人員・時間計画!$D$25 -> 46 | K19: =[25]人員・時間計画!$D$26 -> 0 | L19: =[25]人員・時間計画!$D$11 -> 7 | M19: =[25]人員・時間計画!$D$12 -> 1 | N19: =[25]人員・時間計画!$E$25 -> 50 | O19: =[25]人員・時間計画!$E$26 -> 0 | P19: =[25]人員・時間計画!$E$11 -> 7 | Q19: =[25]人員・時間計画!$E$12 -> 1 | R19: =[25]人員・時間計画!$F$25 -> 54 | S19: =[25]人員・時間計画!$F$26 -> 0 | T19: =[25]人員・時間計画!$F$11 -> 7 | U19: =[25]人員・時間計画!$F$12 -> 1 | V19: =[25]人員・時間計画!$G$25 -> 48 | W19: =[25]人員・時間計画!$G$26 -> 0 | X19: =[25]人員・時間計画!$G$11 -> 7 | Y19: =[25]人員・時間計画!$G$12 -> 1 | Z19: =[25]人員・時間計画!$H$25 -> 46 | AA19: =[25]人員・時間計画!$H$26 -> 0 | AB19: =[25]人員・時間計画!$H$11 -> 7 | AC19: =[25]人員・時間計画!$H$12 -> 1 | AD19: =[25]人員・時間計画!$I$25 -> 54 | AE19: =[25]人員・時間計画!$I$26 -> 0 | AF19: =[25]人員・時間計画!$I$11 -> 7 | AG19: =[25]人員・時間計画!$I$12 -> 2 | AH19: =[25]人員・時間計画!$J$25 -> 48 | AI19: =[25]人員・時間計画!$J$26 -> 0 | AJ19: =[25]人員・時間計画!$J$11 -> 7 | AK19: =[25]人員・時間計画!$J$12 -> 2 | AL19: =[25]人員・時間計画!$K$25 -> 52 | AM19: =[25]人員・時間計画!$K$26 -> 0 | AN19: =[25]人員・時間計画!$K$11 -> 7 | AO19: =[25]人員・時間計画!$K$12 -> 2 | AP19: =[25]人員・時間計画!$L$25 -> 48 | AQ19: =[25]人員・時間計画!$L$26 -> 0 | AR19: =[25]人員・時間計画!$L$11 -> 8 | AS19: =[25]人員・時間計画!$L$12 -> 1 | AT19: =[25]人員・時間計画!$M$25 -> 38 | AU19: =[25]人員・時間計画!$M$26 -> 0 | AV19: =[25]人員・時間計画!$M$11 -> 8 | AW19: =[25]人員・時間計画!$M$12 -> 1 | AX19: =[25]人員・時間計画!$N$25 -> 48 | AY19: =[25]人員・時間計画!$N$26 -> 0 | AZ19: =[25]人員・時間計画!$N$11 -> 8 | BA19: =[25]人員・時間計画!$N$12 -> 1
B20: 6371 | C20: =IF($A$1=1,Sheet1!D24,Sheet1!A24) -> 生産管理部
D21: =IF($A$1=1,Sheet1!C25,Sheet1!B25) -> 生産管理課 | E21: 1412000008 | F21: =[26]人員・時間計画!$C$25 -> 112 | G21: =[26]人員・時間計画!$C$26 -> 0 | H21: =[26]人員・時間計画!$C$11 -> 10 | I21: =[26]人員・時間計画!$C$12 -> 0 | J21: =[26]人員・時間計画!$D$25 -> 108 | K21: =[26]人員・時間計画!$D$26 -> 0 | L21: =[26]人員・時間計画!$D$11 -> 10 | M21: =[26]人員・時間計画!$D$12 -> 0 | N21: =[26]人員・時間計画!$E$25 -> 120 | O21: =[26]人員・時間計画!$E$26 -> 0 | P21: =[26]人員・時間計画!$E$11 -> 10 | Q21: =[26]人員・時間計画!$E$12 -> 0 | R21: =[26]人員・時間計画!$F$25 -> 132 | S21: =[26]人員・時間計画!$F$26 -> 0 | T21: =[26]人員・時間計画!$F$11 -> 10 | U21: =[26]人員・時間計画!$F$12 -> 0 | V21: =[26]人員・時間計画!$G$25 -> 124 | W21: =[26]人員・時間計画!$G$26 -> 0 | X21: =[26]人員・時間計画!$G$11 -> 10 | Y21: =[26]人員・時間計画!$G$12 -> 0 | Z21: =[26]人員・時間計画!$H$25 -> 108 | AA21: =[26]人員・時間計画!$H$26 -> 0 | AB21: =[26]人員・時間計画!$H$11 -> 10 | AC21: =[26]人員・時間計画!$H$12 -> 0 | AD21: =[26]人員・時間計画!$I$25 -> 132 | AE21: =[26]人員・時間計画!$I$26 -> 0 | AF21: =[26]人員・時間計画!$I$11 -> 10 | AG21: =[26]人員・時間計画!$I$12 -> 0 | AH21: =[26]人員・時間計画!$J$25 -> 112 | AI21: =[26]人員・時間計画!$J$26 -> 0 | AJ21: =[26]人員・時間計画!$J$11 -> 10 | AK21: =[26]人員・時間計画!$J$12 -> 0 | AL21: =[26]人員・時間計画!$K$25 -> 124 | AM21: =[26]人員・時間計画!$K$26 -> 0 | AN21: =[26]人員・時間計画!$K$11 -> 10 | AO21: =[26]人員・時間計画!$K$12 -> 0 | AP21: =[26]人員・時間計画!$L$25 -> 114 | AQ21: =[26]人員・時間計画!$L$26 -> 0 | AR21: =[26]人員・時間計画!$L$11 -> 10 | AS21: =[26]人員・時間計画!$L$12 -> 0 | AT21: =[26]人員・時間計画!$M$25 -> 94 | AU21: =[26]人員・時間計画!$M$26 -> 0 | AV21: =[26]人員・時間計画!$M$11 -> 10 | AW21: =[26]人員・時間計画!$M$12 -> 0 | AX21: =[26]人員・時間計画!$N$25 -> 114 | AY21: =[26]人員・時間計画!$N$26 -> 0 | AZ21: =[26]人員・時間計画!$N$11 -> 10 | BA21: =[26]人員・時間計画!$N$12 -> 0
D22: =IF($A$1=1,Sheet1!C26,Sheet1!B26) -> 採算管理課 | E22: 1412000010 | F22: =[27]人員・時間計画!$C$25 -> 76 | G22: =[27]人員・時間計画!$C$26 -> 0 | H22: =[27]人員・時間計画!$C$11 -> 6 | I22: =[27]人員・時間計画!$C$12 -> 0 | J22: =[27]人員・時間計画!$D$25 -> 72 | K22: =[27]人員・時間計画!$D$26 -> 0 | L22: =[27]人員・時間計画!$D$11 -> 6 | M22: =[27]人員・時間計画!$D$12 -> 0 | N22: =[27]人員・時間計画!$E$25 -> 80 | O22: =[27]人員・時間計画!$E$26 -> 0 | P22: =[27]人員・時間計画!$E$11 -> 6 | Q22: =[27]人員・時間計画!$E$12 -> 0 | R22: =[27]人員・時間計画!$F$25 -> 88 | S22: =[27]人員・時間計画!$F$26 -> 0 | T22: =[27]人員・時間計画!$F$11 -> 6 | U22: =[27]人員・時間計画!$F$12 -> 0 | V22: =[27]人員・時間計画!$G$25 -> 76 | W22: =[27]人員・時間計画!$G$26 -> 0 | X22: =[27]人員・時間計画!$G$11 -> 6 | Y22: =[27]人員・時間計画!$G$12 -> 0 | Z22: =[27]人員・時間計画!$H$25 -> 84.75 | AA22: =[27]人員・時間計画!$H$26 -> 0 | AB22: =[27]人員・時間計画!$H$11 -> 6 | AC22: =[27]人員・時間計画!$H$12 -> 0 | AD22: =[27]人員・時間計画!$I$25 -> 88 | AE22: =[27]人員・時間計画!$I$26 -> 0 | AF22: =[27]人員・時間計画!$I$11 -> 6 | AG22: =[27]人員・時間計画!$I$12 -> 0 | AH22: =[27]人員・時間計画!$J$25 -> 76 | AI22: =[27]人員・時間計画!$J$26 -> 0 | AJ22: =[27]人員・時間計画!$J$11 -> 6 | AK22: =[27]人員・時間計画!$J$12 -> 0 | AL22: =[27]人員・時間計画!$K$25 -> 84 | AM22: =[27]人員・時間計画!$K$26 -> 0 | AN22: =[27]人員・時間計画!$K$11 -> 6 | AO22: =[27]人員・時間計画!$K$12 -> 0 | AP22: =[27]人員・時間計画!$L$25 -> 76 | AQ22: =[27]人員・時間計画!$L$26 -> 0 | AR22: =[27]人員・時間計画!$L$11 -> 6 | AS22: =[27]人員・時間計画!$L$12 -> 0 | AT22: =[27]人員・時間計画!$M$25 -> 60 | AU22: =[27]人員・時間計画!$M$26 -> 0 | AV22: =[27]人員・時間計画!$M$11 -> 6 | AW22: =[27]人員・時間計画!$M$12 -> 0 | AX22: =[27]人員・時間計画!$N$25 -> 88.75 | AY22: =[27]人員・時間計画!$N$26 -> 0 | AZ22: =[27]人員・時間計画!$N$11 -> 6 | BA22: =[27]人員・時間計画!$N$12 -> 0
D23: =IF($A$1=1,Sheet1!C27,Sheet1!B27) -> マスター管理課 | E23: 1412000054 | F23: =[28]人員・時間計画!$C$25 -> 152 | G23: =[28]人員・時間計画!$C$26 -> 0 | H23: =[28]人員・時間計画!$C$11 -> 15 | I23: =[28]人員・時間計画!$C$12 -> 1 | J23: =[28]人員・時間計画!$D$25 -> 144 | K23: =[28]人員・時間計画!$D$26 -> 0 | L23: =[28]人員・時間計画!$D$11 -> 16 | M23: =[28]人員・時間計画!$D$12 -> 1 | N23: =[28]人員・時間計画!$E$25 -> 160 | O23: =[28]人員・時間計画!$E$26 -> 0 | P23: =[28]人員・時間計画!$E$11 -> 16 | Q23: =[28]人員・時間計画!$E$12 -> 1 | R23: =[28]人員・時間計画!$F$25 -> 176 | S23: =[28]人員・時間計画!$F$26 -> 0 | T23: =[28]人員・時間計画!$F$11 -> 16 | U23: =[28]人員・時間計画!$F$12 -> 1 | V23: =[28]人員・時間計画!$G$25 -> 177.5 | W23: =[28]人員・時間計画!$G$26 -> 0 | X23: =[28]人員・時間計画!$G$11 -> 16 | Y23: =[28]人員・時間計画!$G$12 -> 1 | Z23: =[28]人員・時間計画!$H$25 -> 144 | AA23: =[28]人員・時間計画!$H$26 -> 0 | AB23: =[28]人員・時間計画!$H$11 -> 16 | AC23: =[28]人員・時間計画!$H$12 -> 1 | AD23: =[28]人員・時間計画!$I$25 -> 176 | AE23: =[28]人員・時間計画!$I$26 -> 0 | AF23: =[28]人員・時間計画!$I$11 -> 16 | AG23: =[28]人員・時間計画!$I$12 -> 1 | AH23: =[28]人員・時間計画!$J$25 -> 152 | AI23: =[28]人員・時間計画!$J$26 -> 0 | AJ23: =[28]人員・時間計画!$J$11 -> 16 | AK23: =[28]人員・時間計画!$J$12 -> 1 | AL23: =[28]人員・時間計画!$K$25 -> 168 | AM23: =[28]人員・時間計画!$K$26 -> 0 | AN23: =[28]人員・時間計画!$K$11 -> 16 | AO23: =[28]人員・時間計画!$K$12 -> 1 | AP23: =[28]人員・時間計画!$L$25 -> 152 | AQ23: =[28]人員・時間計画!$L$26 -> 0 | AR23: =[28]人員・時間計画!$L$11 -> 16 | AS23: =[28]人員・時間計画!$L$12 -> 1 | AT23: =[28]人員・時間計画!$M$25 -> 137.5 | AU23: =[28]人員・時間計画!$M$26 -> 0 | AV23: =[28]人員・時間計画!$M$11 -> 16 | AW23: =[28]人員・時間計画!$M$12 -> 1 | AX23: =[28]人員・時間計画!$N$25 -> 152 | AY23: =[28]人員・時間計画!$N$26 -> 0 | AZ23: =[28]人員・時間計画!$N$11 -> 16 | BA23: =[28]人員・時間計画!$N$12 -> 1
D24: =IF($A$1=1,Sheet1!C28,Sheet1!B28) -> OC管理課 | E24: 1412000094 | F24: =[29]人員・時間計画!$C$25 -> 40 | G24: =[29]人員・時間計画!$C$26 -> 0 | H24: =[29]人員・時間計画!$C$11 -> 3 | I24: =[29]人員・時間計画!$C$12 -> 0 | J24: =[29]人員・時間計画!$D$25 -> 38 | K24: =[29]人員・時間計画!$D$26 -> 0 | L24: =[29]人員・時間計画!$D$11 -> 3 | M24: =[29]人員・時間計画!$D$12 -> 0 | N24: =[29]人員・時間計画!$E$25 -> 42 | O24: =[29]人員・時間計画!$E$26 -> 0 | P24: =[29]人員・時間計画!$E$11 -> 3 | Q24: =[29]人員・時間計画!$E$12 -> 0 | R24: =[29]人員・時間計画!$F$25 -> 46 | S24: =[29]人員・時間計画!$F$26 -> 0 | T24: =[29]人員・時間計画!$F$11 -> 3 | U24: =[29]人員・時間計画!$F$12 -> 0 | V24: =[29]人員・時間計画!$G$25 -> 40 | W24: =[29]人員・時間計画!$G$26 -> 4 | X24: =[29]人員・時間計画!$G$11 -> 3 | Y24: =[29]人員・時間計画!$G$12 -> 0 | Z24: =[29]人員・時間計画!$H$25 -> 38 | AA24: =[29]人員・時間計画!$H$26 -> 0 | AB24: =[29]人員・時間計画!$H$11 -> 3 | AC24: =[29]人員・時間計画!$H$12 -> 0 | AD24: =[29]人員・時間計画!$I$25 -> 46 | AE24: =[29]人員・時間計画!$I$26 -> 0 | AF24: =[29]人員・時間計画!$I$11 -> 3 | AG24: =[29]人員・時間計画!$I$12 -> 0 | AH24: =[29]人員・時間計画!$J$25 -> 40 | AI24: =[29]人員・時間計画!$J$26 -> 0 | AJ24: =[29]人員・時間計画!$J$11 -> 3 | AK24: =[29]人員・時間計画!$J$12 -> 0 | AL24: =[29]人員・時間計画!$K$25 -> 44 | AM24: =[29]人員・時間計画!$K$26 -> 0 | AN24: =[29]人員・時間計画!$K$11 -> 3 | AO24: =[29]人員・時間計画!$K$12 -> 0 | AP24: =[29]人員・時間計画!$L$25 -> 40 | AQ24: =[29]人員・時間計画!$L$26 -> 0 | AR24: =[29]人員・時間計画!$L$11 -> 3 | AS24: =[29]人員・時間計画!$L$12 -> 0 | AT24: =[29]人員・時間計画!$M$25 -> 30 | AU24: =[29]人員・時間計画!$M$26 -> 4 | AV24: =[29]人員・時間計画!$M$11 -> 3 | AW24: =[29]人員・時間計画!$M$12 -> 0 | AX24: =[29]人員・時間計画!$N$25 -> 40 | AY24: =[29]人員・時間計画!$N$26 -> 0 | AZ24: =[29]人員・時間計画!$N$11 -> 3 | BA24: =[29]人員・時間計画!$N$12 -> 0
B25: 6371 | C25: =IF($A$1=1,Sheet1!D29,Sheet1!A29) -> 物流部
