Workbook
Name ______DAT10: #REF!
Name ______dat1000: #REF!
Name ______DAT11: #REF!
Name ______DAT12: #REF!
Name ______DAT3: #REF!
Name ______DAT4: #REF!
Name ______DAT5: #REF!
Name ______DAT6: #REF!
Name ______DAT7: #REF!
Name ______DAT8: #REF!
Name ______DAT9: #REF!
Name _____DAT10: #REF!
Name _____dat1000: #REF!
Name _____DAT11: #REF!
Name _____DAT12: #REF!
Name _____DAT3: #REF!
Name _____DAT4: #REF!
Name _____DAT5: #REF!
Name _____DAT6: #REF!
Name _____DAT7: #REF!
Name _____DAT8: #REF!
Name _____DAT9: #REF!
Name ____DAT10: #REF!
Name ____dat1000: #REF!
Name ____DAT11: #REF!
Name ____DAT12: #REF!
Name ____DAT3: #REF!
Name ____DAT4: #REF!
Name ____DAT5: #REF!
Name ____DAT6: #REF!
Name ____DAT7: #REF!
Name ____DAT8: #REF!
Name ____DAT9: #REF!
Name ___DAT1: #REF!
Name ___DAT10: #REF!
Name ___dat1000: #REF!
Name ___DAT11: #REF!
Name ___DAT12: #REF!
Name ___DAT2: #REF!
Name ___DAT3: #REF!
Name ___DAT4: #REF!
Name ___DAT5: #REF!
Name ___DAT6: #REF!
Name ___DAT7: #REF!
Name ___DAT8: #REF!
Name ___DAT9: #REF!
Name __DAT1: #REF!
Name __DAT10: #REF!
Name __dat1000: #REF!
Name __DAT11: #REF!
Name __DAT12: #REF!
Name __DAT2: #REF!
Name __DAT3: #REF!
Name __DAT4: #REF!
Name __DAT5: #REF!
Name __DAT6: #REF!
Name __DAT7: #REF!
Name __DAT8: #REF!
Name __DAT9: #REF!
Name _DAT1: #REF!

Sheet 減価償却費（Depreciation）
C2: Depreciation | E2: USD | I2: USD | M2: USD
A3: 部署 | C3: 減価償却費 | D3: 46113 | E3: =IF(MONTH(D3)=12,EDATE(D3,1),EDATE(D3,1)) -> 46143 | F3: =IF(MONTH(E3)=12,EDATE(E3,1),EDATE(E3,1)) -> 46174 | G3: =IF(MONTH(F3)=12,EDATE(F3,1),EDATE(F3,1)) -> 46204 | H3: =IF(MONTH(G3)=12,EDATE(G3,1),EDATE(G3,1)) -> 46235 | I3: =IF(MONTH(H3)=12,EDATE(H3,1),EDATE(H3,1)) -> 46266 | J3: =IF(MONTH(I3)=12,EDATE(I3,1),EDATE(I3,1)) -> 46296 | K3: =IF(MONTH(J3)=12,EDATE(J3,1),EDATE(J3,1)) -> 46327 | L3: =IF(MONTH(K3)=12,EDATE(K3,1),EDATE(K3,1)) -> 46357 | ... O3: =IF(MONTH(N3)=12,EDATE(N3,1),EDATE(N3,1)) -> 46447
A4: 振替総額 | C4: 建物 Building | D4: =D133 -> 324649.6 | E4: =E133 -> 324649.6 | F4: =F133 -> 324649.6 | G4: =G133 -> 324649.6 | H4: =H133 -> 324649.6 | I4: =I133 -> 324649.6 | J4: =J133 -> 324649.6 | K4: =K133 -> 324649.6 | ... O4: =O133 -> 324649.6
C5: 土地 Land | D5: =D134 -> 21912.57 | E5: =E134 -> 21912.57 | F5: =F134 -> 21912.57 | G5: =G134 -> 21912.57 | H5: =H134 -> 21912.57 | I5: =I134 -> 21912.57 | J5: =J134 -> 21912.57 | K5: =K134 -> 21912.57 | ... O5: =O134 -> 21912.57
A7: 1 | B7: 機器製造1課 | C7: 建物 Building | D7: =VLOOKUP(B8,'B&L'!$A$7:$BK$69,5,0) -> 13120.54 | E7: =VLOOKUP(B8,'B&L'!$A$7:$BK$69,10,0) -> 13142.14 | F7: =VLOOKUP(B8,'B&L'!$A$7:$BK$69,15,0) -> 12885.42 | G7: =VLOOKUP(B8,'B&L'!$A$7:$BK$69,20,0) -> 13112.58 | H7: =VLOOKUP(B8,'B&L'!$A$7:$BK$69,25,0) -> 13414.69 | I7: =VLOOKUP(B8,'B&L'!$A$7:$BK$69,30,0) -> 13414.5 | J7: =VLOOKUP(B8,'B&L'!$A$7:$BK$69,35,0) -> 13111.32 | K7: =VLOOKUP(B8,'B&L'!$A$7:$BK$69,40,0) -> 13294.21 | L7: =VLOOKUP(B8,'B&L'!$A$7:$BK$69,45,0) -> 13323.41 | M7: =VLOOKUP(B8,'B&L'!$A$7:$BK$69,50,0) -> 13484.92 | N7: =VLOOKUP(B8,'B&L'!$A$7:$BK$69,55,0) -> 14223.59 | O7: =VLOOKUP(B8,'B&L'!$A$7:$BK$69,60,0) -> 13277.16
B8: 1412000004 | C8: 土地 Land | D8: =VLOOKUP(B8,'B&L'!$A$7:$BK$69,6,0) -> 885.58 | E8: =VLOOKUP(B8,'B&L'!$A$7:$BK$69,11,0) -> 887.04 | F8: =VLOOKUP(B8,'B&L'!$A$7:$BK$69,16,0) -> 869.72 | G8: =VLOOKUP(B8,'B&L'!$A$7:$BK$69,21,0) -> 885.05 | H8: =VLOOKUP(B8,'B&L'!$A$7:$BK$69,26,0) -> 905.44 | I8: =VLOOKUP(B8,'B&L'!$A$7:$BK$69,31,0) -> 905.43 | J8: =VLOOKUP(B8,'B&L'!$A$7:$BK$69,36,0) -> 884.96 | K8: =VLOOKUP(B8,'B&L'!$A$7:$BK$69,41,0) -> 897.31 | L8: =VLOOKUP(B8,'B&L'!$A$7:$BK$69,46,0) -> 899.28 | M8: =VLOOKUP(B8,'B&L'!$A$7:$BK$69,51,0) -> 910.18 | N8: =VLOOKUP(B8,'B&L'!$A$7:$BK$69,56,0) -> 960.04 | O8: =VLOOKUP(B8,'B&L'!$A$7:$BK$69,61,0) -> 896.16
A9: 2 | B9: 機器製造2課 | C9: 建物 Building | D9: =VLOOKUP(B10,'B&L'!$A$7:$BK$69,5,0) -> 17807.79 | E9: =VLOOKUP(B10,'B&L'!$A$7:$BK$69,10,0) -> 17919.89 | F9: =VLOOKUP(B10,'B&L'!$A$7:$BK$69,15,0) -> 17978.32 | G9: =VLOOKUP(B10,'B&L'!$A$7:$BK$69,20,0) -> 17998.68 | H9: =VLOOKUP(B10,'B&L'!$A$7:$BK$69,25,0) -> 17958.43 | I9: =VLOOKUP(B10,'B&L'!$A$7:$BK$69,30,0) -> 17963.93 | J9: =VLOOKUP(B10,'B&L'!$A$7:$BK$69,35,0) -> 17945.57 | K9: =VLOOKUP(B10,'B&L'!$A$7:$BK$69,40,0) -> 17916.4 | L9: =VLOOKUP(B10,'B&L'!$A$7:$BK$69,45,0) -> 17802.57 | M9: =VLOOKUP(B10,'B&L'!$A$7:$BK$69,50,0) -> 17884.69 | N9: =VLOOKUP(B10,'B&L'!$A$7:$BK$69,55,0) -> 18164.77 | O9: =VLOOKUP(B10,'B&L'!$A$7:$BK$69,60,0) -> 17840.02
B10: 1412000005 | C10: 土地 Land | D10: =VLOOKUP(B10,'B&L'!$A$7:$BK$69,6,0) -> 1201.96 | E10: =VLOOKUP(B10,'B&L'!$A$7:$BK$69,11,0) -> 1209.52 | F10: =VLOOKUP(B10,'B&L'!$A$7:$BK$69,16,0) -> 1213.47 | G10: =VLOOKUP(B10,'B&L'!$A$7:$BK$69,21,0) -> 1214.84 | H10: =VLOOKUP(B10,'B&L'!$A$7:$BK$69,26,0) -> 1212.12 | I10: =VLOOKUP(B10,'B&L'!$A$7:$BK$69,31,0) -> 1212.49 | J10: =VLOOKUP(B10,'B&L'!$A$7:$BK$69,36,0) -> 1211.26 | K10: =VLOOKUP(B10,'B&L'!$A$7:$BK$69,41,0) -> 1209.29 | L10: =VLOOKUP(B10,'B&L'!$A$7:$BK$69,46,0) -> 1201.6 | M10: =VLOOKUP(B10,'B&L'!$A$7:$BK$69,51,0) -> 1207.15 | N10: =VLOOKUP(B10,'B&L'!$A$7:$BK$69,56,0) -> 1226.05 | O10: =VLOOKUP(B10,'B&L'!$A$7:$BK$69,61,0) -> 1204.13
A11: 3 | B11: 機器製造管理課 | C11: 建物 Building | D11: =VLOOKUP(B12,'B&L'!$A$7:$BK$69,5,0) -> 244.52 | E11: =VLOOKUP(B12,'B&L'!$A$7:$BK$69,10,0) -> 250.28 | F11: =VLOOKUP(B12,'B&L'!$A$7:$BK$69,15,0) -> 265.57 | G11: =VLOOKUP(B12,'B&L'!$A$7:$BK$69,20,0) -> 250.31 | H11: =VLOOKUP(B12,'B&L'!$A$7:$BK$69,25,0) -> 239.84 | I11: =VLOOKUP(B12,'B&L'!$A$7:$BK$69,30,0) -> 244.06 | J11: =VLOOKUP(B12,'B&L'!$A$7:$BK$69,35,0) -> 251.25 | K11: =VLOOKUP(B12,'B&L'!$A$7:$BK$69,40,0) -> 248.2 | L11: =VLOOKUP(B12,'B&L'!$A$7:$BK$69,45,0) -> 246.25 | M11: =VLOOKUP(B12,'B&L'!$A$7:$BK$69,50,0) -> 238.68 | N11: =VLOOKUP(B12,'B&L'!$A$7:$BK$69,55,0) -> 220.76 | O11: =VLOOKUP(B12,'B&L'!$A$7:$BK$69,60,0) -> 244.54
B12: 1412000062 | C12: 土地 Land | D12: =VLOOKUP(B12,'B&L'!$A$7:$BK$69,6,0) -> 16.5 | E12: =VLOOKUP(B12,'B&L'!$A$7:$BK$69,11,0) -> 16.89 | F12: =VLOOKUP(B12,'B&L'!$A$7:$BK$69,16,0) -> 17.92 | G12: =VLOOKUP(B12,'B&L'!$A$7:$BK$69,21,0) -> 16.9 | H12: =VLOOKUP(B12,'B&L'!$A$7:$BK$69,26,0) -> 16.19 | I12: =VLOOKUP(B12,'B&L'!$A$7:$BK$69,31,0) -> 16.47 | J12: =VLOOKUP(B12,'B&L'!$A$7:$BK$69,36,0) -> 16.96 | K12: =VLOOKUP(B12,'B&L'!$A$7:$BK$69,41,0) -> 16.75 | L12: =VLOOKUP(B12,'B&L'!$A$7:$BK$69,46,0) -> 16.62 | M12: =VLOOKUP(B12,'B&L'!$A$7:$BK$69,51,0) -> 16.11 | N12: =VLOOKUP(B12,'B&L'!$A$7:$BK$69,56,0) -> 14.9 | O12: =VLOOKUP(B12,'B&L'!$A$7:$BK$69,61,0) -> 16.51
A13: 4 | B13: RPS製造課 | C13: 建物 Building | D13: =VLOOKUP(B14,'B&L'!$A$7:$BK$69,5,0) -> 6380.12 | E13: =VLOOKUP(B14,'B&L'!$A$7:$BK$69,10,0) -> 6380.12 | F13: =VLOOKUP(B14,'B&L'!$A$7:$BK$69,15,0) -> 6380.12 | G13: =VLOOKUP(B14,'B&L'!$A$7:$BK$69,20,0) -> 6380.12 | H13: =VLOOKUP(B14,'B&L'!$A$7:$BK$69,25,0) -> 6380.12 | I13: =VLOOKUP(B14,'B&L'!$A$7:$BK$69,30,0) -> 6380.12 | J13: =VLOOKUP(B14,'B&L'!$A$7:$BK$69,35,0) -> 6380.12 | K13: =VLOOKUP(B14,'B&L'!$A$7:$BK$69,40,0) -> 6380.12 | L13: =VLOOKUP(B14,'B&L'!$A$7:$BK$69,45,0) -> 6380.12 | M13: =VLOOKUP(B14,'B&L'!$A$7:$BK$69,50,0) -> 6380.12 | N13: =VLOOKUP(B14,'B&L'!$A$7:$BK$69,55,0) -> 6380.12 | O13: =VLOOKUP(B14,'B&L'!$A$7:$BK$69,60,0) -> 6380.12
B14: 1412000066 | C14: 土地 Land | D14: =VLOOKUP(B14,'B&L'!$A$7:$BK$69,6,0) -> 430.63 | E14: =VLOOKUP(B14,'B&L'!$A$7:$BK$69,11,0) -> 430.63 | F14: =VLOOKUP(B14,'B&L'!$A$7:$BK$69,16,0) -> 430.63 | G14: =VLOOKUP(B14,'B&L'!$A$7:$BK$69,21,0) -> 430.63 | H14: =VLOOKUP(B14,'B&L'!$A$7:$BK$69,26,0) -> 430.63 | I14: =VLOOKUP(B14,'B&L'!$A$7:$BK$69,31,0) -> 430.63 | J14: =VLOOKUP(B14,'B&L'!$A$7:$BK$69,36,0) -> 430.63 | K14: =VLOOKUP(B14,'B&L'!$A$7:$BK$69,41,0) -> 430.63 | L14: =VLOOKUP(B14,'B&L'!$A$7:$BK$69,46,0) -> 430.63 | M14: =VLOOKUP(B14,'B&L'!$A$7:$BK$69,51,0) -> 430.63 | N14: =VLOOKUP(B14,'B&L'!$A$7:$BK$69,56,0) -> 430.63 | O14: =VLOOKUP(B14,'B&L'!$A$7:$BK$69,61,0) -> 430.63
A15: 5 | B15: 機器製造3課 | C15: 建物 Building | D15: =VLOOKUP(B16,'B&L'!$A$7:$BK$69,5,0) -> 47907.49 | E15: =VLOOKUP(B16,'B&L'!$A$7:$BK$69,10,0) -> 47628 | F15: =VLOOKUP(B16,'B&L'!$A$7:$BK$69,15,0) -> 47217.51 | G15: =VLOOKUP(B16,'B&L'!$A$7:$BK$69,20,0) -> 47502.29 | H15: =VLOOKUP(B16,'B&L'!$A$7:$BK$69,25,0) -> 47724.65 | I15: =VLOOKUP(B16,'B&L'!$A$7:$BK$69,30,0) -> 47612.51 | J15: =VLOOKUP(B16,'B&L'!$A$7:$BK$69,35,0) -> 47402.45 | K15: =VLOOKUP(B16,'B&L'!$A$7:$BK$69,40,0) -> 47494.1 | L15: =VLOOKUP(B16,'B&L'!$A$7:$BK$69,45,0) -> 47651.73 | M15: =VLOOKUP(B16,'B&L'!$A$7:$BK$69,50,0) -> 47742.78 | N15: =VLOOKUP(B16,'B&L'!$A$7:$BK$69,55,0) -> 47858.19 | O15: =VLOOKUP(B16,'B&L'!$A$7:$BK$69,60,0) -> 47661.03
B16: 1412000081 | C16: 土地 Land | D16: =VLOOKUP(B16,'B&L'!$A$7:$BK$69,6,0) -> 3233.57 | E16: =VLOOKUP(B16,'B&L'!$A$7:$BK$69,11,0) -> 3214.7 | F16: =VLOOKUP(B16,'B&L'!$A$7:$BK$69,16,0) -> 3187 | G16: =VLOOKUP(B16,'B&L'!$A$7:$BK$69,21,0) -> 3206.22 | H16: =VLOOKUP(B16,'B&L'!$A$7:$BK$69,26,0) -> 3221.23 | I16: =VLOOKUP(B16,'B&L'!$A$7:$BK$69,31,0) -> 3213.66 | J16: =VLOOKUP(B16,'B&L'!$A$7:$BK$69,36,0) -> 3199.48 | K16: =VLOOKUP(B16,'B&L'!$A$7:$BK$69,41,0) -> 3205.66 | L16: =VLOOKUP(B16,'B&L'!$A$7:$BK$69,46,0) -> 3216.3 | M16: =VLOOKUP(B16,'B&L'!$A$7:$BK$69,51,0) -> 3222.45 | N16: =VLOOKUP(B16,'B&L'!$A$7:$BK$69,56,0) -> 3230.24 | O16: =VLOOKUP(B16,'B&L'!$A$7:$BK$69,61,0) -> 3216.93
A17: 6 | B17: 電工製造課 | C17: 建物 Building | D17: =VLOOKUP(B18,'B&L'!$A$7:$BK$69,5,0) -> 5396.22 | E17: =VLOOKUP(B18,'B&L'!$A$7:$BK$69,10,0) -> 5395.95 | F17: =VLOOKUP(B18,'B&L'!$A$7:$BK$69,15,0) -> 5409.44 | G17: =VLOOKUP(B18,'B&L'!$A$7:$BK$69,20,0) -> 5396.13 | H17: =VLOOKUP(B18,'B&L'!$A$7:$BK$69,25,0) -> 5382.73 | I17: =VLOOKUP(B18,'B&L'!$A$7:$BK$69,30,0) -> 5384.14 | J17: =VLOOKUP(B18,'B&L'!$A$7:$BK$69,35,0) -> 5398.11 | K17: =VLOOKUP(B18,'B&L'!$A$7:$BK$69,40,0) -> 5389.64 | L17: =VLOOKUP(B18,'B&L'!$A$7:$BK$69,45,0) -> 5388.28 | M17: =VLOOKUP(B18,'B&L'!$A$7:$BK$69,50,0) -> 5369.23 | N17: =VLOOKUP(B18,'B&L'!$A$7:$BK$69,55,0) -> 5336.15 | O17: =VLOOKUP(B18,'B&L'!$A$7:$BK$69,60,0) -> 5379.14
B18: 1412000098 | C18: 土地 Land | D18: =VLOOKUP(B18,'B&L'!$A$7:$BK$69,6,0) -> 364.22 | E18: =VLOOKUP(B18,'B&L'!$A$7:$BK$69,11,0) -> 364.21 | F18: =VLOOKUP(B18,'B&L'!$A$7:$BK$69,16,0) -> 365.12 | G18: =VLOOKUP(B18,'B&L'!$A$7:$BK$69,21,0) -> 364.22 | H18: =VLOOKUP(B18,'B&L'!$A$7:$BK$69,26,0) -> 363.31 | I18: =VLOOKUP(B18,'B&L'!$A$7:$BK$69,31,0) -> 363.41 | J18: =VLOOKUP(B18,'B&L'!$A$7:$BK$69,36,0) -> 364.35 | K18: =VLOOKUP(B18,'B&L'!$A$7:$BK$69,41,0) -> 363.78 | L18: =VLOOKUP(B18,'B&L'!$A$7:$BK$69,46,0) -> 363.69 | M18: =VLOOKUP(B18,'B&L'!$A$7:$BK$69,51,0) -> 362.4 | N18: =VLOOKUP(B18,'B&L'!$A$7:$BK$69,56,0) -> 360.17 | O18: =VLOOKUP(B18,'B&L'!$A$7:$BK$69,61,0) -> 363.07
A19: 7 | B19: トナー製造課 | C19: 建物 Building | D19: =VLOOKUP(B20,'B&L'!$A$7:$BK$69,5,0) -> 9615.17 | E19: =VLOOKUP(B20,'B&L'!$A$7:$BK$69,10,0) -> 9671.62 | F19: =VLOOKUP(B20,'B&L'!$A$7:$BK$69,15,0) -> 9804.64 | G19: =VLOOKUP(B20,'B&L'!$A$7:$BK$69,20,0) -> 9678.64 | H19: =VLOOKUP(B20,'B&L'!$A$7:$BK$69,25,0) -> 9616.83 | I19: =VLOOKUP(B20,'B&L'!$A$7:$BK$69,30,0) -> 9655.23 | J19: =VLOOKUP(B20,'B&L'!$A$7:$BK$69,35,0) -> 9801.82 | K19: =VLOOKUP(B20,'B&L'!$A$7:$BK$69,40,0) -> 9771.68 | L19: =VLOOKUP(B20,'B&L'!$A$7:$BK$69,45,0) -> 9752.37 | M19: =VLOOKUP(B20,'B&L'!$A$7:$BK$69,50,0) -> 9677.42 | N19: =VLOOKUP(B20,'B&L'!$A$7:$BK$69,55,0) -> 9500 | O19: =VLOOKUP(B20,'B&L'!$A$7:$BK$69,60,0) -> 9735.43
B20: 1412000034 | C20: 土地 Land | D20: =VLOOKUP(B20,'B&L'!$A$7:$BK$69,6,0) -> 648.99 | E20: =VLOOKUP(B20,'B&L'!$A$7:$BK$69,11,0) -> 652.8 | F20: =VLOOKUP(B20,'B&L'!$A$7:$BK$69,16,0) -> 661.77 | G20: =VLOOKUP(B20,'B&L'!$A$7:$BK$69,21,0) -> 653.27 | H20: =VLOOKUP(B20,'B&L'!$A$7:$BK$69,26,0) -> 649.1 | I20: =VLOOKUP(B20,'B&L'!$A$7:$BK$69,31,0) -> 651.69 | J20: =VLOOKUP(B20,'B&L'!$A$7:$BK$69,36,0) -> 661.58 | K20: =VLOOKUP(B20,'B&L'!$A$7:$BK$69,41,0) -> 659.55 | L20: =VLOOKUP(B20,'B&L'!$A$7:$BK$69,46,0) -> 658.25 | M20: =VLOOKUP(B20,'B&L'!$A$7:$BK$69,51,0) -> 653.19 | N20: =VLOOKUP(B20,'B&L'!$A$7:$BK$69,56,0) -> 641.21 | O20: =VLOOKUP(B20,'B&L'!$A$7:$BK$69,61,0) -> 657.1
A21: 8 | B21: トナー生産技術 | C21: 建物 Building | D21: =VLOOKUP(B22,'B&L'!$A$7:$BK$69,5,0) -> 303.31 | E21: =VLOOKUP(B22,'B&L'!$A$7:$BK$69,10,0) -> 307.92 | F21: =VLOOKUP(B22,'B&L'!$A$7:$BK$69,15,0) -> 320.15 | G21: =VLOOKUP(B22,'B&L'!$A$7:$BK$69,20,0) -> 307.95 | H21: =VLOOKUP(B22,'B&L'!$A$7:$BK$69,25,0) -> 299.57 | I21: =VLOOKUP(B22,'B&L'!$A$7:$BK$69,30,0) -> 302.94 | J21: =VLOOKUP(B22,'B&L'!$A$7:$BK$69,35,0) -> 308.69 | K21: =VLOOKUP(B22,'B&L'!$A$7:$BK$69,40,0) -> 306.26 | L21: =VLOOKUP(B22,'B&L'!$A$7:$BK$69,45,0) -> 304.7 | M21: =VLOOKUP(B22,'B&L'!$A$7:$BK$69,50,0) -> 298.64 | N21: =VLOOKUP(B22,'B&L'!$A$7:$BK$69,55,0) -> 284.3 | O21: =VLOOKUP(B22,'B&L'!$A$7:$BK$69,60,0) -> 303.33
B22: 1412000048 | C22: 土地 Land | D22: =VLOOKUP(B22,'B&L'!$A$7:$BK$69,6,0) -> 20.47 | E22: =VLOOKUP(B22,'B&L'!$A$7:$BK$69,11,0) -> 20.78 | F22: =VLOOKUP(B22,'B&L'!$A$7:$BK$69,16,0) -> 21.61 | G22: =VLOOKUP(B22,'B&L'!$A$7:$BK$69,21,0) -> 20.79 | H22: =VLOOKUP(B22,'B&L'!$A$7:$BK$69,26,0) -> 20.22 | I22: =VLOOKUP(B22,'B&L'!$A$7:$BK$69,31,0) -> 20.45 | J22: =VLOOKUP(B22,'B&L'!$A$7:$BK$69,36,0) -> 20.84 | K22: =VLOOKUP(B22,'B&L'!$A$7:$BK$69,41,0) -> 20.67 | L22: =VLOOKUP(B22,'B&L'!$A$7:$BK$69,46,0) -> 20.57 | M22: =VLOOKUP(B22,'B&L'!$A$7:$BK$69,51,0) -> 20.16 | N22: =VLOOKUP(B22,'B&L'!$A$7:$BK$69,56,0) -> 19.19 | O22: =VLOOKUP(B22,'B&L'!$A$7:$BK$69,61,0) -> 20.47
A23: 9 | B23: トナー品質管理課 | C23: 建物 Building | D23: =VLOOKUP(B24,'B&L'!$A$7:$BK$69,5,0) -> 202.25 | E23: =VLOOKUP(B24,'B&L'!$A$7:$BK$69,10,0) -> 206.67 | F23: =VLOOKUP(B24,'B&L'!$A$7:$BK$69,15,0) -> 218.39 | G23: =VLOOKUP(B24,'B&L'!$A$7:$BK$69,20,0) -> 206.69 | H23: =VLOOKUP(B24,'B&L'!$A$7:$BK$69,25,0) -> 201.66 | I23: =VLOOKUP(B24,'B&L'!$A$7:$BK$69,30,0) -> 205.04 | J23: =VLOOKUP(B24,'B&L'!$A$7:$BK$69,35,0) -> 210.79 | K23: =VLOOKUP(B24,'B&L'!$A$7:$BK$69,40,0) -> 208.35 | L23: =VLOOKUP(B24,'B&L'!$A$7:$BK$69,45,0) -> 206.79 | M23: =VLOOKUP(B24,'B&L'!$A$7:$BK$69,50,0) -> 200.74 | N23: =VLOOKUP(B24,'B&L'!$A$7:$BK$69,55,0) -> 186.4 | O23: =VLOOKUP(B24,'B&L'!$A$7:$BK$69,60,0) -> 205.42
B24: 1412000055 | C24: 土地 Land | D24: =VLOOKUP(B24,'B&L'!$A$7:$BK$69,6,0) -> 13.65 | E24: =VLOOKUP(B24,'B&L'!$A$7:$BK$69,11,0) -> 13.95 | F24: =VLOOKUP(B24,'B&L'!$A$7:$BK$69,16,0) -> 14.74 | G24: =VLOOKUP(B24,'B&L'!$A$7:$BK$69,21,0) -> 13.95 | H24: =VLOOKUP(B24,'B&L'!$A$7:$BK$69,26,0) -> 13.61 | I24: =VLOOKUP(B24,'B&L'!$A$7:$BK$69,31,0) -> 13.84 | J24: =VLOOKUP(B24,'B&L'!$A$7:$BK$69,36,0) -> 14.23 | K24: =VLOOKUP(B24,'B&L'!$A$7:$BK$69,41,0) -> 14.06 | L24: =VLOOKUP(B24,'B&L'!$A$7:$BK$69,46,0) -> 13.96 | M24: =VLOOKUP(B24,'B&L'!$A$7:$BK$69,51,0) -> 13.55 | N24: =VLOOKUP(B24,'B&L'!$A$7:$BK$69,56,0) -> 12.58 | O24: =VLOOKUP(B24,'B&L'!$A$7:$BK$69,61,0) -> 13.87
A25: 10 | B25: トナー製造管理課 | C25: 建物 Building | D25: =VLOOKUP(B26,'B&L'!$A$7:$BK$69,5,0) -> 37.77 | E25: =VLOOKUP(B26,'B&L'!$A$7:$BK$69,10,0) -> 36.34 | F25: =VLOOKUP(B26,'B&L'!$A$7:$BK$69,15,0) -> 40.92 | G25: =VLOOKUP(B26,'B&L'!$A$7:$BK$69,20,0) -> 43.05 | H25: =VLOOKUP(B26,'B&L'!$A$7:$BK$69,25,0) -> 39.21 | I25: =VLOOKUP(B26,'B&L'!$A$7:$BK$69,30,0) -> 47.04 | J25: =VLOOKUP(B26,'B&L'!$A$7:$BK$69,35,0) -> 46.78 | K25: =VLOOKUP(B26,'B&L'!$A$7:$BK$69,40,0) -> 45.56 | L25: =VLOOKUP(B26,'B&L'!$A$7:$BK$69,45,0) -> 41.56 | M25: =VLOOKUP(B26,'B&L'!$A$7:$BK$69,50,0) -> 38.79 | N25: =VLOOKUP(B26,'B&L'!$A$7:$BK$69,55,0) -> 29.85 | O25: =VLOOKUP(B26,'B&L'!$A$7:$BK$69,60,0) -> 37.78
B26: 1412000063 | C26: 土地 Land | D26: =VLOOKUP(B26,'B&L'!$A$7:$BK$69,6,0) -> 2.55 | E26: =VLOOKUP(B26,'B&L'!$A$7:$BK$69,11,0) -> 2.45 | F26: =VLOOKUP(B26,'B&L'!$A$7:$BK$69,16,0) -> 2.76 | G26: =VLOOKUP(B26,'B&L'!$A$7:$BK$69,21,0) -> 2.91 | H26: =VLOOKUP(B26,'B&L'!$A$7:$BK$69,26,0) -> 2.65 | I26: =VLOOKUP(B26,'B&L'!$A$7:$BK$69,31,0) -> 3.18 | J26: =VLOOKUP(B26,'B&L'!$A$7:$BK$69,36,0) -> 3.16 | K26: =VLOOKUP(B26,'B&L'!$A$7:$BK$69,41,0) -> 3.08 | L26: =VLOOKUP(B26,'B&L'!$A$7:$BK$69,46,0) -> 2.81 | M26: =VLOOKUP(B26,'B&L'!$A$7:$BK$69,51,0) -> 2.62 | N26: =VLOOKUP(B26,'B&L'!$A$7:$BK$69,56,0) -> 2.01 | O26: =VLOOKUP(B26,'B&L'!$A$7:$BK$69,61,0) -> 2.55
A27: 11 | B27: 金型技術課 | C27: 建物 Building | D27: =VLOOKUP(B28,'B&L'!$A$7:$BK$69,5,0) -> 1618.4 | E27: =VLOOKUP(B28,'B&L'!$A$7:$BK$69,10,0) -> 1626.59 | F27: =VLOOKUP(B28,'B&L'!$A$7:$BK$69,15,0) -> 1634.58 | G27: =VLOOKUP(B28,'B&L'!$A$7:$BK$69,20,0) -> 1626.7 | H27: =VLOOKUP(B28,'B&L'!$A$7:$BK$69,25,0) -> 1618.77 | I27: =VLOOKUP(B28,'B&L'!$A$7:$BK$69,30,0) -> 1619.6 | J27: =VLOOKUP(B28,'B&L'!$A$7:$BK$69,35,0) -> 1627.87 | K27: =VLOOKUP(B28,'B&L'!$A$7:$BK$69,40,0) -> 1622.86 | L27: =VLOOKUP(B28,'B&L'!$A$7:$BK$69,45,0) -> 1622.05 | M27: =VLOOKUP(B28,'B&L'!$A$7:$BK$69,50,0) -> 1617.63 | N27: =VLOOKUP(B28,'B&L'!$A$7:$BK$69,55,0) -> 1596.78 | O27: =VLOOKUP(B28,'B&L'!$A$7:$BK$69,60,0) -> 1623.88
B28: 1412000044 | C28: 土地 Land | D28: =VLOOKUP(B28,'B&L'!$A$7:$BK$69,6,0) -> 109.24 | E28: =VLOOKUP(B28,'B&L'!$A$7:$BK$69,11,0) -> 109.79 | F28: =VLOOKUP(B28,'B&L'!$A$7:$BK$69,16,0) -> 110.33 | G28: =VLOOKUP(B28,'B&L'!$A$7:$BK$69,21,0) -> 109.8 | H28: =VLOOKUP(B28,'B&L'!$A$7:$BK$69,26,0) -> 109.26 | I28: =VLOOKUP(B28,'B&L'!$A$7:$BK$69,31,0) -> 109.32 | J28: =VLOOKUP(B28,'B&L'!$A$7:$BK$69,36,0) -> 109.88 | K28: =VLOOKUP(B28,'B&L'!$A$7:$BK$69,41,0) -> 109.54 | L28: =VLOOKUP(B28,'B&L'!$A$7:$BK$69,46,0) -> 109.48 | M28: =VLOOKUP(B28,'B&L'!$A$7:$BK$69,51,0) -> 109.18 | N28: =VLOOKUP(B28,'B&L'!$A$7:$BK$69,56,0) -> 107.78 | O28: =VLOOKUP(B28,'B&L'!$A$7:$BK$69,61,0) -> 109.61
A29: 12 | B29: 部品製造管理課 | C29: 建物 Building | D29: =VLOOKUP(B30,'B&L'!$A$7:$BK$69,5,0) -> 110.03 | E29: =VLOOKUP(B30,'B&L'!$A$7:$BK$69,10,0) -> 109.98 | F29: =VLOOKUP(B30,'B&L'!$A$7:$BK$69,15,0) -> 112.19 | G29: =VLOOKUP(B30,'B&L'!$A$7:$BK$69,20,0) -> 110.01 | H29: =VLOOKUP(B30,'B&L'!$A$7:$BK$69,25,0) -> 107.83 | I29: =VLOOKUP(B30,'B&L'!$A$7:$BK$69,30,0) -> 108.06 | J29: =VLOOKUP(B30,'B&L'!$A$7:$BK$69,35,0) -> 110.34 | K29: =VLOOKUP(B30,'B&L'!$A$7:$BK$69,40,0) -> 108.95 | L29: =VLOOKUP(B30,'B&L'!$A$7:$BK$69,45,0) -> 108.73 | M29: =VLOOKUP(B30,'B&L'!$A$7:$BK$69,50,0) -> 107.51 | N29: =VLOOKUP(B30,'B&L'!$A$7:$BK$69,55,0) -> 101.76 | O29: =VLOOKUP(B30,'B&L'!$A$7:$BK$69,60,0) -> 109.24
B30: 1412000087 | C30: 土地 Land | D30: =VLOOKUP(B30,'B&L'!$A$7:$BK$69,6,0) -> 7.43 | E30: =VLOOKUP(B30,'B&L'!$A$7:$BK$69,11,0) -> 7.42 | F30: =VLOOKUP(B30,'B&L'!$A$7:$BK$69,16,0) -> 7.57 | G30: =VLOOKUP(B30,'B&L'!$A$7:$BK$69,21,0) -> 7.43 | H30: =VLOOKUP(B30,'B&L'!$A$7:$BK$69,26,0) -> 7.28 | I30: =VLOOKUP(B30,'B&L'!$A$7:$BK$69,31,0) -> 7.29 | J30: =VLOOKUP(B30,'B&L'!$A$7:$BK$69,36,0) -> 7.45 | K30: =VLOOKUP(B30,'B&L'!$A$7:$BK$69,41,0) -> 7.35 | L30: =VLOOKUP(B30,'B&L'!$A$7:$BK$69,46,0) -> 7.34 | M30: =VLOOKUP(B30,'B&L'!$A$7:$BK$69,51,0) -> 7.26 | N30: =VLOOKUP(B30,'B&L'!$A$7:$BK$69,56,0) -> 6.87 | O30: =VLOOKUP(B30,'B&L'!$A$7:$BK$69,61,0) -> 7.37
A31: 13 | B31: 品質管理課 | C31: 建物 Building | D31: =VLOOKUP(B32,'B&L'!$A$7:$BK$69,5,0) -> 364.57 | E31: =VLOOKUP(B32,'B&L'!$A$7:$BK$69,10,0) -> 364.43 | F31: =VLOOKUP(B32,'B&L'!$A$7:$BK$69,15,0) -> 371.04 | G31: =VLOOKUP(B32,'B&L'!$A$7:$BK$69,20,0) -> 364.52 | H31: =VLOOKUP(B32,'B&L'!$A$7:$BK$69,25,0) -> 357.96 | I31: =VLOOKUP(B32,'B&L'!$A$7:$BK$69,30,0) -> 358.65 | J31: =VLOOKUP(B32,'B&L'!$A$7:$BK$69,35,0) -> 365.49 | K31: =VLOOKUP(B32,'B&L'!$A$7:$BK$69,40,0) -> 361.34 | L31: =VLOOKUP(B32,'B&L'!$A$7:$BK$69,45,0) -> 360.68 | M31: =VLOOKUP(B32,'B&L'!$A$7:$BK$69,50,0) -> 357.02 | N31: =VLOOKUP(B32,'B&L'!$A$7:$BK$69,55,0) -> 339.76 | O31: =VLOOKUP(B32,'B&L'!$A$7:$BK$69,60,0) -> 362.19
B32: 1412000088 | C32: 土地 Land | D32: =VLOOKUP(B32,'B&L'!$A$7:$BK$69,6,0) -> 24.61 | E32: =VLOOKUP(B32,'B&L'!$A$7:$BK$69,11,0) -> 24.6 | F32: =VLOOKUP(B32,'B&L'!$A$7:$BK$69,16,0) -> 25.04 | G32: =VLOOKUP(B32,'B&L'!$A$7:$BK$69,21,0) -> 24.6 | H32: =VLOOKUP(B32,'B&L'!$A$7:$BK$69,26,0) -> 24.16 | I32: =VLOOKUP(B32,'B&L'!$A$7:$BK$69,31,0) -> 24.21 | J32: =VLOOKUP(B32,'B&L'!$A$7:$BK$69,36,0) -> 24.67 | K32: =VLOOKUP(B32,'B&L'!$A$7:$BK$69,41,0) -> 24.39 | L32: =VLOOKUP(B32,'B&L'!$A$7:$BK$69,46,0) -> 24.34 | M32: =VLOOKUP(B32,'B&L'!$A$7:$BK$69,51,0) -> 24.1 | N32: =VLOOKUP(B32,'B&L'!$A$7:$BK$69,56,0) -> 22.93 | O32: =VLOOKUP(B32,'B&L'!$A$7:$BK$69,61,0) -> 24.45
A33: 14 | B33: 部品製造課 | C33: 建物 Building | D33: =VLOOKUP(B34,'B&L'!$A$7:$BK$69,5,0) -> 11479.77 | E33: =VLOOKUP(B34,'B&L'!$A$7:$BK$69,10,0) -> 11474.95 | F33: =VLOOKUP(B34,'B&L'!$A$7:$BK$69,15,0) -> 11502.72 | G33: =VLOOKUP(B34,'B&L'!$A$7:$BK$69,20,0) -> 11467.04 | H33: =VLOOKUP(B34,'B&L'!$A$7:$BK$69,25,0) -> 11431.69 | I33: =VLOOKUP(B34,'B&L'!$A$7:$BK$69,30,0) -> 11438.89 | J33: =VLOOKUP(B34,'B&L'!$A$7:$BK$69,35,0) -> 11475.9 | K33: =VLOOKUP(B34,'B&L'!$A$7:$BK$69,40,0) -> 11459.89 | L33: =VLOOKUP(B34,'B&L'!$A$7:$BK$69,45,0) -> 11460.65 | M33: =VLOOKUP(B34,'B&L'!$A$7:$BK$69,50,0) -> 11442.67 | N33: =VLOOKUP(B34,'B&L'!$A$7:$BK$69,55,0) -> 11357.81 | O33: =VLOOKUP(B34,'B&L'!$A$7:$BK$69,60,0) -> 11468.08
B34: 1412000056 | C34: 土地 Land | D34: =VLOOKUP(B34,'B&L'!$A$7:$BK$69,6,0) -> 774.84 | E34: =VLOOKUP(B34,'B&L'!$A$7:$BK$69,11,0) -> 774.51 | F34: =VLOOKUP(B34,'B&L'!$A$7:$BK$69,16,0) -> 776.39 | G34: =VLOOKUP(B34,'B&L'!$A$7:$BK$69,21,0) -> 773.98 | H34: =VLOOKUP(B34,'B&L'!$A$7:$BK$69,26,0) -> 771.59 | I34: =VLOOKUP(B34,'B&L'!$A$7:$BK$69,31,0) -> 772.08 | J34: =VLOOKUP(B34,'B&L'!$A$7:$BK$69,36,0) -> 774.58 | K34: =VLOOKUP(B34,'B&L'!$A$7:$BK$69,41,0) -> 773.5 | L34: =VLOOKUP(B34,'B&L'!$A$7:$BK$69,46,0) -> 773.55 | M34: =VLOOKUP(B34,'B&L'!$A$7:$BK$69,51,0) -> 772.34 | N34: =VLOOKUP(B34,'B&L'!$A$7:$BK$69,56,0) -> 766.61 | O34: =VLOOKUP(B34,'B&L'!$A$7:$BK$69,61,0) -> 774.05
A35: 15 | B35: 部品技術課 | C35: 建物 Building | D35: =VLOOKUP(B36,'B&L'!$A$7:$BK$69,5,0) -> 285.47 | E35: =VLOOKUP(B36,'B&L'!$A$7:$BK$69,10,0) -> 285.26 | F35: =VLOOKUP(B36,'B&L'!$A$7:$BK$69,15,0) -> 285.76 | G35: =VLOOKUP(B36,'B&L'!$A$7:$BK$69,20,0) -> 285.08 | H35: =VLOOKUP(B36,'B&L'!$A$7:$BK$69,25,0) -> 296.95 | I35: =VLOOKUP(B36,'B&L'!$A$7:$BK$69,30,0) -> 297.07 | J35: =VLOOKUP(B36,'B&L'!$A$7:$BK$69,35,0) -> 297.43 | K35: =VLOOKUP(B36,'B&L'!$A$7:$BK$69,40,0) -> 297.25 | L35: =VLOOKUP(B36,'B&L'!$A$7:$BK$69,45,0) -> 303.31 | M35: =VLOOKUP(B36,'B&L'!$A$7:$BK$69,50,0) -> 303 | N35: =VLOOKUP(B36,'B&L'!$A$7:$BK$69,55,0) -> 302.02 | O35: =VLOOKUP(B36,'B&L'!$A$7:$BK$69,60,0) -> 303.29
B36: 1412000080 | C36: 土地 Land | D36: =VLOOKUP(B36,'B&L'!$A$7:$BK$69,6,0) -> 19.27 | E36: =VLOOKUP(B36,'B&L'!$A$7:$BK$69,11,0) -> 19.25 | F36: =VLOOKUP(B36,'B&L'!$A$7:$BK$69,16,0) -> 19.29 | G36: =VLOOKUP(B36,'B&L'!$A$7:$BK$69,21,0) -> 19.24 | H36: =VLOOKUP(B36,'B&L'!$A$7:$BK$69,26,0) -> 20.04 | I36: =VLOOKUP(B36,'B&L'!$A$7:$BK$69,31,0) -> 20.05 | J36: =VLOOKUP(B36,'B&L'!$A$7:$BK$69,36,0) -> 20.08 | K36: =VLOOKUP(B36,'B&L'!$A$7:$BK$69,41,0) -> 20.06 | L36: =VLOOKUP(B36,'B&L'!$A$7:$BK$69,46,0) -> 20.47 | M36: =VLOOKUP(B36,'B&L'!$A$7:$BK$69,51,0) -> 20.45 | N36: =VLOOKUP(B36,'B&L'!$A$7:$BK$69,56,0) -> 20.38 | O36: =VLOOKUP(B36,'B&L'!$A$7:$BK$69,61,0) -> 20.47
A37: 16 | B37: 工程品質管理1課 | C37: 建物 Building | D37: =VLOOKUP(B38,'B&L'!$A$7:$BK$69,5,0) -> 515.11 | E37: =VLOOKUP(B38,'B&L'!$A$7:$BK$69,10,0) -> 517.01 | F37: =VLOOKUP(B38,'B&L'!$A$7:$BK$69,15,0) -> 528.79 | G37: =VLOOKUP(B38,'B&L'!$A$7:$BK$69,20,0) -> 537.95 | H37: =VLOOKUP(B38,'B&L'!$A$7:$BK$69,25,0) -> 527.24 | I37: =VLOOKUP(B38,'B&L'!$A$7:$BK$69,30,0) -> 529.92 | J37: =VLOOKUP(B38,'B&L'!$A$7:$BK$69,35,0) -> 547.65 | K37: =VLOOKUP(B38,'B&L'!$A$7:$BK$69,40,0) -> 542.32 | L37: =VLOOKUP(B38,'B&L'!$A$7:$BK$69,45,0) -> 540.74 | M37: =VLOOKUP(B38,'B&L'!$A$7:$BK$69,50,0) -> 533.6 | N37: =VLOOKUP(B38,'B&L'!$A$7:$BK$69,55,0) -> 508.82 | O37: =VLOOKUP(B38,'B&L'!$A$7:$BK$69,60,0) -> 541.27
B38: 1412000053 | C38: 土地 Land | D38: =VLOOKUP(B38,'B&L'!$A$7:$BK$69,6,0) -> 34.77 | E38: =VLOOKUP(B38,'B&L'!$A$7:$BK$69,11,0) -> 34.9 | F38: =VLOOKUP(B38,'B&L'!$A$7:$BK$69,16,0) -> 35.69 | G38: =VLOOKUP(B38,'B&L'!$A$7:$BK$69,21,0) -> 36.31 | H38: =VLOOKUP(B38,'B&L'!$A$7:$BK$69,26,0) -> 35.59 | I38: =VLOOKUP(B38,'B&L'!$A$7:$BK$69,31,0) -> 35.77 | J38: =VLOOKUP(B38,'B&L'!$A$7:$BK$69,36,0) -> 36.96 | K38: =VLOOKUP(B38,'B&L'!$A$7:$BK$69,41,0) -> 36.6 | L38: =VLOOKUP(B38,'B&L'!$A$7:$BK$69,46,0) -> 36.5 | M38: =VLOOKUP(B38,'B&L'!$A$7:$BK$69,51,0) -> 36.02 | N38: =VLOOKUP(B38,'B&L'!$A$7:$BK$69,56,0) -> 34.34 | O38: =VLOOKUP(B38,'B&L'!$A$7:$BK$69,61,0) -> 36.53
A39: 17 | B39: 工程品質管理2課 | C39: 建物 Building | D39: =VLOOKUP(B40,'B&L'!$A$7:$BK$69,5,0) -> 1356.41 | E39: =VLOOKUP(B40,'B&L'!$A$7:$BK$69,10,0) -> 1357.9 | F39: =VLOOKUP(B40,'B&L'!$A$7:$BK$69,15,0) -> 1404.02 | G39: =VLOOKUP(B40,'B&L'!$A$7:$BK$69,20,0) -> 1358.44 | H39: =VLOOKUP(B40,'B&L'!$A$7:$BK$69,25,0) -> 1315.31 | I39: =VLOOKUP(B40,'B&L'!$A$7:$BK$69,30,0) -> 1321.6 | J39: =VLOOKUP(B40,'B&L'!$A$7:$BK$69,35,0) -> 1364.46 | K39: =VLOOKUP(B40,'B&L'!$A$7:$BK$69,40,0) -> 1339.22 | L39: =VLOOKUP(B40,'B&L'!$A$7:$BK$69,45,0) -> 1334.34 | M39: =VLOOKUP(B40,'B&L'!$A$7:$BK$69,50,0) -> 1309.33 | N39: =VLOOKUP(B40,'B&L'!$A$7:$BK$69,55,0) -> 1201.37 | O39: =VLOOKUP(B40,'B&L'!$A$7:$BK$69,60,0) -> 1341.93
B40: 1412000104 | C40: 土地 Land | D40: =VLOOKUP(B40,'B&L'!$A$7:$BK$69,6,0) -> 91.55 | E40: =VLOOKUP(B40,'B&L'!$A$7:$BK$69,11,0) -> 91.65 | F40: =VLOOKUP(B40,'B&L'!$A$7:$BK$69,16,0) -> 94.77 | G40: =VLOOKUP(B40,'B&L'!$A$7:$BK$69,21,0) -> 91.69 | H40: =VLOOKUP(B40,'B&L'!$A$7:$BK$69,26,0) -> 88.78 | I40: =VLOOKUP(B40,'B&L'!$A$7:$BK$69,31,0) -> 89.2 | J40: =VLOOKUP(B40,'B&L'!$A$7:$BK$69,36,0) -> 92.1 | K40: =VLOOKUP(B40,'B&L'!$A$7:$BK$69,41,0) -> 90.39 | L40: =VLOOKUP(B40,'B&L'!$A$7:$BK$69,46,0) -> 90.06 | M40: =VLOOKUP(B40,'B&L'!$A$7:$BK$69,51,0) -> 88.37 | N40: =VLOOKUP(B40,'B&L'!$A$7:$BK$69,56,0) -> 81.09 | O40: =VLOOKUP(B40,'B&L'!$A$7:$BK$69,61,0) -> 90.58
A41: 18 | B41: 工程品質管理3課 | C41: 建物 Building | D41: =VLOOKUP(B42,'B&L'!$A$7:$BK$69,5,0) -> 319.76 | E41: =VLOOKUP(B42,'B&L'!$A$7:$BK$69,10,0) -> 320.2 | F41: =VLOOKUP(B42,'B&L'!$A$7:$BK$69,15,0) -> 326.64 | G41: =VLOOKUP(B42,'B&L'!$A$7:$BK$69,20,0) -> 320.26 | H41: =VLOOKUP(B42,'B&L'!$A$7:$BK$69,25,0) -> 314.49 | I41: =VLOOKUP(B42,'B&L'!$A$7:$BK$69,30,0) -> 315.51 | J41: =VLOOKUP(B42,'B&L'!$A$7:$BK$69,35,0) -> 321.03 | K41: =VLOOKUP(B42,'B&L'!$A$7:$BK$69,40,0) -> 317.86 | L41: =VLOOKUP(B42,'B&L'!$A$7:$BK$69,45,0) -> 317.16 | M41: =VLOOKUP(B42,'B&L'!$A$7:$BK$69,50,0) -> 313.71 | N41: =VLOOKUP(B42,'B&L'!$A$7:$BK$69,55,0) -> 299.81 | O41: =VLOOKUP(B42,'B&L'!$A$7:$BK$69,60,0) -> 317.94
B42: 1412000105 | C42: 土地 Land | D42: =VLOOKUP(B42,'B&L'!$A$7:$BK$69,6,0) -> 21.58 | E42: =VLOOKUP(B42,'B&L'!$A$7:$BK$69,11,0) -> 21.61 | F42: =VLOOKUP(B42,'B&L'!$A$7:$BK$69,16,0) -> 22.05 | G42: =VLOOKUP(B42,'B&L'!$A$7:$BK$69,21,0) -> 21.62 | H42: =VLOOKUP(B42,'B&L'!$A$7:$BK$69,26,0) -> 21.23 | I42: =VLOOKUP(B42,'B&L'!$A$7:$BK$69,31,0) -> 21.3 | J42: =VLOOKUP(B42,'B&L'!$A$7:$BK$69,36,0) -> 21.67 | K42: =VLOOKUP(B42,'B&L'!$A$7:$BK$69,41,0) -> 21.45 | L42: =VLOOKUP(B42,'B&L'!$A$7:$BK$69,46,0) -> 21.41 | M42: =VLOOKUP(B42,'B&L'!$A$7:$BK$69,51,0) -> 21.17 | N42: =VLOOKUP(B42,'B&L'!$A$7:$BK$69,56,0) -> 20.24 | O42: =VLOOKUP(B42,'B&L'!$A$7:$BK$69,61,0) -> 21.46
...

Sheet 固定資産金利（Interest）
C2: Interest | E2: USD | I2: USD
A3: 部署 | C3: 固定資産金利 | D3: 46113 | E3: =IF(MONTH(D3)=12,EDATE(D3,1),EDATE(D3,1)) -> 46143 | F3: =IF(MONTH(E3)=12,EDATE(E3,1),EDATE(E3,1)) -> 46174 | G3: =IF(MONTH(F3)=12,EDATE(F3,1),EDATE(F3,1)) -> 46204 | H3: =IF(MONTH(G3)=12,EDATE(G3,1),EDATE(G3,1)) -> 46235 | I3: =IF(MONTH(H3)=12,EDATE(H3,1),EDATE(H3,1)) -> 46266 | J3: =IF(MONTH(I3)=12,EDATE(I3,1),EDATE(I3,1)) -> 46296 | K3: =IF(MONTH(J3)=12,EDATE(J3,1),EDATE(J3,1)) -> 46327 | L3: =IF(MONTH(K3)=12,EDATE(K3,1),EDATE(K3,1)) -> 46357 | ... O3: =IF(MONTH(N3)=12,EDATE(N3,1),EDATE(N3,1)) -> 46447
A4: 振替総額 | C4: 建物 Building | D4: =D133 -> 208679.16 | E4: =E133 -> 196991.77 | F4: =F133 -> 196991.77 | G4: =G133 -> 196991.77 | H4: =H133 -> 196991.77 | I4: =I133 -> 196991.77 | J4: =J133 -> 196991.77 | K4: =K133 -> 196991.77 | ... O4: =O133 -> 196991.77
C5: 土地 Land | D5: =D134 -> 26458.43 | E5: =E134 -> 25669.57 | F5: =F134 -> 25669.57 | G5: =G134 -> 25669.57 | H5: =H134 -> 25669.57 | I5: =I134 -> 25669.57 | J5: =J134 -> 25669.57 | K5: =K134 -> 25669.57 | ... O5: =O134 -> 25669.57
A7: 1 | B7: 機器製造1課 | C7: 建物 Building | D7: =VLOOKUP(B8,'B&L'!$A$7:$BK$69,7,0) -> 8433.66 | E7: =VLOOKUP(B8,'B&L'!$A$7:$BK$69,12,0) -> 7974.42 | F7: =VLOOKUP(B8,'B&L'!$A$7:$BK$69,17,0) -> 7818.65 | G7: =VLOOKUP(B8,'B&L'!$A$7:$BK$69,22,0) -> 7956.49 | H7: =VLOOKUP(B8,'B&L'!$A$7:$BK$69,27,0) -> 8139.8 | I7: =VLOOKUP(B8,'B&L'!$A$7:$BK$69,32,0) -> 8139.69 | J7: =VLOOKUP(B8,'B&L'!$A$7:$BK$69,37,0) -> 7955.72 | K7: =VLOOKUP(B8,'B&L'!$A$7:$BK$69,42,0) -> 8066.7 | L7: =VLOOKUP(B8,'B&L'!$A$7:$BK$69,47,0) -> 8084.42 | M7: =VLOOKUP(B8,'B&L'!$A$7:$BK$69,52,0) -> 8182.42 | N7: =VLOOKUP(B8,'B&L'!$A$7:$BK$69,57,0) -> 8630.63 | O7: =VLOOKUP(B8,'B&L'!$A$7:$BK$69,62,0) -> 8056.35
B8: 1412000004 | C8: 土地 Land | D8: =VLOOKUP(B8,'B&L'!$A$7:$BK$69,8,0) -> 1069.3 | E8: =VLOOKUP(B8,'B&L'!$A$7:$BK$69,13,0) -> 1039.13 | F8: =VLOOKUP(B8,'B&L'!$A$7:$BK$69,18,0) -> 1018.83 | G8: =VLOOKUP(B8,'B&L'!$A$7:$BK$69,23,0) -> 1036.79 | H8: =VLOOKUP(B8,'B&L'!$A$7:$BK$69,28,0) -> 1060.68 | I8: =VLOOKUP(B8,'B&L'!$A$7:$BK$69,33,0) -> 1060.67 | J8: =VLOOKUP(B8,'B&L'!$A$7:$BK$69,38,0) -> 1036.69 | K8: =VLOOKUP(B8,'B&L'!$A$7:$BK$69,43,0) -> 1051.15 | L8: =VLOOKUP(B8,'B&L'!$A$7:$BK$69,48,0) -> 1053.46 | M8: =VLOOKUP(B8,'B&L'!$A$7:$BK$69,53,0) -> 1066.23 | N8: =VLOOKUP(B8,'B&L'!$A$7:$BK$69,58,0) -> 1124.64 | O8: =VLOOKUP(B8,'B&L'!$A$7:$BK$69,63,0) -> 1049.81
A9: 2 | B9: 機器製造2課 | C9: 建物 Building | D9: =VLOOKUP(B10,'B&L'!$A$7:$BK$69,7,0) -> 11446.54 | E9: =VLOOKUP(B10,'B&L'!$A$7:$BK$69,12,0) -> 10873.48 | F9: =VLOOKUP(B10,'B&L'!$A$7:$BK$69,17,0) -> 10908.94 | G9: =VLOOKUP(B10,'B&L'!$A$7:$BK$69,22,0) -> 10921.29 | H9: =VLOOKUP(B10,'B&L'!$A$7:$BK$69,27,0) -> 10896.86 | I9: =VLOOKUP(B10,'B&L'!$A$7:$BK$69,32,0) -> 10900.2 | J9: =VLOOKUP(B10,'B&L'!$A$7:$BK$69,37,0) -> 10889.06 | K9: =VLOOKUP(B10,'B&L'!$A$7:$BK$69,42,0) -> 10871.36 | L9: =VLOOKUP(B10,'B&L'!$A$7:$BK$69,47,0) -> 10802.29 | M9: =VLOOKUP(B10,'B&L'!$A$7:$BK$69,52,0) -> 10852.12 | N9: =VLOOKUP(B10,'B&L'!$A$7:$BK$69,57,0) -> 11022.07 | O9: =VLOOKUP(B10,'B&L'!$A$7:$BK$69,62,0) -> 10825.02
B10: 1412000005 | C10: 土地 Land | D10: =VLOOKUP(B10,'B&L'!$A$7:$BK$69,8,0) -> 1451.31 | E10: =VLOOKUP(B10,'B&L'!$A$7:$BK$69,13,0) -> 1416.9 | F10: =VLOOKUP(B10,'B&L'!$A$7:$BK$69,18,0) -> 1421.52 | G10: =VLOOKUP(B10,'B&L'!$A$7:$BK$69,23,0) -> 1423.13 | H10: =VLOOKUP(B10,'B&L'!$A$7:$BK$69,28,0) -> 1419.95 | I10: =VLOOKUP(B10,'B&L'!$A$7:$BK$69,33,0) -> 1420.38 | J10: =VLOOKUP(B10,'B&L'!$A$7:$BK$69,38,0) -> 1418.93 | K10: =VLOOKUP(B10,'B&L'!$A$7:$BK$69,43,0) -> 1416.62 | L10: =VLOOKUP(B10,'B&L'!$A$7:$BK$69,48,0) -> 1407.62 | M10: =VLOOKUP(B10,'B&L'!$A$7:$BK$69,53,0) -> 1414.12 | N10: =VLOOKUP(B10,'B&L'!$A$7:$BK$69,58,0) -> 1436.26 | O10: =VLOOKUP(B10,'B&L'!$A$7:$BK$69,63,0) -> 1410.58
A11: 3 | B11: 機器製造管理課 | C11: 建物 Building | D11: =VLOOKUP(B12,'B&L'!$A$7:$BK$69,7,0) -> 157.17 | E11: =VLOOKUP(B12,'B&L'!$A$7:$BK$69,12,0) -> 151.86 | F11: =VLOOKUP(B12,'B&L'!$A$7:$BK$69,17,0) -> 161.14 | G11: =VLOOKUP(B12,'B&L'!$A$7:$BK$69,22,0) -> 151.89 | H11: =VLOOKUP(B12,'B&L'!$A$7:$BK$69,27,0) -> 145.53 | I11: =VLOOKUP(B12,'B&L'!$A$7:$BK$69,32,0) -> 148.09 | J11: =VLOOKUP(B12,'B&L'!$A$7:$BK$69,37,0) -> 152.45 | K11: =VLOOKUP(B12,'B&L'!$A$7:$BK$69,42,0) -> 150.6 | L11: =VLOOKUP(B12,'B&L'!$A$7:$BK$69,47,0) -> 149.42 | M11: =VLOOKUP(B12,'B&L'!$A$7:$BK$69,52,0) -> 144.83 | N11: =VLOOKUP(B12,'B&L'!$A$7:$BK$69,57,0) -> 133.95 | O11: =VLOOKUP(B12,'B&L'!$A$7:$BK$69,62,0) -> 148.38
B12: 1412000062 | C12: 土地 Land | D12: =VLOOKUP(B12,'B&L'!$A$7:$BK$69,8,0) -> 19.93 | E12: =VLOOKUP(B12,'B&L'!$A$7:$BK$69,13,0) -> 19.79 | F12: =VLOOKUP(B12,'B&L'!$A$7:$BK$69,18,0) -> 21 | G12: =VLOOKUP(B12,'B&L'!$A$7:$BK$69,23,0) -> 19.79 | H12: =VLOOKUP(B12,'B&L'!$A$7:$BK$69,28,0) -> 18.96 | I12: =VLOOKUP(B12,'B&L'!$A$7:$BK$69,33,0) -> 19.3 | J12: =VLOOKUP(B12,'B&L'!$A$7:$BK$69,38,0) -> 19.87 | K12: =VLOOKUP(B12,'B&L'!$A$7:$BK$69,43,0) -> 19.62 | L12: =VLOOKUP(B12,'B&L'!$A$7:$BK$69,48,0) -> 19.47 | M12: =VLOOKUP(B12,'B&L'!$A$7:$BK$69,53,0) -> 18.87 | N12: =VLOOKUP(B12,'B&L'!$A$7:$BK$69,58,0) -> 17.46 | O12: =VLOOKUP(B12,'B&L'!$A$7:$BK$69,63,0) -> 19.34
A13: 4 | B13: RPS製造課 | C13: 建物 Building | D13: =VLOOKUP(B14,'B&L'!$A$7:$BK$69,7,0) -> 4101.03 | E13: =VLOOKUP(B14,'B&L'!$A$7:$BK$69,12,0) -> 3871.34 | F13: =VLOOKUP(B14,'B&L'!$A$7:$BK$69,17,0) -> 3871.34 | G13: =VLOOKUP(B14,'B&L'!$A$7:$BK$69,22,0) -> 3871.34 | H13: =VLOOKUP(B14,'B&L'!$A$7:$BK$69,27,0) -> 3871.34 | I13: =VLOOKUP(B14,'B&L'!$A$7:$BK$69,32,0) -> 3871.34 | J13: =VLOOKUP(B14,'B&L'!$A$7:$BK$69,37,0) -> 3871.34 | K13: =VLOOKUP(B14,'B&L'!$A$7:$BK$69,42,0) -> 3871.34 | L13: =VLOOKUP(B14,'B&L'!$A$7:$BK$69,47,0) -> 3871.34 | M13: =VLOOKUP(B14,'B&L'!$A$7:$BK$69,52,0) -> 3871.34 | N13: =VLOOKUP(B14,'B&L'!$A$7:$BK$69,57,0) -> 3871.34 | O13: =VLOOKUP(B14,'B&L'!$A$7:$BK$69,62,0) -> 3871.34
B14: 1412000066 | C14: 土地 Land | D14: =VLOOKUP(B14,'B&L'!$A$7:$BK$69,8,0) -> 519.97 | E14: =VLOOKUP(B14,'B&L'!$A$7:$BK$69,13,0) -> 504.47 | F14: =VLOOKUP(B14,'B&L'!$A$7:$BK$69,18,0) -> 504.47 | G14: =VLOOKUP(B14,'B&L'!$A$7:$BK$69,23,0) -> 504.47 | H14: =VLOOKUP(B14,'B&L'!$A$7:$BK$69,28,0) -> 504.47 | I14: =VLOOKUP(B14,'B&L'!$A$7:$BK$69,33,0) -> 504.47 | J14: =VLOOKUP(B14,'B&L'!$A$7:$BK$69,38,0) -> 504.47 | K14: =VLOOKUP(B14,'B&L'!$A$7:$BK$69,43,0) -> 504.47 | L14: =VLOOKUP(B14,'B&L'!$A$7:$BK$69,48,0) -> 504.47 | M14: =VLOOKUP(B14,'B&L'!$A$7:$BK$69,53,0) -> 504.47 | N14: =VLOOKUP(B14,'B&L'!$A$7:$BK$69,58,0) -> 504.47 | O14: =VLOOKUP(B14,'B&L'!$A$7:$BK$69,63,0) -> 504.47
A15: 5 | B15: 機器製造3課 | C15: 建物 Building | D15: =VLOOKUP(B16,'B&L'!$A$7:$BK$69,7,0) -> 30794.11 | E15: =VLOOKUP(B16,'B&L'!$A$7:$BK$69,12,0) -> 28899.84 | F15: =VLOOKUP(B16,'B&L'!$A$7:$BK$69,17,0) -> 28650.77 | G15: =VLOOKUP(B16,'B&L'!$A$7:$BK$69,22,0) -> 28823.57 | H15: =VLOOKUP(B16,'B&L'!$A$7:$BK$69,27,0) -> 28958.5 | I15: =VLOOKUP(B16,'B&L'!$A$7:$BK$69,32,0) -> 28890.45 | J15: =VLOOKUP(B16,'B&L'!$A$7:$BK$69,37,0) -> 28762.99 | K15: =VLOOKUP(B16,'B&L'!$A$7:$BK$69,42,0) -> 28818.6 | L15: =VLOOKUP(B16,'B&L'!$A$7:$BK$69,47,0) -> 28914.25 | M15: =VLOOKUP(B16,'B&L'!$A$7:$BK$69,52,0) -> 28969.5 | N15: =VLOOKUP(B16,'B&L'!$A$7:$BK$69,57,0) -> 29039.52 | O15: =VLOOKUP(B16,'B&L'!$A$7:$BK$69,62,0) -> 28919.89
B16: 1412000081 | C16: 土地 Land | D16: =VLOOKUP(B16,'B&L'!$A$7:$BK$69,8,0) -> 3904.38 | E16: =VLOOKUP(B16,'B&L'!$A$7:$BK$69,13,0) -> 3765.88 | F16: =VLOOKUP(B16,'B&L'!$A$7:$BK$69,18,0) -> 3733.42 | G16: =VLOOKUP(B16,'B&L'!$A$7:$BK$69,23,0) -> 3755.94 | H16: =VLOOKUP(B16,'B&L'!$A$7:$BK$69,28,0) -> 3773.52 | I16: =VLOOKUP(B16,'B&L'!$A$7:$BK$69,33,0) -> 3764.65 | J16: =VLOOKUP(B16,'B&L'!$A$7:$BK$69,38,0) -> 3748.04 | K16: =VLOOKUP(B16,'B&L'!$A$7:$BK$69,43,0) -> 3755.29 | L16: =VLOOKUP(B16,'B&L'!$A$7:$BK$69,48,0) -> 3767.75 | M16: =VLOOKUP(B16,'B&L'!$A$7:$BK$69,53,0) -> 3774.95 | N16: =VLOOKUP(B16,'B&L'!$A$7:$BK$69,58,0) -> 3784.08 | O16: =VLOOKUP(B16,'B&L'!$A$7:$BK$69,63,0) -> 3768.49
A17: 6 | B17: 電工製造課 | C17: 建物 Building | D17: =VLOOKUP(B18,'B&L'!$A$7:$BK$69,7,0) -> 3468.6 | E17: =VLOOKUP(B18,'B&L'!$A$7:$BK$69,12,0) -> 3274.17 | F17: =VLOOKUP(B18,'B&L'!$A$7:$BK$69,17,0) -> 3282.36 | G17: =VLOOKUP(B18,'B&L'!$A$7:$BK$69,22,0) -> 3274.28 | H17: =VLOOKUP(B18,'B&L'!$A$7:$BK$69,27,0) -> 3266.15 | I17: =VLOOKUP(B18,'B&L'!$A$7:$BK$69,32,0) -> 3267 | J17: =VLOOKUP(B18,'B&L'!$A$7:$BK$69,37,0) -> 3275.48 | K17: =VLOOKUP(B18,'B&L'!$A$7:$BK$69,42,0) -> 3270.34 | L17: =VLOOKUP(B18,'B&L'!$A$7:$BK$69,47,0) -> 3269.51 | M17: =VLOOKUP(B18,'B&L'!$A$7:$BK$69,52,0) -> 3257.96 | N17: =VLOOKUP(B18,'B&L'!$A$7:$BK$69,57,0) -> 3237.89 | O17: =VLOOKUP(B18,'B&L'!$A$7:$BK$69,62,0) -> 3263.97
B18: 1412000098 | C18: 土地 Land | D18: =VLOOKUP(B18,'B&L'!$A$7:$BK$69,8,0) -> 439.78 | E18: =VLOOKUP(B18,'B&L'!$A$7:$BK$69,13,0) -> 426.65 | F18: =VLOOKUP(B18,'B&L'!$A$7:$BK$69,18,0) -> 427.72 | G18: =VLOOKUP(B18,'B&L'!$A$7:$BK$69,23,0) -> 426.66 | H18: =VLOOKUP(B18,'B&L'!$A$7:$BK$69,28,0) -> 425.6 | I18: =VLOOKUP(B18,'B&L'!$A$7:$BK$69,33,0) -> 425.72 | J18: =VLOOKUP(B18,'B&L'!$A$7:$BK$69,38,0) -> 426.82 | K18: =VLOOKUP(B18,'B&L'!$A$7:$BK$69,43,0) -> 426.15 | L18: =VLOOKUP(B18,'B&L'!$A$7:$BK$69,48,0) -> 426.04 | M18: =VLOOKUP(B18,'B&L'!$A$7:$BK$69,53,0) -> 424.54 | N18: =VLOOKUP(B18,'B&L'!$A$7:$BK$69,58,0) -> 421.92 | O18: =VLOOKUP(B18,'B&L'!$A$7:$BK$69,63,0) -> 425.32
A19: 7 | B19: トナー製造課 | C19: 建物 Building | D19: =VLOOKUP(B20,'B&L'!$A$7:$BK$69,7,0) -> 6180.47 | E19: =VLOOKUP(B20,'B&L'!$A$7:$BK$69,12,0) -> 5868.57 | F19: =VLOOKUP(B20,'B&L'!$A$7:$BK$69,17,0) -> 5949.28 | G19: =VLOOKUP(B20,'B&L'!$A$7:$BK$69,22,0) -> 5872.83 | H19: =VLOOKUP(B20,'B&L'!$A$7:$BK$69,27,0) -> 5835.32 | I19: =VLOOKUP(B20,'B&L'!$A$7:$BK$69,32,0) -> 5858.63 | J19: =VLOOKUP(B20,'B&L'!$A$7:$BK$69,37,0) -> 5947.58 | K19: =VLOOKUP(B20,'B&L'!$A$7:$BK$69,42,0) -> 5929.29 | L19: =VLOOKUP(B20,'B&L'!$A$7:$BK$69,47,0) -> 5917.57 | M19: =VLOOKUP(B20,'B&L'!$A$7:$BK$69,52,0) -> 5872.09 | N19: =VLOOKUP(B20,'B&L'!$A$7:$BK$69,57,0) -> 5764.43 | O19: =VLOOKUP(B20,'B&L'!$A$7:$BK$69,62,0) -> 5907.29
B20: 1412000034 | C20: 土地 Land | D20: =VLOOKUP(B20,'B&L'!$A$7:$BK$69,8,0) -> 783.62 | E20: =VLOOKUP(B20,'B&L'!$A$7:$BK$69,13,0) -> 764.72 | F20: =VLOOKUP(B20,'B&L'!$A$7:$BK$69,18,0) -> 775.24 | G20: =VLOOKUP(B20,'B&L'!$A$7:$BK$69,23,0) -> 765.28 | H20: =VLOOKUP(B20,'B&L'!$A$7:$BK$69,28,0) -> 760.39 | I20: =VLOOKUP(B20,'B&L'!$A$7:$BK$69,33,0) -> 763.43 | J20: =VLOOKUP(B20,'B&L'!$A$7:$BK$69,38,0) -> 775.02 | K20: =VLOOKUP(B20,'B&L'!$A$7:$BK$69,43,0) -> 772.63 | L20: =VLOOKUP(B20,'B&L'!$A$7:$BK$69,48,0) -> 771.11 | M20: =VLOOKUP(B20,'B&L'!$A$7:$BK$69,53,0) -> 765.18 | N20: =VLOOKUP(B20,'B&L'!$A$7:$BK$69,58,0) -> 751.15 | O20: =VLOOKUP(B20,'B&L'!$A$7:$BK$69,63,0) -> 769.77
A21: 8 | B21: トナー生産技術 | C21: 建物 Building | D21: =VLOOKUP(B22,'B&L'!$A$7:$BK$69,7,0) -> 194.96 | E21: =VLOOKUP(B22,'B&L'!$A$7:$BK$69,12,0) -> 186.84 | F21: =VLOOKUP(B22,'B&L'!$A$7:$BK$69,17,0) -> 194.26 | G21: =VLOOKUP(B22,'B&L'!$A$7:$BK$69,22,0) -> 186.86 | H21: =VLOOKUP(B22,'B&L'!$A$7:$BK$69,27,0) -> 181.77 | I21: =VLOOKUP(B22,'B&L'!$A$7:$BK$69,32,0) -> 183.82 | J21: =VLOOKUP(B22,'B&L'!$A$7:$BK$69,37,0) -> 187.31 | K21: =VLOOKUP(B22,'B&L'!$A$7:$BK$69,42,0) -> 185.83 | L21: =VLOOKUP(B22,'B&L'!$A$7:$BK$69,47,0) -> 184.89 | M21: =VLOOKUP(B22,'B&L'!$A$7:$BK$69,52,0) -> 181.21 | N21: =VLOOKUP(B22,'B&L'!$A$7:$BK$69,57,0) -> 172.51 | O21: =VLOOKUP(B22,'B&L'!$A$7:$BK$69,62,0) -> 184.06
B22: 1412000048 | C22: 土地 Land | D22: =VLOOKUP(B22,'B&L'!$A$7:$BK$69,8,0) -> 24.72 | E22: =VLOOKUP(B22,'B&L'!$A$7:$BK$69,13,0) -> 24.35 | F22: =VLOOKUP(B22,'B&L'!$A$7:$BK$69,18,0) -> 25.31 | G22: =VLOOKUP(B22,'B&L'!$A$7:$BK$69,23,0) -> 24.35 | H22: =VLOOKUP(B22,'B&L'!$A$7:$BK$69,28,0) -> 23.69 | I22: =VLOOKUP(B22,'B&L'!$A$7:$BK$69,33,0) -> 23.95 | J22: =VLOOKUP(B22,'B&L'!$A$7:$BK$69,38,0) -> 24.41 | K22: =VLOOKUP(B22,'B&L'!$A$7:$BK$69,43,0) -> 24.22 | L22: =VLOOKUP(B22,'B&L'!$A$7:$BK$69,48,0) -> 24.09 | M22: =VLOOKUP(B22,'B&L'!$A$7:$BK$69,53,0) -> 23.61 | N22: =VLOOKUP(B22,'B&L'!$A$7:$BK$69,58,0) -> 22.48 | O22: =VLOOKUP(B22,'B&L'!$A$7:$BK$69,63,0) -> 23.98
A23: 9 | B23: トナー品質管理課 | C23: 建物 Building | D23: =VLOOKUP(B24,'B&L'!$A$7:$BK$69,7,0) -> 130 | E23: =VLOOKUP(B24,'B&L'!$A$7:$BK$69,12,0) -> 125.4 | F23: =VLOOKUP(B24,'B&L'!$A$7:$BK$69,17,0) -> 132.51 | G23: =VLOOKUP(B24,'B&L'!$A$7:$BK$69,22,0) -> 125.42 | H23: =VLOOKUP(B24,'B&L'!$A$7:$BK$69,27,0) -> 122.37 | I23: =VLOOKUP(B24,'B&L'!$A$7:$BK$69,32,0) -> 124.41 | J23: =VLOOKUP(B24,'B&L'!$A$7:$BK$69,37,0) -> 127.9 | K23: =VLOOKUP(B24,'B&L'!$A$7:$BK$69,42,0) -> 126.43 | L23: =VLOOKUP(B24,'B&L'!$A$7:$BK$69,47,0) -> 125.48 | M23: =VLOOKUP(B24,'B&L'!$A$7:$BK$69,52,0) -> 121.8 | N23: =VLOOKUP(B24,'B&L'!$A$7:$BK$69,57,0) -> 113.1 | O23: =VLOOKUP(B24,'B&L'!$A$7:$BK$69,62,0) -> 124.65
B24: 1412000055 | C24: 土地 Land | D24: =VLOOKUP(B24,'B&L'!$A$7:$BK$69,8,0) -> 16.48 | E24: =VLOOKUP(B24,'B&L'!$A$7:$BK$69,13,0) -> 16.34 | F24: =VLOOKUP(B24,'B&L'!$A$7:$BK$69,18,0) -> 17.27 | G24: =VLOOKUP(B24,'B&L'!$A$7:$BK$69,23,0) -> 16.34 | H24: =VLOOKUP(B24,'B&L'!$A$7:$BK$69,28,0) -> 15.95 | I24: =VLOOKUP(B24,'B&L'!$A$7:$BK$69,33,0) -> 16.21 | J24: =VLOOKUP(B24,'B&L'!$A$7:$BK$69,38,0) -> 16.67 | K24: =VLOOKUP(B24,'B&L'!$A$7:$BK$69,43,0) -> 16.47 | L24: =VLOOKUP(B24,'B&L'!$A$7:$BK$69,48,0) -> 16.35 | M24: =VLOOKUP(B24,'B&L'!$A$7:$BK$69,53,0) -> 15.87 | N24: =VLOOKUP(B24,'B&L'!$A$7:$BK$69,58,0) -> 14.74 | O24: =VLOOKUP(B24,'B&L'!$A$7:$BK$69,63,0) -> 16.24
A25: 10 | B25: トナー製造管理課 | C25: 建物 Building | D25: =VLOOKUP(B26,'B&L'!$A$7:$BK$69,7,0) -> 24.28 | E25: =VLOOKUP(B26,'B&L'!$A$7:$BK$69,12,0) -> 22.05 | F25: =VLOOKUP(B26,'B&L'!$A$7:$BK$69,17,0) -> 24.83 | G25: =VLOOKUP(B26,'B&L'!$A$7:$BK$69,22,0) -> 26.12 | H25: =VLOOKUP(B26,'B&L'!$A$7:$BK$69,27,0) -> 23.79 | I25: =VLOOKUP(B26,'B&L'!$A$7:$BK$69,32,0) -> 28.55 | J25: =VLOOKUP(B26,'B&L'!$A$7:$BK$69,37,0) -> 28.38 | K25: =VLOOKUP(B26,'B&L'!$A$7:$BK$69,42,0) -> 27.64 | L25: =VLOOKUP(B26,'B&L'!$A$7:$BK$69,47,0) -> 25.22 | M25: =VLOOKUP(B26,'B&L'!$A$7:$BK$69,52,0) -> 23.53 | N25: =VLOOKUP(B26,'B&L'!$A$7:$BK$69,57,0) -> 18.11 | O25: =VLOOKUP(B26,'B&L'!$A$7:$BK$69,62,0) -> 22.92
B26: 1412000063 | C26: 土地 Land | D26: =VLOOKUP(B26,'B&L'!$A$7:$BK$69,8,0) -> 3.08 | E26: =VLOOKUP(B26,'B&L'!$A$7:$BK$69,13,0) -> 2.87 | F26: =VLOOKUP(B26,'B&L'!$A$7:$BK$69,18,0) -> 3.24 | G26: =VLOOKUP(B26,'B&L'!$A$7:$BK$69,23,0) -> 3.4 | H26: =VLOOKUP(B26,'B&L'!$A$7:$BK$69,28,0) -> 3.1 | I26: =VLOOKUP(B26,'B&L'!$A$7:$BK$69,33,0) -> 3.72 | J26: =VLOOKUP(B26,'B&L'!$A$7:$BK$69,38,0) -> 3.7 | K26: =VLOOKUP(B26,'B&L'!$A$7:$BK$69,43,0) -> 3.6 | L26: =VLOOKUP(B26,'B&L'!$A$7:$BK$69,48,0) -> 3.29 | M26: =VLOOKUP(B26,'B&L'!$A$7:$BK$69,53,0) -> 3.07 | N26: =VLOOKUP(B26,'B&L'!$A$7:$BK$69,58,0) -> 2.36 | O26: =VLOOKUP(B26,'B&L'!$A$7:$BK$69,63,0) -> 2.99
A27: 11 | B27: 金型技術課 | C27: 建物 Building | D27: =VLOOKUP(B28,'B&L'!$A$7:$BK$69,7,0) -> 1040.28 | E27: =VLOOKUP(B28,'B&L'!$A$7:$BK$69,12,0) -> 986.99 | F27: =VLOOKUP(B28,'B&L'!$A$7:$BK$69,17,0) -> 991.83 | G27: =VLOOKUP(B28,'B&L'!$A$7:$BK$69,22,0) -> 987.05 | H27: =VLOOKUP(B28,'B&L'!$A$7:$BK$69,27,0) -> 982.24 | I27: =VLOOKUP(B28,'B&L'!$A$7:$BK$69,32,0) -> 982.75 | J27: =VLOOKUP(B28,'B&L'!$A$7:$BK$69,37,0) -> 987.77 | K27: =VLOOKUP(B28,'B&L'!$A$7:$BK$69,42,0) -> 984.72 | L27: =VLOOKUP(B28,'B&L'!$A$7:$BK$69,47,0) -> 984.23 | M27: =VLOOKUP(B28,'B&L'!$A$7:$BK$69,52,0) -> 981.55 | N27: =VLOOKUP(B28,'B&L'!$A$7:$BK$69,57,0) -> 968.9 | O27: =VLOOKUP(B28,'B&L'!$A$7:$BK$69,62,0) -> 985.34
B28: 1412000044 | C28: 土地 Land | D28: =VLOOKUP(B28,'B&L'!$A$7:$BK$69,8,0) -> 131.9 | E28: =VLOOKUP(B28,'B&L'!$A$7:$BK$69,13,0) -> 128.61 | F28: =VLOOKUP(B28,'B&L'!$A$7:$BK$69,18,0) -> 129.24 | G28: =VLOOKUP(B28,'B&L'!$A$7:$BK$69,23,0) -> 128.62 | H28: =VLOOKUP(B28,'B&L'!$A$7:$BK$69,28,0) -> 127.99 | I28: =VLOOKUP(B28,'B&L'!$A$7:$BK$69,33,0) -> 128.06 | J28: =VLOOKUP(B28,'B&L'!$A$7:$BK$69,38,0) -> 128.71 | K28: =VLOOKUP(B28,'B&L'!$A$7:$BK$69,43,0) -> 128.32 | L28: =VLOOKUP(B28,'B&L'!$A$7:$BK$69,48,0) -> 128.25 | M28: =VLOOKUP(B28,'B&L'!$A$7:$BK$69,53,0) -> 127.9 | N28: =VLOOKUP(B28,'B&L'!$A$7:$BK$69,58,0) -> 126.25 | O28: =VLOOKUP(B28,'B&L'!$A$7:$BK$69,63,0) -> 128.4
A29: 12 | B29: 部品製造管理課 | C29: 建物 Building | D29: =VLOOKUP(B30,'B&L'!$A$7:$BK$69,7,0) -> 70.72 | E29: =VLOOKUP(B30,'B&L'!$A$7:$BK$69,12,0) -> 66.74 | F29: =VLOOKUP(B30,'B&L'!$A$7:$BK$69,17,0) -> 68.07 | G29: =VLOOKUP(B30,'B&L'!$A$7:$BK$69,22,0) -> 66.75 | H29: =VLOOKUP(B30,'B&L'!$A$7:$BK$69,27,0) -> 65.43 | I29: =VLOOKUP(B30,'B&L'!$A$7:$BK$69,32,0) -> 65.57 | J29: =VLOOKUP(B30,'B&L'!$A$7:$BK$69,37,0) -> 66.95 | K29: =VLOOKUP(B30,'B&L'!$A$7:$BK$69,42,0) -> 66.11 | L29: =VLOOKUP(B30,'B&L'!$A$7:$BK$69,47,0) -> 65.98 | M29: =VLOOKUP(B30,'B&L'!$A$7:$BK$69,52,0) -> 65.24 | N29: =VLOOKUP(B30,'B&L'!$A$7:$BK$69,57,0) -> 61.75 | O29: =VLOOKUP(B30,'B&L'!$A$7:$BK$69,62,0) -> 66.28
B30: 1412000087 | C30: 土地 Land | D30: =VLOOKUP(B30,'B&L'!$A$7:$BK$69,8,0) -> 8.97 | E30: =VLOOKUP(B30,'B&L'!$A$7:$BK$69,13,0) -> 8.7 | F30: =VLOOKUP(B30,'B&L'!$A$7:$BK$69,18,0) -> 8.87 | G30: =VLOOKUP(B30,'B&L'!$A$7:$BK$69,23,0) -> 8.7 | H30: =VLOOKUP(B30,'B&L'!$A$7:$BK$69,28,0) -> 8.53 | I30: =VLOOKUP(B30,'B&L'!$A$7:$BK$69,33,0) -> 8.54 | J30: =VLOOKUP(B30,'B&L'!$A$7:$BK$69,38,0) -> 8.72 | K30: =VLOOKUP(B30,'B&L'!$A$7:$BK$69,43,0) -> 8.61 | L30: =VLOOKUP(B30,'B&L'!$A$7:$BK$69,48,0) -> 8.6 | M30: =VLOOKUP(B30,'B&L'!$A$7:$BK$69,53,0) -> 8.5 | N30: =VLOOKUP(B30,'B&L'!$A$7:$BK$69,58,0) -> 8.05 | O30: =VLOOKUP(B30,'B&L'!$A$7:$BK$69,63,0) -> 8.64
A31: 13 | B31: 品質管理課 | C31: 建物 Building | D31: =VLOOKUP(B32,'B&L'!$A$7:$BK$69,7,0) -> 234.34 | E31: =VLOOKUP(B32,'B&L'!$A$7:$BK$69,12,0) -> 221.13 | F31: =VLOOKUP(B32,'B&L'!$A$7:$BK$69,17,0) -> 225.14 | G31: =VLOOKUP(B32,'B&L'!$A$7:$BK$69,22,0) -> 221.19 | H31: =VLOOKUP(B32,'B&L'!$A$7:$BK$69,27,0) -> 217.2 | I31: =VLOOKUP(B32,'B&L'!$A$7:$BK$69,32,0) -> 217.62 | J31: =VLOOKUP(B32,'B&L'!$A$7:$BK$69,37,0) -> 221.78 | K31: =VLOOKUP(B32,'B&L'!$A$7:$BK$69,42,0) -> 219.26 | L31: =VLOOKUP(B32,'B&L'!$A$7:$BK$69,47,0) -> 218.85 | M31: =VLOOKUP(B32,'B&L'!$A$7:$BK$69,52,0) -> 216.63 | N31: =VLOOKUP(B32,'B&L'!$A$7:$BK$69,57,0) -> 206.16 | O31: =VLOOKUP(B32,'B&L'!$A$7:$BK$69,62,0) -> 219.77
B32: 1412000088 | C32: 土地 Land | D32: =VLOOKUP(B32,'B&L'!$A$7:$BK$69,8,0) -> 29.71 | E32: =VLOOKUP(B32,'B&L'!$A$7:$BK$69,13,0) -> 28.82 | F32: =VLOOKUP(B32,'B&L'!$A$7:$BK$69,18,0) -> 29.34 | G32: =VLOOKUP(B32,'B&L'!$A$7:$BK$69,23,0) -> 28.82 | H32: =VLOOKUP(B32,'B&L'!$A$7:$BK$69,28,0) -> 28.3 | I32: =VLOOKUP(B32,'B&L'!$A$7:$BK$69,33,0) -> 28.36 | J32: =VLOOKUP(B32,'B&L'!$A$7:$BK$69,38,0) -> 28.9 | K32: =VLOOKUP(B32,'B&L'!$A$7:$BK$69,43,0) -> 28.57 | L32: =VLOOKUP(B32,'B&L'!$A$7:$BK$69,48,0) -> 28.52 | M32: =VLOOKUP(B32,'B&L'!$A$7:$BK$69,53,0) -> 28.23 | N32: =VLOOKUP(B32,'B&L'!$A$7:$BK$69,58,0) -> 26.86 | O32: =VLOOKUP(B32,'B&L'!$A$7:$BK$69,63,0) -> 28.64
A33: 14 | B33: 部品製造課 | C33: 建物 Building | D33: =VLOOKUP(B34,'B&L'!$A$7:$BK$69,7,0) -> 7379 | E33: =VLOOKUP(B34,'B&L'!$A$7:$BK$69,12,0) -> 6962.8 | F33: =VLOOKUP(B34,'B&L'!$A$7:$BK$69,17,0) -> 6979.65 | G33: =VLOOKUP(B34,'B&L'!$A$7:$BK$69,22,0) -> 6958 | H33: =VLOOKUP(B34,'B&L'!$A$7:$BK$69,27,0) -> 6936.55 | I33: =VLOOKUP(B34,'B&L'!$A$7:$BK$69,32,0) -> 6940.92 | J33: =VLOOKUP(B34,'B&L'!$A$7:$BK$69,37,0) -> 6963.38 | K33: =VLOOKUP(B34,'B&L'!$A$7:$BK$69,42,0) -> 6953.66 | L33: =VLOOKUP(B34,'B&L'!$A$7:$BK$69,47,0) -> 6954.12 | M33: =VLOOKUP(B34,'B&L'!$A$7:$BK$69,52,0) -> 6943.21 | N33: =VLOOKUP(B34,'B&L'!$A$7:$BK$69,57,0) -> 6891.72 | O33: =VLOOKUP(B34,'B&L'!$A$7:$BK$69,62,0) -> 6958.63
B34: 1412000056 | C34: 土地 Land | D34: =VLOOKUP(B34,'B&L'!$A$7:$BK$69,8,0) -> 935.58 | E34: =VLOOKUP(B34,'B&L'!$A$7:$BK$69,13,0) -> 907.31 | F34: =VLOOKUP(B34,'B&L'!$A$7:$BK$69,18,0) -> 909.5 | G34: =VLOOKUP(B34,'B&L'!$A$7:$BK$69,23,0) -> 906.68 | H34: =VLOOKUP(B34,'B&L'!$A$7:$BK$69,28,0) -> 903.89 | I34: =VLOOKUP(B34,'B&L'!$A$7:$BK$69,33,0) -> 904.46 | J34: =VLOOKUP(B34,'B&L'!$A$7:$BK$69,38,0) -> 907.38 | K34: =VLOOKUP(B34,'B&L'!$A$7:$BK$69,43,0) -> 906.12 | L34: =VLOOKUP(B34,'B&L'!$A$7:$BK$69,48,0) -> 906.18 | M34: =VLOOKUP(B34,'B&L'!$A$7:$BK$69,53,0) -> 904.76 | N34: =VLOOKUP(B34,'B&L'!$A$7:$BK$69,58,0) -> 898.05 | O34: =VLOOKUP(B34,'B&L'!$A$7:$BK$69,63,0) -> 906.76
A35: 15 | B35: 部品技術課 | C35: 建物 Building | D35: =VLOOKUP(B36,'B&L'!$A$7:$BK$69,7,0) -> 183.49 | E35: =VLOOKUP(B36,'B&L'!$A$7:$BK$69,12,0) -> 173.09 | F35: =VLOOKUP(B36,'B&L'!$A$7:$BK$69,17,0) -> 173.39 | G35: =VLOOKUP(B36,'B&L'!$A$7:$BK$69,22,0) -> 172.98 | H35: =VLOOKUP(B36,'B&L'!$A$7:$BK$69,27,0) -> 180.18 | I35: =VLOOKUP(B36,'B&L'!$A$7:$BK$69,32,0) -> 180.26 | J35: =VLOOKUP(B36,'B&L'!$A$7:$BK$69,37,0) -> 180.47 | K35: =VLOOKUP(B36,'B&L'!$A$7:$BK$69,42,0) -> 180.37 | L35: =VLOOKUP(B36,'B&L'!$A$7:$BK$69,47,0) -> 184.04 | M35: =VLOOKUP(B36,'B&L'!$A$7:$BK$69,52,0) -> 183.85 | N35: =VLOOKUP(B36,'B&L'!$A$7:$BK$69,57,0) -> 183.26 | O35: =VLOOKUP(B36,'B&L'!$A$7:$BK$69,62,0) -> 184.03
B36: 1412000080 | C36: 土地 Land | D36: =VLOOKUP(B36,'B&L'!$A$7:$BK$69,8,0) -> 23.26 | E36: =VLOOKUP(B36,'B&L'!$A$7:$BK$69,13,0) -> 22.56 | F36: =VLOOKUP(B36,'B&L'!$A$7:$BK$69,18,0) -> 22.59 | G36: =VLOOKUP(B36,'B&L'!$A$7:$BK$69,23,0) -> 22.54 | H36: =VLOOKUP(B36,'B&L'!$A$7:$BK$69,28,0) -> 23.48 | I36: =VLOOKUP(B36,'B&L'!$A$7:$BK$69,33,0) -> 23.49 | J36: =VLOOKUP(B36,'B&L'!$A$7:$BK$69,38,0) -> 23.52 | K36: =VLOOKUP(B36,'B&L'!$A$7:$BK$69,43,0) -> 23.5 | L36: =VLOOKUP(B36,'B&L'!$A$7:$BK$69,48,0) -> 23.98 | M36: =VLOOKUP(B36,'B&L'!$A$7:$BK$69,53,0) -> 23.96 | N36: =VLOOKUP(B36,'B&L'!$A$7:$BK$69,58,0) -> 23.88 | O36: =VLOOKUP(B36,'B&L'!$A$7:$BK$69,63,0) -> 23.98
A37: 16 | B37: 工程品質管理1課 | C37: 建物 Building | D37: =VLOOKUP(B38,'B&L'!$A$7:$BK$69,7,0) -> 331.11 | E37: =VLOOKUP(B38,'B&L'!$A$7:$BK$69,12,0) -> 313.71 | F37: =VLOOKUP(B38,'B&L'!$A$7:$BK$69,17,0) -> 320.86 | G37: =VLOOKUP(B38,'B&L'!$A$7:$BK$69,22,0) -> 326.42 | H37: =VLOOKUP(B38,'B&L'!$A$7:$BK$69,27,0) -> 319.92 | I37: =VLOOKUP(B38,'B&L'!$A$7:$BK$69,32,0) -> 321.55 | J37: =VLOOKUP(B38,'B&L'!$A$7:$BK$69,37,0) -> 332.3 | K37: =VLOOKUP(B38,'B&L'!$A$7:$BK$69,42,0) -> 329.07 | L37: =VLOOKUP(B38,'B&L'!$A$7:$BK$69,47,0) -> 328.11 | M37: =VLOOKUP(B38,'B&L'!$A$7:$BK$69,52,0) -> 323.78 | N37: =VLOOKUP(B38,'B&L'!$A$7:$BK$69,57,0) -> 308.74 | O37: =VLOOKUP(B38,'B&L'!$A$7:$BK$69,62,0) -> 328.43
B38: 1412000053 | C38: 土地 Land | D38: =VLOOKUP(B38,'B&L'!$A$7:$BK$69,8,0) -> 41.98 | E38: =VLOOKUP(B38,'B&L'!$A$7:$BK$69,13,0) -> 40.88 | F38: =VLOOKUP(B38,'B&L'!$A$7:$BK$69,18,0) -> 41.81 | G38: =VLOOKUP(B38,'B&L'!$A$7:$BK$69,23,0) -> 42.53 | H38: =VLOOKUP(B38,'B&L'!$A$7:$BK$69,28,0) -> 41.69 | I38: =VLOOKUP(B38,'B&L'!$A$7:$BK$69,33,0) -> 41.9 | J38: =VLOOKUP(B38,'B&L'!$A$7:$BK$69,38,0) -> 43.3 | K38: =VLOOKUP(B38,'B&L'!$A$7:$BK$69,43,0) -> 42.88 | L38: =VLOOKUP(B38,'B&L'!$A$7:$BK$69,48,0) -> 42.76 | M38: =VLOOKUP(B38,'B&L'!$A$7:$BK$69,53,0) -> 42.19 | N38: =VLOOKUP(B38,'B&L'!$A$7:$BK$69,58,0) -> 40.23 | O38: =VLOOKUP(B38,'B&L'!$A$7:$BK$69,63,0) -> 42.8
A39: 17 | B39: 工程品質管理2課 | C39: 建物 Building | D39: =VLOOKUP(B40,'B&L'!$A$7:$BK$69,7,0) -> 871.88 | E39: =VLOOKUP(B40,'B&L'!$A$7:$BK$69,12,0) -> 823.95 | F39: =VLOOKUP(B40,'B&L'!$A$7:$BK$69,17,0) -> 851.93 | G39: =VLOOKUP(B40,'B&L'!$A$7:$BK$69,22,0) -> 824.28 | H39: =VLOOKUP(B40,'B&L'!$A$7:$BK$69,27,0) -> 798.11 | I39: =VLOOKUP(B40,'B&L'!$A$7:$BK$69,32,0) -> 801.92 | J39: =VLOOKUP(B40,'B&L'!$A$7:$BK$69,37,0) -> 827.93 | K39: =VLOOKUP(B40,'B&L'!$A$7:$BK$69,42,0) -> 812.62 | L39: =VLOOKUP(B40,'B&L'!$A$7:$BK$69,47,0) -> 809.65 | M39: =VLOOKUP(B40,'B&L'!$A$7:$BK$69,52,0) -> 794.48 | N39: =VLOOKUP(B40,'B&L'!$A$7:$BK$69,57,0) -> 728.97 | O39: =VLOOKUP(B40,'B&L'!$A$7:$BK$69,62,0) -> 814.26
B40: 1412000104 | C40: 土地 Land | D40: =VLOOKUP(B40,'B&L'!$A$7:$BK$69,8,0) -> 110.55 | E40: =VLOOKUP(B40,'B&L'!$A$7:$BK$69,13,0) -> 107.37 | F40: =VLOOKUP(B40,'B&L'!$A$7:$BK$69,18,0) -> 111.01 | G40: =VLOOKUP(B40,'B&L'!$A$7:$BK$69,23,0) -> 107.41 | H40: =VLOOKUP(B40,'B&L'!$A$7:$BK$69,28,0) -> 104 | I40: =VLOOKUP(B40,'B&L'!$A$7:$BK$69,33,0) -> 104.5 | J40: =VLOOKUP(B40,'B&L'!$A$7:$BK$69,38,0) -> 107.89 | K40: =VLOOKUP(B40,'B&L'!$A$7:$BK$69,43,0) -> 105.89 | L40: =VLOOKUP(B40,'B&L'!$A$7:$BK$69,48,0) -> 105.5 | M40: =VLOOKUP(B40,'B&L'!$A$7:$BK$69,53,0) -> 103.53 | N40: =VLOOKUP(B40,'B&L'!$A$7:$BK$69,58,0) -> 94.99 | O40: =VLOOKUP(B40,'B&L'!$A$7:$BK$69,63,0) -> 106.1
A41: 18 | B41: 工程品質管理3課 | C41: 建物 Building | D41: =VLOOKUP(B42,'B&L'!$A$7:$BK$69,7,0) -> 205.54 | E41: =VLOOKUP(B42,'B&L'!$A$7:$BK$69,12,0) -> 194.29 | F41: =VLOOKUP(B42,'B&L'!$A$7:$BK$69,17,0) -> 198.2 | G41: =VLOOKUP(B42,'B&L'!$A$7:$BK$69,22,0) -> 194.33 | H41: =VLOOKUP(B42,'B&L'!$A$7:$BK$69,27,0) -> 190.83 | I41: =VLOOKUP(B42,'B&L'!$A$7:$BK$69,32,0) -> 191.45 | J41: =VLOOKUP(B42,'B&L'!$A$7:$BK$69,37,0) -> 194.8 | K41: =VLOOKUP(B42,'B&L'!$A$7:$BK$69,42,0) -> 192.87 | L41: =VLOOKUP(B42,'B&L'!$A$7:$BK$69,47,0) -> 192.45 | M41: =VLOOKUP(B42,'B&L'!$A$7:$BK$69,52,0) -> 190.35 | N41: =VLOOKUP(B42,'B&L'!$A$7:$BK$69,57,0) -> 181.92 | O41: =VLOOKUP(B42,'B&L'!$A$7:$BK$69,62,0) -> 192.92
B42: 1412000105 | C42: 土地 Land | D42: =VLOOKUP(B42,'B&L'!$A$7:$BK$69,8,0) -> 26.06 | E42: =VLOOKUP(B42,'B&L'!$A$7:$BK$69,13,0) -> 25.32 | F42: =VLOOKUP(B42,'B&L'!$A$7:$BK$69,18,0) -> 25.83 | G42: =VLOOKUP(B42,'B&L'!$A$7:$BK$69,23,0) -> 25.32 | H42: =VLOOKUP(B42,'B&L'!$A$7:$BK$69,28,0) -> 24.87 | I42: =VLOOKUP(B42,'B&L'!$A$7:$BK$69,33,0) -> 24.95 | J42: =VLOOKUP(B42,'B&L'!$A$7:$BK$69,38,0) -> 25.38 | K42: =VLOOKUP(B42,'B&L'!$A$7:$BK$69,43,0) -> 25.13 | L42: =VLOOKUP(B42,'B&L'!$A$7:$BK$69,48,0) -> 25.08 | M42: =VLOOKUP(B42,'B&L'!$A$7:$BK$69,53,0) -> 24.8 | N42: =VLOOKUP(B42,'B&L'!$A$7:$BK$69,58,0) -> 23.71 | O42: =VLOOKUP(B42,'B&L'!$A$7:$BK$69,63,0) -> 25.14
...

Sheet 水道光熱費（Electric & Water）
F2: VND | J2: VND | M2: VND
B3: 部署 | C3: 水道光熱費 | D3: 46113 | E3: =IF(MONTH(D3)=12,EDATE(D3,1),EDATE(D3,1)) -> 46143 | F3: =IF(MONTH(E3)=12,EDATE(E3,1),EDATE(E3,1)) -> 46174 | G3: =IF(MONTH(F3)=12,EDATE(F3,1),EDATE(F3,1)) -> 46204 | H3: =IF(MONTH(G3)=12,EDATE(G3,1),EDATE(G3,1)) -> 46235 | I3: =IF(MONTH(H3)=12,EDATE(H3,1),EDATE(H3,1)) -> 46266 | J3: =IF(MONTH(I3)=12,EDATE(I3,1),EDATE(I3,1)) -> 46296 | K3: =IF(MONTH(J3)=12,EDATE(J3,1),EDATE(J3,1)) -> 46327 | L3: =IF(MONTH(K3)=12,EDATE(K3,1),EDATE(K3,1)) -> 46357 | ... O3: =IF(MONTH(N3)=12,EDATE(N3,1),EDATE(N3,1)) -> 46447
B4: 振替総額 | C4: 電気代 Electric | D4: =D132 -> 2389607989 | E4: =E132 -> 2341505283 | F4: =F132 -> 2662705192 | G4: =G132 -> 2890515886 | H4: =H132 -> 3008051207 | I4: =I132 -> 2667455145 | J4: =J132 -> 2398897481 | K4: =K132 -> 2375784802 | ... O4: =O132 -> 2249588940
C5: 水道代 Water | D5: =D133 -> 168200000 | E5: =E133 -> 178572000 | F5: =F133 -> 194100000 | G5: =G133 -> 297620000 | H5: =H133 -> 271740000 | I5: =I133 -> 270446000 | J5: =J133 -> 251036000 | K5: =K133 -> 194100000 | ... O5: =O133 -> 194100000
A6: 1 | B6: 機器製造1課 | C6: 電気代 Electric | D6: =VLOOKUP(B7,'E&W'!$A$7:$P$69,7,0) -> 217557171 | E6: =VLOOKUP(B7,'E&W'!$A$7:$P$69,9,0) -> 195546170 | F6: =VLOOKUP(B7,'E&W'!$A$7:$P$69,11,0) -> 216687222 | G6: =VLOOKUP(B7,'E&W'!$A$7:$P$69,13,0) -> 233958853 | H6: =VLOOKUP(B7,'E&W'!$A$7:$P$69,15,0) -> 239911156 | I6: =VLOOKUP(B7,'E&W'!$A$7:$AD$69,17,0) -> 224873351 | J6: =VLOOKUP(B7,'E&W'!$A$7:$AD$69,19,0) -> 198924667 | K6: =VLOOKUP(B7,'E&W'!$A$7:$AD$69,21,0) -> 192388076 | L6: =VLOOKUP(B7,'E&W'!$A$7:$AD$69,23,0) -> 172751094 | M6: =VLOOKUP(B7,'E&W'!$A$7:$AD$69,25,0) -> 223709328 | N6: =VLOOKUP(B7,'E&W'!$A$7:$AD$69,27,0) -> 222227053 | O6: =VLOOKUP(B7,'E&W'!$A$7:$AD$69,29,0) -> 205654872
B7: 1412000004 | C7: 水道代 Water | D7: =VLOOKUP(B7,'E&W'!$A$7:$P$69,8,0) -> 29926417 | E7: =VLOOKUP(B7,'E&W'!$A$7:$P$69,10,0) -> 32802865 | F7: =VLOOKUP(B7,'E&W'!$A$7:$P$69,12,0) -> 34177076 | G7: =VLOOKUP(B7,'E&W'!$A$7:$P$69,14,0) -> 54224430 | H7: =VLOOKUP(B7,'E&W'!$A$7:$P$69,16,0) -> 52664895 | I7: =VLOOKUP(B7,'E&W'!$A$7:$AD$69,18,0) -> 53168533 | J7: =VLOOKUP(B7,'E&W'!$A$7:$AD$69,20,0) -> 45556371 | K7: =VLOOKUP(B7,'E&W'!$A$7:$AD$69,22,0) -> 37212998 | L7: =VLOOKUP(B7,'E&W'!$A$7:$AD$69,24,0) -> 37043358 | M7: =VLOOKUP(B7,'E&W'!$A$7:$AD$69,26,0) -> 35623360 | N7: =VLOOKUP(B7,'E&W'!$A$7:$AD$69,28,0) -> 39263637 | O7: =VLOOKUP(B7,'E&W'!$A$7:$AD$69,30,0) -> 36261546
A8: 2 | B8: 機器製造2課 | C8: 電気代 Electric | D8: =VLOOKUP(B9,'E&W'!$A$7:$P$69,7,0) -> 145656656 | E8: =VLOOKUP(B9,'E&W'!$A$7:$P$69,9,0) -> 125903402 | F8: =VLOOKUP(B9,'E&W'!$A$7:$P$69,11,0) -> 138835031 | G8: =VLOOKUP(B9,'E&W'!$A$7:$P$69,13,0) -> 147155898 | H8: =VLOOKUP(B9,'E&W'!$A$7:$P$69,15,0) -> 153790158 | I8: =VLOOKUP(B9,'E&W'!$A$7:$AD$69,17,0) -> 134570184 | J8: =VLOOKUP(B9,'E&W'!$A$7:$AD$69,19,0) -> 120271965 | K8: =VLOOKUP(B9,'E&W'!$A$7:$AD$69,21,0) -> 129168668 | L8: =VLOOKUP(B9,'E&W'!$A$7:$AD$69,23,0) -> 137246842 | M8: =VLOOKUP(B9,'E&W'!$A$7:$AD$69,25,0) -> 160269338 | N8: =VLOOKUP(B9,'E&W'!$A$7:$AD$69,27,0) -> 159326628 | O8: =VLOOKUP(B9,'E&W'!$A$7:$AD$69,29,0) -> 160608544
B9: 1412000005 | C9: 水道代 Water | D9: =VLOOKUP(B9,'E&W'!$A$7:$P$69,8,0) -> 43433030 | E9: =VLOOKUP(B9,'E&W'!$A$7:$P$69,10,0) -> 45693141 | F9: =VLOOKUP(B9,'E&W'!$A$7:$P$69,12,0) -> 47491343 | G9: =VLOOKUP(B9,'E&W'!$A$7:$P$69,14,0) -> 77356625 | H9: =VLOOKUP(B9,'E&W'!$A$7:$P$69,16,0) -> 72527343 | I9: =VLOOKUP(B9,'E&W'!$A$7:$AD$69,18,0) -> 70569143 | J9: =VLOOKUP(B9,'E&W'!$A$7:$AD$69,20,0) -> 64322875 | K9: =VLOOKUP(B9,'E&W'!$A$7:$AD$69,22,0) -> 49503841 | L9: =VLOOKUP(B9,'E&W'!$A$7:$AD$69,24,0) -> 48410454 | M9: =VLOOKUP(B9,'E&W'!$A$7:$AD$69,26,0) -> 47706660 | N9: =VLOOKUP(B9,'E&W'!$A$7:$AD$69,28,0) -> 48929597 | O9: =VLOOKUP(B9,'E&W'!$A$7:$AD$69,30,0) -> 49893202
A10: 3 | B10: 機器製造管理課 | C10: 電気代 Electric | D10: =VLOOKUP(B11,'E&W'!$A$7:$P$69,7,0) -> 1006022 | E10: =VLOOKUP(B11,'E&W'!$A$7:$P$69,9,0) -> 790110 | F10: =VLOOKUP(B11,'E&W'!$A$7:$P$69,11,0) -> 727029 | G10: =VLOOKUP(B11,'E&W'!$A$7:$P$69,13,0) -> 769064 | H10: =VLOOKUP(B11,'E&W'!$A$7:$P$69,15,0) -> 810421 | I10: =VLOOKUP(B11,'E&W'!$A$7:$AD$69,17,0) -> 764773 | J10: =VLOOKUP(B11,'E&W'!$A$7:$AD$69,19,0) -> 692555 | K10: =VLOOKUP(B11,'E&W'!$A$7:$AD$69,21,0) -> 755120 | L10: =VLOOKUP(B11,'E&W'!$A$7:$AD$69,23,0) -> 911565 | M10: =VLOOKUP(B11,'E&W'!$A$7:$AD$69,25,0) -> 1096034 | N10: =VLOOKUP(B11,'E&W'!$A$7:$AD$69,27,0) -> 1112669 | O10: =VLOOKUP(B11,'E&W'!$A$7:$AD$69,29,0) -> 1045056
B11: 1412000062 | C11: 水道代 Water | D11: =VLOOKUP(B11,'E&W'!$A$7:$P$69,8,0) -> 882785 | E11: =VLOOKUP(B11,'E&W'!$A$7:$P$69,10,0) -> 961961 | F11: =VLOOKUP(B11,'E&W'!$A$7:$P$69,12,0) -> 1137971 | G11: =VLOOKUP(B11,'E&W'!$A$7:$P$69,14,0) -> 1602693 | H11: =VLOOKUP(B11,'E&W'!$A$7:$P$69,16,0) -> 1357343 | I11: =VLOOKUP(B11,'E&W'!$A$7:$AD$69,18,0) -> 1381001 | J11: =VLOOKUP(B11,'E&W'!$A$7:$AD$69,20,0) -> 1359892 | K11: =VLOOKUP(B11,'E&W'!$A$7:$AD$69,22,0) -> 1021400 | L11: =VLOOKUP(B11,'E&W'!$A$7:$AD$69,24,0) -> 1002979 | M11: =VLOOKUP(B11,'E&W'!$A$7:$AD$69,26,0) -> 895059 | N11: =VLOOKUP(B11,'E&W'!$A$7:$AD$69,28,0) -> 692074 | O11: =VLOOKUP(B11,'E&W'!$A$7:$AD$69,30,0) -> 1007265
A12: 4 | B12: RPS製造課 | C12: 電気代 Electric | D12: =VLOOKUP(B13,'E&W'!$A$7:$P$69,7,0) -> 8660259 | E12: =VLOOKUP(B13,'E&W'!$A$7:$P$69,9,0) -> 9557487 | F12: =VLOOKUP(B13,'E&W'!$A$7:$P$69,11,0) -> 15187227 | G12: =VLOOKUP(B13,'E&W'!$A$7:$P$69,13,0) -> 16298009 | H12: =VLOOKUP(B13,'E&W'!$A$7:$P$69,15,0) -> 17082503 | I12: =VLOOKUP(B13,'E&W'!$A$7:$AD$69,17,0) -> 13771437 | J12: =VLOOKUP(B13,'E&W'!$A$7:$AD$69,19,0) -> 11786489 | K12: =VLOOKUP(B13,'E&W'!$A$7:$AD$69,21,0) -> 11009413 | L12: =VLOOKUP(B13,'E&W'!$A$7:$AD$69,23,0) -> 8888349 | M12: =VLOOKUP(B13,'E&W'!$A$7:$AD$69,25,0) -> 7686171 | N12: =VLOOKUP(B13,'E&W'!$A$7:$AD$69,27,0) -> 6901292 | O12: =VLOOKUP(B13,'E&W'!$A$7:$AD$69,29,0) -> 6900755
B13: 1412000066 | C13: 水道代 Water | D13: =VLOOKUP(B13,'E&W'!$A$7:$P$69,8,0) -> 0 | E13: =VLOOKUP(B13,'E&W'!$A$7:$P$69,10,0) -> 0 | F13: =VLOOKUP(B13,'E&W'!$A$7:$P$69,12,0) -> 0 | G13: =VLOOKUP(B13,'E&W'!$A$7:$P$69,14,0) -> 0 | H13: =VLOOKUP(B13,'E&W'!$A$7:$P$69,16,0) -> 0 | I13: =VLOOKUP(B13,'E&W'!$A$7:$AD$69,18,0) -> 0 | J13: =VLOOKUP(B13,'E&W'!$A$7:$AD$69,20,0) -> 0 | K13: =VLOOKUP(B13,'E&W'!$A$7:$AD$69,22,0) -> 0 | L13: =VLOOKUP(B13,'E&W'!$A$7:$AD$69,24,0) -> 0 | M13: =VLOOKUP(B13,'E&W'!$A$7:$AD$69,26,0) -> 0 | N13: =VLOOKUP(B13,'E&W'!$A$7:$AD$69,28,0) -> 0 | O13: =VLOOKUP(B13,'E&W'!$A$7:$AD$69,30,0) -> 0
A14: 5 | B14: 機器製造3課 | C14: 電気代 Electric | D14: =VLOOKUP(B15,'E&W'!$A$7:$P$69,7,0) -> 207136304 | E14: =VLOOKUP(B15,'E&W'!$A$7:$P$69,9,0) -> 205029766 | F14: =VLOOKUP(B15,'E&W'!$A$7:$P$69,11,0) -> 233767130 | G14: =VLOOKUP(B15,'E&W'!$A$7:$P$69,13,0) -> 244248329 | H14: =VLOOKUP(B15,'E&W'!$A$7:$P$69,15,0) -> 263505172 | I14: =VLOOKUP(B15,'E&W'!$A$7:$AD$69,17,0) -> 229805941 | J14: =VLOOKUP(B15,'E&W'!$A$7:$AD$69,19,0) -> 202139773 | K14: =VLOOKUP(B15,'E&W'!$A$7:$AD$69,21,0) -> 205410262 | L14: =VLOOKUP(B15,'E&W'!$A$7:$AD$69,23,0) -> 211450047 | M14: =VLOOKUP(B15,'E&W'!$A$7:$AD$69,25,0) -> 193612701 | N14: =VLOOKUP(B15,'E&W'!$A$7:$AD$69,27,0) -> 214847892 | O14: =VLOOKUP(B15,'E&W'!$A$7:$AD$69,29,0) -> 219383962
