Workbook
Name ____DAT1: #REF!
Name ____DAT1: #REF!
Name ____DAT1: #REF!
Name ____DAT10: #REF!
Name ____DAT10: #REF!
Name ____DAT10: #REF!
Name ____DAT11: #REF!
Name ____DAT11: #REF!
Name ____DAT11: #REF!
Name ____DAT12: #REF!
Name ____DAT12: #REF!
Name ____DAT12: #REF!
Name ____DAT2: #REF!
Name ____DAT2: #REF!
Name ____DAT2: #REF!
Name ____DAT3: #REF!
Name ____DAT3: #REF!
Name ____DAT3: #REF!
Name ____DAT4: #REF!
Name ____DAT4: #REF!
Name ____DAT4: #REF!
Name ____DAT5: #REF!
Name ____DAT5: #REF!
Name ____DAT5: #REF!
Name ____DAT6: #REF!
Name ____DAT6: #REF!
Name ____DAT6: #REF!
Name ____DAT7: #REF!
Name ____DAT7: #REF!
Name ____DAT7: #REF!
Name ____DAT8: #REF!
Name ____DAT8: #REF!
Name ____DAT8: #REF!
Name ____DAT9: #REF!
Name ____DAT9: #REF!
Name ____DAT9: #REF!
Name ___DAT1: #REF!
Name ___DAT1: #REF!
Name ___DAT1: #REF!
Name ___DAT10: #REF!
Name ___DAT10: #REF!
Name ___DAT10: #REF!
Name ___DAT11: #REF!
Name ___DAT11: #REF!
Name ___DAT11: #REF!
Name ___DAT12: #REF!
Name ___DAT12: #REF!
Name ___DAT12: #REF!
Name ___DAT2: #REF!
Name ___DAT2: #REF!
Name ___DAT2: #REF!
Name ___DAT3: #REF!
Name ___DAT3: #REF!
Name ___DAT3: #REF!
Name ___DAT4: #REF!
Name ___DAT4: #REF!
Name ___DAT4: #REF!
Name ___DAT5: #REF!
Name ___DAT5: #REF!
Name ___DAT5: #REF!

Sheet FY2026予定
A1: 共通経費（総務課配賦分）
A2: 更新日：2024年12月24日
A4: 項目 | B4: 2025年 4月予定 Yotei 4 VND | C4: 2025年 5月予定 Yotei 5 VND | D4: 2025年 6月予定 Yotei 6 VND | E4: 2025年 7月予定 Yotei 7 VND | F4: 2025年 8月予定 Yotei 8 VND | G4: 2025年 9月予定 Yotei 9 VND | H4: 2025年 10月予定 Yotei 10 VND | I4: 2025年 11月予定 Yotei 11 VND | J4: 2025年 12月予定 Yotei 12 VND | K4: 2026年 1月予定 Yotei 1 VND | L4: 2026年 2月予定 Yotei 2 VND | M4: 2026年 3月予定 Yotei 3 VND | N4: 備考 | O4: 計上基準 | P4: 製造コード | Q4: 間接コード | R4: 販売コード | S4: 採算科目
A5: 食堂燃料費 Gas | B5: ='Cách tính phân bổ 振替計算'!C9 -> 40366 | C5: ='Cách tính phân bổ 振替計算'!D9 -> 39111 | D5: ='Cách tính phân bổ 振替計算'!E9 -> 44856 | E5: ='Cách tính phân bổ 振替計算'!F9 -> 46929 | F5: ='Cách tính phân bổ 振替計算'!G9 -> 42688 | G5: ='Cách tính phân bổ 振替計算'!H9 -> 38491 | H5: ='Cách tính phân bổ 振替計算'!I9 -> 46977 | I5: ='Cách tính phân bổ 振替計算'!J9 -> 41126 | ... M5: ='Cách tính phân bổ 振替計算'!N9 -> 42542 | N5: 一人当たり | O5: 振替単価は予定と同額とし、当月1日～末日購入分を前月末の実績人数（当月初の人事課の人員データ）に応じ各部門に振替。 Đơn giá phân bổ thực tích giống như đơn giá dự định, phân bổ số tiền mua trong tháng cho số người thực tế của các phòng ban cuối tháng trước (số liệu của phòng nhân sự cung cấp vào đầu tháng sau khi chốt Cost center) 計上月に組織変更がある部署は総務課までに連絡しなければなりません。総務課は該当の部署にて連絡された人数をベースに振り替えます。 Trong tháng phân bổ, các phòng ban có sự thay đổi về sơ đồ tổ chức phải liên lạc cho phòng hành chính. Phòng hành chính sẽ phân bổ chi phí dựa trên số lượng người được phòng ban thông báo. *Lưu ý: Chỉ tính nhân viên chính thức của KDTVN (bao gồm biệt phái) căn cứ trên dữ liệu do phòng Nhân sự cung cấp chốt Cost Center 注：人事課の人員データにはKDTVNの正社員（日本人を含む）のみ | P5: 5005056281 | Q5: 6005056625 | R5: 6005056543 | S5: 水道光熱費
A6: 手洗い洗剤 Nước rửa tay | B6: ='Cách tính phân bổ 振替計算'!C14 -> 1122 | C6: ='Cách tính phân bổ 振替計算'!D14 -> 1130 | D6: ='Cách tính phân bổ 振替計算'!E14 -> 1157 | E6: ='Cách tính phân bổ 振替計算'!F14 -> 1113 | F6: ='Cách tính phân bổ 振替計算'!G14 -> 1080 | G6: ='Cách tính phân bổ 振替計算'!H14 -> 1093 | H6: ='Cách tính phân bổ 振替計算'!I14 -> 1131 | I6: ='Cách tính phân bổ 振替計算'!J14 -> 1114 | ... M6: ='Cách tính phân bổ 振替計算'!N14 -> 1085 | N6: 一人当たり | P6: 5005016372 | Q6: 6005016422 | R6: 6005016413 | S6: 消耗品費
A7: トイレットペーパー Giấy vệ sinh | B7: ='Cách tính phân bổ 振替計算'!C20 -> 18424 | C7: ='Cách tính phân bổ 振替計算'!D20 -> 17736 | D7: ='Cách tính phân bổ 振替計算'!E20 -> 19401 | E7: ='Cách tính phân bổ 振替計算'!F20 -> 21138 | F7: ='Cách tính phân bổ 振替計算'!G20 -> 18404 | G7: ='Cách tính phân bổ 振替計算'!H20 -> 17500 | H7: ='Cách tính phân bổ 振替計算'!I20 -> 21110 | I7: ='Cách tính phân bổ 振替計算'!J20 -> 18421 | ... M7: ='Cách tính phân bổ 振替計算'!N20 -> 18435 | N7: 一人当たり | P7: 5005016372 | Q7: 6005016422 | R7: 6005016413 | S7: 消耗品費
A8: 清掃費 Chi phí làm sạch | B8: ='Cách tính phân bổ 振替計算'!C23 -> 56247 | C8: ='Cách tính phân bổ 振替計算'!D23 -> 56462 | D8: ='Cách tính phân bổ 振替計算'!E23 -> 58201 | E8: ='Cách tính phân bổ 振替計算'!F23 -> 53306 | F8: ='Cách tính phân bổ 振替計算'!G23 -> 51891 | G8: ='Cách tính phân bổ 振替計算'!H23 -> 49590 | H8: ='Cách tính phân bổ 振替計算'!I23 -> 47432 | I8: ='Cách tính phân bổ 振替計算'!J23 -> 46844 | ... M8: ='Cách tính phân bổ 振替計算'!N23 -> 44540 | N8: 一人当たり | O8: 振替単価は予定と同額とし、前月末の実績人数（当月初の人事課の人員データ）に応じ各部門に振替。 Đơn giá phân bổ thực tích giống như đơn giá dự định, phân bổ cho số người thực tế của các phòng ban cuối tháng trước (số liệu của phòng nhân sự cung cấp vào đầu tháng sau khi chốt Cost center) 計上月に組織変更がある部署は総務課までに連絡しなければなりません。総務課は該当の部署にて連絡された人数をベースに振り替えます。 Trong tháng phân bổ, các phòng ban có sự thay đổi về sơ đồ tổ chức phải liên lạc cho phòng hành chính. Phòng hành chính sẽ phân bổ chi phí dựa trên số lượng người được phòng ban thông báo. | P8: 5005246286 | Q8: 6005246673 | R8: 6005246542 | S8: 手数料
A9: 出向者送迎費 Xe đưa đón người Nhật | B9: ='Cách tính phân bổ 振替計算'!C30 -> 748000 | C9: ='Cách tính phân bổ 振替計算'!D30 -> 763266 | D9: ='Cách tính phân bổ 振替計算'!E30 -> 740817 | E9: ='Cách tính phân bổ 振替計算'!F30 -> 740817 | F9: ='Cách tính phân bổ 振替計算'!G30 -> 808164 | G9: ='Cách tính phân bổ 振替計算'!H30 -> 763266 | H9: ='Cách tính phân bổ 振替計算'!I30 -> 763266 | I9: ='Cách tính phân bổ 振替計算'!J30 -> 808164 | ... M9: ='Cách tính phân bổ 振替計算'!N30 -> 477552 | N9: 一人当たり | O9: ・通常出勤・シフト出勤のバス代：前月16日～当月15日分を実際使用人数で按分翌月に振替する（バス使用の場合のみ） ・シフト・残業・休日出勤のタクシー代：前月16日～当月15日分を各部門での使用実績に応じて部門で按分翌月に振替する（タクシー使用の場合のみ） タクシー費用は毎日ポータルにアップデートされ、採算の作成時に振替額を確定する（Bảng kê chi phí taxiタクシー費用一覧表） ・Đối với chi phí xe bus đi làm ngày thường và làm ca: Phân bổ chi phí từ ngày 16 tháng trước đến ngày 15 tháng hiện tại vào tháng tiếp theo cho số người sử dụng xe bus của toàn công ty (chỉ áp dụng cho xe bus) ・Đối với chi phí xe taxi đi làm ca, tăng ca, đi làm ngày nghỉ: Phân bổ chi phí từ ngày 16 tháng trước đến ngày 15 tháng hiện tại vào tháng tiếp theo cho thực tích sử dụng của các phòng ban (chỉ áp dụng cho xe taxi) Chi phí taxi sử dụng thực tế của các phòng ban sẽ được cập nhật hàng ngày trên portal ( Link bên dưới) (Bảng kê chi phí taxiタクシー費用一覧表), các phòng ban hãy xác nhận để dự tính chi phí của phòng ban mình. *Lưu ý: Chi phí xe đưa đón phân bổ cho tất cả những trường hợp sử dụng thực tế. 注：送迎費：全ての実際使用場合に振替する | P9: 5004086291 | Q9: 6004086651 | R9: 6004086551 | S9: 福利厚生費
A10: ローカル社員送迎費 Xe đưa đón người Việt | B10: ='Cách tính phân bổ 振替計算'!C39 -> 1374678 | C10: ='Cách tính phân bổ 振替計算'!D39 -> 1586747 | D10: ='Cách tính phân bổ 振替計算'!E39 -> 1418477 | E10: ='Cách tính phân bổ 振替計算'!F39 -> 1487463 | F10: ='Cách tính phân bổ 振替計算'!G39 -> 1588334 | G10: ='Cách tính phân bổ 振替計算'!H39 -> 1593513 | H10: ='Cách tính phân bổ 振替計算'!I39 -> 1194735 | I10: ='Cách tính phân bổ 振替計算'!J39 -> 1452617 | ... M10: ='Cách tính phân bổ 振替計算'!N39 -> 1296228 | N10: 一人当たり | P10: 5004086291 | Q10: 6004086651 | R10: 6004086551 | S10: 福利厚生費
A16: ※食堂燃料費購入単価は、政府発表の市場価格に基づき、毎月3日改定されます。
A17: Đơn giá gas thay đổi theo giá công bố của nhà nước. Thường được cập nhật vào ngày 03 hàng tháng.

Sheet Cách tính phân bổ 振替計算
B1: 稼働日 Số ngày làm việc | C1: 20 | D1: 19 | E1: 21 | F1: 23 | G1: 20 | H1: 19 | I1: 23 | J1: 20 | K1: 22 | L1: 20 | M1: 15 | N1: 20
B2: 人員数 Số người dự kiến | C2: 5797 | D2: 5753 | E2: 5618 | F2: 6137 | G2: 6325 | H2: 6547 | I2: 6897 | J2: 7003 | K2: 6941 | L2: 7207 | M2: 7661 | N2: 7193
C4: 2025年 4月予定 Yotei 4 VND | D4: 2025年 5月予定 Yotei 5 VND | E4: 2025年 6月予定 Yotei 6 VND | F4: 2025年 7月予定 Yotei 7 VND | G4: 2025年 8月予定 Yotei 8 VND | H4: 2025年 9月予定 Yotei 9 VND | I4: 2025年 10月予定 Yotei 10 VND | J4: 2025年 11月予定 Yotei 11 VND | K4: 2025年 12月予定 Yotei 12 VND | L4: 2026年 1月予定 Yotei 1 VND | M4: 2026年 2月予定 Yotei 2 VND | N4: 2026年 3月予定 Yotei 3 VND
A5: ガス Gas | B5: 単価 Đơn giá VND | C5: 1800000 | D5: 1800000 | E5: 1800000 | F5: 1800000 | G5: 1800000 | H5: 1800000 | I5: 1800000 | J5: 1800000 | K5: 1800000 | L5: 1800000 | M5: 1800000 | N5: 1800000
B6: 数量 Số lượng | C6: 130 | D6: 125 | E6: 140 | F6: 160 | G6: 150 | H6: 140 | I6: 180 | J6: 160 | K6: 170 | L6: 170 | M6: 140 | N6: 170
B7: 合計 Tổng tiền VND | C7: =C5*C6 -> 234000000 | D7: =D5*D6 -> 225000000 | E7: =E5*E6 -> 252000000 | F7: =F5*F6 -> 288000000 | G7: =G5*G6 -> 270000000 | H7: =H5*H6 -> 252000000 | I7: =I5*I6 -> 324000000 | J7: =J5*J6 -> 288000000 | ... N7: =N5*N6 -> 306000000
B8: 一人当たり 1 người VND | C8: =ROUNDUP(C7/C$2,0) -> 40366 | D8: =ROUNDUP(D7/D$2,0) -> 39111 | E8: =ROUNDUP(E7/E$2,0) -> 44856 | F8: =ROUNDUP(F7/F$2,0) -> 46929 | G8: =ROUNDUP(G7/G$2,0) -> 42688 | H8: =ROUNDUP(H7/H$2,0) -> 38491 | I8: =ROUNDUP(I7/I$2,0) -> 46977 | J8: =ROUNDUP(J7/J$2,0) -> 41126 | ... N8: =ROUNDUP(N7/N$2,0) -> 42542
B9: 配信金額 Số tiền phân bổ VND | C9: =C8 -> 40366 | D9: =D8 -> 39111 | E9: =E8 -> 44856 | F9: =F8 -> 46929 | G9: =G8 -> 42688 | H9: =H8 -> 38491 | I9: =I8 -> 46977 | J9: =J8 -> 41126 | ... N9: =N8 -> 42542
A10: 手洗い洗剤 Handwashing | B10: 単価 Đơn giá | C10: 325000 | D10: 325000 | E10: 325000 | F10: 325000 | G10: 325000 | H10: 325000 | I10: 325000 | J10: 325000 | K10: 325000 | L10: 325000 | M10: 325000 | N10: 325000
B11: 数量 Số lượng | C11: 20 | D11: 20 | E11: 20 | F11: 21 | G11: 21 | H11: 22 | I11: 24 | J11: 24 | K11: 24 | L11: 25 | M11: 27 | N11: 24
B12: 合計 total | C12: =C10*C11 -> 6500000 | D12: =D10*D11 -> 6500000 | E12: =E10*E11 -> 6500000 | F12: =F10*F11 -> 6825000 | G12: =G10*G11 -> 6825000 | H12: =H10*H11 -> 7150000 | I12: =I10*I11 -> 7800000 | J12: =J10*J11 -> 7800000 | ... N12: =N10*N11 -> 7800000
B13: 一人当たり 1 người VND | C13: =ROUNDUP(C12/C$2,0) -> 1122 | D13: =ROUNDUP(D12/D$2,0) -> 1130 | E13: =ROUNDUP(E12/E$2,0) -> 1157 | F13: =ROUNDUP(F12/F$2,0) -> 1113 | G13: =ROUNDUP(G12/G$2,0) -> 1080 | H13: =ROUNDUP(H12/H$2,0) -> 1093 | I13: =ROUNDUP(I12/I$2,0) -> 1131 | J13: =ROUNDUP(J12/J$2,0) -> 1114 | ... N13: =ROUNDUP(N12/N$2,0) -> 1085
B14: 配信金額 Số tiền phân bổ VND | C14: =C13 -> 1122 | D14: =D13 -> 1130 | E14: =E13 -> 1157 | F14: =F13 -> 1113 | G14: =G13 -> 1080 | H14: =H13 -> 1093 | I14: =I13 -> 1131 | J14: =J13 -> 1114 | ... N14: =N13 -> 1085
A15: アルコール消毒 Cồn khử trùng | B15: 合計 Total VND
B16: 一人当たり 1 người VND | C16: =ROUNDUP(C15/C$2,0) -> 0 | D16: =ROUNDUP(D15/D$2,0) -> 0 | E16: =ROUNDUP(E15/E$2,0) -> 0 | F16: =ROUNDUP(F15/F$2,0) -> 0 | G16: =ROUNDUP(G15/G$2,0) -> 0 | H16: =ROUNDUP(H15/H$2,0) -> 0 | I16: =ROUNDUP(I15/I$2,0) -> 0 | J16: =ROUNDUP(J15/J$2,0) -> 0 | ... N16: =ROUNDUP(N15/N$2,0) -> 0
B17: 配信金額 Số tiền phân bổ VND | C17: =C16 -> 0 | D17: =D16 -> 0 | E17: =E16 -> 0 | F17: =F16 -> 0 | G17: =G16 -> 0 | H17: =H16 -> 0 | I17: =I16 -> 0 | J17: =J16 -> 0 | ... N17: =N16 -> 0
A18: トイレットペーパー Toiletpaper | B18: 合計 Total VND | C18: =(178*30000*C1) -> 106800000 | D18: =(179*30000*D1) -> 102030000 | E18: =(173*30000*E1) -> 108990000 | F18: =(188*30000*F1) -> 129720000 | G18: =(194*30000*G1) -> 116400000 | H18: =(201*30000*H1) -> 114570000 | I18: =(211*30000*I1) -> 145590000 | J18: =(215*30000*J1) -> 129000000 | K18: =(213*30000*K1) -> 140580000 | L18: =(221*30000*L1) -> 132600000 | M18: =(236*30000*M1) -> 106200000 | N18: =(221*30000*N1) -> 132600000
B19: 一人当たり 1 người VND | C19: =ROUNDUP(C18/C$2,0) -> 18424 | D19: =ROUNDUP(D18/D$2,0) -> 17736 | E19: =ROUNDUP(E18/E$2,0) -> 19401 | F19: =ROUNDUP(F18/F$2,0) -> 21138 | G19: =ROUNDUP(G18/G$2,0) -> 18404 | H19: =ROUNDUP(H18/H$2,0) -> 17500 | I19: =ROUNDUP(I18/I$2,0) -> 21110 | J19: =ROUNDUP(J18/J$2,0) -> 18421 | ... N19: =ROUNDUP(N18/N$2,0) -> 18435
B20: 配信金額 Số tiền phân bổ VND | C20: =C19 -> 18424 | D20: =D19 -> 17736 | E20: =E19 -> 19401 | F20: =F19 -> 21138 | G20: =G19 -> 18404 | H20: =H19 -> 17500 | I20: =I19 -> 21110 | J20: =J19 -> 18421 | ... N20: =N19 -> 18435
A21: 清掃費 cleaning | B21: 合計 Tổng tiền VND | C21: =(39*7690000)+(951*27500) -> 326062500 | D21: =(39*7690000)+(906*27500) -> 324825000 | E21: =(39*7690000)+(984*27500) -> 326970000 | F21: =(39*7690000)+(990*27500) -> 327135000 | G21: =(39*7690000)+(1029*27500) -> 328207500 | H21: =(39*7690000)+(900*27500) -> 324660000 | I21: =(39*7690000)+(990*27500) -> 327135000 | J21: =(39*7690000)+(1023*27500) -> 328042500 | K21: =(39*7690000)+(951*27500) -> 326062500 | L21: =(39*7690000)+(879*27500) -> 324082500 | M21: =(39*7690000)+(951*27500) -> 326062500 | N21: =(39*7690000)+(744*27500) -> 320370000
B22: 一人当たり 1 người VND | C22: =ROUNDUP(C21/C$2,0) -> 56247 | D22: =ROUNDUP(D21/D$2,0) -> 56462 | E22: =ROUNDUP(E21/E$2,0) -> 58201 | F22: =ROUNDUP(F21/F$2,0) -> 53306 | G22: =ROUNDUP(G21/G$2,0) -> 51891 | H22: =ROUNDUP(H21/H$2,0) -> 49590 | I22: =ROUNDUP(I21/I$2,0) -> 47432 | J22: =ROUNDUP(J21/J$2,0) -> 46844 | ... N22: =ROUNDUP(N21/N$2,0) -> 44540
B23: 配信金額 Số tiền phân bổ VND | C23: =C22 -> 56247 | D23: =D22 -> 56462 | E23: =E22 -> 58201 | F23: =F22 -> 53306 | G23: =G22 -> 51891 | H23: =H22 -> 49590 | I23: =I22 -> 47432 | J23: =J22 -> 46844 | ... N23: =N22 -> 44540
A24: 出向者送迎費 Xe đưa đón người Nhật | B24: Hai Anh | C24: 35600000 | D24: 35600000 | E24: 34500000 | F24: 34500000 | G24: 37800000 | H24: 35600000 | I24: 35600000 | J24: 37800000 | K24: 35600000 | L24: 35600000 | M24: 35600000 | N24: 21600000
B25: Trung Kien | C25: 1800000 | D25: 1800000 | E25: 1800000 | F25: 1800000 | G25: 1800000 | H25: 1800000 | I25: 1800000 | J25: 1800000 | K25: 1800000 | L25: 1800000 | M25: 1800000 | N25: 1800000
B26: Hoang Anh
B27: 合計 Tổng tiền VND | C27: =SUM(C24:C26) -> 37400000 | D27: =SUM(D24:D26) -> 37400000 | E27: =SUM(E24:E26) -> 36300000 | F27: =SUM(F24:F26) -> 36300000 | G27: =SUM(G24:G26) -> 39600000 | H27: =SUM(H24:H26) -> 37400000 | I27: =SUM(I24:I26) -> 37400000 | J27: =SUM(J24:J26) -> 39600000 | ... N27: =SUM(N24:N26) -> 23400000
B28: 人数 Số người | C28: 50 | D28: 49 | E28: 49 | F28: 49 | G28: 49 | H28: 49 | I28: 49 | J28: 49 | K28: 49 | L28: 49 | M28: 49 | N28: 49
B29: 一人当たり 1 người VND | C29: =ROUNDUP(C27/C28,0) -> 748000 | D29: =ROUNDUP(D27/D28,0) -> 763266 | E29: =ROUNDUP(E27/E28,0) -> 740817 | F29: =ROUNDUP(F27/F28,0) -> 740817 | G29: =ROUNDUP(G27/G28,0) -> 808164 | H29: =ROUNDUP(H27/H28,0) -> 763266 | I29: =ROUNDUP(I27/I28,0) -> 763266 | J29: =ROUNDUP(J27/J28,0) -> 808164 | ... N29: =ROUNDUP(N27/N28,0) -> 477552
B30: 配信金額 Số tiền phân bổ VND | C30: =C29 -> 748000 | D30: =D29 -> 763266 | E30: =E29 -> 740817 | F30: =F29 -> 740817 | G30: =G29 -> 808164 | H30: =H29 -> 763266 | I30: =I29 -> 763266 | J30: =J29 -> 808164 | ... N30: =N29 -> 477552
A31: Staff者送迎費 Bus cho CNV | B31: Gia Vu | C31: 162192000 | D31: 184224000 | E31: 162192000 | F31: 184224000 | G31: 216568000 | H31: 223912000 | I31: 184848000 | J31: 221568000 | K31: 221568000 | L31: 224224000 | M31: 216880000 | N31: 201880000
B32: Hai Anh | C32: 862397920 | D32: 989464240 | E32: 862397920 | F32: 989464240 | G32: 1081819680 | H32: 1124175120 | I32: 880042480 | J32: 1091819680 | K32: 1091819680 | L32: 1059464240 | M32: 1027108800 | N32: 1002108800
B33: Ngoc Quang | C33: 550790080 | D33: 630921760 | E33: 550790080 | F33: 630921760 | G33: 687632320 | H33: 714342880 | I33: 564079520 | J33: 697632320 | K33: 697632320 | L33: 680921760 | M33: 654211200 | N33: 639211200
B34: Trung Kien
B35: Hoang Anh
B36: 合計 Tổng tiền VND | C36: =SUM(C31:C35) -> 1575380000 | D36: =SUM(D31:D35) -> 1804610000 | E36: =SUM(E31:E35) -> 1575380000 | F36: =SUM(F31:F35) -> 1804610000 | G36: =SUM(G31:G35) -> 1986020000 | H36: =SUM(H31:H35) -> 2062430000 | I36: =SUM(I31:I35) -> 1628970000 | J36: =SUM(J31:J35) -> 2011020000 | ... N36: =SUM(N31:N35) -> 1843200000
B37: 人数 Số người | C37: 1146 | D37: 1137.3017 | E37: 1110.6138 | F37: 1213.2141 | G37: 1250.3795 | H37: 1294.2663 | I37: 1363.4573 | J37: 1384.4123 | K37: 1372.1556 | L37: 1424.7407 | M37: 1514.4913 | N37: 1421.9731
B38: 一人当たり 1 người VND | C38: =ROUNDUP(C36/C37,0) -> 1374678 | D38: =ROUNDUP(D36/D37,0) -> 1586747 | E38: =ROUNDUP(E36/E37,0) -> 1418477 | F38: =ROUNDUP(F36/F37,0) -> 1487463 | G38: =ROUNDUP(G36/G37,0) -> 1588334 | H38: =ROUNDUP(H36/H37,0) -> 1593513 | I38: =ROUNDUP(I36/I37,0) -> 1194735 | J38: =ROUNDUP(J36/J37,0) -> 1452617 | ... N38: =ROUNDUP(N36/N37,0) -> 1296228
B39: 配信金額 Số tiền phân bổ VND | C39: =C38 -> 1374678 | D39: =D38 -> 1586747 | E39: =E38 -> 1418477 | F39: =F38 -> 1487463 | G39: =G38 -> 1588334 | H39: =H38 -> 1593513 | I39: =I38 -> 1194735 | J39: =J38 -> 1452617 | ... N39: =N38 -> 1296228
A41: ※出向者送迎費は、これまで 一人一日あたり の人頭比を配信していましたが、
A42: 一人当たり（一ヶ月分）の予定数字として連絡する方法に変更いたします。
...

Sheet Tính gas
B2: 45017 | C2: 45047 | D2: 45078 | E2: 45108 | F2: 45139 | G2: 45170 | H2: 45200 | I2: 45231 | J2: 45261 | K2: 45292
A3: Số tiền phân bổ thực tế/người/tháng | B3: 52658 | C3: 36715 | D3: 47660 | E3: 37572 | F3: 43019 | G3: 46732 | H3: 54893 | I3: 60869 | J3: 44639 | K3: 37975
A5: Số tiền trung bình từ tháng 4.2023 đến tháng 1.2024 | B5: =AVERAGEA(B3:K3) -> 46273.2 | C5: người/tháng
B6: =B5/20 -> 2313.66 | C6: người/ngày
A7: Số ngày làm việc của FY2025 | B7: 19 | C7: 21 | D7: 20 | E7: 23 | F7: 22 | G7: 18 | H7: 23 | I7: 21 | J7: 20 | K7: 17 | L7: 19 | M7: 20
A8: Số người FY2025 | B8: 5768 | C8: 5444 | D8: 5866 | E8: 5754 | F8: 6181 | G8: 6323 | H8: 6334 | I8: 6275 | J8: 6419 | K8: 6672 | L8: 6136 | M8: 6398
A9: 1862880 | B9: T4 | C9: T5 | D9: T6 | E9: T7 | F9: T8 | G9: T9 | H9: T10 | I9: T11 | J9: T12 | K9: T1 | L9: T2 | M9: T3
B10: =B6*B7*B8 -> 2.5355863e+08 | C10: =B6*C7*C8 -> 2.6450687e+08 | D10: =B6*D7*D8 -> 2.7143859e+08 | E10: =B6*E7*E8 -> 3.0619439e+08 | F10: =B6*F7*F8 -> 3.1461611e+08 | G10: =B6*G7*G8 -> 2.633269e+08 | H10: =B6*H7*H8 -> 3.3705862e+08 | I10: =B6*I7*I8 -> 3.0488255e+08 | J10: =B6*J7*J8 -> 2.9702767e+08 | K10: =B6*K7*K8 -> 2.6242457e+08 | L10: =B6*L7*L8 -> 2.6973574e+08 | M10: =B6*M7*M8 -> 2.9605593e+08
B11: =B10/A9 -> 136.11109 | C11: =C10/A9 -> 141.98814 | D11: =D10/A9 -> 145.70911 | E11: =E10/A9 -> 164.36614 | F11: =F10/A9 -> 168.88695 | G11: =G10/A9 -> 141.35473 | H11: =H10/A9 -> 180.93415 | I11: =I10/A9 -> 163.66194 | J11: =J10/A9 -> 159.44541 | K11: =K10/A9 -> 140.87036 | L11: =L10/A9 -> 144.79501 | M11: =M10/A9 -> 158.92378
A12: Tổng số bình dự tính mua cho FY25 (Dự phòng 10 bình) | B12: 150 | C12: 150 | D12: 160 | E12: 180 | F12: 180 | G12: 150 | H12: 190 | I12: 180 | J12: 170 | K12: 150 | L12: 160 | M12: 170
B13: =B12+10 -> 160 | C13: =C12+10 -> 160 | D13: =D12+10 -> 170 | E13: =E12+10 -> 190 | F13: =F12+10 -> 190 | G13: =G12+10 -> 160 | H13: =H12+10 -> 200 | I13: =I12+10 -> 190 | ... M13: =M12+10 -> 180

Sheet Tính NRT, GVS
D3: SỐ NGƯỜI | F3: Hand wash | G3: GIẤY VS | H3: Làm sạch | I3: 345000
D4: T4.2023 | E4: 5553 | F4: 1240 | G4: 19321 | H4: 57158
D5: T5.2023 | E5: 5507 | F5: 1252 | G5: 19736 | H5: 57499
D6: T6.2023 | E6: 5550 | F6: 1247 | G6: 20987 | H6: 31247
D7: T7.2023 | E7: 5748 | F7: 1194 | G7: 19177 | H7: 55976
D8: T8.2023 | E8: 5674 | F8: 1212 | G8: 18543 | H8: 56235
D9: T9.2023 | E9: 5561 | F9: 1051 | G9: 17199 | H9: 56664
D10: T10.2023 | E10: 5580 | F10: 1173 | G10: 18639 | H10: 56583
D11: T11.2023 | E11: 5709 | F11: 1206 | G11: 19061 | H11: 55229
D12: T12.2023 | E12: 5643 | F12: 1162 | G12: 18452 | H12: 56012
D14: Trung bình 1 người/ tháng | F14: =AVERAGE(F4:F12) -> 1193 | G14: =AVERAGE(G4:G12) -> 19012.778 | H14: =AVERAGE(H4:H12) -> 53622.556
D16: 1 ngày | F16: =F14/21 -> 56.809524 | G16: =G14/21 -> 905.37037 | H16: =H14/21 -> 2553.455
D17: Thang 4 | E17: Thang 5 | F17: Thang 6 | G17: Thang 7 | H17: Thang 8 | I17: Thang 9 | J17: Thang 10 | K17: Thang 11 | L17: Thang 12 | M17: Thang 1 | N17: Thang 2 | O17: Thang 3
D18: 19 | E18: 21 | F18: 20 | G18: 23 | H18: 22 | I18: 18 | J18: 23 | K18: 21 | L18: 20 | M18: 17 | N18: 19 | O18: 20
D19: 5550 | E19: 5768 | F19: 5444 | G19: 5866 | H19: 5754 | I19: 6181 | J19: 6323 | K19: 6334 | L19: 6275 | M19: 6419 | N19: 6672 | O19: 6136
D20: 56.81 | E20: 56.81 | F20: 56.81 | G20: 56.81 | H20: 56.81 | I20: 56.81 | J20: 56.81 | K20: 56.81 | L20: 56.81 | M20: 56.81 | N20: 56.81 | O20: 56.81
D21: =D18*D19*D20 -> 5990614.5 | E21: =E18*E19*E20 -> 6881281.7 | F21: =F18*F19*F20 -> 6185472.8 | G21: =G18*G19*G20 -> 7664691.6 | H21: =H18*H19*H20 -> 7191464.3 | I21: =I18*I19*I20 -> 6320567 | J21: =J18*J19*J20 -> 8261821.5 | K21: =K18*K19*K20 -> 7556525.3 | ... O21: =O18*O19*O20 -> 6971723.2
D22: =D21/345000 -> 17.3641 | E22: =E21/345000 -> 19.945744 | F22: =F21/345000 -> 17.928907 | G22: =G21/345000 -> 22.216497 | H22: =H21/345000 -> 20.844824 | I22: =I21/345000 -> 18.320484 | J22: =J21/345000 -> 23.947309 | K22: =K21/345000 -> 21.902972 | ... O22: =O21/345000 -> 20.207893
D23: 18 | E23: =ROUND(E22,0) -> 20 | F23: =ROUND(F22,0) -> 18 | G23: 23 | H23: 21 | I23: 19 | J23: =ROUND(J22,0) -> 24 | K23: =ROUND(K22,0) -> 22 | L23: =ROUND(L22,0) -> 21 | M23: =ROUND(M22,0) -> 18 | N23: =ROUND(N22,0) -> 21 | O23: 21
D24: =D23*$I$3 -> 6210000 | E24: =E23*$I$3 -> 6900000 | F24: =F23*$I$3 -> 6210000 | G24: =G23*$I$3 -> 7935000 | H24: =H23*$I$3 -> 7245000 | I24: =I23*$I$3 -> 6555000 | J24: =J23*$I$3 -> 8280000 | K24: =K23*$I$3 -> 7590000 | ... O24: =O23*$I$3 -> 7245000
D25: =D24/D19 -> 1118.9189 | E25: =E24/E19 -> 1196.2552 | F25: =F24/F19 -> 1140.7054 | G25: =G24/G19 -> 1352.7105 | H25: =H24/H19 -> 1259.1241 | I25: =I24/I19 -> 1060.508 | J25: =J24/J19 -> 1309.505 | K25: =K24/K19 -> 1198.2949 | ... O25: =O24/O19 -> 1180.7366
D28: 2 | E28: 2 | F28: 2 | G28: 2 | H28: 2 | I28: 2 | J28: 2 | K28: 2 | L28: 2 | M28: 2 | N28: 2 | O28: 2
D29: Thang 5 | E29: Thang 5 | F29: Thang 6 | G29: Thang 7 | H29: Thang 8 | I29: Thang 9 | J29: Thang 10 | K29: Thang 11 | L29: Thang 12 | M29: Thang 1 | N29: Thang 2 | O29: Thang 3
B30: Giay ve sinh | D30: 19 | E30: 21 | F30: 20 | G30: 23 | H30: 22 | I30: 18 | J30: 23 | K30: 21 | L30: 20 | M30: 17 | N30: 19 | O30: 20
B31: 32000 | D31: 5550 | E31: 5768 | F31: 5444 | G31: 5866 | H31: 5754 | I31: 6181 | J31: 6323 | K31: 6334 | L31: 6275 | M31: 6419 | N31: 6672 | O31: 6136
A32: số người đi ca | B32: 1000 | D32: 905.37 | E32: 905.37 | F32: 905.37 | G32: 905.37 | H32: 905.37 | I32: 905.37 | J32: 905.37 | K32: 905.37 | L32: 905.37 | M32: 905.37 | N32: 905.37 | O32: 905.37
A33: số tiền làm ngày nghỉ | B33: =B32*D32*2 -> 1810740 | D33: =(D30*D31*D32)+(D32*B32*2) -> 97282006 | E33: =(E30*E31*E32)+(E32*B32*E28) -> 1.114764e+08 | F33: =F30*F31*F32+1810740 -> 1.0038743e+08 | G33: =G30*G31*G32+1810740 -> 1.2396145e+08 | H33: =H30*H31*H32+1810740 -> 1.1641972e+08 | I33: =I30*I31*I32+1810740 -> 1.025404e+08 | J33: =J30*J31*J32+1810740 -> 1.3347779e+08 | K33: =K30*K31*K32+1810740 -> 1.2223763e+08 | L33: =L30*L31*L32+1810740 -> 115434675 | M33: =M30*M31*M32+1810740 -> 1.0060743e+08 | ... O33: =O30*O31*O32+1810740 -> 1.1291775e+08
D34: =D33/$B$31 -> 3040.0627 | E34: =E33/$B$31 -> 3483.6374 | F34: =F33/$B$31 -> 3137.107 | G34: =G33/$B$31 -> 3873.7953 | H34: =H33/$B$31 -> 3638.1162 | I34: =I33/$B$31 -> 3204.3874 | J34: =J33/$B$31 -> 4171.1811 | K34: =K33/$B$31 -> 3819.9258 | ... O34: =O33/$B$31 -> 3528.6796
D35: =ROUNDUP(D34,0) -> 3041 | E35: =ROUNDUP(E34,0) -> 3484 | F35: =ROUNDUP(F34,0) -> 3138 | G35: =ROUNDUP(G34,0) -> 3874 | H35: =ROUNDUP(H34,0) -> 3639 | I35: =ROUNDUP(I34,0) -> 3205 | J35: =ROUNDUP(J34,0) -> 4172 | K35: =ROUNDUP(K34,0) -> 3820 | ... O35: =ROUNDUP(O34,0) -> 3529
D36: =D35*$B$31 -> 97312000 | E36: =E35*$B$31 -> 111488000 | F36: =F35*$B$31 -> 100416000 | G36: =G35*$B$31 -> 123968000 | H36: =H35*$B$31 -> 116448000 | I36: =I35*$B$31 -> 102560000 | J36: =J35*$B$31 -> 133504000 | K36: =K35*$B$31 -> 122240000 | ... O36: =O35*$B$31 -> 112928000
D37: =+D35/19 -> 160.05263 | E37: =+E35/19 -> 183.36842 | F37: =+F35/19 -> 165.15789 | G37: =+G35/19 -> 203.89474 | H37: =+H35/19 -> 191.52632 | I37: =+I35/19 -> 168.68421 | J37: =+J35/19 -> 219.57895 | K37: =+K35/19 -> 201.05263 | ... O37: =+O35/19 -> 185.73684
D38: =ROUNDUP(D37,0) -> 161 | E38: =ROUNDUP(E37,0) -> 184 | F38: =ROUNDUP(F37,0) -> 166 | G38: =ROUNDUP(G37,0) -> 204 | H38: =ROUNDUP(H37,0) -> 192 | I38: =ROUNDUP(I37,0) -> 169 | J38: =ROUNDUP(J37,0) -> 220 | K38: =ROUNDUP(K37,0) -> 202 | ... O38: =ROUNDUP(O37,0) -> 186
D39: =D38*19*$B$31 -> 97888000 | E39: =E38*19*$B$31 -> 111872000 | F39: =F38*19*$B$31 -> 100928000 | G39: =G38*19*$B$31 -> 124032000 | H39: =H38*19*$B$31 -> 116736000 | I39: =I38*19*$B$31 -> 102752000 | J39: =J38*19*$B$31 -> 133760000 | K39: =K38*19*$B$31 -> 122816000 | ... O39: =O38*19*$B$31 -> 113088000
D40: =162*19*32000 -> 98496000 | E40: =181*19*32000 -> 110048000 | F40: =170*19*32000 -> 103360000 | G40: =205*19*32000 -> 124640000 | H40: =202*19*32000 -> 122816000 | I40: =172*19*32000 -> 104576000 | J40: =220*19*32000 -> 133760000 | K40: =199*19*32000 -> 120992000 | L40: =195*19*32000 -> 118560000 | M40: =169*19*32000 -> 102752000 | N40: =191*19*32000 -> 116128000 | O40: =185*19*32000 -> 112480000
D49: 313020000 | E49: 313185000 | F49: 314092500 | G49: 312112500 | H49: 314257500 | I49: 313020000 | J49: 313185000 | K49: 314257500 | L49: 311947500 | M49: 314257500 | N49: 314092500 | O49: 311040000
D50: -313020000 | E50: -313185000 | F50: -314092500 | G50: -312112500 | H50: -314257500 | I50: -313020000 | J50: -313185000 | K50: -314257500 | L50: -311947500 | M50: -314257500 | N50: -314092500 | O50: -311040000

Sheet Tính bus VN
B1: 4 | C1: 5 | D1: 6 | E1: 7 | F1: 8 | G1: 9 | H1: 10 | I1: 11 | J1: 12 | K1: 1 | L1: 2 | M1: 3 | N1: 1 ngày | O1: Hải Anh | P1: Ngọc Quang
A2: Hành chính | B2: =COUNTA(B21:B51) -> 21 | C2: =COUNTA(C21:C51) -> 21 | D2: =COUNTA(D21:D51) -> 17 | E2: =COUNTA(E21:E51) -> 22 | F2: =COUNTA(F21:F51) -> 21 | G2: =COUNTA(G21:G51) -> 23 | H2: =COUNTA(H21:H51) -> 18 | I2: =COUNTA(I21:I51) -> 22 | ... M2: =COUNTA(M21:M51) -> 17 | N2: HC/ Ngày | O2: 36720000 | P2: 26697000
A3: Đi ca | B3: =COUNTA(B53:B83) -> 22 | C3: =COUNTA(C53:C83) -> 22 | D3: =COUNTA(D53:D83) -> 19 | E3: =COUNTA(E53:E83) -> 23 | F3: =COUNTA(F53:F83) -> 22 | G3: =COUNTA(G53:G83) -> 24 | H3: =COUNTA(H53:H83) -> 19 | I3: =COUNTA(I53:I83) -> 23 | ... L3: =COUNTA(L53:L83) -> 21 | M3: 18 | N3: Ca/ Ngày | O3: 4968000 | P3: 2106000
A4: Tiền HC | B4: =B2*$O$2 -> 771120000 | C4: =C2*$O$2 -> 771120000 | D4: =D2*$O$2 -> 624240000 | E4: =E2*$O$2 -> 807840000 | F4: =F2*$O$2 -> 771120000 | G4: =G2*$O$2 -> 844560000 | H4: =H2*$O$2 -> 660960000 | I4: =I2*$O$2 -> 807840000 | ... M4: =M2*$O$2 -> 624240000
A5: Tiền ca | B5: =B3*$O$3 -> 109296000 | C5: =C3*$O$3 -> 109296000 | D5: =D3*$O$3 -> 94392000 | E5: =E3*$O$3 -> 114264000 | F5: =F3*$O$3 -> 109296000 | G5: =G3*$O$3 -> 119232000 | H5: =H3*$O$3 -> 94392000 | I5: =I3*$O$3 -> 114264000 | ... M5: =M3*$O$3 -> 89424000
A6: Tiền tăng ca | B6: 15000000 | C6: 15000000 | D6: 15000000 | E6: 15000000 | F6: 15000000 | G6: 15000000 | H6: 15000000 | I6: 15000000 | J6: 15000000 | K6: 15000000 | L6: 15000000 | M6: 15000000
A7: Tiền sự kiện | D7: 35000000 | H7: 25000000 | K7: 20000000
A8: Tổng HA | B8: =SUM(B4:B7) -> 895416000 | C8: =SUM(C4:C7)+10*1600000 -> 911416000 | D8: =SUM(D4:D7) -> 768632000 | E8: =SUM(E4:E7)+10*1600000 -> 953104000 | F8: =SUM(F4:F7)+10*1600000 -> 911416000 | G8: =SUM(G4:G7)+20*1600000 -> 1010792000 | H8: =SUM(H4:H7)+30*1600000 -> 843352000 | I8: =SUM(I4:I7)+30*1600000 -> 985104000 | J8: =SUM(J4:J7)+30*1600000 -> 1031760000 | K8: =SUM(K4:K7)+30*1600000 -> 921728000 | L8: =SUM(L4:L7)+50*1600000 -> 933728000 | M8: =SUM(M4:M7)+20*1600000 -> 760664000
A9: Hành chính | B9: 21 | C9: 21 | D9: 17 | E9: 22 | F9: 21 | G9: 23 | H9: 18 | I9: 22 | J9: 23 | K9: 20 | L9: 20 | M9: 17
A10: Đi ca | B10: 22 | C10: 22 | D10: 19 | E10: 23 | F10: 22 | G10: 24 | H10: 19 | I10: 23 | J10: 25 | K10: 21 | L10: 21 | M10: 18
A11: Tiền HC | B11: =B9*$P$2 -> 560637000 | C11: =C9*$P$2 -> 560637000 | D11: =D9*$P$2 -> 453849000 | E11: =E9*$P$2 -> 587334000 | F11: =F9*$P$2 -> 560637000 | G11: =G9*$P$2 -> 614031000 | H11: =H9*$P$2 -> 480546000 | I11: =I9*$P$2 -> 587334000 | ... M11: =M9*$P$2 -> 453849000
A12: Tiền ca | B12: =B10*$P$3 -> 46332000 | C12: =C10*$P$3 -> 46332000 | D12: =D10*$P$3 -> 40014000 | E12: =E10*$P$3 -> 48438000 | F12: =F10*$P$3 -> 46332000 | G12: =G10*$P$3 -> 50544000 | H12: =H10*$P$3 -> 40014000 | I12: =I10*$P$3 -> 48438000 | ... M12: =M10*$P$3 -> 37908000
A13: Tiền tăng ca | B13: 10000000 | C13: 10000000 | D13: 10000000 | E13: 10000000 | F13: 10000000 | G13: 10000000 | H13: 10000000 | I13: 10000000 | J13: 10000000 | K13: 10000000 | L13: 10000000 | M13: 10000000
A14: Tiền sự kiện | D14: 25000000 | H14: 20000000 | K14: 15000000
A15: Tổng NQ | B15: =SUM(B11:B14) -> 616969000 | C15: =SUM(C11:C14)+10*1600000 -> 632969000 | D15: =SUM(D11:D14) -> 528863000 | E15: =SUM(E11:E14)+10*1600000 -> 661772000 | F15: =SUM(F11:F14)+10*1600000 -> 632969000 | G15: =SUM(G11:G14)+20*1600000 -> 706575000 | H15: =SUM(H11:H14)+30*1600000 -> 598560000 | I15: =SUM(I11:I14)+30*1600000 -> 693772000 | J15: =SUM(J11:J14)+30*1600000 -> 724681000 | K15: =SUM(K11:K14)+30*1600000 -> 651166000 | L15: =SUM(L11:L14)+50*1600000 -> 668166000 | M15: =SUM(M11:M14)+20*1600000 -> 533757000
B16: =B8+B15 -> 1512385000 | C16: =C8+C15 -> 1544385000 | D16: =D8+D15 -> 1297495000 | E16: =E8+E15 -> 1614876000 | F16: =F8+F15 -> 1544385000 | G16: =G8+G15 -> 1717367000 | H16: =H8+H15 -> 1441912000 | I16: =I8+I15 -> 1678876000 | ... M16: =M8+M15 -> 1294421000
A17: Người | B17: 5550 | C17: 5768 | D17: 5444 | E17: 5866 | F17: 5754 | G17: 6181 | H17: 6323 | I17: 6334 | J17: 6275 | K17: 6419 | L17: 6672 | M17: 6136
A18: Số người bus | B18: 880 | C18: =ROUNDUP(C17*16%,0)-10 -> 913 | D18: =ROUNDUP(D17*16%,0)-10 -> 862 | E18: =ROUNDUP(E17*16%,0)-10 -> 929 | F18: =ROUNDUP(F17*16%,0)-10 -> 911 | G18: =ROUNDUP(G17*16%,0)-10 -> 979 | H18: =ROUNDUP(H17*16%,0)-10 -> 1002 | I18: =ROUNDUP(I17*16%,0)-10 -> 1004 | J18: =ROUNDUP(J17*16%,0)-10 -> 994 | ... L18: =ROUNDUP(L17*16%,0)-10 -> 1058 | M18: =ROUNDUP(M17*16%,0)-20 -> 962
A19: Tiền/người | B19: =ROUNDUP(B16/B18,0) -> 1718620 | C19: =ROUNDUP(C16/C18,0) -> 1691550 | D19: =ROUNDUP(D16/D18,0) -> 1505215 | E19: =ROUNDUP(E16/E18,0) -> 1738295 | F19: =ROUNDUP(F16/F18,0) -> 1695264 | G19: =ROUNDUP(G16/G18,0) -> 1754206 | H19: =ROUNDUP(H16/H18,0) -> 1439034 | I19: =ROUNDUP(I16/I18,0) -> 1672188 | ... M19: =ROUNDUP(M16/M18,0) -> 1345552
A21: HC | B21: 45338 | D21: 45398 | E21: 45428 | G21: 45489 | H21: 45520 | I21: 45551 | J21: 45581 | L21: 45642 | M21: 45673
B22: 45339 | D22: 45399 | E22: 45429 | F22: 45460 | G22: 45490 | I22: 45552 | J22: 45582 | L22: 45643 | M22: 45674
C23: 45369 | F23: 45461 | G23: 45491 | I23: 45553 | J23: 45583 | K23: 45614 | L23: 45644
B24: 45341 | C24: 45370 | D24: 45401 | F24: 45462 | G24: 45492 | H24: 45523 | I24: 45554 | K24: 45615 | L24: 45645
B25: 45342 | C25: 45371 | E25: 45432 | F25: 45463 | H25: 45524 | I25: 45555 | K25: 45616 | L25: 45646 | M25: 45677
B26: 45343 | C26: 45372 | E26: 45433 | F26: 45464 | H26: 45525 | J26: 45586 | K26: 45617 | M26: 45678
B27: 45344 | C27: 45373 | D27: 45404 | E27: 45434 | G27: 45495 | H27: 45526 | J27: 45587 | K27: 45618 | M27: 45679
B28: 45345 | D28: 45405 | E28: 45435 | G28: 45496 | H28: 45527 | I28: 45558 | J28: 45588 | L28: 45649 | M28: 45680
D29: 45406 | E29: 45436 | F29: 45467 | G29: 45497 | I29: 45559 | J29: 45589 | L29: 45650 | M29: 45681
C30: 45376 | D30: 45407 | F30: 45468 | G30: 45498 | I30: 45560 | J30: 45590 | K30: 45621 | L30: 45651
B31: 45348 | C31: 45377 | D31: 45408 | F31: 45469 | G31: 45499 | H31: 45530 | I31: 45561 | K31: 45622 | L31: 45652
B32: 45349 | C32: 45378 | E32: 45439 | F32: 45470 | H32: 45531 | I32: 45562 | K32: 45623 | L32: 45653
B33: 45350 | C33: 45379 | E33: 45440 | F33: 45471 | H33: 45532 | J33: 45593 | K33: 45624
B34: 45351 | C34: 45380 | E34: 45441 | G34: 45502 | H34: 45533 | J34: 45594 | K34: 45625
E35: 45442 | G35: 45503 | H35: 45534 | I35: 45565 | J35: 45595
E36: 45443 | F36: 45474 | G36: 45504 | I36: 45566 | J36: 45596
C37: 45383 | D37: 45414 | F37: 45475 | G37: 45505 | I37: 45567 | J37: 45597 | K37: 45628
B38: 45355 | C38: 45384 | D38: 45415 | F38: 45476 | G38: 45506 | I38: 45568 | K38: 45629 | L38: 45659
B39: 45356 | C39: 45385 | E39: 45446 | F39: 45477 | I39: 45569 | K39: 45630 | L39: 45660 | M39: 45691
B40: 45357 | C40: 45386 | E40: 45447 | F40: 45478 | J40: 45600 | K40: 45631 | M40: 45692
B41: 45358 | C41: 45387 | D41: 45418 | E41: 45448 | G41: 45509 | J41: 45601 | K41: 45632 | M41: 45693
...

Sheet Dự kiến tuyển dụng
A2: FY2025 | B2: 4 | C2: 5 | D2: 6 | E2: 7 | F2: 8 | G2: 9 | H2: 10 | I2: 11 | J2: 12 | K2: 1 | L2: 2 | M2: 3 | N2: 合
A3: G5 以上 | B3: 7 | C3: 10 | D3: 9 | E3: 2 | F3: 12 | G3: 9 | H3: 5 | I3: 1 | J3: 2 | K3: 0 | L3: 0 | M3: 1 | N3: =SUM(B3:M3) -> 58
A4: G6, G7 | B4: 149 | C4: 0 | D4: 251 | E4: 89 | F4: 400 | G4: 194 | H4: 94 | I4: 14 | J4: 250 | K4: 229 | L4: 45 | M4: 46 | N4: =SUM(B4:M4) -> 1761
A5: 合 | B5: =SUM(B3:B4) -> 156 | C5: =SUM(C3:C4) -> 10 | D5: =SUM(D3:D4) -> 260 | E5: =SUM(E3:E4) -> 91 | F5: =SUM(F3:F4) -> 412 | G5: =SUM(G3:G4) -> 203 | H5: =SUM(H3:H4) -> 99 | I5: =SUM(I3:I4) -> 15 | ... M5: =SUM(M3:M4) -> 47 | N5: =SUM(B5:M5) -> 1819

Sheet Số ngày xe bus
B1: 4 | C1: 5 | D1: 6 | E1: 7 | F1: 8 | G1: 9 | H1: 10 | I1: 11 | J1: 12 | K1: 1 | L1: 2 | M1: 3
B2: =COUNTA(B3:B33) -> 21 | C2: =COUNTA(C3:C33) -> 21 | D2: =COUNTA(D3:D33) -> 17 | E2: =COUNTA(E3:E33) -> 22 | F2: =COUNTA(F3:F33) -> 21 | G2: =COUNTA(G3:G33) -> 23 | H2: =COUNTA(H3:H33) -> 18 | I2: =COUNTA(I3:I33) -> 22 | ... M2: =COUNTA(M3:M33) -> 17
B3: 45338 | D3: 45398 | E3: 45428 | G3: 45489 | H3: 45520 | I3: 45551 | J3: 45581 | L3: 45642 | M3: 45673
B4: 45339 | D4: 45399 | E4: 45429 | F4: 45460 | G4: 45490 | I4: 45552 | J4: 45582 | L4: 45643 | M4: 45674
C5: 45369 | F5: 45461 | G5: 45491 | I5: 45553 | J5: 45583 | K5: 45614 | L5: 45644
B6: 45341 | C6: 45370 | D6: 45401 | F6: 45462 | G6: 45492 | H6: 45523 | I6: 45554 | K6: 45615 | L6: 45645
B7: 45342 | C7: 45371 | E7: 45432 | F7: 45463 | H7: 45524 | I7: 45555 | K7: 45616 | L7: 45646 | M7: 45677
B8: 45343 | C8: 45372 | E8: 45433 | F8: 45464 | H8: 45525 | J8: 45586 | K8: 45617 | M8: 45678
B9: 45344 | C9: 45373 | D9: 45404 | E9: 45434 | G9: 45495 | H9: 45526 | J9: 45587 | K9: 45618 | M9: 45679
B10: 45345 | D10: 45405 | E10: 45435 | G10: 45496 | H10: 45527 | I10: 45558 | J10: 45588 | L10: 45649 | M10: 45680
D11: 45406 | E11: 45436 | F11: 45467 | G11: 45497 | I11: 45559 | J11: 45589 | L11: 45650 | M11: 45681
C12: 45376 | D12: 45407 | F12: 45468 | G12: 45498 | I12: 45560 | J12: 45590 | K12: 45621 | L12: 45651
B13: 45348 | C13: 45377 | D13: 45408 | F13: 45469 | G13: 45499 | H13: 45530 | I13: 45561 | K13: 45622 | L13: 45652
B14: 45349 | C14: 45378 | E14: 45439 | F14: 45470 | H14: 45531 | I14: 45562 | K14: 45623 | L14: 45653
B15: 45350 | C15: 45379 | E15: 45440 | F15: 45471 | H15: 45532 | J15: 45593 | K15: 45624
B16: 45351 | C16: 45380 | E16: 45441 | G16: 45502 | H16: 45533 | J16: 45594 | K16: 45625
E17: 45442 | G17: 45503 | H17: 45534 | I17: 45565 | J17: 45595
E18: 45443 | F18: 45474 | G18: 45504 | I18: 45566 | J18: 45596
C19: 45383 | D19: 45414 | F19: 45475 | G19: 45505 | I19: 45567 | J19: 45597 | K19: 45628
B20: 45355 | C20: 45384 | D20: 45415 | F20: 45476 | G20: 45506 | I20: 45568 | K20: 45629 | L20: 45659
B21: 45356 | C21: 45385 | E21: 45446 | F21: 45477 | I21: 45569 | K21: 45630 | L21: 45660 | M21: 45691
B22: 45357 | C22: 45386 | E22: 45447 | F22: 45478 | J22: 45600 | K22: 45631 | M22: 45692
B23: 45358 | C23: 45387 | D23: 45418 | E23: 45448 | G23: 45509 | J23: 45601 | K23: 45632 | M23: 45693
B24: 45359 | D24: 45419 | E24: 45449 | G24: 45510 | H24: 45541 | I24: 45572 | J24: 45602 | L24: 45663 | M24: 45694
D25: 45420 | E25: 45450 | F25: 45481 | G25: 45511 | H25: 45542 | I25: 45573 | J25: 45603 | L25: 45664 | M25: 45695
C26: 45390 | D26: 45421 | F26: 45482 | G26: 45512 | I26: 45574 | J26: 45604 | K26: 45635 | L26: 45665
B27: 45362 | C27: 45391 | F27: 45483 | G27: 45513 | H27: 45544 | I27: 45575 | K27: 45636 | L27: 45666
B28: 45363 | C28: 45392 | E28: 45453 | F28: 45484 | H28: 45545 | I28: 45576 | K28: 45637 | L28: 45667 | M28: 45698
B29: 45364 | C29: 45393 | E29: 45454 | F29: 45485 | H29: 45546 | J29: 45607 | K29: 45638 | M29: 45699
B30: 45365 | C30: 45394 | D30: 45425 | E30: 45455 | G30: 45516 | H30: 45547 | J30: 45608 | K30: 45639 | M30: 45700
B31: 45366 | D31: 45426 | E31: 45456 | G31: 45517 | H31: 45548 | I31: 45579 | J31: 45609 | L31: 45670 | M31: 45701
D32: 45427 | E32: 45457 | F32: 45488 | G32: 45518 | I32: 45580 | J32: 45610 | L32: 45671 | M32: 45702
C33: 45397 | G33: 45519 | J33: 45611 | L33: 45672
