Workbook
Name WBS: 原価センタ!$G$2:$G$3

Sheet 採算表(USD)
B1: 組織名 | C1: ='採算表(VND)'!C1 -> MP FY2026_各予定 | N1: ='内訳ﾘｽﾄ(4～3月)'!B2 -> 25390
B2: ='採算表(VND)'!B2 -> 工程品質管理1課
B4: 項目 ＼ 部門 | C4: ='採算表(VND)'!C4 -> 4 | D4: ='採算表(VND)'!D4 -> 5 | E4: ='採算表(VND)'!E4 -> 6 | F4: ='採算表(VND)'!F4 -> 7 | G4: ='採算表(VND)'!G4 -> 8 | H4: ='採算表(VND)'!H4 -> 9 | I4: ='採算表(VND)'!I4 -> 10 | J4: ='採算表(VND)'!J4 -> 11 | ... O4: ='採算表(VND)'!O4 -> 合計
B5: 総出荷 | C5: =C8+C9 -> 0 | D5: =D8+D9 -> 0 | E5: =E8+E9 -> 0 | F5: =F8+F9 -> 0 | G5: =G8+G9 -> 0 | H5: =H8+H9 -> 0 | I5: =I8+I9 -> 0 | J5: =J8+J9 -> 0 | ... O5: =O8+O9 -> 0
B6: 社外出荷 | C6: =ROUNDDOWN('採算表(VND)'!C6/$N$1,2) -> 0 | D6: =ROUNDDOWN('採算表(VND)'!D6/$N$1,2) -> 0 | E6: =ROUNDDOWN('採算表(VND)'!E6/$N$1,2) -> 0 | F6: =ROUNDDOWN('採算表(VND)'!F6/$N$1,2) -> 0 | G6: =ROUNDDOWN('採算表(VND)'!G6/$N$1,2) -> 0 | H6: =ROUNDDOWN('採算表(VND)'!H6/$N$1,2) -> 0 | I6: =ROUNDDOWN('採算表(VND)'!I6/$N$1,2) -> 0 | J6: =ROUNDDOWN('採算表(VND)'!J6/$N$1,2) -> 0 | ... N6: =ROUNDDOWN('採算表(VND)'!N6/$N$1,2) -> 0 | O6: =SUM(C6:N6) -> 0
B7: 販売支援 | C7: =ROUNDDOWN('採算表(VND)'!C7/$N$1,2) -> 0 | D7: =ROUNDDOWN('採算表(VND)'!D7/$N$1,2) -> 0 | E7: =ROUNDDOWN('採算表(VND)'!E7/$N$1,2) -> 0 | F7: =ROUNDDOWN('採算表(VND)'!F7/$N$1,2) -> 0 | G7: =ROUNDDOWN('採算表(VND)'!G7/$N$1,2) -> 0 | H7: =ROUNDDOWN('採算表(VND)'!H7/$N$1,2) -> 0 | I7: =ROUNDDOWN('採算表(VND)'!I7/$N$1,2) -> 0 | J7: =ROUNDDOWN('採算表(VND)'!J7/$N$1,2) -> 0 | ... N7: =ROUNDDOWN('採算表(VND)'!N7/$N$1,2) -> 0 | O7: =SUM(C7:N7) -> 0
B8: 社外出荷合計 | C8: =C6+C7 -> 0 | D8: =D6+D7 -> 0 | E8: =E6+E7 -> 0 | F8: =F6+F7 -> 0 | G8: =G6+G7 -> 0 | H8: =H6+H7 -> 0 | I8: =I6+I7 -> 0 | J8: =J6+J7 -> 0 | ... O8: =O6+O7 -> 0
B9: 社内売 | C9: =ROUNDDOWN('採算表(VND)'!C9/$N$1,2) -> 0 | D9: =ROUNDDOWN('採算表(VND)'!D9/$N$1,2) -> 0 | E9: =ROUNDDOWN('採算表(VND)'!E9/$N$1,2) -> 0 | F9: =ROUNDDOWN('採算表(VND)'!F9/$N$1,2) -> 0 | G9: =ROUNDDOWN('採算表(VND)'!G9/$N$1,2) -> 0 | H9: =ROUNDDOWN('採算表(VND)'!H9/$N$1,2) -> 0 | I9: =ROUNDDOWN('採算表(VND)'!I9/$N$1,2) -> 0 | J9: =ROUNDDOWN('採算表(VND)'!J9/$N$1,2) -> 0 | ... N9: =ROUNDDOWN('採算表(VND)'!N9/$N$1,2) -> 0 | O9: =SUM(C9:N9) -> 0
B10: 社内買 | C10: =ROUNDDOWN('採算表(VND)'!C10/$N$1,2) -> 0 | D10: =ROUNDDOWN('採算表(VND)'!D10/$N$1,2) -> 0 | E10: =ROUNDDOWN('採算表(VND)'!E10/$N$1,2) -> 0 | F10: =ROUNDDOWN('採算表(VND)'!F10/$N$1,2) -> 0 | G10: =ROUNDDOWN('採算表(VND)'!G10/$N$1,2) -> 0 | H10: =ROUNDDOWN('採算表(VND)'!H10/$N$1,2) -> 0 | I10: =ROUNDDOWN('採算表(VND)'!I10/$N$1,2) -> 0 | J10: =ROUNDDOWN('採算表(VND)'!J10/$N$1,2) -> 0 | ... N10: =ROUNDDOWN('採算表(VND)'!N10/$N$1,2) -> 0 | O10: =SUM(C10:N10) -> 0
B12: 総生産 | C12: =C5-C10 -> 0 | D12: =D5-D10 -> 0 | E12: =E5-E10 -> 0 | F12: =F5-F10 -> 0 | G12: =G5-G10 -> 0 | H12: =H5-H10 -> 0 | I12: =I5-I10 -> 0 | J12: =J5-J10 -> 0 | ... O12: =O5-O10 -> 0
B13: 控除額 | C13: =SUM(C14:C65) -> 0.03 | D13: =SUM(D14:D65) -> 0.07 | E13: =SUM(E14:E65) -> 0.05 | F13: =SUM(F14:F65) -> 0.04 | G13: =SUM(G14:G65) -> 0.03 | H13: =SUM(H14:H65) -> 0.03 | I13: =SUM(I14:I65) -> 0.03 | J13: =SUM(J14:J65) -> 0.03 | ... O13: =SUM(O14:O65) -> 0.41
B14: 材料費 | C14: =ROUNDUP('採算表(VND)'!C14/$N$1,2) -> 0 | D14: =ROUNDUP('採算表(VND)'!D14/$N$1,2) -> 0 | E14: =ROUNDUP('採算表(VND)'!E14/$N$1,2) -> 0 | F14: =ROUNDUP('採算表(VND)'!F14/$N$1,2) -> 0 | G14: =ROUNDUP('採算表(VND)'!G14/$N$1,2) -> 0 | H14: =ROUNDUP('採算表(VND)'!H14/$N$1,2) -> 0 | I14: =ROUNDUP('採算表(VND)'!I14/$N$1,2) -> 0 | J14: =ROUNDUP('採算表(VND)'!J14/$N$1,2) -> 0 | ... N14: =ROUNDUP('採算表(VND)'!N14/$N$1,2) -> 0 | O14: =SUM(C14:N14) -> 0
B15: 設計変更材料費 | C15: =ROUNDUP('採算表(VND)'!C15/$N$1,2) -> 0 | D15: =ROUNDUP('採算表(VND)'!D15/$N$1,2) -> 0 | E15: =ROUNDUP('採算表(VND)'!E15/$N$1,2) -> 0 | F15: =ROUNDUP('採算表(VND)'!F15/$N$1,2) -> 0 | G15: =ROUNDUP('採算表(VND)'!G15/$N$1,2) -> 0 | H15: =ROUNDUP('採算表(VND)'!H15/$N$1,2) -> 0 | I15: =ROUNDUP('採算表(VND)'!I15/$N$1,2) -> 0 | J15: =ROUNDUP('採算表(VND)'!J15/$N$1,2) -> 0 | ... N15: =ROUNDUP('採算表(VND)'!N15/$N$1,2) -> 0 | O15: =SUM(C15:N15) -> 0
B16: 仕掛仕損 | C16: =ROUNDUP('採算表(VND)'!C16/$N$1,2) -> 0 | D16: =ROUNDUP('採算表(VND)'!D16/$N$1,2) -> 0 | E16: =ROUNDUP('採算表(VND)'!E16/$N$1,2) -> 0 | F16: =ROUNDUP('採算表(VND)'!F16/$N$1,2) -> 0 | G16: =ROUNDUP('採算表(VND)'!G16/$N$1,2) -> 0 | H16: =ROUNDUP('採算表(VND)'!H16/$N$1,2) -> 0 | I16: =ROUNDUP('採算表(VND)'!I16/$N$1,2) -> 0 | J16: =ROUNDUP('採算表(VND)'!J16/$N$1,2) -> 0 | ... N16: =ROUNDUP('採算表(VND)'!N16/$N$1,2) -> 0 | O16: =SUM(C16:N16) -> 0
B17: 仕入製商品費 | C17: =ROUNDUP('採算表(VND)'!C17/$N$1,2) -> 0 | D17: =ROUNDUP('採算表(VND)'!D17/$N$1,2) -> 0 | E17: =ROUNDUP('採算表(VND)'!E17/$N$1,2) -> 0 | F17: =ROUNDUP('採算表(VND)'!F17/$N$1,2) -> 0 | G17: =ROUNDUP('採算表(VND)'!G17/$N$1,2) -> 0 | H17: =ROUNDUP('採算表(VND)'!H17/$N$1,2) -> 0 | I17: =ROUNDUP('採算表(VND)'!I17/$N$1,2) -> 0 | J17: =ROUNDUP('採算表(VND)'!J17/$N$1,2) -> 0 | ... N17: =ROUNDUP('採算表(VND)'!N17/$N$1,2) -> 0 | O17: =SUM(C17:N17) -> 0
B18: 内製品有償支給原価 | C18: =ROUNDUP('採算表(VND)'!C18/$N$1,2) -> 0 | D18: =ROUNDUP('採算表(VND)'!D18/$N$1,2) -> 0 | E18: =ROUNDUP('採算表(VND)'!E18/$N$1,2) -> 0 | F18: =ROUNDUP('採算表(VND)'!F18/$N$1,2) -> 0 | G18: =ROUNDUP('採算表(VND)'!G18/$N$1,2) -> 0 | H18: =ROUNDUP('採算表(VND)'!H18/$N$1,2) -> 0 | I18: =ROUNDUP('採算表(VND)'!I18/$N$1,2) -> 0 | J18: =ROUNDUP('採算表(VND)'!J18/$N$1,2) -> 0 | ... N18: =ROUNDUP('採算表(VND)'!N18/$N$1,2) -> 0 | O18: =SUM(C18:N18) -> 0
B19: 外注加工費 | C19: =ROUNDUP('採算表(VND)'!C19/$N$1,2) -> 0 | D19: =ROUNDUP('採算表(VND)'!D19/$N$1,2) -> 0 | E19: =ROUNDUP('採算表(VND)'!E19/$N$1,2) -> 0 | F19: =ROUNDUP('採算表(VND)'!F19/$N$1,2) -> 0 | G19: =ROUNDUP('採算表(VND)'!G19/$N$1,2) -> 0 | H19: =ROUNDUP('採算表(VND)'!H19/$N$1,2) -> 0 | I19: =ROUNDUP('採算表(VND)'!I19/$N$1,2) -> 0 | J19: =ROUNDUP('採算表(VND)'!J19/$N$1,2) -> 0 | ... N19: =ROUNDUP('採算表(VND)'!N19/$N$1,2) -> 0 | O19: =SUM(C19:N19) -> 0
B20: 減価償却費 | C20: =ROUNDUP('採算表(VND)'!C20/$N$1,2) -> 2547.39 | D20: =ROUNDUP('採算表(VND)'!D20/$N$1,2) -> 2539.82 | E20: =ROUNDUP('採算表(VND)'!E20/$N$1,2) -> 2548.96 | F20: =ROUNDUP('採算表(VND)'!F20/$N$1,2) -> 2480.9 | G20: =ROUNDUP('採算表(VND)'!G20/$N$1,2) -> 1225.22 | H20: =ROUNDUP('採算表(VND)'!H20/$N$1,2) -> 1195.8 | I20: =ROUNDUP('採算表(VND)'!I20/$N$1,2) -> 1181.98 | J20: =ROUNDUP('採算表(VND)'!J20/$N$1,2) -> 1179.52 | ... N20: =ROUNDUP('採算表(VND)'!N20/$N$1,2) -> 1200.06 | O20: =SUM(C20:N20) -> 19637.07
B21: 金型償却費 | C21: =ROUNDUP('採算表(VND)'!C21/$N$1,2) -> 0 | D21: =ROUNDUP('採算表(VND)'!D21/$N$1,2) -> 0 | E21: =ROUNDUP('採算表(VND)'!E21/$N$1,2) -> 0 | F21: =ROUNDUP('採算表(VND)'!F21/$N$1,2) -> 0 | G21: =ROUNDUP('採算表(VND)'!G21/$N$1,2) -> 0 | H21: =ROUNDUP('採算表(VND)'!H21/$N$1,2) -> 0 | I21: =ROUNDUP('採算表(VND)'!I21/$N$1,2) -> 0 | J21: =ROUNDUP('採算表(VND)'!J21/$N$1,2) -> 0 | ... N21: =ROUNDUP('採算表(VND)'!N21/$N$1,2) -> 0 | O21: =SUM(C21:N21) -> 0
B22: 賃借料 | C22: =ROUNDUP('採算表(VND)'!C22/$N$1,2) -> 0 | D22: =ROUNDUP('採算表(VND)'!D22/$N$1,2) -> 0 | E22: =ROUNDUP('採算表(VND)'!E22/$N$1,2) -> 0 | F22: =ROUNDUP('採算表(VND)'!F22/$N$1,2) -> 0 | G22: =ROUNDUP('採算表(VND)'!G22/$N$1,2) -> 0 | H22: =ROUNDUP('採算表(VND)'!H22/$N$1,2) -> 0 | I22: =ROUNDUP('採算表(VND)'!I22/$N$1,2) -> 0 | J22: =ROUNDUP('採算表(VND)'!J22/$N$1,2) -> 0 | ... N22: =ROUNDUP('採算表(VND)'!N22/$N$1,2) -> 0 | O22: =SUM(C22:N22) -> 0
B23: 保険料 | C23: =ROUNDUP('採算表(VND)'!C23/$N$1,2) -> 0 | D23: =ROUNDUP('採算表(VND)'!D23/$N$1,2) -> 0 | E23: =ROUNDUP('採算表(VND)'!E23/$N$1,2) -> 0 | F23: =ROUNDUP('採算表(VND)'!F23/$N$1,2) -> 0 | G23: =ROUNDUP('採算表(VND)'!G23/$N$1,2) -> 0 | H23: =ROUNDUP('採算表(VND)'!H23/$N$1,2) -> 0 | I23: =ROUNDUP('採算表(VND)'!I23/$N$1,2) -> 0 | J23: =ROUNDUP('採算表(VND)'!J23/$N$1,2) -> 0 | ... N23: =ROUNDUP('採算表(VND)'!N23/$N$1,2) -> 0 | O23: =SUM(C23:N23) -> 0
B24: 設計委託費 | C24: =ROUNDUP('採算表(VND)'!C24/$N$1,2) -> 0 | D24: =ROUNDUP('採算表(VND)'!D24/$N$1,2) -> 0 | E24: =ROUNDUP('採算表(VND)'!E24/$N$1,2) -> 0 | F24: =ROUNDUP('採算表(VND)'!F24/$N$1,2) -> 0 | G24: =ROUNDUP('採算表(VND)'!G24/$N$1,2) -> 0 | H24: =ROUNDUP('採算表(VND)'!H24/$N$1,2) -> 0 | I24: =ROUNDUP('採算表(VND)'!I24/$N$1,2) -> 0 | J24: =ROUNDUP('採算表(VND)'!J24/$N$1,2) -> 0 | ... N24: =ROUNDUP('採算表(VND)'!N24/$N$1,2) -> 0 | O24: =SUM(C24:N24) -> 0
B25: 消耗品費 | C25: =ROUNDUP('採算表(VND)'!C25/$N$1,2) -> 531.34 | D25: =ROUNDUP('採算表(VND)'!D25/$N$1,2) -> 507.7 | E25: =ROUNDUP('採算表(VND)'!E25/$N$1,2) -> 562.17 | F25: =ROUNDUP('採算表(VND)'!F25/$N$1,2) -> 616.65 | G25: =ROUNDUP('採算表(VND)'!G25/$N$1,2) -> 39.69 | H25: =ROUNDUP('採算表(VND)'!H25/$N$1,2) -> 38.71 | I25: =ROUNDUP('採算表(VND)'!I25/$N$1,2) -> 50.84 | J25: =ROUNDUP('採算表(VND)'!J25/$N$1,2) -> 42.82 | ... N25: =ROUNDUP('採算表(VND)'!N25/$N$1,2) -> 52.02 | O25: =SUM(C25:N25) -> 2571.66
... B65: 本社機構経費 | C65: =ROUNDUP('採算表(VND)'!C65/$N$1,2) -> 0 | D65: =ROUNDUP('採算表(VND)'!D65/$N$1,2) -> 0 | E65: =ROUNDUP('採算表(VND)'!E65/$N$1,2) -> 0 | F65: =ROUNDUP('採算表(VND)'!F65/$N$1,2) -> 0 | G65: =ROUNDUP('採算表(VND)'!G65/$N$1,2) -> 0 | H65: =ROUNDUP('採算表(VND)'!H65/$N$1,2) -> 0 | I65: =ROUNDUP('採算表(VND)'!I65/$N$1,2) -> 0 | J65: =ROUNDUP('採算表(VND)'!J65/$N$1,2) -> 0 | ... N65: =ROUNDUP('採算表(VND)'!N65/$N$1,2) -> 0 | O65: =SUM(C65:N65) -> 0
B66: 差引収益 | C66: =C12-C13 -> -0.03 | D66: =IF(ISBLANK(D4),"",D12-D13) -> -0.07 | E66: =IF(ISBLANK(E4),"",E12-E13) -> -0.05 | F66: =IF(ISBLANK(F4),"",F12-F13) -> -0.04 | G66: =IF(ISBLANK(G4),"",G12-G13) -> -0.03 | H66: =IF(ISBLANK(H4),"",H12-H13) -> -0.03 | I66: =IF(ISBLANK(I4),"",I12-I13) -> -0.03 | J66: =IF(ISBLANK(J4),"",J12-J13) -> -0.03 | K66: =IF(ISBLANK(K4),"",K12-K13) -> -0.03 | ... O66: =IF(ISBLANK(O4),"",O12-O13) -> -0.41
B67: 総時間 | C67: =C73+C79 -> 0 | D67: =IF(ISBLANK(D4),"",D73+D79) -> 0 | E67: =IF(ISBLANK(E4),"",E73+E79) -> 0 | F67: =IF(ISBLANK(F4),"",F73+F79) -> 0 | G67: =IF(ISBLANK(G4),"",G73+G79) -> 0 | H67: =IF(ISBLANK(H4),"",H73+H79) -> 0 | I67: =IF(ISBLANK(I4),"",I73+I79) -> 0 | J67: =IF(ISBLANK(J4),"",J73+J79) -> 0 | K67: =IF(ISBLANK(K4),"",K73+K79) -> 0 | ... O67: =IF(ISBLANK(O4),"",O73+O79) -> 0
B68: 直接部門 | C68: ='採算表(VND)'!C68 -> 31644 | D68: ='採算表(VND)'!D68 -> 30078 | E68: ='採算表(VND)'!E68 -> 33244 | F68: ='採算表(VND)'!F68 -> 5169 | G68: ='採算表(VND)'!G68 -> 4452.5 | H68: ='採算表(VND)'!H68 -> 4253 | I68: ='採算表(VND)'!I68 -> 5904 | J68: ='採算表(VND)'!J68 -> 5134 | ... N68: ='採算表(VND)'!N68 -> 5773 | O68: =SUM(C68:N68) -> 140871.5
B69: 部内間接部門 | C69: ='採算表(VND)'!C69 -> -31644 | D69: ='採算表(VND)'!D69 -> -30078 | E69: ='採算表(VND)'!E69 -> -33244 | F69: ='採算表(VND)'!F69 -> -5169 | G69: ='採算表(VND)'!G69 -> -4452.5 | H69: ='採算表(VND)'!H69 -> -4253 | I69: ='採算表(VND)'!I69 -> -5904 | J69: ='採算表(VND)'!J69 -> -5134 | ... N69: ='採算表(VND)'!N69 -> -5773 | O69: =SUM(C69:N69) -> -140871.5
B70: 部外間接部門1 | C70: ='採算表(VND)'!C70 -> 0 | D70: ='採算表(VND)'!D70 -> 0 | E70: ='採算表(VND)'!E70 -> 0 | F70: ='採算表(VND)'!F70 -> 0 | G70: ='採算表(VND)'!G70 -> 0 | H70: ='採算表(VND)'!H70 -> 0 | I70: ='採算表(VND)'!I70 -> 0 | J70: ='採算表(VND)'!J70 -> 0 | ... N70: ='採算表(VND)'!N70 -> 0 | O70: =SUM(C70:N70) -> 0
B71: 部外間接部門2 | C71: ='採算表(VND)'!C71 -> 0 | D71: ='採算表(VND)'!D71 -> 0 | E71: ='採算表(VND)'!E71 -> 0 | F71: ='採算表(VND)'!F71 -> 0 | G71: ='採算表(VND)'!G71 -> 0 | H71: ='採算表(VND)'!H71 -> 0 | I71: ='採算表(VND)'!I71 -> 0 | J71: ='採算表(VND)'!J71 -> 0 | ... N71: ='採算表(VND)'!N71 -> 0 | O71: =SUM(C71:N71) -> 0
B72: 工場間接部門 | C72: ='採算表(VND)'!C72 -> 0 | D72: ='採算表(VND)'!D72 -> 0 | E72: ='採算表(VND)'!E72 -> 0 | F72: ='採算表(VND)'!F72 -> 0 | G72: ='採算表(VND)'!G72 -> 0 | H72: ='採算表(VND)'!H72 -> 0 | I72: ='採算表(VND)'!I72 -> 0 | J72: ='採算表(VND)'!J72 -> 0 | ... N72: ='採算表(VND)'!N72 -> 0 | O72: =SUM(C72:N72) -> 0
B73: 定時間合計 | C73: =SUM(C68:C72) -> 0 | D73: =IF(ISBLANK(D4),"",SUM(D68:D72)) -> 0 | E73: =IF(ISBLANK(E4),"",SUM(E68:E72)) -> 0 | F73: =IF(ISBLANK(F4),"",SUM(F68:F72)) -> 0 | G73: =IF(ISBLANK(G4),"",SUM(G68:G72)) -> 0 | H73: =IF(ISBLANK(H4),"",SUM(H68:H72)) -> 0 | I73: =IF(ISBLANK(I4),"",SUM(I68:I72)) -> 0 | J73: =IF(ISBLANK(J4),"",SUM(J68:J72)) -> 0 | K73: =IF(ISBLANK(K4),"",SUM(K68:K72)) -> 0 | ... O73: =IF(ISBLANK(O4),"",SUM(O68:O72)) -> 0
B74: 直接部門 | C74: ='採算表(VND)'!C74 -> 5021 | D74: ='採算表(VND)'!D74 -> 5015 | E74: ='採算表(VND)'!E74 -> 5035 | F74: ='採算表(VND)'!F74 -> 763 | G74: ='採算表(VND)'!G74 -> 735 | H74: ='採算表(VND)'!H74 -> 735 | I74: ='採算表(VND)'!I74 -> 863 | J74: ='採算表(VND)'!J74 -> 845 | ... N74: ='採算表(VND)'!N74 -> 945 | O74: =SUM(C74:N74) -> 22587
B75: 部内間接部門 | C75: ='採算表(VND)'!C75 -> -5021 | D75: ='採算表(VND)'!D75 -> -5015 | E75: ='採算表(VND)'!E75 -> -5035 | F75: ='採算表(VND)'!F75 -> -763 | G75: ='採算表(VND)'!G75 -> -735 | H75: ='採算表(VND)'!H75 -> -735 | I75: ='採算表(VND)'!I75 -> -863 | J75: ='採算表(VND)'!J75 -> -845 | ... N75: ='採算表(VND)'!N75 -> -945 | O75: =SUM(C75:N75) -> -22587
B76: 部外間接部門1 | C76: ='採算表(VND)'!C76 -> 0 | D76: ='採算表(VND)'!D76 -> 0 | E76: ='採算表(VND)'!E76 -> 0 | F76: ='採算表(VND)'!F76 -> 0 | G76: ='採算表(VND)'!G76 -> 0 | H76: ='採算表(VND)'!H76 -> 0 | I76: ='採算表(VND)'!I76 -> 0 | J76: ='採算表(VND)'!J76 -> 0 | ... N76: ='採算表(VND)'!N76 -> 0 | O76: =SUM(C76:N76) -> 0
B77: 部外間接部門2 | C77: ='採算表(VND)'!C77 -> 0 | D77: ='採算表(VND)'!D77 -> 0 | E77: ='採算表(VND)'!E77 -> 0 | F77: ='採算表(VND)'!F77 -> 0 | G77: ='採算表(VND)'!G77 -> 0 | H77: ='採算表(VND)'!H77 -> 0 | I77: ='採算表(VND)'!I77 -> 0 | J77: ='採算表(VND)'!J77 -> 0 | ... N77: ='採算表(VND)'!N77 -> 0 | O77: =SUM(C77:N77) -> 0
B78: 工場間接部門 | C78: ='採算表(VND)'!C78 -> 0 | D78: ='採算表(VND)'!D78 -> 0 | E78: ='採算表(VND)'!E78 -> 0 | F78: ='採算表(VND)'!F78 -> 0 | G78: ='採算表(VND)'!G78 -> 0 | H78: ='採算表(VND)'!H78 -> 0 | I78: ='採算表(VND)'!I78 -> 0 | J78: ='採算表(VND)'!J78 -> 0 | ... N78: ='採算表(VND)'!N78 -> 0 | O78: =SUM(C78:N78) -> 0
B79: 残業時間合計 | C79: =SUM(C74:C78) -> 0 | D79: =IF(ISBLANK(D4),"",SUM(D74:D78)) -> 0 | E79: =IF(ISBLANK(E4),"",SUM(E74:E78)) -> 0 | F79: =IF(ISBLANK(F4),"",SUM(F74:F78)) -> 0 | G79: =IF(ISBLANK(G4),"",SUM(G74:G78)) -> 0 | H79: =IF(ISBLANK(H4),"",SUM(H74:H78)) -> 0 | I79: =IF(ISBLANK(I4),"",SUM(I74:I78)) -> 0 | J79: =IF(ISBLANK(J4),"",SUM(J74:J78)) -> 0 | K79: =IF(ISBLANK(K4),"",SUM(K74:K78)) -> 0 | ... O79: =IF(ISBLANK(O4),"",SUM(O74:O78)) -> 0
B80: 当月時間当り | C80: =IFERROR(ROUNDDOWN(C66/C67,0),0) -> 0 | D80: =IFERROR(ROUNDDOWN(D66/D67,0),0) -> 0 | E80: =IFERROR(ROUNDDOWN(E66/E67,0),0) -> 0 | F80: =IFERROR(ROUNDDOWN(F66/F67,0),0) -> 0 | G80: =IFERROR(ROUNDDOWN(G66/G67,0),0) -> 0 | H80: =IFERROR(ROUNDDOWN(H66/H67,0),0) -> 0 | I80: =IFERROR(ROUNDDOWN(I66/I67,0),0) -> 0 | J80: =IFERROR(ROUNDDOWN(J66/J67,0),0) -> 0 | ... O80: =IFERROR(ROUNDDOWN(O66/O67,0),0) -> 0
B81: 時間当り生産高 | C81: =IFERROR(ROUNDDOWN(C12/C67,0),0) -> 0 | D81: =IFERROR(ROUNDDOWN(D12/D67,0),0) -> 0 | E81: =IFERROR(ROUNDDOWN(E12/E67,0),0) -> 0 | F81: =IFERROR(ROUNDDOWN(F12/F67,0),0) -> 0 | G81: =IFERROR(ROUNDDOWN(G12/G67,0),0) -> 0 | H81: =IFERROR(ROUNDDOWN(H12/H67,0),0) -> 0 | I81: =IFERROR(ROUNDDOWN(I12/I67,0),0) -> 0 | J81: =IFERROR(ROUNDDOWN(J12/J67,0),0) -> 0 | ... O81: =IFERROR(ROUNDDOWN(O12/O67,0),0) -> 0
...

Sheet 採算表(VND)
B1: 組織名 | C1: ='内訳ﾘｽﾄ(4～3月)'!A1 -> MP FY2026_各予定
B2: ='内訳ﾘｽﾄ(4～3月)'!C5 -> 工程品質管理1課
C3: 2 | D3: 3 | E3: 4 | F3: 5 | G3: 6 | H3: 7 | I3: 8 | J3: 9 | K3: 10 | L3: 11 | M3: 12 | N3: 13
B4: 項目 ＼ 部門 | C4: ='内訳ﾘｽﾄ(4～3月)'!F4 -> 4 | D4: 5 | E4: 6 | F4: 7 | G4: 8 | H4: 9 | I4: 10 | J4: 11 | K4: 12 | L4: 1 | M4: 2 | N4: 3 | O4: 合計
B5: 総出荷 | C5: =C8+C9 -> 0 | D5: =D8+D9 -> 0 | E5: =E8+E9 -> 0 | F5: =F8+F9 -> 0 | G5: =G8+G9 -> 0 | H5: =H8+H9 -> 0 | I5: =I8+I9 -> 0 | J5: =J8+J9 -> 0 | ... O5: =O8+O9 -> 0
B6: 社外出荷 | C6: =SUMIF('内訳ﾘｽﾄ(4～3月)'!$D$26:$D$1004,'採算表(VND)'!$B6,'内訳ﾘｽﾄ(4～3月)'!F$26:F$1004) -> 0 | D6: =SUMIF('内訳ﾘｽﾄ(4～3月)'!$D$26:$D$1004,'採算表(VND)'!$B6,'内訳ﾘｽﾄ(4～3月)'!G$26:G$1004) -> 0 | E6: =SUMIF('内訳ﾘｽﾄ(4～3月)'!$D$26:$D$1004,'採算表(VND)'!$B6,'内訳ﾘｽﾄ(4～3月)'!H$26:H$1004) -> 0 | F6: =SUMIF('内訳ﾘｽﾄ(4～3月)'!$D$26:$D$1004,'採算表(VND)'!$B6,'内訳ﾘｽﾄ(4～3月)'!I$26:I$1004) -> 0 | G6: =SUMIF('内訳ﾘｽﾄ(4～3月)'!$D$26:$D$1004,'採算表(VND)'!$B6,'内訳ﾘｽﾄ(4～3月)'!J$26:J$1004) -> 0 | H6: =SUMIF('内訳ﾘｽﾄ(4～3月)'!$D$26:$D$1004,'採算表(VND)'!$B6,'内訳ﾘｽﾄ(4～3月)'!K$26:K$1004) -> 0 | I6: =SUMIF('内訳ﾘｽﾄ(4～3月)'!$D$26:$D$1004,'採算表(VND)'!$B6,'内訳ﾘｽﾄ(4～3月)'!L$26:L$1004) -> 0 | J6: =SUMIF('内訳ﾘｽﾄ(4～3月)'!$D$26:$D$1004,'採算表(VND)'!$B6,'内訳ﾘｽﾄ(4～3月)'!M$26:M$1004) -> 0 | ... N6: =SUMIF('内訳ﾘｽﾄ(4～3月)'!$D$26:$D$1004,'採算表(VND)'!$B6,'内訳ﾘｽﾄ(4～3月)'!Q$26:Q$1004) -> 0 | O6: =SUMIF('内訳ﾘｽﾄ(4～3月)'!$D$26:$D$803,'採算表(VND)'!$B6,'内訳ﾘｽﾄ(4～3月)'!R$26:R$803) -> 0
B7: 販売支援 | C7: =SUMIF('内訳ﾘｽﾄ(4～3月)'!$D$26:$D$1004,'採算表(VND)'!$B7,'内訳ﾘｽﾄ(4～3月)'!F$26:F$1004) -> 0 | D7: =SUMIF('内訳ﾘｽﾄ(4～3月)'!$D$26:$D$1004,'採算表(VND)'!$B7,'内訳ﾘｽﾄ(4～3月)'!G$26:G$1004) -> 0 | E7: =SUMIF('内訳ﾘｽﾄ(4～3月)'!$D$26:$D$1004,'採算表(VND)'!$B7,'内訳ﾘｽﾄ(4～3月)'!H$26:H$1004) -> 0 | F7: =SUMIF('内訳ﾘｽﾄ(4～3月)'!$D$26:$D$1004,'採算表(VND)'!$B7,'内訳ﾘｽﾄ(4～3月)'!I$26:I$1004) -> 0 | G7: =SUMIF('内訳ﾘｽﾄ(4～3月)'!$D$26:$D$1004,'採算表(VND)'!$B7,'内訳ﾘｽﾄ(4～3月)'!J$26:J$1004) -> 0 | H7: =SUMIF('内訳ﾘｽﾄ(4～3月)'!$D$26:$D$1004,'採算表(VND)'!$B7,'内訳ﾘｽﾄ(4～3月)'!K$26:K$1004) -> 0 | I7: =SUMIF('内訳ﾘｽﾄ(4～3月)'!$D$26:$D$1004,'採算表(VND)'!$B7,'内訳ﾘｽﾄ(4～3月)'!L$26:L$1004) -> 0 | J7: =SUMIF('内訳ﾘｽﾄ(4～3月)'!$D$26:$D$1004,'採算表(VND)'!$B7,'内訳ﾘｽﾄ(4～3月)'!M$26:M$1004) -> 0 | ... N7: =SUMIF('内訳ﾘｽﾄ(4～3月)'!$D$26:$D$1004,'採算表(VND)'!$B7,'内訳ﾘｽﾄ(4～3月)'!Q$26:Q$1004) -> 0 | O7: =SUMIF('内訳ﾘｽﾄ(4～3月)'!$D$26:$D$803,'採算表(VND)'!$B7,'内訳ﾘｽﾄ(4～3月)'!R$26:R$803) -> 0
B8: 社外出荷合計 | C8: =C6+C7 -> 0 | D8: =D6+D7 -> 0 | E8: =E6+E7 -> 0 | F8: =F6+F7 -> 0 | G8: =G6+G7 -> 0 | H8: =H6+H7 -> 0 | I8: =I6+I7 -> 0 | J8: =J6+J7 -> 0 | ... O8: =O6+O7 -> 0
B9: 社内売 | C9: =SUMIF('内訳ﾘｽﾄ(4～3月)'!$D$26:$D$1004,'採算表(VND)'!$B9,'内訳ﾘｽﾄ(4～3月)'!F$26:F$1004) -> 0 | D9: =SUMIF('内訳ﾘｽﾄ(4～3月)'!$D$26:$D$1004,'採算表(VND)'!$B9,'内訳ﾘｽﾄ(4～3月)'!G$26:G$1004) -> 0 | E9: =SUMIF('内訳ﾘｽﾄ(4～3月)'!$D$26:$D$1004,'採算表(VND)'!$B9,'内訳ﾘｽﾄ(4～3月)'!H$26:H$1004) -> 0 | F9: =SUMIF('内訳ﾘｽﾄ(4～3月)'!$D$26:$D$1004,'採算表(VND)'!$B9,'内訳ﾘｽﾄ(4～3月)'!I$26:I$1004) -> 0 | G9: =SUMIF('内訳ﾘｽﾄ(4～3月)'!$D$26:$D$1004,'採算表(VND)'!$B9,'内訳ﾘｽﾄ(4～3月)'!J$26:J$1004) -> 0 | H9: =SUMIF('内訳ﾘｽﾄ(4～3月)'!$D$26:$D$1004,'採算表(VND)'!$B9,'内訳ﾘｽﾄ(4～3月)'!K$26:K$1004) -> 0 | I9: =SUMIF('内訳ﾘｽﾄ(4～3月)'!$D$26:$D$1004,'採算表(VND)'!$B9,'内訳ﾘｽﾄ(4～3月)'!L$26:L$1004) -> 0 | J9: =SUMIF('内訳ﾘｽﾄ(4～3月)'!$D$26:$D$1004,'採算表(VND)'!$B9,'内訳ﾘｽﾄ(4～3月)'!M$26:M$1004) -> 0 | ... N9: =SUMIF('内訳ﾘｽﾄ(4～3月)'!$D$26:$D$1004,'採算表(VND)'!$B9,'内訳ﾘｽﾄ(4～3月)'!Q$26:Q$1004) -> 0 | O9: =SUMIF('内訳ﾘｽﾄ(4～3月)'!$D$26:$D$803,'採算表(VND)'!$B9,'内訳ﾘｽﾄ(4～3月)'!R$26:R$803) -> 0
B10: 社内買 | C10: =SUMIF('内訳ﾘｽﾄ(4～3月)'!$D$26:$D$1004,'採算表(VND)'!$B10,'内訳ﾘｽﾄ(4～3月)'!F$26:F$1004) -> 0 | D10: =SUMIF('内訳ﾘｽﾄ(4～3月)'!$D$26:$D$1004,'採算表(VND)'!$B10,'内訳ﾘｽﾄ(4～3月)'!G$26:G$1004) -> 0 | E10: =SUMIF('内訳ﾘｽﾄ(4～3月)'!$D$26:$D$1004,'採算表(VND)'!$B10,'内訳ﾘｽﾄ(4～3月)'!H$26:H$1004) -> 0 | F10: =SUMIF('内訳ﾘｽﾄ(4～3月)'!$D$26:$D$1004,'採算表(VND)'!$B10,'内訳ﾘｽﾄ(4～3月)'!I$26:I$1004) -> 0 | G10: =SUMIF('内訳ﾘｽﾄ(4～3月)'!$D$26:$D$1004,'採算表(VND)'!$B10,'内訳ﾘｽﾄ(4～3月)'!J$26:J$1004) -> 0 | H10: =SUMIF('内訳ﾘｽﾄ(4～3月)'!$D$26:$D$1004,'採算表(VND)'!$B10,'内訳ﾘｽﾄ(4～3月)'!K$26:K$1004) -> 0 | I10: =SUMIF('内訳ﾘｽﾄ(4～3月)'!$D$26:$D$1004,'採算表(VND)'!$B10,'内訳ﾘｽﾄ(4～3月)'!L$26:L$1004) -> 0 | J10: =SUMIF('内訳ﾘｽﾄ(4～3月)'!$D$26:$D$1004,'採算表(VND)'!$B10,'内訳ﾘｽﾄ(4～3月)'!M$26:M$1004) -> 0 | ... N10: =SUMIF('内訳ﾘｽﾄ(4～3月)'!$D$26:$D$1004,'採算表(VND)'!$B10,'内訳ﾘｽﾄ(4～3月)'!Q$26:Q$1004) -> 0 | O10: =SUMIF('内訳ﾘｽﾄ(4～3月)'!$D$26:$D$803,'採算表(VND)'!$B10,'内訳ﾘｽﾄ(4～3月)'!R$26:R$803) -> 0
B12: 総生産 | C12: =C5-C10 -> 0 | D12: =D5-D10 -> 0 | E12: =E5-E10 -> 0 | F12: =F5-F10 -> 0 | G12: =G5-G10 -> 0 | H12: =H5-H10 -> 0 | I12: =I5-I10 -> 0 | J12: =J5-J10 -> 0 | ... O12: =O5-O10 -> 0
B13: 控除額 | C13: =SUM(C14:C65) -> 0 | D13: =SUM(D14:D65) -> 0 | E13: =SUM(E14:E65) -> 0 | F13: =SUM(F14:F65) -> 0 | G13: =SUM(G14:G65) -> 0 | H13: =SUM(H14:H65) -> 0 | I13: =SUM(I14:I65) -> 0 | J13: =SUM(J14:J65) -> 0 | ... O13: =SUM(O14:O65) -> 0
B14: 材料費 | C14: =SUMIF('内訳ﾘｽﾄ(4～3月)'!$D$26:$D$1004,$B14,'内訳ﾘｽﾄ(4～3月)'!F$26:F$1004) -> 0 | D14: =SUMIF('内訳ﾘｽﾄ(4～3月)'!$D$26:$D$1004,$B14,'内訳ﾘｽﾄ(4～3月)'!G$26:G$1004) -> 0 | E14: =SUMIF('内訳ﾘｽﾄ(4～3月)'!$D$26:$D$1004,$B14,'内訳ﾘｽﾄ(4～3月)'!H$26:H$1004) -> 0 | F14: =SUMIF('内訳ﾘｽﾄ(4～3月)'!$D$26:$D$1004,$B14,'内訳ﾘｽﾄ(4～3月)'!I$26:I$1004) -> 0 | G14: =SUMIF('内訳ﾘｽﾄ(4～3月)'!$D$26:$D$1004,$B14,'内訳ﾘｽﾄ(4～3月)'!J$26:J$1004) -> 0 | H14: =SUMIF('内訳ﾘｽﾄ(4～3月)'!$D$26:$D$1004,$B14,'内訳ﾘｽﾄ(4～3月)'!K$26:K$1004) -> 0 | I14: =SUMIF('内訳ﾘｽﾄ(4～3月)'!$D$26:$D$1004,$B14,'内訳ﾘｽﾄ(4～3月)'!L$26:L$1004) -> 0 | J14: =SUMIF('内訳ﾘｽﾄ(4～3月)'!$D$26:$D$1004,$B14,'内訳ﾘｽﾄ(4～3月)'!M$26:M$1004) -> 0 | ... N14: =SUMIF('内訳ﾘｽﾄ(4～3月)'!$D$26:$D$1004,$B14,'内訳ﾘｽﾄ(4～3月)'!Q$26:Q$1004) -> 0 | O14: =SUMIF('内訳ﾘｽﾄ(4～3月)'!$D$26:$D$803,'採算表(VND)'!$B14,'内訳ﾘｽﾄ(4～3月)'!R$26:R$803) -> 0
B15: 設計変更材料費 | C15: =SUMIF('内訳ﾘｽﾄ(4～3月)'!$D$26:$D$1004,$B15,'内訳ﾘｽﾄ(4～3月)'!F$26:F$1004) -> 0 | D15: =SUMIF('内訳ﾘｽﾄ(4～3月)'!$D$26:$D$1004,$B15,'内訳ﾘｽﾄ(4～3月)'!G$26:G$1004) -> 0 | E15: =SUMIF('内訳ﾘｽﾄ(4～3月)'!$D$26:$D$1004,$B15,'内訳ﾘｽﾄ(4～3月)'!H$26:H$1004) -> 0 | F15: =SUMIF('内訳ﾘｽﾄ(4～3月)'!$D$26:$D$1004,$B15,'内訳ﾘｽﾄ(4～3月)'!I$26:I$1004) -> 0 | G15: =SUMIF('内訳ﾘｽﾄ(4～3月)'!$D$26:$D$1004,$B15,'内訳ﾘｽﾄ(4～3月)'!J$26:J$1004) -> 0 | H15: =SUMIF('内訳ﾘｽﾄ(4～3月)'!$D$26:$D$1004,$B15,'内訳ﾘｽﾄ(4～3月)'!K$26:K$1004) -> 0 | I15: =SUMIF('内訳ﾘｽﾄ(4～3月)'!$D$26:$D$1004,$B15,'内訳ﾘｽﾄ(4～3月)'!L$26:L$1004) -> 0 | J15: =SUMIF('内訳ﾘｽﾄ(4～3月)'!$D$26:$D$1004,$B15,'内訳ﾘｽﾄ(4～3月)'!M$26:M$1004) -> 0 | ... N15: =SUMIF('内訳ﾘｽﾄ(4～3月)'!$D$26:$D$1004,$B15,'内訳ﾘｽﾄ(4～3月)'!Q$26:Q$1004) -> 0 | O15: =SUMIF('内訳ﾘｽﾄ(4～3月)'!$D$26:$D$803,'採算表(VND)'!$B15,'内訳ﾘｽﾄ(4～3月)'!R$26:R$803) -> 0
B16: 仕掛仕損 | C16: =SUMIF('内訳ﾘｽﾄ(4～3月)'!$D$26:$D$1004,$B16,'内訳ﾘｽﾄ(4～3月)'!F$26:F$1004) -> 0 | D16: =SUMIF('内訳ﾘｽﾄ(4～3月)'!$D$26:$D$1004,$B16,'内訳ﾘｽﾄ(4～3月)'!G$26:G$1004) -> 0 | E16: =SUMIF('内訳ﾘｽﾄ(4～3月)'!$D$26:$D$1004,$B16,'内訳ﾘｽﾄ(4～3月)'!H$26:H$1004) -> 0 | F16: =SUMIF('内訳ﾘｽﾄ(4～3月)'!$D$26:$D$1004,$B16,'内訳ﾘｽﾄ(4～3月)'!I$26:I$1004) -> 0 | G16: =SUMIF('内訳ﾘｽﾄ(4～3月)'!$D$26:$D$1004,$B16,'内訳ﾘｽﾄ(4～3月)'!J$26:J$1004) -> 0 | H16: =SUMIF('内訳ﾘｽﾄ(4～3月)'!$D$26:$D$1004,$B16,'内訳ﾘｽﾄ(4～3月)'!K$26:K$1004) -> 0 | I16: =SUMIF('内訳ﾘｽﾄ(4～3月)'!$D$26:$D$1004,$B16,'内訳ﾘｽﾄ(4～3月)'!L$26:L$1004) -> 0 | J16: =SUMIF('内訳ﾘｽﾄ(4～3月)'!$D$26:$D$1004,$B16,'内訳ﾘｽﾄ(4～3月)'!M$26:M$1004) -> 0 | ... N16: =SUMIF('内訳ﾘｽﾄ(4～3月)'!$D$26:$D$1004,$B16,'内訳ﾘｽﾄ(4～3月)'!Q$26:Q$1004) -> 0 | O16: =SUMIF('内訳ﾘｽﾄ(4～3月)'!$D$26:$D$803,'採算表(VND)'!$B16,'内訳ﾘｽﾄ(4～3月)'!R$26:R$803) -> 0
B17: 仕入製商品費 | C17: =SUMIF('内訳ﾘｽﾄ(4～3月)'!$D$26:$D$1004,$B17,'内訳ﾘｽﾄ(4～3月)'!F$26:F$1004) -> 0 | D17: =SUMIF('内訳ﾘｽﾄ(4～3月)'!$D$26:$D$1004,$B17,'内訳ﾘｽﾄ(4～3月)'!G$26:G$1004) -> 0 | E17: =SUMIF('内訳ﾘｽﾄ(4～3月)'!$D$26:$D$1004,$B17,'内訳ﾘｽﾄ(4～3月)'!H$26:H$1004) -> 0 | F17: =SUMIF('内訳ﾘｽﾄ(4～3月)'!$D$26:$D$1004,$B17,'内訳ﾘｽﾄ(4～3月)'!I$26:I$1004) -> 0 | G17: =SUMIF('内訳ﾘｽﾄ(4～3月)'!$D$26:$D$1004,$B17,'内訳ﾘｽﾄ(4～3月)'!J$26:J$1004) -> 0 | H17: =SUMIF('内訳ﾘｽﾄ(4～3月)'!$D$26:$D$1004,$B17,'内訳ﾘｽﾄ(4～3月)'!K$26:K$1004) -> 0 | I17: =SUMIF('内訳ﾘｽﾄ(4～3月)'!$D$26:$D$1004,$B17,'内訳ﾘｽﾄ(4～3月)'!L$26:L$1004) -> 0 | J17: =SUMIF('内訳ﾘｽﾄ(4～3月)'!$D$26:$D$1004,$B17,'内訳ﾘｽﾄ(4～3月)'!M$26:M$1004) -> 0 | ... N17: =SUMIF('内訳ﾘｽﾄ(4～3月)'!$D$26:$D$1004,$B17,'内訳ﾘｽﾄ(4～3月)'!Q$26:Q$1004) -> 0 | O17: =SUMIF('内訳ﾘｽﾄ(4～3月)'!$D$26:$D$803,'採算表(VND)'!$B17,'内訳ﾘｽﾄ(4～3月)'!R$26:R$803) -> 0
B18: 内製品有償支給原価 | C18: =SUMIF('内訳ﾘｽﾄ(4～3月)'!$D$26:$D$1004,$B18,'内訳ﾘｽﾄ(4～3月)'!F$26:F$1004) -> 0 | D18: =SUMIF('内訳ﾘｽﾄ(4～3月)'!$D$26:$D$1004,$B18,'内訳ﾘｽﾄ(4～3月)'!G$26:G$1004) -> 0 | E18: =SUMIF('内訳ﾘｽﾄ(4～3月)'!$D$26:$D$1004,$B18,'内訳ﾘｽﾄ(4～3月)'!H$26:H$1004) -> 0 | F18: =SUMIF('内訳ﾘｽﾄ(4～3月)'!$D$26:$D$1004,$B18,'内訳ﾘｽﾄ(4～3月)'!I$26:I$1004) -> 0 | G18: =SUMIF('内訳ﾘｽﾄ(4～3月)'!$D$26:$D$1004,$B18,'内訳ﾘｽﾄ(4～3月)'!J$26:J$1004) -> 0 | H18: =SUMIF('内訳ﾘｽﾄ(4～3月)'!$D$26:$D$1004,$B18,'内訳ﾘｽﾄ(4～3月)'!K$26:K$1004) -> 0 | I18: =SUMIF('内訳ﾘｽﾄ(4～3月)'!$D$26:$D$1004,$B18,'内訳ﾘｽﾄ(4～3月)'!L$26:L$1004) -> 0 | J18: =SUMIF('内訳ﾘｽﾄ(4～3月)'!$D$26:$D$1004,$B18,'内訳ﾘｽﾄ(4～3月)'!M$26:M$1004) -> 0 | ... N18: =SUMIF('内訳ﾘｽﾄ(4～3月)'!$D$26:$D$1004,$B18,'内訳ﾘｽﾄ(4～3月)'!Q$26:Q$1004) -> 0 | O18: =SUMIF('内訳ﾘｽﾄ(4～3月)'!$D$26:$D$803,'採算表(VND)'!$B18,'内訳ﾘｽﾄ(4～3月)'!R$26:R$803) -> 0
B19: 外注加工費 | C19: =SUMIF('内訳ﾘｽﾄ(4～3月)'!$D$26:$D$1004,$B19,'内訳ﾘｽﾄ(4～3月)'!F$26:F$1004) -> 0 | D19: =SUMIF('内訳ﾘｽﾄ(4～3月)'!$D$26:$D$1004,$B19,'内訳ﾘｽﾄ(4～3月)'!G$26:G$1004) -> 0 | E19: =SUMIF('内訳ﾘｽﾄ(4～3月)'!$D$26:$D$1004,$B19,'内訳ﾘｽﾄ(4～3月)'!H$26:H$1004) -> 0 | F19: =SUMIF('内訳ﾘｽﾄ(4～3月)'!$D$26:$D$1004,$B19,'内訳ﾘｽﾄ(4～3月)'!I$26:I$1004) -> 0 | G19: =SUMIF('内訳ﾘｽﾄ(4～3月)'!$D$26:$D$1004,$B19,'内訳ﾘｽﾄ(4～3月)'!J$26:J$1004) -> 0 | H19: =SUMIF('内訳ﾘｽﾄ(4～3月)'!$D$26:$D$1004,$B19,'内訳ﾘｽﾄ(4～3月)'!K$26:K$1004) -> 0 | I19: =SUMIF('内訳ﾘｽﾄ(4～3月)'!$D$26:$D$1004,$B19,'内訳ﾘｽﾄ(4～3月)'!L$26:L$1004) -> 0 | J19: =SUMIF('内訳ﾘｽﾄ(4～3月)'!$D$26:$D$1004,$B19,'内訳ﾘｽﾄ(4～3月)'!M$26:M$1004) -> 0 | ... N19: =SUMIF('内訳ﾘｽﾄ(4～3月)'!$D$26:$D$1004,$B19,'内訳ﾘｽﾄ(4～3月)'!Q$26:Q$1004) -> 0 | O19: =SUMIF('内訳ﾘｽﾄ(4～3月)'!$D$26:$D$803,'採算表(VND)'!$B19,'内訳ﾘｽﾄ(4～3月)'!R$26:R$803) -> 0
B20: 減価償却費 | C20: =SUMIF('内訳ﾘｽﾄ(4～3月)'!$D$26:$D$1004,$B20,'内訳ﾘｽﾄ(4～3月)'!F$26:F$1004) -> 64678232 | D20: =SUMIF('内訳ﾘｽﾄ(4～3月)'!$D$26:$D$1004,$B20,'内訳ﾘｽﾄ(4～3月)'!G$26:G$1004) -> 64485776 | E20: =SUMIF('内訳ﾘｽﾄ(4～3月)'!$D$26:$D$1004,$B20,'内訳ﾘｽﾄ(4～3月)'!H$26:H$1004) -> 64718094 | F20: =SUMIF('内訳ﾘｽﾄ(4～3月)'!$D$26:$D$1004,$B20,'内訳ﾘｽﾄ(4～3月)'!I$26:I$1004) -> 62990051 | G20: =SUMIF('内訳ﾘｽﾄ(4～3月)'!$D$26:$D$1004,$B20,'内訳ﾘｽﾄ(4～3月)'!J$26:J$1004) -> 31108335 | H20: =SUMIF('内訳ﾘｽﾄ(4～3月)'!$D$26:$D$1004,$B20,'内訳ﾘｽﾄ(4～3月)'!K$26:K$1004) -> 30361361 | I20: =SUMIF('内訳ﾘｽﾄ(4～3月)'!$D$26:$D$1004,$B20,'内訳ﾘｽﾄ(4～3月)'!L$26:L$1004) -> 30010472 | J20: =SUMIF('内訳ﾘｽﾄ(4～3月)'!$D$26:$D$1004,$B20,'内訳ﾘｽﾄ(4～3月)'!M$26:M$1004) -> 29947759 | ... N20: =SUMIF('内訳ﾘｽﾄ(4～3月)'!$D$26:$D$1004,$B20,'内訳ﾘｽﾄ(4～3月)'!Q$26:Q$1004) -> 30469523 | O20: =SUMIF('内訳ﾘｽﾄ(4～3月)'!$D$26:$D$803,'採算表(VND)'!$B20,'内訳ﾘｽﾄ(4～3月)'!R$26:R$803) -> 498584694
B21: 金型償却費 | C21: =SUMIF('内訳ﾘｽﾄ(4～3月)'!$D$26:$D$1004,$B21,'内訳ﾘｽﾄ(4～3月)'!F$26:F$1004) -> 0 | D21: =SUMIF('内訳ﾘｽﾄ(4～3月)'!$D$26:$D$1004,$B21,'内訳ﾘｽﾄ(4～3月)'!G$26:G$1004) -> 0 | E21: =SUMIF('内訳ﾘｽﾄ(4～3月)'!$D$26:$D$1004,$B21,'内訳ﾘｽﾄ(4～3月)'!H$26:H$1004) -> 0 | F21: =SUMIF('内訳ﾘｽﾄ(4～3月)'!$D$26:$D$1004,$B21,'内訳ﾘｽﾄ(4～3月)'!I$26:I$1004) -> 0 | G21: =SUMIF('内訳ﾘｽﾄ(4～3月)'!$D$26:$D$1004,$B21,'内訳ﾘｽﾄ(4～3月)'!J$26:J$1004) -> 0 | H21: =SUMIF('内訳ﾘｽﾄ(4～3月)'!$D$26:$D$1004,$B21,'内訳ﾘｽﾄ(4～3月)'!K$26:K$1004) -> 0 | I21: =SUMIF('内訳ﾘｽﾄ(4～3月)'!$D$26:$D$1004,$B21,'内訳ﾘｽﾄ(4～3月)'!L$26:L$1004) -> 0 | J21: =SUMIF('内訳ﾘｽﾄ(4～3月)'!$D$26:$D$1004,$B21,'内訳ﾘｽﾄ(4～3月)'!M$26:M$1004) -> 0 | ... N21: =SUMIF('内訳ﾘｽﾄ(4～3月)'!$D$26:$D$1004,$B21,'内訳ﾘｽﾄ(4～3月)'!Q$26:Q$1004) -> 0 | O21: =SUMIF('内訳ﾘｽﾄ(4～3月)'!$D$26:$D$803,'採算表(VND)'!$B21,'内訳ﾘｽﾄ(4～3月)'!R$26:R$803) -> 0
B22: 賃借料 | C22: =SUMIF('内訳ﾘｽﾄ(4～3月)'!$D$26:$D$1004,$B22,'内訳ﾘｽﾄ(4～3月)'!F$26:F$1004) -> 0 | D22: =SUMIF('内訳ﾘｽﾄ(4～3月)'!$D$26:$D$1004,$B22,'内訳ﾘｽﾄ(4～3月)'!G$26:G$1004) -> 0 | E22: =SUMIF('内訳ﾘｽﾄ(4～3月)'!$D$26:$D$1004,$B22,'内訳ﾘｽﾄ(4～3月)'!H$26:H$1004) -> 0 | F22: =SUMIF('内訳ﾘｽﾄ(4～3月)'!$D$26:$D$1004,$B22,'内訳ﾘｽﾄ(4～3月)'!I$26:I$1004) -> 0 | G22: =SUMIF('内訳ﾘｽﾄ(4～3月)'!$D$26:$D$1004,$B22,'内訳ﾘｽﾄ(4～3月)'!J$26:J$1004) -> 0 | H22: =SUMIF('内訳ﾘｽﾄ(4～3月)'!$D$26:$D$1004,$B22,'内訳ﾘｽﾄ(4～3月)'!K$26:K$1004) -> 0 | I22: =SUMIF('内訳ﾘｽﾄ(4～3月)'!$D$26:$D$1004,$B22,'内訳ﾘｽﾄ(4～3月)'!L$26:L$1004) -> 0 | J22: =SUMIF('内訳ﾘｽﾄ(4～3月)'!$D$26:$D$1004,$B22,'内訳ﾘｽﾄ(4～3月)'!M$26:M$1004) -> 0 | ... N22: =SUMIF('内訳ﾘｽﾄ(4～3月)'!$D$26:$D$1004,$B22,'内訳ﾘｽﾄ(4～3月)'!Q$26:Q$1004) -> 0 | O22: =SUMIF('内訳ﾘｽﾄ(4～3月)'!$D$26:$D$803,'採算表(VND)'!$B22,'内訳ﾘｽﾄ(4～3月)'!R$26:R$803) -> 0
B23: 保険料 | C23: =SUMIF('内訳ﾘｽﾄ(4～3月)'!$D$26:$D$1004,$B23,'内訳ﾘｽﾄ(4～3月)'!F$26:F$1004) -> 0 | D23: =SUMIF('内訳ﾘｽﾄ(4～3月)'!$D$26:$D$1004,$B23,'内訳ﾘｽﾄ(4～3月)'!G$26:G$1004) -> 0 | E23: =SUMIF('内訳ﾘｽﾄ(4～3月)'!$D$26:$D$1004,$B23,'内訳ﾘｽﾄ(4～3月)'!H$26:H$1004) -> 0 | F23: =SUMIF('内訳ﾘｽﾄ(4～3月)'!$D$26:$D$1004,$B23,'内訳ﾘｽﾄ(4～3月)'!I$26:I$1004) -> 0 | G23: =SUMIF('内訳ﾘｽﾄ(4～3月)'!$D$26:$D$1004,$B23,'内訳ﾘｽﾄ(4～3月)'!J$26:J$1004) -> 0 | H23: =SUMIF('内訳ﾘｽﾄ(4～3月)'!$D$26:$D$1004,$B23,'内訳ﾘｽﾄ(4～3月)'!K$26:K$1004) -> 0 | I23: =SUMIF('内訳ﾘｽﾄ(4～3月)'!$D$26:$D$1004,$B23,'内訳ﾘｽﾄ(4～3月)'!L$26:L$1004) -> 0 | J23: =SUMIF('内訳ﾘｽﾄ(4～3月)'!$D$26:$D$1004,$B23,'内訳ﾘｽﾄ(4～3月)'!M$26:M$1004) -> 0 | ... N23: =SUMIF('内訳ﾘｽﾄ(4～3月)'!$D$26:$D$1004,$B23,'内訳ﾘｽﾄ(4～3月)'!Q$26:Q$1004) -> 0 | O23: =SUMIF('内訳ﾘｽﾄ(4～3月)'!$D$26:$D$803,'採算表(VND)'!$B23,'内訳ﾘｽﾄ(4～3月)'!R$26:R$803) -> 0
B24: 設計委託費 | C24: =SUMIF('内訳ﾘｽﾄ(4～3月)'!$D$26:$D$1004,$B24,'内訳ﾘｽﾄ(4～3月)'!F$26:F$1004) -> 0 | D24: =SUMIF('内訳ﾘｽﾄ(4～3月)'!$D$26:$D$1004,$B24,'内訳ﾘｽﾄ(4～3月)'!G$26:G$1004) -> 0 | E24: =SUMIF('内訳ﾘｽﾄ(4～3月)'!$D$26:$D$1004,$B24,'内訳ﾘｽﾄ(4～3月)'!H$26:H$1004) -> 0 | F24: =SUMIF('内訳ﾘｽﾄ(4～3月)'!$D$26:$D$1004,$B24,'内訳ﾘｽﾄ(4～3月)'!I$26:I$1004) -> 0 | G24: =SUMIF('内訳ﾘｽﾄ(4～3月)'!$D$26:$D$1004,$B24,'内訳ﾘｽﾄ(4～3月)'!J$26:J$1004) -> 0 | H24: =SUMIF('内訳ﾘｽﾄ(4～3月)'!$D$26:$D$1004,$B24,'内訳ﾘｽﾄ(4～3月)'!K$26:K$1004) -> 0 | I24: =SUMIF('内訳ﾘｽﾄ(4～3月)'!$D$26:$D$1004,$B24,'内訳ﾘｽﾄ(4～3月)'!L$26:L$1004) -> 0 | J24: =SUMIF('内訳ﾘｽﾄ(4～3月)'!$D$26:$D$1004,$B24,'内訳ﾘｽﾄ(4～3月)'!M$26:M$1004) -> 0 | ... N24: =SUMIF('内訳ﾘｽﾄ(4～3月)'!$D$26:$D$1004,$B24,'内訳ﾘｽﾄ(4～3月)'!Q$26:Q$1004) -> 0 | O24: =SUMIF('内訳ﾘｽﾄ(4～3月)'!$D$26:$D$803,'採算表(VND)'!$B24,'内訳ﾘｽﾄ(4～3月)'!R$26:R$803) -> 0
B25: 消耗品費 | C25: =SUMIF('内訳ﾘｽﾄ(4～3月)'!$D$26:$D$1004,$B25,'内訳ﾘｽﾄ(4～3月)'!F$26:F$1004) -> 13490470 | D25: =SUMIF('内訳ﾘｽﾄ(4～3月)'!$D$26:$D$1004,$B25,'内訳ﾘｽﾄ(4～3月)'!G$26:G$1004) -> 12890468 | E25: =SUMIF('内訳ﾘｽﾄ(4～3月)'!$D$26:$D$1004,$B25,'内訳ﾘｽﾄ(4～3月)'!H$26:H$1004) -> 14273484 | F25: =SUMIF('内訳ﾘｽﾄ(4～3月)'!$D$26:$D$1004,$B25,'内訳ﾘｽﾄ(4～3月)'!I$26:I$1004) -> 15656698 | G25: =SUMIF('内訳ﾘｽﾄ(4～3月)'!$D$26:$D$1004,$B25,'内訳ﾘｽﾄ(4～3月)'!J$26:J$1004) -> 1007552 | H25: =SUMIF('内訳ﾘｽﾄ(4～3月)'!$D$26:$D$1004,$B25,'内訳ﾘｽﾄ(4～3月)'!K$26:K$1004) -> 982604 | I25: =SUMIF('内訳ﾘｽﾄ(4～3月)'!$D$26:$D$1004,$B25,'内訳ﾘｽﾄ(4～3月)'!L$26:L$1004) -> 1290748 | J25: =SUMIF('内訳ﾘｽﾄ(4～3月)'!$D$26:$D$1004,$B25,'内訳ﾘｽﾄ(4～3月)'!M$26:M$1004) -> 1087120 | ... N25: =SUMIF('内訳ﾘｽﾄ(4～3月)'!$D$26:$D$1004,$B25,'内訳ﾘｽﾄ(4～3月)'!Q$26:Q$1004) -> 1320720 | O25: =SUMIF('内訳ﾘｽﾄ(4～3月)'!$D$26:$D$803,'採算表(VND)'!$B25,'内訳ﾘｽﾄ(4～3月)'!R$26:R$803) -> 65293121
... B60: 内部技術料 | C60: =SUMIF('内訳ﾘｽﾄ(4～3月)'!$D$26:$D$1004,$B60,'内訳ﾘｽﾄ(4～3月)'!F$26:F$1004) -> 0 | D60: =SUMIF('内訳ﾘｽﾄ(4～3月)'!$D$26:$D$1004,$B60,'内訳ﾘｽﾄ(4～3月)'!G$26:G$1004) -> 0 | E60: =SUMIF('内訳ﾘｽﾄ(4～3月)'!$D$26:$D$1004,$B60,'内訳ﾘｽﾄ(4～3月)'!H$26:H$1004) -> 0 | F60: =SUMIF('内訳ﾘｽﾄ(4～3月)'!$D$26:$D$1004,$B60,'内訳ﾘｽﾄ(4～3月)'!I$26:I$1004) -> 0 | G60: =SUMIF('内訳ﾘｽﾄ(4～3月)'!$D$26:$D$1004,$B60,'内訳ﾘｽﾄ(4～3月)'!J$26:J$1004) -> 0 | H60: =SUMIF('内訳ﾘｽﾄ(4～3月)'!$D$26:$D$1004,$B60,'内訳ﾘｽﾄ(4～3月)'!K$26:K$1004) -> 0 | I60: =SUMIF('内訳ﾘｽﾄ(4～3月)'!$D$26:$D$1004,$B60,'内訳ﾘｽﾄ(4～3月)'!L$26:L$1004) -> 0 | J60: =SUMIF('内訳ﾘｽﾄ(4～3月)'!$D$26:$D$1004,$B60,'内訳ﾘｽﾄ(4～3月)'!M$26:M$1004) -> 0 | ... N60: =SUMIF('内訳ﾘｽﾄ(4～3月)'!$D$26:$D$1004,$B60,'内訳ﾘｽﾄ(4～3月)'!Q$26:Q$1004) -> 0 | O60: =SUMIF('内訳ﾘｽﾄ(4～3月)'!$D$26:$D$803,'採算表(VND)'!$B60,'内訳ﾘｽﾄ(4～3月)'!R$26:R$803) -> 0
B61: 部内間接経費 | C61: =IF('内訳ﾘｽﾄ(4～3月)'!$D$5="製造",SUMIF('内訳ﾘｽﾄ(4～3月)'!$D$26:$D$1004,$B61,'内訳ﾘｽﾄ(4～3月)'!F$26:F$1004),IF('内訳ﾘｽﾄ(4～3月)'!$D$5="部内間接",-SUM(C$14:C$60,C$65),0)) -> -511006405 | D61: =IF('内訳ﾘｽﾄ(4～3月)'!$D$5="製造",SUMIF('内訳ﾘｽﾄ(4～3月)'!$D$26:$D$1004,$B61,'内訳ﾘｽﾄ(4～3月)'!G$26:G$1004),IF('内訳ﾘｽﾄ(4～3月)'!$D$5="部内間接",-SUM(D$14:D$60,D$65),0)) -> -736447527 | E61: =IF('内訳ﾘｽﾄ(4～3月)'!$D$5="製造",SUMIF('内訳ﾘｽﾄ(4～3月)'!$D$26:$D$1004,$B61,'内訳ﾘｽﾄ(4～3月)'!H$26:H$1004),IF('内訳ﾘｽﾄ(4～3月)'!$D$5="部内間接",-SUM(E$14:E$60,E$65),0)) -> -329640069 | F61: =IF('内訳ﾘｽﾄ(4～3月)'!$D$5="製造",SUMIF('内訳ﾘｽﾄ(4～3月)'!$D$26:$D$1004,$B61,'内訳ﾘｽﾄ(4～3月)'!I$26:I$1004),IF('内訳ﾘｽﾄ(4～3月)'!$D$5="部内間接",-SUM(F$14:F$60,F$65),0)) -> -295575098 | G61: =IF('内訳ﾘｽﾄ(4～3月)'!$D$5="製造",SUMIF('内訳ﾘｽﾄ(4～3月)'!$D$26:$D$1004,$B61,'内訳ﾘｽﾄ(4～3月)'!J$26:J$1004),IF('内訳ﾘｽﾄ(4～3月)'!$D$5="部内間接",-SUM(G$14:G$60,G$65),0)) -> -122869681 | H61: =IF('内訳ﾘｽﾄ(4～3月)'!$D$5="製造",SUMIF('内訳ﾘｽﾄ(4～3月)'!$D$26:$D$1004,$B61,'内訳ﾘｽﾄ(4～3月)'!K$26:K$1004),IF('内訳ﾘｽﾄ(4～3月)'!$D$5="部内間接",-SUM(H$14:H$60,H$65),0)) -> -127855273 | I61: =IF('内訳ﾘｽﾄ(4～3月)'!$D$5="製造",SUMIF('内訳ﾘｽﾄ(4～3月)'!$D$26:$D$1004,$B61,'内訳ﾘｽﾄ(4～3月)'!L$26:L$1004),IF('内訳ﾘｽﾄ(4～3月)'!$D$5="部内間接",-SUM(I$14:I$60,I$65),0)) -> -106916421 | J61: =IF('内訳ﾘｽﾄ(4～3月)'!$D$5="製造",SUMIF('内訳ﾘｽﾄ(4～3月)'!$D$26:$D$1004,$B61,'内訳ﾘｽﾄ(4～3月)'!M$26:M$1004),IF('内訳ﾘｽﾄ(4～3月)'!$D$5="部内間接",-SUM(J$14:J$60,J$65),0)) -> -101679511 | ... N61: =IF('内訳ﾘｽﾄ(4～3月)'!$D$5="製造",SUMIF('内訳ﾘｽﾄ(4～3月)'!$D$26:$D$1004,$B61,'内訳ﾘｽﾄ(4～3月)'!Q$26:Q$1004),IF('内訳ﾘｽﾄ(4～3月)'!$D$5="部内間接",-SUM(N$14:N$60,N$65),0)) -> -79669917 | O61: =IF('内訳ﾘｽﾄ(4～3月)'!$D$5="部内間接",-SUM(O$65,O$14:O$60),IF('内訳ﾘｽﾄ(4～3月)'!$D$5="製造",SUMIF('内訳ﾘｽﾄ(4～3月)'!$D$26:$D$803,'採算表(VND)'!$B61,'内訳ﾘｽﾄ(4～3月)'!R$26:R$803),0)) -> -2714812100
B62: 部外間接1経費 | C62: =IF('内訳ﾘｽﾄ(4～3月)'!$D$5="製造",SUMIF('内訳ﾘｽﾄ(4～3月)'!$D$26:$D$1004,$B62,'内訳ﾘｽﾄ(4～3月)'!F$26:F$1004),IF('内訳ﾘｽﾄ(4～3月)'!$D$5="部外間接1",-SUM(C$14:C$60,C$65),0)) -> 0 | D62: =IF('内訳ﾘｽﾄ(4～3月)'!$D$5="製造",SUMIF('内訳ﾘｽﾄ(4～3月)'!$D$26:$D$1004,$B62,'内訳ﾘｽﾄ(4～3月)'!G$26:G$1004),IF('内訳ﾘｽﾄ(4～3月)'!$D$5="部外間接1",-SUM(D$14:D$60,D$65),0)) -> 0 | E62: =IF('内訳ﾘｽﾄ(4～3月)'!$D$5="製造",SUMIF('内訳ﾘｽﾄ(4～3月)'!$D$26:$D$1004,$B62,'内訳ﾘｽﾄ(4～3月)'!H$26:H$1004),IF('内訳ﾘｽﾄ(4～3月)'!$D$5="部外間接1",-SUM(E$14:E$60,E$65),0)) -> 0 | F62: =IF('内訳ﾘｽﾄ(4～3月)'!$D$5="製造",SUMIF('内訳ﾘｽﾄ(4～3月)'!$D$26:$D$1004,$B62,'内訳ﾘｽﾄ(4～3月)'!I$26:I$1004),IF('内訳ﾘｽﾄ(4～3月)'!$D$5="部外間接1",-SUM(F$14:F$60,F$65),0)) -> 0 | G62: =IF('内訳ﾘｽﾄ(4～3月)'!$D$5="製造",SUMIF('内訳ﾘｽﾄ(4～3月)'!$D$26:$D$1004,$B62,'内訳ﾘｽﾄ(4～3月)'!J$26:J$1004),IF('内訳ﾘｽﾄ(4～3月)'!$D$5="部外間接1",-SUM(G$14:G$60,G$65),0)) -> 0 | H62: =IF('内訳ﾘｽﾄ(4～3月)'!$D$5="製造",SUMIF('内訳ﾘｽﾄ(4～3月)'!$D$26:$D$1004,$B62,'内訳ﾘｽﾄ(4～3月)'!K$26:K$1004),IF('内訳ﾘｽﾄ(4～3月)'!$D$5="部外間接1",-SUM(H$14:H$60,H$65),0)) -> 0 | I62: =IF('内訳ﾘｽﾄ(4～3月)'!$D$5="製造",SUMIF('内訳ﾘｽﾄ(4～3月)'!$D$26:$D$1004,$B62,'内訳ﾘｽﾄ(4～3月)'!L$26:L$1004),IF('内訳ﾘｽﾄ(4～3月)'!$D$5="部外間接1",-SUM(I$14:I$60,I$65),0)) -> 0 | J62: =IF('内訳ﾘｽﾄ(4～3月)'!$D$5="製造",SUMIF('内訳ﾘｽﾄ(4～3月)'!$D$26:$D$1004,$B62,'内訳ﾘｽﾄ(4～3月)'!M$26:M$1004),IF('内訳ﾘｽﾄ(4～3月)'!$D$5="部外間接1",-SUM(J$14:J$60,J$65),0)) -> 0 | ... N62: =IF('内訳ﾘｽﾄ(4～3月)'!$D$5="製造",SUMIF('内訳ﾘｽﾄ(4～3月)'!$D$26:$D$1004,$B62,'内訳ﾘｽﾄ(4～3月)'!Q$26:Q$1004),IF('内訳ﾘｽﾄ(4～3月)'!$D$5="部外間接1",-SUM(N$14:N$60,N$65),0)) -> 0 | O62: =IF('内訳ﾘｽﾄ(4～3月)'!$D$5="部外間接1",-SUM(O$65,O$14:O$60),IF('内訳ﾘｽﾄ(4～3月)'!$D$5="製造",SUMIF('内訳ﾘｽﾄ(4～3月)'!$D$26:$D$803,'採算表(VND)'!$B62,'内訳ﾘｽﾄ(4～3月)'!R$26:R$803),0)) -> 0
B63: 部外間接2経費 | C63: =IF('内訳ﾘｽﾄ(4～3月)'!$D$5="製造",SUMIF('内訳ﾘｽﾄ(4～3月)'!$D$26:$D$1004,$B63,'内訳ﾘｽﾄ(4～3月)'!F$26:F$1004),IF('内訳ﾘｽﾄ(4～3月)'!$D$5="部外間接2",-SUM(C$14:C$60,C$65),0)) -> 0 | D63: =IF('内訳ﾘｽﾄ(4～3月)'!$D$5="製造",SUMIF('内訳ﾘｽﾄ(4～3月)'!$D$26:$D$1004,$B63,'内訳ﾘｽﾄ(4～3月)'!G$26:G$1004),IF('内訳ﾘｽﾄ(4～3月)'!$D$5="部外間接2",-SUM(D$14:D$60,D$65),0)) -> 0 | E63: =IF('内訳ﾘｽﾄ(4～3月)'!$D$5="製造",SUMIF('内訳ﾘｽﾄ(4～3月)'!$D$26:$D$1004,$B63,'内訳ﾘｽﾄ(4～3月)'!H$26:H$1004),IF('内訳ﾘｽﾄ(4～3月)'!$D$5="部外間接2",-SUM(E$14:E$60,E$65),0)) -> 0 | F63: =IF('内訳ﾘｽﾄ(4～3月)'!$D$5="製造",SUMIF('内訳ﾘｽﾄ(4～3月)'!$D$26:$D$1004,$B63,'内訳ﾘｽﾄ(4～3月)'!I$26:I$1004),IF('内訳ﾘｽﾄ(4～3月)'!$D$5="部外間接2",-SUM(F$14:F$60,F$65),0)) -> 0 | G63: =IF('内訳ﾘｽﾄ(4～3月)'!$D$5="製造",SUMIF('内訳ﾘｽﾄ(4～3月)'!$D$26:$D$1004,$B63,'内訳ﾘｽﾄ(4～3月)'!J$26:J$1004),IF('内訳ﾘｽﾄ(4～3月)'!$D$5="部外間接2",-SUM(G$14:G$60,G$65),0)) -> 0 | H63: =IF('内訳ﾘｽﾄ(4～3月)'!$D$5="製造",SUMIF('内訳ﾘｽﾄ(4～3月)'!$D$26:$D$1004,$B63,'内訳ﾘｽﾄ(4～3月)'!K$26:K$1004),IF('内訳ﾘｽﾄ(4～3月)'!$D$5="部外間接2",-SUM(H$14:H$60,H$65),0)) -> 0 | I63: =IF('内訳ﾘｽﾄ(4～3月)'!$D$5="製造",SUMIF('内訳ﾘｽﾄ(4～3月)'!$D$26:$D$1004,$B63,'内訳ﾘｽﾄ(4～3月)'!L$26:L$1004),IF('内訳ﾘｽﾄ(4～3月)'!$D$5="部外間接2",-SUM(I$14:I$60,I$65),0)) -> 0 | J63: =IF('内訳ﾘｽﾄ(4～3月)'!$D$5="製造",SUMIF('内訳ﾘｽﾄ(4～3月)'!$D$26:$D$1004,$B63,'内訳ﾘｽﾄ(4～3月)'!M$26:M$1004),IF('内訳ﾘｽﾄ(4～3月)'!$D$5="部外間接2",-SUM(J$14:J$60,J$65),0)) -> 0 | ... N63: =IF('内訳ﾘｽﾄ(4～3月)'!$D$5="製造",SUMIF('内訳ﾘｽﾄ(4～3月)'!$D$26:$D$1004,$B63,'内訳ﾘｽﾄ(4～3月)'!Q$26:Q$1004),IF('内訳ﾘｽﾄ(4～3月)'!$D$5="部外間接2",-SUM(N$14:N$60,N$65),0)) -> 0 | O63: =IF('内訳ﾘｽﾄ(4～3月)'!$D$5="部外間接2",-SUM(O$65,O$14:O$60),IF('内訳ﾘｽﾄ(4～3月)'!$D$5="製造",SUMIF('内訳ﾘｽﾄ(4～3月)'!$D$26:$D$803,'採算表(VND)'!$B63,'内訳ﾘｽﾄ(4～3月)'!R$26:R$803),0)) -> 0
B64: 工場間接経費 | C64: =IF('内訳ﾘｽﾄ(4～3月)'!$D$5="製造",SUMIF('内訳ﾘｽﾄ(4～3月)'!$D$26:$D$1004,$B64,'内訳ﾘｽﾄ(4～3月)'!F$26:F$1004),IF('内訳ﾘｽﾄ(4～3月)'!$D$5="工場間接",-SUM(C$14:C$60,C$65),0)) -> 0 | D64: =IF('内訳ﾘｽﾄ(4～3月)'!$D$5="製造",SUMIF('内訳ﾘｽﾄ(4～3月)'!$D$26:$D$1004,$B64,'内訳ﾘｽﾄ(4～3月)'!G$26:G$1004),IF('内訳ﾘｽﾄ(4～3月)'!$D$5="工場間接",-SUM(D$14:D$60,D$65),0)) -> 0 | E64: =IF('内訳ﾘｽﾄ(4～3月)'!$D$5="製造",SUMIF('内訳ﾘｽﾄ(4～3月)'!$D$26:$D$1004,$B64,'内訳ﾘｽﾄ(4～3月)'!H$26:H$1004),IF('内訳ﾘｽﾄ(4～3月)'!$D$5="工場間接",-SUM(E$14:E$60,E$65),0)) -> 0 | F64: =IF('内訳ﾘｽﾄ(4～3月)'!$D$5="製造",SUMIF('内訳ﾘｽﾄ(4～3月)'!$D$26:$D$1004,$B64,'内訳ﾘｽﾄ(4～3月)'!I$26:I$1004),IF('内訳ﾘｽﾄ(4～3月)'!$D$5="工場間接",-SUM(F$14:F$60,F$65),0)) -> 0 | G64: =IF('内訳ﾘｽﾄ(4～3月)'!$D$5="製造",SUMIF('内訳ﾘｽﾄ(4～3月)'!$D$26:$D$1004,$B64,'内訳ﾘｽﾄ(4～3月)'!J$26:J$1004),IF('内訳ﾘｽﾄ(4～3月)'!$D$5="工場間接",-SUM(G$14:G$60,G$65),0)) -> 0 | H64: =IF('内訳ﾘｽﾄ(4～3月)'!$D$5="製造",SUMIF('内訳ﾘｽﾄ(4～3月)'!$D$26:$D$1004,$B64,'内訳ﾘｽﾄ(4～3月)'!K$26:K$1004),IF('内訳ﾘｽﾄ(4～3月)'!$D$5="工場間接",-SUM(H$14:H$60,H$65),0)) -> 0 | I64: =IF('内訳ﾘｽﾄ(4～3月)'!$D$5="製造",SUMIF('内訳ﾘｽﾄ(4～3月)'!$D$26:$D$1004,$B64,'内訳ﾘｽﾄ(4～3月)'!L$26:L$1004),IF('内訳ﾘｽﾄ(4～3月)'!$D$5="工場間接",-SUM(I$14:I$60,I$65),0)) -> 0 | J64: =IF('内訳ﾘｽﾄ(4～3月)'!$D$5="製造",SUMIF('内訳ﾘｽﾄ(4～3月)'!$D$26:$D$1004,$B64,'内訳ﾘｽﾄ(4～3月)'!M$26:M$1004),IF('内訳ﾘｽﾄ(4～3月)'!$D$5="工場間接",-SUM(J$14:J$60,J$65),0)) -> 0 | ... N64: =IF('内訳ﾘｽﾄ(4～3月)'!$D$5="製造",SUMIF('内訳ﾘｽﾄ(4～3月)'!$D$26:$D$1004,$B64,'内訳ﾘｽﾄ(4～3月)'!Q$26:Q$1004),IF('内訳ﾘｽﾄ(4～3月)'!$D$5="工場間接",-SUM(N$14:N$60,N$65),0)) -> 0 | O64: =IF('内訳ﾘｽﾄ(4～3月)'!$D$5="工場間接",-SUM(O$65,O$14:O$60),IF('内訳ﾘｽﾄ(4～3月)'!$D$5="製造",SUMIF('内訳ﾘｽﾄ(4～3月)'!$D$26:$D$803,'採算表(VND)'!$B64,'内訳ﾘｽﾄ(4～3月)'!R$26:R$803),0)) -> 0
B65: 本社機構経費 | C65: =SUMIF('内訳ﾘｽﾄ(4～3月)'!$D$26:$D$1004,$B65,'内訳ﾘｽﾄ(4～3月)'!F$26:F$1004) -> 0 | D65: =SUMIF('内訳ﾘｽﾄ(4～3月)'!$D$26:$D$1004,$B65,'内訳ﾘｽﾄ(4～3月)'!G$26:G$1004) -> 0 | E65: =SUMIF('内訳ﾘｽﾄ(4～3月)'!$D$26:$D$1004,$B65,'内訳ﾘｽﾄ(4～3月)'!H$26:H$1004) -> 0 | F65: =SUMIF('内訳ﾘｽﾄ(4～3月)'!$D$26:$D$1004,$B65,'内訳ﾘｽﾄ(4～3月)'!I$26:I$1004) -> 0 | G65: =SUMIF('内訳ﾘｽﾄ(4～3月)'!$D$26:$D$1004,$B65,'内訳ﾘｽﾄ(4～3月)'!J$26:J$1004) -> 0 | H65: =SUMIF('内訳ﾘｽﾄ(4～3月)'!$D$26:$D$1004,$B65,'内訳ﾘｽﾄ(4～3月)'!K$26:K$1004) -> 0 | I65: =SUMIF('内訳ﾘｽﾄ(4～3月)'!$D$26:$D$1004,$B65,'内訳ﾘｽﾄ(4～3月)'!L$26:L$1004) -> 0 | J65: =SUMIF('内訳ﾘｽﾄ(4～3月)'!$D$26:$D$1004,$B65,'内訳ﾘｽﾄ(4～3月)'!M$26:M$1004) -> 0 | ... N65: =SUMIF('内訳ﾘｽﾄ(4～3月)'!$D$26:$D$1004,$B65,'内訳ﾘｽﾄ(4～3月)'!Q$26:Q$1004) -> 0 | O65: =SUMIF('内訳ﾘｽﾄ(4～3月)'!$D$26:$D$803,'採算表(VND)'!$B65,'内訳ﾘｽﾄ(4～3月)'!R$26:R$803) -> 0
B66: 差引収益 | C66: =C12-C13 -> 0 | D66: =D12-D13 -> 0 | E66: =E12-E13 -> 0 | F66: =F12-F13 -> 0 | G66: =G12-G13 -> 0 | H66: =H12-H13 -> 0 | I66: =I12-I13 -> 0 | J66: =J12-J13 -> 0 | ... N66: =N12-N13 -> 0 | O66: =IF(ISBLANK(O4),"",O12-O13) -> 0
B67: 総時間 | C67: =C73+C79 -> 0 | D67: =D73+D79 -> 0 | E67: =E73+E79 -> 0 | F67: =F73+F79 -> 0 | G67: =G73+G79 -> 0 | H67: =H73+H79 -> 0 | I67: =I73+I79 -> 0 | J67: =J73+J79 -> 0 | ... N67: =N73+N79 -> 0 | O67: =IF(ISBLANK(O4),"",O73+O79) -> 0
B68: 直接部門 | C68: =SUMIF('内訳ﾘｽﾄ(4～3月)'!$D$8:$D$15,'採算表(VND)'!$B68,'内訳ﾘｽﾄ(4～3月)'!F$8:F$15) -> 31644 | D68: =SUMIF('内訳ﾘｽﾄ(4～3月)'!$D$8:$D$15,'採算表(VND)'!$B68,'内訳ﾘｽﾄ(4～3月)'!G$8:G$15) -> 30078 | E68: =SUMIF('内訳ﾘｽﾄ(4～3月)'!$D$8:$D$15,'採算表(VND)'!$B68,'内訳ﾘｽﾄ(4～3月)'!H$8:H$15) -> 33244 | F68: =SUMIF('内訳ﾘｽﾄ(4～3月)'!$D$8:$D$15,'採算表(VND)'!$B68,'内訳ﾘｽﾄ(4～3月)'!I$8:I$15) -> 5169 | G68: =SUMIF('内訳ﾘｽﾄ(4～3月)'!$D$8:$D$15,'採算表(VND)'!$B68,'内訳ﾘｽﾄ(4～3月)'!J$8:J$15) -> 4452.5 | H68: =SUMIF('内訳ﾘｽﾄ(4～3月)'!$D$8:$D$15,'採算表(VND)'!$B68,'内訳ﾘｽﾄ(4～3月)'!K$8:K$15) -> 4253 | I68: =SUMIF('内訳ﾘｽﾄ(4～3月)'!$D$8:$D$15,'採算表(VND)'!$B68,'内訳ﾘｽﾄ(4～3月)'!L$8:L$15) -> 5904 | J68: =SUMIF('内訳ﾘｽﾄ(4～3月)'!$D$8:$D$15,'採算表(VND)'!$B68,'内訳ﾘｽﾄ(4～3月)'!M$8:M$15) -> 5134 | ... N68: =SUMIF('内訳ﾘｽﾄ(4～3月)'!$D$8:$D$15,'採算表(VND)'!$B68,'内訳ﾘｽﾄ(4～3月)'!Q$8:Q$15) -> 5773 | O68: =SUMIF('内訳ﾘｽﾄ(4～3月)'!$D$8:$D$15,'採算表(VND)'!$B68,'内訳ﾘｽﾄ(4～3月)'!$R$8:$R$15) -> 140871.5
B69: 部内間接部門 | C69: =IF('内訳ﾘｽﾄ(4～3月)'!$D$5="製造",SUMIF('内訳ﾘｽﾄ(4～3月)'!$D$8:$D$15,$B69,'内訳ﾘｽﾄ(4～3月)'!F$8:F$15),IF('内訳ﾘｽﾄ(4～3月)'!$D$5="部内間接",-C$68,0)) -> -31644 | D69: =IF('内訳ﾘｽﾄ(4～3月)'!$D$5="製造",SUMIF('内訳ﾘｽﾄ(4～3月)'!$D$8:$D$15,$B69,'内訳ﾘｽﾄ(4～3月)'!G$8:G$15),IF('内訳ﾘｽﾄ(4～3月)'!$D$5="部内間接",-D$68,0)) -> -30078 | E69: =IF('内訳ﾘｽﾄ(4～3月)'!$D$5="製造",SUMIF('内訳ﾘｽﾄ(4～3月)'!$D$8:$D$15,$B69,'内訳ﾘｽﾄ(4～3月)'!H$8:H$15),IF('内訳ﾘｽﾄ(4～3月)'!$D$5="部内間接",-E$68,0)) -> -33244 | F69: =IF('内訳ﾘｽﾄ(4～3月)'!$D$5="製造",SUMIF('内訳ﾘｽﾄ(4～3月)'!$D$8:$D$15,$B69,'内訳ﾘｽﾄ(4～3月)'!I$8:I$15),IF('内訳ﾘｽﾄ(4～3月)'!$D$5="部内間接",-F$68,0)) -> -5169 | G69: =IF('内訳ﾘｽﾄ(4～3月)'!$D$5="製造",SUMIF('内訳ﾘｽﾄ(4～3月)'!$D$8:$D$15,$B69,'内訳ﾘｽﾄ(4～3月)'!J$8:J$15),IF('内訳ﾘｽﾄ(4～3月)'!$D$5="部内間接",-G$68,0)) -> -4452.5 | H69: =IF('内訳ﾘｽﾄ(4～3月)'!$D$5="製造",SUMIF('内訳ﾘｽﾄ(4～3月)'!$D$8:$D$15,$B69,'内訳ﾘｽﾄ(4～3月)'!K$8:K$15),IF('内訳ﾘｽﾄ(4～3月)'!$D$5="部内間接",-H$68,0)) -> -4253 | I69: =IF('内訳ﾘｽﾄ(4～3月)'!$D$5="製造",SUMIF('内訳ﾘｽﾄ(4～3月)'!$D$8:$D$15,$B69,'内訳ﾘｽﾄ(4～3月)'!L$8:L$15),IF('内訳ﾘｽﾄ(4～3月)'!$D$5="部内間接",-I$68,0)) -> -5904 | J69: =IF('内訳ﾘｽﾄ(4～3月)'!$D$5="製造",SUMIF('内訳ﾘｽﾄ(4～3月)'!$D$8:$D$15,$B69,'内訳ﾘｽﾄ(4～3月)'!M$8:M$15),IF('内訳ﾘｽﾄ(4～3月)'!$D$5="部内間接",-J$68,0)) -> -5134 | ... N69: =IF('内訳ﾘｽﾄ(4～3月)'!$D$5="製造",SUMIF('内訳ﾘｽﾄ(4～3月)'!$D$8:$D$15,$B69,'内訳ﾘｽﾄ(4～3月)'!Q$8:Q$15),IF('内訳ﾘｽﾄ(4～3月)'!$D$5="部内間接",-N$68,0)) -> -5773 | O69: =IF('内訳ﾘｽﾄ(4～3月)'!$D$5="部内間接",-SUM(O$68),IF('内訳ﾘｽﾄ(4～3月)'!$D$5="製造",SUMIF('内訳ﾘｽﾄ(4～3月)'!$D$8:$D$15,'採算表(VND)'!$B69,'内訳ﾘｽﾄ(4～3月)'!$R$8:$R$15),0)) -> -140871.5
B70: 部外間接部門1 | C70: =IF('内訳ﾘｽﾄ(4～3月)'!$D$5="製造",SUMIF('内訳ﾘｽﾄ(4～3月)'!$D$8:$D$15,$B70,'内訳ﾘｽﾄ(4～3月)'!F$8:F$15),IF('内訳ﾘｽﾄ(4～3月)'!$D$5="部外間接1",-C$68,0)) -> 0 | D70: =IF('内訳ﾘｽﾄ(4～3月)'!$D$5="製造",SUMIF('内訳ﾘｽﾄ(4～3月)'!$D$8:$D$15,$B70,'内訳ﾘｽﾄ(4～3月)'!G$8:G$15),IF('内訳ﾘｽﾄ(4～3月)'!$D$5="部外間接1",-D$68,0)) -> 0 | E70: =IF('内訳ﾘｽﾄ(4～3月)'!$D$5="製造",SUMIF('内訳ﾘｽﾄ(4～3月)'!$D$8:$D$15,$B70,'内訳ﾘｽﾄ(4～3月)'!H$8:H$15),IF('内訳ﾘｽﾄ(4～3月)'!$D$5="部外間接1",-E$68,0)) -> 0 | F70: =IF('内訳ﾘｽﾄ(4～3月)'!$D$5="製造",SUMIF('内訳ﾘｽﾄ(4～3月)'!$D$8:$D$15,$B70,'内訳ﾘｽﾄ(4～3月)'!I$8:I$15),IF('内訳ﾘｽﾄ(4～3月)'!$D$5="部外間接1",-F$68,0)) -> 0 | G70: =IF('内訳ﾘｽﾄ(4～3月)'!$D$5="製造",SUMIF('内訳ﾘｽﾄ(4～3月)'!$D$8:$D$15,$B70,'内訳ﾘｽﾄ(4～3月)'!J$8:J$15),IF('内訳ﾘｽﾄ(4～3月)'!$D$5="部外間接1",-G$68,0)) -> 0 | H70: =IF('内訳ﾘｽﾄ(4～3月)'!$D$5="製造",SUMIF('内訳ﾘｽﾄ(4～3月)'!$D$8:$D$15,$B70,'内訳ﾘｽﾄ(4～3月)'!K$8:K$15),IF('内訳ﾘｽﾄ(4～3月)'!$D$5="部外間接1",-H$68,0)) -> 0 | I70: =IF('内訳ﾘｽﾄ(4～3月)'!$D$5="製造",SUMIF('内訳ﾘｽﾄ(4～3月)'!$D$8:$D$15,$B70,'内訳ﾘｽﾄ(4～3月)'!L$8:L$15),IF('内訳ﾘｽﾄ(4～3月)'!$D$5="部外間接1",-I$68,0)) -> 0 | J70: =IF('内訳ﾘｽﾄ(4～3月)'!$D$5="製造",SUMIF('内訳ﾘｽﾄ(4～3月)'!$D$8:$D$15,$B70,'内訳ﾘｽﾄ(4～3月)'!M$8:M$15),IF('内訳ﾘｽﾄ(4～3月)'!$D$5="部外間接1",-J$68,0)) -> 0 | ... N70: =IF('内訳ﾘｽﾄ(4～3月)'!$D$5="製造",SUMIF('内訳ﾘｽﾄ(4～3月)'!$D$8:$D$15,$B70,'内訳ﾘｽﾄ(4～3月)'!Q$8:Q$15),IF('内訳ﾘｽﾄ(4～3月)'!$D$5="部外間接1",-N$68,0)) -> 0 | O70: =IF('内訳ﾘｽﾄ(4～3月)'!$D$5="部外間接1",-SUM(O$68),IF('内訳ﾘｽﾄ(4～3月)'!$D$5="製造",SUMIF('内訳ﾘｽﾄ(4～3月)'!$D$8:$D$15,'採算表(VND)'!$B70,'内訳ﾘｽﾄ(4～3月)'!$R$8:$R$15),0)) -> 0
B71: 部外間接部門2 | C71: =IF('内訳ﾘｽﾄ(4～3月)'!$D$5="製造",SUMIF('内訳ﾘｽﾄ(4～3月)'!$D$8:$D$15,$B71,'内訳ﾘｽﾄ(4～3月)'!F$8:F$15),IF('内訳ﾘｽﾄ(4～3月)'!$D$5="部外間接2",-C$68,0)) -> 0 | D71: =IF('内訳ﾘｽﾄ(4～3月)'!$D$5="製造",SUMIF('内訳ﾘｽﾄ(4～3月)'!$D$8:$D$15,$B71,'内訳ﾘｽﾄ(4～3月)'!G$8:G$15),IF('内訳ﾘｽﾄ(4～3月)'!$D$5="部外間接2",-D$68,0)) -> 0 | E71: =IF('内訳ﾘｽﾄ(4～3月)'!$D$5="製造",SUMIF('内訳ﾘｽﾄ(4～3月)'!$D$8:$D$15,$B71,'内訳ﾘｽﾄ(4～3月)'!H$8:H$15),IF('内訳ﾘｽﾄ(4～3月)'!$D$5="部外間接2",-E$68,0)) -> 0 | F71: =IF('内訳ﾘｽﾄ(4～3月)'!$D$5="製造",SUMIF('内訳ﾘｽﾄ(4～3月)'!$D$8:$D$15,$B71,'内訳ﾘｽﾄ(4～3月)'!I$8:I$15),IF('内訳ﾘｽﾄ(4～3月)'!$D$5="部外間接2",-F$68,0)) -> 0 | G71: =IF('内訳ﾘｽﾄ(4～3月)'!$D$5="製造",SUMIF('内訳ﾘｽﾄ(4～3月)'!$D$8:$D$15,$B71,'内訳ﾘｽﾄ(4～3月)'!J$8:J$15),IF('内訳ﾘｽﾄ(4～3月)'!$D$5="部外間接2",-G$68,0)) -> 0 | H71: =IF('内訳ﾘｽﾄ(4～3月)'!$D$5="製造",SUMIF('内訳ﾘｽﾄ(4～3月)'!$D$8:$D$15,$B71,'内訳ﾘｽﾄ(4～3月)'!K$8:K$15),IF('内訳ﾘｽﾄ(4～3月)'!$D$5="部外間接2",-H$68,0)) -> 0 | I71: =IF('内訳ﾘｽﾄ(4～3月)'!$D$5="製造",SUMIF('内訳ﾘｽﾄ(4～3月)'!$D$8:$D$15,$B71,'内訳ﾘｽﾄ(4～3月)'!L$8:L$15),IF('内訳ﾘｽﾄ(4～3月)'!$D$5="部外間接2",-I$68,0)) -> 0 | J71: =IF('内訳ﾘｽﾄ(4～3月)'!$D$5="製造",SUMIF('内訳ﾘｽﾄ(4～3月)'!$D$8:$D$15,$B71,'内訳ﾘｽﾄ(4～3月)'!M$8:M$15),IF('内訳ﾘｽﾄ(4～3月)'!$D$5="部外間接2",-J$68,0)) -> 0 | ... N71: =IF('内訳ﾘｽﾄ(4～3月)'!$D$5="製造",SUMIF('内訳ﾘｽﾄ(4～3月)'!$D$8:$D$15,$B71,'内訳ﾘｽﾄ(4～3月)'!Q$8:Q$15),IF('内訳ﾘｽﾄ(4～3月)'!$D$5="部外間接2",-N$68,0)) -> 0 | O71: =IF('内訳ﾘｽﾄ(4～3月)'!$D$5="部外間接2",-SUM(O$68),IF('内訳ﾘｽﾄ(4～3月)'!$D$5="製造",SUMIF('内訳ﾘｽﾄ(4～3月)'!$D$8:$D$15,'採算表(VND)'!$B71,'内訳ﾘｽﾄ(4～3月)'!$R$8:$R$15),0)) -> 0
B72: 工場間接部門 | C72: =IF('内訳ﾘｽﾄ(4～3月)'!$D$5="製造",SUMIF('内訳ﾘｽﾄ(4～3月)'!$D$8:$D$15,$B72,'内訳ﾘｽﾄ(4～3月)'!F$8:F$15),IF('内訳ﾘｽﾄ(4～3月)'!$D$5="工場間接",-C$68,0)) -> 0 | D72: =IF('内訳ﾘｽﾄ(4～3月)'!$D$5="製造",SUMIF('内訳ﾘｽﾄ(4～3月)'!$D$8:$D$15,$B72,'内訳ﾘｽﾄ(4～3月)'!G$8:G$15),IF('内訳ﾘｽﾄ(4～3月)'!$D$5="工場間接",-D$68,0)) -> 0 | E72: =IF('内訳ﾘｽﾄ(4～3月)'!$D$5="製造",SUMIF('内訳ﾘｽﾄ(4～3月)'!$D$8:$D$15,$B72,'内訳ﾘｽﾄ(4～3月)'!H$8:H$15),IF('内訳ﾘｽﾄ(4～3月)'!$D$5="工場間接",-E$68,0)) -> 0 | F72: =IF('内訳ﾘｽﾄ(4～3月)'!$D$5="製造",SUMIF('内訳ﾘｽﾄ(4～3月)'!$D$8:$D$15,$B72,'内訳ﾘｽﾄ(4～3月)'!I$8:I$15),IF('内訳ﾘｽﾄ(4～3月)'!$D$5="工場間接",-F$68,0)) -> 0 | G72: =IF('内訳ﾘｽﾄ(4～3月)'!$D$5="製造",SUMIF('内訳ﾘｽﾄ(4～3月)'!$D$8:$D$15,$B72,'内訳ﾘｽﾄ(4～3月)'!J$8:J$15),IF('内訳ﾘｽﾄ(4～3月)'!$D$5="工場間接",-G$68,0)) -> 0 | H72: =IF('内訳ﾘｽﾄ(4～3月)'!$D$5="製造",SUMIF('内訳ﾘｽﾄ(4～3月)'!$D$8:$D$15,$B72,'内訳ﾘｽﾄ(4～3月)'!K$8:K$15),IF('内訳ﾘｽﾄ(4～3月)'!$D$5="工場間接",-H$68,0)) -> 0 | I72: =IF('内訳ﾘｽﾄ(4～3月)'!$D$5="製造",SUMIF('内訳ﾘｽﾄ(4～3月)'!$D$8:$D$15,$B72,'内訳ﾘｽﾄ(4～3月)'!L$8:L$15),IF('内訳ﾘｽﾄ(4～3月)'!$D$5="工場間接",-I$68,0)) -> 0 | J72: =IF('内訳ﾘｽﾄ(4～3月)'!$D$5="製造",SUMIF('内訳ﾘｽﾄ(4～3月)'!$D$8:$D$15,$B72,'内訳ﾘｽﾄ(4～3月)'!M$8:M$15),IF('内訳ﾘｽﾄ(4～3月)'!$D$5="工場間接",-J$68,0)) -> 0 | ... N72: =IF('内訳ﾘｽﾄ(4～3月)'!$D$5="製造",SUMIF('内訳ﾘｽﾄ(4～3月)'!$D$8:$D$15,$B72,'内訳ﾘｽﾄ(4～3月)'!Q$8:Q$15),IF('内訳ﾘｽﾄ(4～3月)'!$D$5="工場間接",-N$68,0)) -> 0 | O72: =IF('内訳ﾘｽﾄ(4～3月)'!$D$5="工場間接",-SUM(O$68),IF('内訳ﾘｽﾄ(4～3月)'!$D$5="製造",SUMIF('内訳ﾘｽﾄ(4～3月)'!$D$8:$D$15,'採算表(VND)'!$B72,'内訳ﾘｽﾄ(4～3月)'!$R$8:$R$15),0)) -> 0
B73: 定時間合計 | C73: =SUM(C68:C72) -> 0 | D73: =SUM(D68:D72) -> 0 | E73: =SUM(E68:E72) -> 0 | F73: =SUM(F68:F72) -> 0 | G73: =SUM(G68:G72) -> 0 | H73: =SUM(H68:H72) -> 0 | I73: =SUM(I68:I72) -> 0 | J73: =SUM(J68:J72) -> 0 | ... N73: =SUM(N68:N72) -> 0 | O73: =IF(ISBLANK(O4),"",SUM(O68:O72)) -> 0
B74: 直接部門 | C74: =SUMIF('内訳ﾘｽﾄ(4～3月)'!$D$16:$D$23,'採算表(VND)'!$B74,'内訳ﾘｽﾄ(4～3月)'!F$16:F$23) -> 5021 | D74: =SUMIF('内訳ﾘｽﾄ(4～3月)'!$D$16:$D$23,'採算表(VND)'!$B74,'内訳ﾘｽﾄ(4～3月)'!G$16:G$23) -> 5015 | E74: =SUMIF('内訳ﾘｽﾄ(4～3月)'!$D$16:$D$23,'採算表(VND)'!$B74,'内訳ﾘｽﾄ(4～3月)'!H$16:H$23) -> 5035 | F74: =SUMIF('内訳ﾘｽﾄ(4～3月)'!$D$16:$D$23,'採算表(VND)'!$B74,'内訳ﾘｽﾄ(4～3月)'!I$16:I$23) -> 763 | G74: =SUMIF('内訳ﾘｽﾄ(4～3月)'!$D$16:$D$23,'採算表(VND)'!$B74,'内訳ﾘｽﾄ(4～3月)'!J$16:J$23) -> 735 | H74: =SUMIF('内訳ﾘｽﾄ(4～3月)'!$D$16:$D$23,'採算表(VND)'!$B74,'内訳ﾘｽﾄ(4～3月)'!K$16:K$23) -> 735 | I74: =SUMIF('内訳ﾘｽﾄ(4～3月)'!$D$16:$D$23,'採算表(VND)'!$B74,'内訳ﾘｽﾄ(4～3月)'!L$16:L$23) -> 863 | J74: =SUMIF('内訳ﾘｽﾄ(4～3月)'!$D$16:$D$23,'採算表(VND)'!$B74,'内訳ﾘｽﾄ(4～3月)'!M$16:M$23) -> 845 | ... N74: =SUMIF('内訳ﾘｽﾄ(4～3月)'!$D$16:$D$23,'採算表(VND)'!$B74,'内訳ﾘｽﾄ(4～3月)'!Q$16:Q$23) -> 945 | O74: =SUMIF('内訳ﾘｽﾄ(4～3月)'!$D$16:$D$23,'採算表(VND)'!$B74,'内訳ﾘｽﾄ(4～3月)'!$R$16:$R$23) -> 22587
B75: 部内間接部門 | C75: =IF('内訳ﾘｽﾄ(4～3月)'!$D$5="製造",SUMIF('内訳ﾘｽﾄ(4～3月)'!$D$16:$D$23,$B75,'内訳ﾘｽﾄ(4～3月)'!F$16:F$23),IF('内訳ﾘｽﾄ(4～3月)'!$D$5="部内間接",-C$74,0)) -> -5021 | D75: =IF('内訳ﾘｽﾄ(4～3月)'!$D$5="製造",SUMIF('内訳ﾘｽﾄ(4～3月)'!$D$16:$D$23,$B75,'内訳ﾘｽﾄ(4～3月)'!G$16:G$23),IF('内訳ﾘｽﾄ(4～3月)'!$D$5="部内間接",-D$74,0)) -> -5015 | E75: =IF('内訳ﾘｽﾄ(4～3月)'!$D$5="製造",SUMIF('内訳ﾘｽﾄ(4～3月)'!$D$16:$D$23,$B75,'内訳ﾘｽﾄ(4～3月)'!H$16:H$23),IF('内訳ﾘｽﾄ(4～3月)'!$D$5="部内間接",-E$74,0)) -> -5035 | F75: =IF('内訳ﾘｽﾄ(4～3月)'!$D$5="製造",SUMIF('内訳ﾘｽﾄ(4～3月)'!$D$16:$D$23,$B75,'内訳ﾘｽﾄ(4～3月)'!I$16:I$23),IF('内訳ﾘｽﾄ(4～3月)'!$D$5="部内間接",-F$74,0)) -> -763 | G75: =IF('内訳ﾘｽﾄ(4～3月)'!$D$5="製造",SUMIF('内訳ﾘｽﾄ(4～3月)'!$D$16:$D$23,$B75,'内訳ﾘｽﾄ(4～3月)'!J$16:J$23),IF('内訳ﾘｽﾄ(4～3月)'!$D$5="部内間接",-G$74,0)) -> -735 | H75: =IF('内訳ﾘｽﾄ(4～3月)'!$D$5="製造",SUMIF('内訳ﾘｽﾄ(4～3月)'!$D$16:$D$23,$B75,'内訳ﾘｽﾄ(4～3月)'!K$16:K$23),IF('内訳ﾘｽﾄ(4～3月)'!$D$5="部内間接",-H$74,0)) -> -735 | I75: =IF('内訳ﾘｽﾄ(4～3月)'!$D$5="製造",SUMIF('内訳ﾘｽﾄ(4～3月)'!$D$16:$D$23,$B75,'内訳ﾘｽﾄ(4～3月)'!L$16:L$23),IF('内訳ﾘｽﾄ(4～3月)'!$D$5="部内間接",-I$74,0)) -> -863 | J75: =IF('内訳ﾘｽﾄ(4～3月)'!$D$5="製造",SUMIF('内訳ﾘｽﾄ(4～3月)'!$D$16:$D$23,$B75,'内訳ﾘｽﾄ(4～3月)'!M$16:M$23),IF('内訳ﾘｽﾄ(4～3月)'!$D$5="部内間接",-J$74,0)) -> -845 | ... N75: =IF('内訳ﾘｽﾄ(4～3月)'!$D$5="製造",SUMIF('内訳ﾘｽﾄ(4～3月)'!$D$16:$D$23,$B75,'内訳ﾘｽﾄ(4～3月)'!Q$16:Q$23),IF('内訳ﾘｽﾄ(4～3月)'!$D$5="部内間接",-N$74,0)) -> -945 | O75: =IF('内訳ﾘｽﾄ(4～3月)'!$D$5="部内間接",-SUM(O$74),IF('内訳ﾘｽﾄ(4～3月)'!$D$5="製造",SUMIF('内訳ﾘｽﾄ(4～3月)'!$D$16:$D$23,'採算表(VND)'!$B75,'内訳ﾘｽﾄ(4～3月)'!$R$16:$R$23),0)) -> -22587
...

Sheet 内訳ﾘｽﾄ(4～3月)
A1: MP FY2026_各予定
B2: 25390 | E2: 稼働日数 | F2: =OFFSET(稼働日!$B$2,MATCH('内訳ﾘｽﾄ(4～3月)'!F4,稼働日!$A$3:$A$14,0),0) -> 20 | G2: =OFFSET(稼働日!$B$2,MATCH('内訳ﾘｽﾄ(4～3月)'!G4,稼働日!$A$3:$A$14,0),0) -> 19 | H2: =OFFSET(稼働日!$B$2,MATCH('内訳ﾘｽﾄ(4～3月)'!H4,稼働日!$A$3:$A$14,0),0) -> 21 | I2: =OFFSET(稼働日!$B$2,MATCH('内訳ﾘｽﾄ(4～3月)'!I4,稼働日!$A$3:$A$14,0),0) -> 23 | J2: =OFFSET(稼働日!$B$2,MATCH('内訳ﾘｽﾄ(4～3月)'!J4,稼働日!$A$3:$A$14,0),0) -> 20 | K2: =OFFSET(稼働日!$B$2,MATCH('内訳ﾘｽﾄ(4～3月)'!K4,稼働日!$A$3:$A$14,0),0) -> 19 | L2: =OFFSET(稼働日!$B$2,MATCH('内訳ﾘｽﾄ(4～3月)'!L4,稼働日!$A$3:$A$14,0),0) -> 23 | M2: =OFFSET(稼働日!$B$2,MATCH('内訳ﾘｽﾄ(4～3月)'!M4,稼働日!$A$3:$A$14,0),0) -> 20 | ... Q2: =OFFSET(稼働日!$B$2,MATCH('内訳ﾘｽﾄ(4～3月)'!Q4,稼働日!$A$3:$A$14,0),0) -> 20
E3: CHECK | F3: {=IF(SUM((F8:F25)-ROUNDDOWN((F8:F25)*4,0)/4)<>0,"時間➝0.25の倍数では無い",IF(SUM(ROUND((F26:F1004),0)-ROUND((F26:F1004),4))<>0,"経費➝小数点",IF(F5<>IF($D$5="製造",'採算表(VND)'!C13,-VLOOKUP($D$5&"経費",'採算表(VND)'!$B:$N,'採算表(VND)'!C3,0)),"経費➝NG","OK")))} -> OK | G3: {=IF(SUM((G8:G25)-ROUNDDOWN((G8:G25)*4,0)/4)<>0,"時間➝0.25の倍数では無い",IF(SUM(ROUND((G26:G1004),0)-ROUND((G26:G1004),4))<>0,"経費➝小数点",IF(G5<>IF($D$5="製造",'採算表(VND)'!D13,-VLOOKUP($D$5&"経費",'採算表(VND)'!$B:$N,'採算表(VND)'!D3,0)),"経費➝NG","OK")))} -> OK | H3: {=IF(SUM((H8:H25)-ROUNDDOWN((H8:H25)*4,0)/4)<>0,"時間➝0.25の倍数では無い",IF(SUM(ROUND((H26:H1004),0)-ROUND((H26:H1004),4))<>0,"経費➝小数点",IF(H5<>IF($D$5="製造",'採算表(VND)'!E13,-VLOOKUP($D$5&"経費",'採算表(VND)'!$B:$N,'採算表(VND)'!E3,0)),"経費➝NG","OK")))} -> OK | I3: {=IF(SUM((I8:I25)-ROUNDDOWN((I8:I25)*4,0)/4)<>0,"時間➝0.25の倍数では無い",IF(SUM(ROUND((I26:I1004),0)-ROUND((I26:I1004),4))<>0,"経費➝小数点",IF(I5<>IF($D$5="製造",'採算表(VND)'!F13,-VLOOKUP($D$5&"経費",'採算表(VND)'!$B:$N,'採算表(VND)'!F3,0)),"経費➝NG","OK")))} -> OK | J3: {=IF(SUM((J8:J25)-ROUNDDOWN((J8:J25)*4,0)/4)<>0,"時間➝0.25の倍数では無い",IF(SUM(ROUND((J26:J1004),0)-ROUND((J26:J1004),4))<>0,"経費➝小数点",IF(J5<>IF($D$5="製造",'採算表(VND)'!G13,-VLOOKUP($D$5&"経費",'採算表(VND)'!$B:$N,'採算表(VND)'!G3,0)),"経費➝NG","OK")))} -> OK | K3: {=IF(SUM((K8:K25)-ROUNDDOWN((K8:K25)*4,0)/4)<>0,"時間➝0.25の倍数では無い",IF(SUM(ROUND((K26:K1004),0)-ROUND((K26:K1004),4))<>0,"経費➝小数点",IF(K5<>IF($D$5="製造",'採算表(VND)'!H13,-VLOOKUP($D$5&"経費",'採算表(VND)'!$B:$N,'採算表(VND)'!H3,0)),"経費➝NG","OK")))} -> OK | L3: {=IF(SUM((L8:L25)-ROUNDDOWN((L8:L25)*4,0)/4)<>0,"時間➝0.25の倍数では無い",IF(SUM(ROUND((L26:L1004),0)-ROUND((L26:L1004),4))<>0,"経費➝小数点",IF(L5<>IF($D$5="製造",'採算表(VND)'!I13,-VLOOKUP($D$5&"経費",'採算表(VND)'!$B:$N,'採算表(VND)'!I3,0)),"経費➝NG","OK")))} -> OK | M3: {=IF(SUM((M8:M25)-ROUNDDOWN((M8:M25)*4,0)/4)<>0,"時間➝0.25の倍数では無い",IF(SUM(ROUND((M26:M1004),0)-ROUND((M26:M1004),4))<>0,"経費➝小数点",IF(M5<>IF($D$5="製造",'採算表(VND)'!J13,-VLOOKUP($D$5&"経費",'採算表(VND)'!$B:$N,'採算表(VND)'!J3,0)),"経費➝NG","OK")))} -> OK | ... Q3: {=IF(SUM((Q8:Q25)-ROUNDDOWN((Q8:Q25)*4,0)/4)<>0,"時間➝0.25の倍数では無い",IF(SUM(ROUND((Q26:Q1004),0)-ROUND((Q26:Q1004),4))<>0,"経費➝小数点",IF(Q5<>IF($D$5="製造",'採算表(VND)'!N13,-VLOOKUP($D$5&"経費",'採算表(VND)'!$B:$N,'採算表(VND)'!N3,0)),"経費➝NG","OK")))} -> OK
B4: 原価センター | C4: 組織名 | D4: 採算区分 | E4: 原価区分 | F4: 4 | G4: 5 | H4: 6 | I4: 7 | J4: 8 | K4: 9 | L4: 10 | M4: 11 | N4: 12 | O4: 1 | P4: 2 | Q4: 3 | R4: 合計 | S4: ※MEBIUS経費になると "V02V0800" は T列に 反映お願いします
B5: 1412000053 | C5: =VLOOKUP($B$5,原価センタ!$A:$E,2,0) -> 工程品質管理1課 | D5: =VLOOKUP($B$5,原価センタ!$A:$E,4,0) -> 部内間接 | E5: =VLOOKUP($B$5,原価センタ!$A:$E,5,0) -> 製造 | F5: =SUM(F29:F1004) -> 511006405 | G5: =SUM(G29:G1004) -> 736447527 | H5: =SUM(H29:H1004) -> 329640069 | I5: =SUM(I29:I1004) -> 295575098 | J5: =SUM(J29:J1004) -> 122869681 | K5: =SUM(K29:K1004) -> 127855273 | L5: =SUM(L29:L1004) -> 106916421 | M5: =SUM(M29:M1004) -> 101679511 | ... R5: =SUM(R29:R1004) -> 2714812100
C7: 勘定科目名称 | D7: 採算科目 | E7: ﾃｰﾏｺｰﾄﾞ | F7: MP | G7: MP | H7: MP | I7: MP | J7: MP | K7: MP | L7: MP | M7: MP | N7: MP | O7: MP | P7: MP | Q7: MP | R7: MP | S7: 備考 | T7: WBS | BC7: WBS
B8: 出向社員定時 | C8: 定時間（日本社員） | D8: 直接部門 | F8: 323 | G8: 323 | H8: 357 | I8: 391 | J8: 297.5 | K8: 306 | L8: 391 | M8: 340 | N8: 357 | O8: 306 | P8: 255 | Q8: 340 | R8: =SUM(F8:Q8) -> 3986.5
B9: ローカル社員定時 | C9: 定時間（ベトナム社員） | D9: 直接部門 | F9: 31321 | G9: 29755 | H9: 32887 | I9: 4778 | J9: 4155 | K9: 3947 | L9: 5513 | M9: 4794 | N9: 5273 | O9: 4954 | P9: 4075 | Q9: 5433 | R9: =SUM(F9:Q9) -> 136885
B10: 出向社員定時 | C10: 定時間（移動分日本社員） | D10: 直接部門 | R10: =SUM(F10:Q10) -> 0
B11: ローカル社員定時 | C11: 定時間（移動分ベトナム社員） | D11: 直接部門 | R11: =SUM(F11:Q11) -> 0
C12: 定時間（部内間接部門） | D12: 部内間接部門 | R12: =SUM(F12:Q12) -> 0 | S12: この分には間接部門から直接部門に配賦された数字
C13: 定時間（部外間接部門1） | D13: 部外間接部門1 | R13: =SUM(F13:Q13) -> 0 | S13: この分には間接部門から直接部門に配賦された数字
C14: 定時間（部外間接部門2） | D14: 部外間接部門2 | R14: =SUM(F14:Q14) -> 0 | S14: この分には間接部門から直接部門に配賦された数字
C15: 定時間（工場間接部門） | D15: 工場間接部門 | R15: =SUM(F15:Q15) -> 0 | S15: この分には間接部門から直接部門に配賦された数字
B16: 出向社員残業 | C16: 残業時間（日本社員） | D16: 直接部門 | F16: 76 | G16: 76 | H16: 84 | I16: 92 | J16: 70 | K16: 72 | L16: 92 | M16: 80 | N16: 84 | O16: 72 | P16: 60 | Q16: 80 | R16: =SUM(F16:Q16) -> 938
B17: ローカル社員残業 | C17: 残業時間（ベトナム社員） | D17: 直接部門 | F17: 4945 | G17: 4939 | H17: 4951 | I17: 671 | J17: 665 | K17: 663 | L17: 771 | M17: 765 | N17: 769 | O17: 790 | P17: 855 | Q17: 865 | R17: =SUM(F17:Q17) -> 21649
B18: 出向社員残業 | C18: 残業時間（移動分日本社員） | D18: 直接部門 | R18: =SUM(F18:Q18) -> 0
B19: ローカル社員残業 | C19: 残業時間（移動分ベトナム社員） | D19: 直接部門 | R19: =SUM(F19:Q19) -> 0
C20: 残業時間（部内間接部門） | D20: 部内間接部門 | R20: =SUM(F20:Q20) -> 0 | S20: この分には間接部門から直接部門に配賦された数字
C21: 残業時間（部外間接部門1） | D21: 部外間接部門1 | R21: =SUM(F21:Q21) -> 0 | S21: この分には間接部門から直接部門に配賦された数字
C22: 残業時間（部外間接部門2） | D22: 部外間接部門2 | R22: =SUM(F22:Q22) -> 0 | S22: この分には間接部門から直接部門に配賦された数字
C23: 残業時間（工場間接部門） | D23: 工場間接部門 | R23: =SUM(F23:Q23) -> 0 | S23: この分には間接部門から直接部門に配賦された数字
B24: 出向社員(人) | C24: 出向社員(人) | D24: 出向社員(人) | F24: 2 | G24: 2 | H24: 2 | I24: 2 | J24: 2 | K24: 2 | L24: 2 | M24: 2 | N24: 2 | O24: 2 | P24: 2 | Q24: 2 | R24: =Q24 -> 2
B25: ローカル社員(人) | C25: ローカル社員(人) | D25: ローカル社員(人) | F25: 196 | G25: 196 | H25: 196 | I25: 26 | J25: 26 | K25: 26 | L25: 30 | M25: 30 | N25: 30 | O25: 31 | P25: 34 | Q25: 34 | R25: =Q25 -> 34 | V25: 4 | W25: 5 | X25: 6 | Y25: 7 | Z25: 8 | AA25: 9 | AB25: 10 | AC25: 11 | AD25: 12 | AE25: 1 | AF25: 2 | AG25: 3
B26: 9114120002 | C26: =IFERROR(IF(VLOOKUP($B26,勘定科目!$A:$H,HLOOKUP($E$5,勘定科目!$F$1:$H$2,2,0),0)="","",VLOOKUP($B26,勘定科目!$A:$E,2,0)),"") -> 社外出荷 | D26: =IF(C26="","",VLOOKUP($B26,勘定科目!$A:$E,4,0)) -> 社外出荷 | F26: =ROUNDDOWN(V26*$B$2,0) -> 0 | G26: =ROUNDDOWN(W26*$B$2,0) -> 0 | H26: =ROUNDDOWN(X26*$B$2,0) -> 0 | I26: =ROUNDDOWN(Y26*$B$2,0) -> 0 | J26: =ROUNDDOWN(Z26*$B$2,0) -> 0 | K26: =ROUNDDOWN(AA26*$B$2,0) -> 0 | L26: =ROUNDDOWN(AB26*$B$2,0) -> 0 | M26: =ROUNDDOWN(AC26*$B$2,0) -> 0 | ... Q26: =ROUNDDOWN(AG26*$B$2,0) -> 0 | R26: =SUM(F26:Q26) -> 0 | S26: 総生産
B27: 9114120004 | C27: =IFERROR(IF(VLOOKUP($B27,勘定科目!$A:$H,HLOOKUP($E$5,勘定科目!$F$1:$H$2,2,0),0)="","",VLOOKUP($B27,勘定科目!$A:$E,2,0)),"") -> 社内売 | D27: =IF(C27="","",VLOOKUP($B27,勘定科目!$A:$E,4,0)) -> 社内売 | F27: =ROUNDDOWN(V27*$B$2,0) -> 0 | G27: =ROUNDDOWN(W27*$B$2,0) -> 0 | H27: =ROUNDDOWN(X27*$B$2,0) -> 0 | I27: =ROUNDDOWN(Y27*$B$2,0) -> 0 | J27: =ROUNDDOWN(Z27*$B$2,0) -> 0 | K27: =ROUNDDOWN(AA27*$B$2,0) -> 0 | L27: =ROUNDDOWN(AB27*$B$2,0) -> 0 | M27: =ROUNDDOWN(AC27*$B$2,0) -> 0 | ... Q27: =ROUNDDOWN(AG27*$B$2,0) -> 0 | R27: =SUM(F27:Q27) -> 0 | S27: 総生産
B28: 9114120014 | C28: =IFERROR(IF(VLOOKUP($B28,勘定科目!$A:$H,HLOOKUP($E$5,勘定科目!$F$1:$H$2,2,0),0)="","",VLOOKUP($B28,勘定科目!$A:$E,2,0)),"") -> 社内買 | D28: =IF(C28="","",VLOOKUP($B28,勘定科目!$A:$E,4,0)) -> 社内買 | F28: =ROUNDDOWN(V28*$B$2,0) -> 0 | G28: =ROUNDDOWN(W28*$B$2,0) -> 0 | H28: =ROUNDDOWN(X28*$B$2,0) -> 0 | I28: =ROUNDDOWN(Y28*$B$2,0) -> 0 | J28: =ROUNDDOWN(Z28*$B$2,0) -> 0 | K28: =ROUNDDOWN(AA28*$B$2,0) -> 0 | L28: =ROUNDDOWN(AB28*$B$2,0) -> 0 | M28: =ROUNDDOWN(AC28*$B$2,0) -> 0 | ... Q28: =ROUNDDOWN(AG28*$B$2,0) -> 0 | R28: =SUM(F28:Q28) -> 0 | S28: 総生産
B29: 9114120006 | C29: =IFERROR(IF(VLOOKUP($B29,勘定科目!$A:$H,HLOOKUP($E$5,勘定科目!$F$1:$H$2,2,0),0)="","",VLOOKUP($B29,勘定科目!$A:$E,2,0)),"") -> 材料費(指図出庫） | D29: =IF(C29="","",VLOOKUP($B29,勘定科目!$A:$E,4,0)) -> 材料費 | F29: =ROUNDUP(V29*$B$2,0) -> 0 | G29: =ROUNDUP(W29*$B$2,0) -> 0 | H29: =ROUNDUP(X29*$B$2,0) -> 0 | I29: =ROUNDUP(Y29*$B$2,0) -> 0 | J29: =ROUNDUP(Z29*$B$2,0) -> 0 | K29: =ROUNDUP(AA29*$B$2,0) -> 0 | L29: =ROUNDUP(AB29*$B$2,0) -> 0 | M29: =ROUNDUP(AC29*$B$2,0) -> 0 | ... Q29: =ROUNDUP(AG29*$B$2,0) -> 0 | R29: =SUM(F29:Q29) -> 0 | S29: 総生産
C30: =IFERROR(IF(VLOOKUP($B30,勘定科目!$A:$H,HLOOKUP($E$5,勘定科目!$F$1:$H$2,2,0),0)="","",VLOOKUP($B30,勘定科目!$A:$E,2,0)),"") | D30: =IF(C30="","",VLOOKUP($B30,勘定科目!$A:$E,4,0)) | R30: =SUM(F30:Q30) -> 0
B31: 9114120018 | C31: =IFERROR(IF(VLOOKUP($B31,勘定科目!$A:$H,HLOOKUP($E$5,勘定科目!$F$1:$H$2,2,0),0)="","",VLOOKUP($B31,勘定科目!$A:$E,2,0)),"") -> 部内間接経費 | D31: =IF(C31="","",VLOOKUP($B31,勘定科目!$A:$E,4,0)) -> 部内間接経費 | R31: =SUM(F31:Q31) -> 0 | S31: この分には間接部門から直接部門に配賦された数字
B32: 9114120029 | C32: =IFERROR(IF(VLOOKUP($B32,勘定科目!$A:$H,HLOOKUP($E$5,勘定科目!$F$1:$H$2,2,0),0)="","",VLOOKUP($B32,勘定科目!$A:$E,2,0)),"") -> 部外間接経費1 | D32: =IF(C32="","",VLOOKUP($B32,勘定科目!$A:$E,4,0)) -> 部外間接経費1 | R32: =SUM(F32:Q32) -> 0 | S32: この分には間接部門から直接部門に配賦された数字
B33: 9114120030 | C33: =IFERROR(IF(VLOOKUP($B33,勘定科目!$A:$H,HLOOKUP($E$5,勘定科目!$F$1:$H$2,2,0),0)="","",VLOOKUP($B33,勘定科目!$A:$E,2,0)),"") -> 部外間接経費2 | D33: =IF(C33="","",VLOOKUP($B33,勘定科目!$A:$E,4,0)) -> 部外間接経費2 | R33: =SUM(F33:Q33) -> 0 | S33: この分には間接部門から直接部門に配賦された数字
B34: 9114120021 | C34: =IFERROR(IF(VLOOKUP($B34,勘定科目!$A:$H,HLOOKUP($E$5,勘定科目!$F$1:$H$2,2,0),0)="","",VLOOKUP($B34,勘定科目!$A:$E,2,0)),"") -> 工場間接経費 | D34: =IF(C34="","",VLOOKUP($B34,勘定科目!$A:$E,4,0)) -> 工場間接経費 | R34: =SUM(F34:Q34) -> 0 | S34: この分には間接部門から直接部門に配賦された数字
C35: =IFERROR(IF(VLOOKUP($B35,勘定科目!$A:$H,HLOOKUP($E$5,勘定科目!$F$1:$H$2,2,0),0)="","",VLOOKUP($B35,勘定科目!$A:$E,2,0)),"") | D35: =IF(C35="","",VLOOKUP($B35,勘定科目!$A:$E,4,0)) | R35: =SUM(F35:Q35) -> 0
B36: 9114120009 | C36: =IFERROR(IF(VLOOKUP($B36,勘定科目!$A:$H,HLOOKUP($E$5,勘定科目!$F$1:$H$2,2,0),0)="","",VLOOKUP($B36,勘定科目!$A:$E,2,0)),"") -> 社内金利（在庫） | D36: =IF(C36="","",VLOOKUP($B36,勘定科目!$A:$E,4,0)) -> 在庫金利 | R36: =SUM(F36:Q36) -> 0 | S36: LIBRA 2 PMT 在庫金利
C37: =IFERROR(IF(VLOOKUP($B37,勘定科目!$A:$H,HLOOKUP($E$5,勘定科目!$F$1:$H$2,2,0),0)="","",VLOOKUP($B37,勘定科目!$A:$E,2,0)),"") | D37: =IF(C37="","",VLOOKUP($B37,勘定科目!$A:$E,4,0)) | R37: =SUM(F37:Q37) -> 0
C38: =IFERROR(IF(VLOOKUP($B38,勘定科目!$A:$H,HLOOKUP($E$5,勘定科目!$F$1:$H$2,2,0),0)="","",VLOOKUP($B38,勘定科目!$A:$E,2,0)),"") | D38: =IF(C38="","",VLOOKUP($B38,勘定科目!$A:$E,4,0)) | R38: =SUM(F38:Q38) -> 0
B39: 9114120007 | C39: =IFERROR(IF(VLOOKUP($B39,勘定科目!$A:$H,HLOOKUP($E$5,勘定科目!$F$1:$H$2,2,0),0)="","",VLOOKUP($B39,勘定科目!$A:$E,2,0)),"") -> 社内金利（固定資産） | D39: =IF(C39="","",VLOOKUP($B39,勘定科目!$A:$E,4,0)) -> 固定資産金利 | R39: =SUM(F39:Q39) -> 0 | S39: 粉塵計測器 Máy đếm bụi
B40: 9114120007 | C40: =IFERROR(IF(VLOOKUP($B40,勘定科目!$A:$H,HLOOKUP($E$5,勘定科目!$F$1:$H$2,2,0),0)="","",VLOOKUP($B40,勘定科目!$A:$E,2,0)),"") -> 社内金利（固定資産） | D40: =IF(C40="","",VLOOKUP($B40,勘定科目!$A:$E,4,0)) -> 固定資産金利 | R40: =SUM(F40:Q40) -> 0 | S40: ライトĐèn pin Lãi
B41: 9114120007 | C41: =IFERROR(IF(VLOOKUP($B41,勘定科目!$A:$H,HLOOKUP($E$5,勘定科目!$F$1:$H$2,2,0),0)="","",VLOOKUP($B41,勘定科目!$A:$E,2,0)),"") -> 社内金利（固定資産） | D41: =IF(C41="","",VLOOKUP($B41,勘定科目!$A:$E,4,0)) -> 固定資産金利 | F41: =ROUND(1619.79*25390,0) -> 41126468 | G41: =ROUND(1529.32*25390,0) -> 38829435 | H41: =ROUND(1534.83*25390,0) -> 38969334 | I41: =ROUND(1493.85*25390,0) -> 37928852 | J41: =ROUND(737.76*25390,0) -> 18731726 | K41: =ROUND(720.04*25390,0)-254 -> 18281562 | L41: =ROUND(711.72*25390,0)-254 -> 18070317 | M41: =ROUND(710.23*25390,0)+253 -> 18032993 | N41: =ROUND(711.31*25390,0)+1 -> 18060162 | O41: =ROUND(708.23*25390,0) -> 17981960 | P41: =ROUND(710.48*25390,0) -> 18039087 | Q41: =ROUND(722.6*25390,0)+254 -> 18347068 | R41: =SUM(F41:Q41) -> 302398964 | S41: 固定資産金利/Interest (建物Building) Lãi TSCĐ ( Nhà) | BD41: #REF!
...

Sheet 設備投資計画
B1: 設備投資金額一覧表 | D1: ='内訳ﾘｽﾄ(4～3月)'!C5 -> 工程品質管理1課 | E1: (単位： VND)
B3: 部門ｺｰﾄﾞ | C3: 購入物品名 | D3: 目 的 | E3: 4 | F3: 5 | G3: 6 | H3: 7 | I3: 8 | J3: 9 | K3: 10 | L3: 11 | M3: 12 | N3: 1 | O3: 2 | P3: 3 | Q3: 償却期間 (ヶ月) | R3: 購入金額合計 | S3: WBS
R4: =SUM(E4:P4) -> 0
R5: =SUM(E5:P5) -> 0
R6: =SUM(E6:P6) -> 0
R7: =SUM(E7:P7) -> 0
R8: =SUM(E8:P8) -> 0
R9: =SUM(E9:P9) -> 0
R10: =SUM(E10:P10) -> 0
R11: =SUM(E11:P11) -> 0
R12: =SUM(E12:P12) -> 0
R13: =SUM(E13:P13) -> 0
R14: =SUM(E14:P14) -> 0
R15: =SUM(E15:P15) -> 0
... R49: =SUM(E49:P49) -> 0
D50: TOTAL | R50: =SUM(E50:P50) -> 0
B52: ＊設備投資は、30,000,000VND以上、且つ1年以上使用するものが対象となります。
B53: ＊建設仮勘定を含む、取得基準にて記入して下さい。
B54: ＊重複を避ける為、稟議起案部門にて記入して下さい。
B55: ＊リースによる設備投資を含めないで下さい。

Sheet 勘定科目
A1: Account_Code | B1: JPN (50cha) | C1: Tiếng Việt_Tên tài khoản kế toán | D1: JP_Name | E1: Tiếng Việt_Hạng mục lợi nhuận | F1: 製造 | G1: 一般 | H1: 販売 | I1: REMARK
F2: =COLUMNS($A$2:F2) -> 6 | G2: =COLUMNS($A$2:G2) -> 7 | H2: =COLUMNS($A$2:H2) -> 8
A3: 7001065118 | B3: 雑収入 | C3: Doanh thu khác | D3: 雑収入 | E3: Thu nhập khác | F3: 7001065118 | G3: 7001065118 | H3: 7001065118
