Workbook
Name WBS: 原価センタ!$G$2:$G$3

Sheet 採算表(USD)
B1: 組織名 | C1: ='採算表(VND)'!C1 -> MP FY2026_各予定 | N1: ='内訳ﾘｽﾄ(4～3月)'!B2 -> 25390
B2: ='採算表(VND)'!B2 -> 総務課
B4: 項目 ＼ 部門 | C4: ='採算表(VND)'!C4 -> 4 | D4: ='採算表(VND)'!D4 -> 5 | E4: ='採算表(VND)'!E4 -> 6 | F4: ='採算表(VND)'!F4 -> 7 | G4: ='採算表(VND)'!G4 -> 8 | H4: ='採算表(VND)'!H4 -> 9 | I4: ='採算表(VND)'!I4 -> 10 | J4: ='採算表(VND)'!J4 -> 11 | ... O4: ='採算表(VND)'!O4 -> 合計
B5: 総出荷 | C5: =C8+C9 -> 0 | D5: =D8+D9 -> 0 | E5: =E8+E9 -> 0 | F5: =F8+F9 -> 0 | G5: =G8+G9 -> 0 | H5: =H8+H9 -> 0 | I5: =I8+I9 -> 0 | J5: =J8+J9 -> 0 | ... O5: =O8+O9 -> 0
B6: 社外出荷 | C6: =ROUNDDOWN('採算表(VND)'!C6/$N$1,2) -> 0 | D6: =ROUNDDOWN('採算表(VND)'!D6/$N$1,2) -> 0 | E6: =ROUNDDOWN('採算表(VND)'!E6/$N$1,2) -> 0 | F6: =ROUNDDOWN('採算表(VND)'!F6/$N$1,2) -> 0 | G6: =ROUNDDOWN('採算表(VND)'!G6/$N$1,2) -> 0 | H6: =ROUNDDOWN('採算表(VND)'!H6/$N$1,2) -> 0 | I6: =ROUNDDOWN('採算表(VND)'!I6/$N$1,2) -> 0 | J6: =ROUNDDOWN('採算表(VND)'!J6/$N$1,2) -> 0 | ... N6: =ROUNDDOWN('採算表(VND)'!N6/$N$1,2) -> 0 | O6: =SUM(C6:N6) -> 0
B7: 販売支援 | C7: =ROUNDDOWN('採算表(VND)'!C7/$N$1,2) -> 0 | D7: =ROUNDDOWN('採算表(VND)'!D7/$N$1,2) -> 0 | E7: =ROUNDDOWN('採算表(VND)'!E7/$N$1,2) -> 0 | F7: =ROUNDDOWN('採算表(VND)'!F7/$N$1,2) -> 0 | G7: =ROUNDDOWN('採算表(VND)'!G7/$N$1,2) -> 0 | H7: =ROUNDDOWN('採算表(VND)'!H7/$N$1,2) -> 0 | I7: =ROUNDDOWN('採算表(VND)'!I7/$N$1,2) -> 0 | J7: =ROUNDDOWN('採算表(VND)'!J7/$N$1,2) -> 0 | ... N7: =ROUNDDOWN('採算表(VND)'!N7/$N$1,2) -> 0 | O7: =SUM(C7:N7) -> 0
B8: 社外出荷合計 | C8: =C6+C7 -> 0 | D8: =D6+D7 -> 0 | E8: =E6+E7 -> 0 | F8: =F6+F7 -> 0 | G8: =G6+G7 -> 0 | H8: =H6+H7 -> 0 | I8: =I6+I7 -> 0 | J8: =J6+J7 -> 0 | ... O8: =O6+O7 -> 0
B9: 社内売 | C9: =ROUNDDOWN('採算表(VND)'!C9/$N$1,2) -> 0 | D9: =ROUNDDOWN('採算表(VND)'!D9/$N$1,2) -> 0 | E9: =ROUNDDOWN('採算表(VND)'!E9/$N$1,2) -> 0 | F9: =ROUNDDOWN('採算表(VND)'!F9/$N$1,2) -> 0 | G9: =ROUNDDOWN('採算表(VND)'!G9/$N$1,2) -> 0 | H9: =ROUNDDOWN('採算表(VND)'!H9/$N$1,2) -> 0 | I9: =ROUNDDOWN('採算表(VND)'!I9/$N$1,2) -> 0 | J9: =ROUNDDOWN('採算表(VND)'!J9/$N$1,2) -> 0 | ... N9: =ROUNDDOWN('採算表(VND)'!N9/$N$1,2) -> 0 | O9: =SUM(C9:N9) -> 0
B10: 社内買 | C10: =ROUNDDOWN('採算表(VND)'!C10/$N$1,2) -> 0 | D10: =ROUNDDOWN('採算表(VND)'!D10/$N$1,2) -> 0 | E10: =ROUNDDOWN('採算表(VND)'!E10/$N$1,2) -> 0 | F10: =ROUNDDOWN('採算表(VND)'!F10/$N$1,2) -> 0 | G10: =ROUNDDOWN('採算表(VND)'!G10/$N$1,2) -> 0 | H10: =ROUNDDOWN('採算表(VND)'!H10/$N$1,2) -> 0 | I10: =ROUNDDOWN('採算表(VND)'!I10/$N$1,2) -> 0 | J10: =ROUNDDOWN('採算表(VND)'!J10/$N$1,2) -> 0 | ... N10: =ROUNDDOWN('採算表(VND)'!N10/$N$1,2) -> 0 | O10: =SUM(C10:N10) -> 0
B12: 総生産 | C12: =C5-C10 -> 0 | D12: =D5-D10 -> 0 | E12: =E5-E10 -> 0 | F12: =F5-F10 -> 0 | G12: =G5-G10 -> 0 | H12: =H5-H10 -> 0 | I12: =I5-I10 -> 0 | J12: =J5-J10 -> 0 | ... O12: =O5-O10 -> 0
B13: 控除額 | C13: =SUM(C14:C65) -> 0.06 | D13: =SUM(D14:D65) -> 0.06 | E13: =SUM(E14:E65) -> 0.04 | F13: =SUM(F14:F65) -> 0.05 | G13: =SUM(G14:G65) -> 0.06 | H13: =SUM(H14:H65) -> 0.07 | I13: =SUM(I14:I65) -> 0.05 | J13: =SUM(J14:J65) -> 0.06 | ... O13: =SUM(O14:O65) -> 0.7
B14: 材料費 | C14: =ROUNDUP('採算表(VND)'!C14/$N$1,2) -> 0 | D14: =ROUNDUP('採算表(VND)'!D14/$N$1,2) -> 0 | E14: =ROUNDUP('採算表(VND)'!E14/$N$1,2) -> 0 | F14: =ROUNDUP('採算表(VND)'!F14/$N$1,2) -> 0 | G14: =ROUNDUP('採算表(VND)'!G14/$N$1,2) -> 0 | H14: =ROUNDUP('採算表(VND)'!H14/$N$1,2) -> 0 | I14: =ROUNDUP('採算表(VND)'!I14/$N$1,2) -> 0 | J14: =ROUNDUP('採算表(VND)'!J14/$N$1,2) -> 0 | ... N14: =ROUNDUP('採算表(VND)'!N14/$N$1,2) -> 0 | O14: =SUM(C14:N14) -> 0
B15: 設計変更材料費 | C15: =ROUNDUP('採算表(VND)'!C15/$N$1,2) -> 0 | D15: =ROUNDUP('採算表(VND)'!D15/$N$1,2) -> 0 | E15: =ROUNDUP('採算表(VND)'!E15/$N$1,2) -> 0 | F15: =ROUNDUP('採算表(VND)'!F15/$N$1,2) -> 0 | G15: =ROUNDUP('採算表(VND)'!G15/$N$1,2) -> 0 | H15: =ROUNDUP('採算表(VND)'!H15/$N$1,2) -> 0 | I15: =ROUNDUP('採算表(VND)'!I15/$N$1,2) -> 0 | J15: =ROUNDUP('採算表(VND)'!J15/$N$1,2) -> 0 | ... N15: =ROUNDUP('採算表(VND)'!N15/$N$1,2) -> 0 | O15: =SUM(C15:N15) -> 0
B16: 仕掛仕損 | C16: =ROUNDUP('採算表(VND)'!C16/$N$1,2) -> 0 | D16: =ROUNDUP('採算表(VND)'!D16/$N$1,2) -> 0 | E16: =ROUNDUP('採算表(VND)'!E16/$N$1,2) -> 0 | F16: =ROUNDUP('採算表(VND)'!F16/$N$1,2) -> 0 | G16: =ROUNDUP('採算表(VND)'!G16/$N$1,2) -> 0 | H16: =ROUNDUP('採算表(VND)'!H16/$N$1,2) -> 0 | I16: =ROUNDUP('採算表(VND)'!I16/$N$1,2) -> 0 | J16: =ROUNDUP('採算表(VND)'!J16/$N$1,2) -> 0 | ... N16: =ROUNDUP('採算表(VND)'!N16/$N$1,2) -> 0 | O16: =SUM(C16:N16) -> 0
B17: 仕入製商品費 | C17: =ROUNDUP('採算表(VND)'!C17/$N$1,2) -> 0 | D17: =ROUNDUP('採算表(VND)'!D17/$N$1,2) -> 0 | E17: =ROUNDUP('採算表(VND)'!E17/$N$1,2) -> 0 | F17: =ROUNDUP('採算表(VND)'!F17/$N$1,2) -> 0 | G17: =ROUNDUP('採算表(VND)'!G17/$N$1,2) -> 0 | H17: =ROUNDUP('採算表(VND)'!H17/$N$1,2) -> 0 | I17: =ROUNDUP('採算表(VND)'!I17/$N$1,2) -> 0 | J17: =ROUNDUP('採算表(VND)'!J17/$N$1,2) -> 0 | ... N17: =ROUNDUP('採算表(VND)'!N17/$N$1,2) -> 0 | O17: =SUM(C17:N17) -> 0
B18: 内製品有償支給原価 | C18: =ROUNDUP('採算表(VND)'!C18/$N$1,2) -> 0 | D18: =ROUNDUP('採算表(VND)'!D18/$N$1,2) -> 0 | E18: =ROUNDUP('採算表(VND)'!E18/$N$1,2) -> 0 | F18: =ROUNDUP('採算表(VND)'!F18/$N$1,2) -> 0 | G18: =ROUNDUP('採算表(VND)'!G18/$N$1,2) -> 0 | H18: =ROUNDUP('採算表(VND)'!H18/$N$1,2) -> 0 | I18: =ROUNDUP('採算表(VND)'!I18/$N$1,2) -> 0 | J18: =ROUNDUP('採算表(VND)'!J18/$N$1,2) -> 0 | ... N18: =ROUNDUP('採算表(VND)'!N18/$N$1,2) -> 0 | O18: =SUM(C18:N18) -> 0
B19: 外注加工費 | C19: =ROUNDUP('採算表(VND)'!C19/$N$1,2) -> 0 | D19: =ROUNDUP('採算表(VND)'!D19/$N$1,2) -> 0 | E19: =ROUNDUP('採算表(VND)'!E19/$N$1,2) -> 0 | F19: =ROUNDUP('採算表(VND)'!F19/$N$1,2) -> 0 | G19: =ROUNDUP('採算表(VND)'!G19/$N$1,2) -> 0 | H19: =ROUNDUP('採算表(VND)'!H19/$N$1,2) -> 0 | I19: =ROUNDUP('採算表(VND)'!I19/$N$1,2) -> 0 | J19: =ROUNDUP('採算表(VND)'!J19/$N$1,2) -> 0 | ... N19: =ROUNDUP('採算表(VND)'!N19/$N$1,2) -> 0 | O19: =SUM(C19:N19) -> 0
B20: 減価償却費 | C20: =ROUNDUP('採算表(VND)'!C20/$N$1,2) -> 20970.69 | D20: =ROUNDUP('採算表(VND)'!D20/$N$1,2) -> 20988.92 | E20: =ROUNDUP('採算表(VND)'!E20/$N$1,2) -> 20989.03 | F20: =ROUNDUP('採算表(VND)'!F20/$N$1,2) -> 21054.4 | G20: =ROUNDUP('採算表(VND)'!G20/$N$1,2) -> 21054.28 | H20: =ROUNDUP('採算表(VND)'!H20/$N$1,2) -> 21048.7 | I20: =ROUNDUP('採算表(VND)'!I20/$N$1,2) -> 21202.64 | J20: =ROUNDUP('採算表(VND)'!J20/$N$1,2) -> 21202.58 | ... N20: =ROUNDUP('採算表(VND)'!N20/$N$1,2) -> 21202.48 | O20: =SUM(C20:N20) -> 253321.08
B21: 金型償却費 | C21: =ROUNDUP('採算表(VND)'!C21/$N$1,2) -> 0 | D21: =ROUNDUP('採算表(VND)'!D21/$N$1,2) -> 0 | E21: =ROUNDUP('採算表(VND)'!E21/$N$1,2) -> 0 | F21: =ROUNDUP('採算表(VND)'!F21/$N$1,2) -> 0 | G21: =ROUNDUP('採算表(VND)'!G21/$N$1,2) -> 0 | H21: =ROUNDUP('採算表(VND)'!H21/$N$1,2) -> 0 | I21: =ROUNDUP('採算表(VND)'!I21/$N$1,2) -> 0 | J21: =ROUNDUP('採算表(VND)'!J21/$N$1,2) -> 0 | ... N21: =ROUNDUP('採算表(VND)'!N21/$N$1,2) -> 0 | O21: =SUM(C21:N21) -> 0
B22: 賃借料 | C22: =ROUNDUP('採算表(VND)'!C22/$N$1,2) -> 0 | D22: =ROUNDUP('採算表(VND)'!D22/$N$1,2) -> 0 | E22: =ROUNDUP('採算表(VND)'!E22/$N$1,2) -> 0 | F22: =ROUNDUP('採算表(VND)'!F22/$N$1,2) -> 0 | G22: =ROUNDUP('採算表(VND)'!G22/$N$1,2) -> 0 | H22: =ROUNDUP('採算表(VND)'!H22/$N$1,2) -> 0 | I22: =ROUNDUP('採算表(VND)'!I22/$N$1,2) -> 0 | J22: =ROUNDUP('採算表(VND)'!J22/$N$1,2) -> 0 | ... N22: =ROUNDUP('採算表(VND)'!N22/$N$1,2) -> 0 | O22: =SUM(C22:N22) -> 0
B23: 保険料 | C23: =ROUNDUP('採算表(VND)'!C23/$N$1,2) -> 0 | D23: =ROUNDUP('採算表(VND)'!D23/$N$1,2) -> 2166.21 | E23: =ROUNDUP('採算表(VND)'!E23/$N$1,2) -> 0 | F23: =ROUNDUP('採算表(VND)'!F23/$N$1,2) -> 0 | G23: =ROUNDUP('採算表(VND)'!G23/$N$1,2) -> 0 | H23: =ROUNDUP('採算表(VND)'!H23/$N$1,2) -> 0 | I23: =ROUNDUP('採算表(VND)'!I23/$N$1,2) -> 0 | J23: =ROUNDUP('採算表(VND)'!J23/$N$1,2) -> 0 | ... N23: =ROUNDUP('採算表(VND)'!N23/$N$1,2) -> 0 | O23: =SUM(C23:N23) -> 2166.21
B24: 設計委託費 | C24: =ROUNDUP('採算表(VND)'!C24/$N$1,2) -> 0 | D24: =ROUNDUP('採算表(VND)'!D24/$N$1,2) -> 0 | E24: =ROUNDUP('採算表(VND)'!E24/$N$1,2) -> 0 | F24: =ROUNDUP('採算表(VND)'!F24/$N$1,2) -> 0 | G24: =ROUNDUP('採算表(VND)'!G24/$N$1,2) -> 0 | H24: =ROUNDUP('採算表(VND)'!H24/$N$1,2) -> 0 | I24: =ROUNDUP('採算表(VND)'!I24/$N$1,2) -> 0 | J24: =ROUNDUP('採算表(VND)'!J24/$N$1,2) -> 0 | ... N24: =ROUNDUP('採算表(VND)'!N24/$N$1,2) -> 0 | O24: =SUM(C24:N24) -> 0
B25: 消耗品費 | C25: =ROUNDUP('採算表(VND)'!C25/$N$1,2) -> 139.32 | D25: =ROUNDUP('採算表(VND)'!D25/$N$1,2) -> 97.15 | E25: =ROUNDUP('採算表(VND)'!E25/$N$1,2) -> 140.93 | F25: =ROUNDUP('採算表(VND)'!F25/$N$1,2) -> 99.42 | G25: =ROUNDUP('採算表(VND)'!G25/$N$1,2) -> 139.92 | H25: =ROUNDUP('採算表(VND)'!H25/$N$1,2) -> 103.85 | I25: =ROUNDUP('採算表(VND)'!I25/$N$1,2) -> 141.27 | J25: =ROUNDUP('採算表(VND)'!J25/$N$1,2) -> 97.72 | ... N25: =ROUNDUP('採算表(VND)'!N25/$N$1,2) -> 97.56 | O25: =SUM(C25:N25) -> 1433.12
... B65: 本社機構経費 | C65: =ROUNDUP('採算表(VND)'!C65/$N$1,2) -> 0 | D65: =ROUNDUP('採算表(VND)'!D65/$N$1,2) -> 0 | E65: =ROUNDUP('採算表(VND)'!E65/$N$1,2) -> 0 | F65: =ROUNDUP('採算表(VND)'!F65/$N$1,2) -> 0 | G65: =ROUNDUP('採算表(VND)'!G65/$N$1,2) -> 0 | H65: =ROUNDUP('採算表(VND)'!H65/$N$1,2) -> 0 | I65: =ROUNDUP('採算表(VND)'!I65/$N$1,2) -> 0 | J65: =ROUNDUP('採算表(VND)'!J65/$N$1,2) -> 0 | ... N65: =ROUNDUP('採算表(VND)'!N65/$N$1,2) -> 0 | O65: =SUM(C65:N65) -> 0
B66: 差引収益 | C66: =C12-C13 -> -0.06 | D66: =IF(ISBLANK(D4),"",D12-D13) -> -0.06 | E66: =IF(ISBLANK(E4),"",E12-E13) -> -0.04 | F66: =IF(ISBLANK(F4),"",F12-F13) -> -0.05 | G66: =IF(ISBLANK(G4),"",G12-G13) -> -0.06 | H66: =IF(ISBLANK(H4),"",H12-H13) -> -0.07 | I66: =IF(ISBLANK(I4),"",I12-I13) -> -0.05 | J66: =IF(ISBLANK(J4),"",J12-J13) -> -0.06 | K66: =IF(ISBLANK(K4),"",K12-K13) -> -0.06 | ... O66: =IF(ISBLANK(O4),"",O12-O13) -> -0.7
B67: 総時間 | C67: =C73+C79 -> 0 | D67: =IF(ISBLANK(D4),"",D73+D79) -> 0 | E67: =IF(ISBLANK(E4),"",E73+E79) -> 0 | F67: =IF(ISBLANK(F4),"",F73+F79) -> 0 | G67: =IF(ISBLANK(G4),"",G73+G79) -> 0 | H67: =IF(ISBLANK(H4),"",H73+H79) -> 0 | I67: =IF(ISBLANK(I4),"",I73+I79) -> 0 | J67: =IF(ISBLANK(J4),"",J73+J79) -> 0 | K67: =IF(ISBLANK(K4),"",K73+K79) -> 0 | ... O67: =IF(ISBLANK(O4),"",O73+O79) -> 0
B68: 直接部門 | C68: ='採算表(VND)'!C68 -> 2767 | D68: ='採算表(VND)'!D68 -> 2709.5 | E68: ='採算表(VND)'!E68 -> 2979.5 | F68: ='採算表(VND)'!F68 -> 3190 | G68: ='採算表(VND)'!G68 -> 2767 | H68: ='採算表(VND)'!H68 -> 2616 | I68: ='採算表(VND)'!I68 -> 3190 | J68: ='採算表(VND)'!J68 -> 2767 | ... N68: ='採算表(VND)'!N68 -> 2902 | O68: =SUM(C68:N68) -> 34066
B69: 部内間接部門 | C69: ='採算表(VND)'!C69 -> 0 | D69: ='採算表(VND)'!D69 -> 0 | E69: ='採算表(VND)'!E69 -> 0 | F69: ='採算表(VND)'!F69 -> 0 | G69: ='採算表(VND)'!G69 -> 0 | H69: ='採算表(VND)'!H69 -> 0 | I69: ='採算表(VND)'!I69 -> 0 | J69: ='採算表(VND)'!J69 -> 0 | ... N69: ='採算表(VND)'!N69 -> 0 | O69: =SUM(C69:N69) -> 0
B70: 部外間接部門1 | C70: ='採算表(VND)'!C70 -> 0 | D70: ='採算表(VND)'!D70 -> 0 | E70: ='採算表(VND)'!E70 -> 0 | F70: ='採算表(VND)'!F70 -> 0 | G70: ='採算表(VND)'!G70 -> 0 | H70: ='採算表(VND)'!H70 -> 0 | I70: ='採算表(VND)'!I70 -> 0 | J70: ='採算表(VND)'!J70 -> 0 | ... N70: ='採算表(VND)'!N70 -> 0 | O70: =SUM(C70:N70) -> 0
B71: 部外間接部門2 | C71: ='採算表(VND)'!C71 -> 0 | D71: ='採算表(VND)'!D71 -> 0 | E71: ='採算表(VND)'!E71 -> 0 | F71: ='採算表(VND)'!F71 -> 0 | G71: ='採算表(VND)'!G71 -> 0 | H71: ='採算表(VND)'!H71 -> 0 | I71: ='採算表(VND)'!I71 -> 0 | J71: ='採算表(VND)'!J71 -> 0 | ... N71: ='採算表(VND)'!N71 -> 0 | O71: =SUM(C71:N71) -> 0
B72: 工場間接部門 | C72: ='採算表(VND)'!C72 -> -2767 | D72: ='採算表(VND)'!D72 -> -2709.5 | E72: ='採算表(VND)'!E72 -> -2979.5 | F72: ='採算表(VND)'!F72 -> -3190 | G72: ='採算表(VND)'!G72 -> -2767 | H72: ='採算表(VND)'!H72 -> -2616 | I72: ='採算表(VND)'!I72 -> -3190 | J72: ='採算表(VND)'!J72 -> -2767 | ... N72: ='採算表(VND)'!N72 -> -2902 | O72: =SUM(C72:N72) -> -34066
B73: 定時間合計 | C73: =SUM(C68:C72) -> 0 | D73: =IF(ISBLANK(D4),"",SUM(D68:D72)) -> 0 | E73: =IF(ISBLANK(E4),"",SUM(E68:E72)) -> 0 | F73: =IF(ISBLANK(F4),"",SUM(F68:F72)) -> 0 | G73: =IF(ISBLANK(G4),"",SUM(G68:G72)) -> 0 | H73: =IF(ISBLANK(H4),"",SUM(H68:H72)) -> 0 | I73: =IF(ISBLANK(I4),"",SUM(I68:I72)) -> 0 | J73: =IF(ISBLANK(J4),"",SUM(J68:J72)) -> 0 | K73: =IF(ISBLANK(K4),"",SUM(K68:K72)) -> 0 | ... O73: =IF(ISBLANK(O4),"",SUM(O68:O72)) -> 0
B74: 直接部門 | C74: ='採算表(VND)'!C74 -> 176.5 | D74: ='採算表(VND)'!D74 -> 193.5 | E74: ='採算表(VND)'!E74 -> 185.5 | F74: ='採算表(VND)'!F74 -> 203.5 | G74: ='採算表(VND)'!G74 -> 176.5 | H74: ='採算表(VND)'!H74 -> 251.5 | I74: ='採算表(VND)'!I74 -> 203.5 | J74: ='採算表(VND)'!J74 -> 246.5 | ... N74: ='採算表(VND)'!N74 -> 176.5 | O74: =SUM(C74:N74) -> 2316
B75: 部内間接部門 | C75: ='採算表(VND)'!C75 -> 0 | D75: ='採算表(VND)'!D75 -> 0 | E75: ='採算表(VND)'!E75 -> 0 | F75: ='採算表(VND)'!F75 -> 0 | G75: ='採算表(VND)'!G75 -> 0 | H75: ='採算表(VND)'!H75 -> 0 | I75: ='採算表(VND)'!I75 -> 0 | J75: ='採算表(VND)'!J75 -> 0 | ... N75: ='採算表(VND)'!N75 -> 0 | O75: =SUM(C75:N75) -> 0
B76: 部外間接部門1 | C76: ='採算表(VND)'!C76 -> 0 | D76: ='採算表(VND)'!D76 -> 0 | E76: ='採算表(VND)'!E76 -> 0 | F76: ='採算表(VND)'!F76 -> 0 | G76: ='採算表(VND)'!G76 -> 0 | H76: ='採算表(VND)'!H76 -> 0 | I76: ='採算表(VND)'!I76 -> 0 | J76: ='採算表(VND)'!J76 -> 0 | ... N76: ='採算表(VND)'!N76 -> 0 | O76: =SUM(C76:N76) -> 0
B77: 部外間接部門2 | C77: ='採算表(VND)'!C77 -> 0 | D77: ='採算表(VND)'!D77 -> 0 | E77: ='採算表(VND)'!E77 -> 0 | F77: ='採算表(VND)'!F77 -> 0 | G77: ='採算表(VND)'!G77 -> 0 | H77: ='採算表(VND)'!H77 -> 0 | I77: ='採算表(VND)'!I77 -> 0 | J77: ='採算表(VND)'!J77 -> 0 | ... N77: ='採算表(VND)'!N77 -> 0 | O77: =SUM(C77:N77) -> 0
B78: 工場間接部門 | C78: ='採算表(VND)'!C78 -> -176.5 | D78: ='採算表(VND)'!D78 -> -193.5 | E78: ='採算表(VND)'!E78 -> -185.5 | F78: ='採算表(VND)'!F78 -> -203.5 | G78: ='採算表(VND)'!G78 -> -176.5 | H78: ='採算表(VND)'!H78 -> -251.5 | I78: ='採算表(VND)'!I78 -> -203.5 | J78: ='採算表(VND)'!J78 -> -246.5 | ... N78: ='採算表(VND)'!N78 -> -176.5 | O78: =SUM(C78:N78) -> -2316
B79: 残業時間合計 | C79: =SUM(C74:C78) -> 0 | D79: =IF(ISBLANK(D4),"",SUM(D74:D78)) -> 0 | E79: =IF(ISBLANK(E4),"",SUM(E74:E78)) -> 0 | F79: =IF(ISBLANK(F4),"",SUM(F74:F78)) -> 0 | G79: =IF(ISBLANK(G4),"",SUM(G74:G78)) -> 0 | H79: =IF(ISBLANK(H4),"",SUM(H74:H78)) -> 0 | I79: =IF(ISBLANK(I4),"",SUM(I74:I78)) -> 0 | J79: =IF(ISBLANK(J4),"",SUM(J74:J78)) -> 0 | K79: =IF(ISBLANK(K4),"",SUM(K74:K78)) -> 0 | ... O79: =IF(ISBLANK(O4),"",SUM(O74:O78)) -> 0
B80: 当月時間当り | C80: =IFERROR(ROUNDDOWN(C66/C67,0),0) -> 0 | D80: =IFERROR(ROUNDDOWN(D66/D67,0),0) -> 0 | E80: =IFERROR(ROUNDDOWN(E66/E67,0),0) -> 0 | F80: =IFERROR(ROUNDDOWN(F66/F67,0),0) -> 0 | G80: =IFERROR(ROUNDDOWN(G66/G67,0),0) -> 0 | H80: =IFERROR(ROUNDDOWN(H66/H67,0),0) -> 0 | I80: =IFERROR(ROUNDDOWN(I66/I67,0),0) -> 0 | J80: =IFERROR(ROUNDDOWN(J66/J67,0),0) -> 0 | ... O80: =IFERROR(ROUNDDOWN(O66/O67,0),0) -> 0
B81: 時間当り生産高 | C81: =IFERROR(ROUNDDOWN(C12/C67,0),0) -> 0 | D81: =IFERROR(ROUNDDOWN(D12/D67,0),0) -> 0 | E81: =IFERROR(ROUNDDOWN(E12/E67,0),0) -> 0 | F81: =IFERROR(ROUNDDOWN(F12/F67,0),0) -> 0 | G81: =IFERROR(ROUNDDOWN(G12/G67,0),0) -> 0 | H81: =IFERROR(ROUNDDOWN(H12/H67,0),0) -> 0 | I81: =IFERROR(ROUNDDOWN(I12/I67,0),0) -> 0 | J81: =IFERROR(ROUNDDOWN(J12/J67,0),0) -> 0 | ... O81: =IFERROR(ROUNDDOWN(O12/O67,0),0) -> 0
...

Sheet 採算表(VND)
B1: 組織名 | C1: ='内訳ﾘｽﾄ(4～3月)'!A1 -> MP FY2026_各予定
B2: ='内訳ﾘｽﾄ(4～3月)'!C5 -> 総務課
C3: 2 | D3: 3 | E3: 4 | F3: 5 | G3: 6 | H3: 7 | I3: 8 | J3: 9 | K3: 10 | L3: 11 | M3: 12 | N3: 13
B4: 項目 ＼ 部門 | C4: ='内訳ﾘｽﾄ(4～3月)'!F4 -> 4 | D4: 5 | E4: 6 | F4: 7 | G4: 8 | H4: 9 | I4: 10 | J4: 11 | K4: 12 | L4: 1 | M4: 2 | N4: 3 | O4: 合計
B5: 総出荷 | C5: =C8+C9 -> 0 | D5: =D8+D9 -> 0 | E5: =E8+E9 -> 0 | F5: =F8+F9 -> 0 | G5: =G8+G9 -> 0 | H5: =H8+H9 -> 0 | I5: =I8+I9 -> 0 | J5: =J8+J9 -> 0 | ... O5: =O8+O9 -> 0
B6: 社外出荷 | C6: =SUMIF('内訳ﾘｽﾄ(4～3月)'!$D$26:$D$973,'採算表(VND)'!$B6,'内訳ﾘｽﾄ(4～3月)'!F$26:F$973) -> 0 | D6: =SUMIF('内訳ﾘｽﾄ(4～3月)'!$D$26:$D$973,'採算表(VND)'!$B6,'内訳ﾘｽﾄ(4～3月)'!G$26:G$973) -> 0 | E6: =SUMIF('内訳ﾘｽﾄ(4～3月)'!$D$26:$D$973,'採算表(VND)'!$B6,'内訳ﾘｽﾄ(4～3月)'!H$26:H$973) -> 0 | F6: =SUMIF('内訳ﾘｽﾄ(4～3月)'!$D$26:$D$973,'採算表(VND)'!$B6,'内訳ﾘｽﾄ(4～3月)'!I$26:I$973) -> 0 | G6: =SUMIF('内訳ﾘｽﾄ(4～3月)'!$D$26:$D$973,'採算表(VND)'!$B6,'内訳ﾘｽﾄ(4～3月)'!J$26:J$973) -> 0 | H6: =SUMIF('内訳ﾘｽﾄ(4～3月)'!$D$26:$D$973,'採算表(VND)'!$B6,'内訳ﾘｽﾄ(4～3月)'!K$26:K$973) -> 0 | I6: =SUMIF('内訳ﾘｽﾄ(4～3月)'!$D$26:$D$973,'採算表(VND)'!$B6,'内訳ﾘｽﾄ(4～3月)'!L$26:L$973) -> 0 | J6: =SUMIF('内訳ﾘｽﾄ(4～3月)'!$D$26:$D$973,'採算表(VND)'!$B6,'内訳ﾘｽﾄ(4～3月)'!M$26:M$973) -> 0 | ... N6: =SUMIF('内訳ﾘｽﾄ(4～3月)'!$D$26:$D$973,'採算表(VND)'!$B6,'内訳ﾘｽﾄ(4～3月)'!Q$26:Q$973) -> 0 | O6: =SUMIF('内訳ﾘｽﾄ(4～3月)'!$D$26:$D$772,'採算表(VND)'!$B6,'内訳ﾘｽﾄ(4～3月)'!R$26:R$772) -> 0
B7: 販売支援 | C7: =SUMIF('内訳ﾘｽﾄ(4～3月)'!$D$26:$D$973,'採算表(VND)'!$B7,'内訳ﾘｽﾄ(4～3月)'!F$26:F$973) -> 0 | D7: =SUMIF('内訳ﾘｽﾄ(4～3月)'!$D$26:$D$973,'採算表(VND)'!$B7,'内訳ﾘｽﾄ(4～3月)'!G$26:G$973) -> 0 | E7: =SUMIF('内訳ﾘｽﾄ(4～3月)'!$D$26:$D$973,'採算表(VND)'!$B7,'内訳ﾘｽﾄ(4～3月)'!H$26:H$973) -> 0 | F7: =SUMIF('内訳ﾘｽﾄ(4～3月)'!$D$26:$D$973,'採算表(VND)'!$B7,'内訳ﾘｽﾄ(4～3月)'!I$26:I$973) -> 0 | G7: =SUMIF('内訳ﾘｽﾄ(4～3月)'!$D$26:$D$973,'採算表(VND)'!$B7,'内訳ﾘｽﾄ(4～3月)'!J$26:J$973) -> 0 | H7: =SUMIF('内訳ﾘｽﾄ(4～3月)'!$D$26:$D$973,'採算表(VND)'!$B7,'内訳ﾘｽﾄ(4～3月)'!K$26:K$973) -> 0 | I7: =SUMIF('内訳ﾘｽﾄ(4～3月)'!$D$26:$D$973,'採算表(VND)'!$B7,'内訳ﾘｽﾄ(4～3月)'!L$26:L$973) -> 0 | J7: =SUMIF('内訳ﾘｽﾄ(4～3月)'!$D$26:$D$973,'採算表(VND)'!$B7,'内訳ﾘｽﾄ(4～3月)'!M$26:M$973) -> 0 | ... N7: =SUMIF('内訳ﾘｽﾄ(4～3月)'!$D$26:$D$973,'採算表(VND)'!$B7,'内訳ﾘｽﾄ(4～3月)'!Q$26:Q$973) -> 0 | O7: =SUMIF('内訳ﾘｽﾄ(4～3月)'!$D$26:$D$772,'採算表(VND)'!$B7,'内訳ﾘｽﾄ(4～3月)'!R$26:R$772) -> 0
B8: 社外出荷合計 | C8: =C6+C7 -> 0 | D8: =D6+D7 -> 0 | E8: =E6+E7 -> 0 | F8: =F6+F7 -> 0 | G8: =G6+G7 -> 0 | H8: =H6+H7 -> 0 | I8: =I6+I7 -> 0 | J8: =J6+J7 -> 0 | ... O8: =O6+O7 -> 0
B9: 社内売 | C9: =SUMIF('内訳ﾘｽﾄ(4～3月)'!$D$26:$D$973,'採算表(VND)'!$B9,'内訳ﾘｽﾄ(4～3月)'!F$26:F$973) -> 0 | D9: =SUMIF('内訳ﾘｽﾄ(4～3月)'!$D$26:$D$973,'採算表(VND)'!$B9,'内訳ﾘｽﾄ(4～3月)'!G$26:G$973) -> 0 | E9: =SUMIF('内訳ﾘｽﾄ(4～3月)'!$D$26:$D$973,'採算表(VND)'!$B9,'内訳ﾘｽﾄ(4～3月)'!H$26:H$973) -> 0 | F9: =SUMIF('内訳ﾘｽﾄ(4～3月)'!$D$26:$D$973,'採算表(VND)'!$B9,'内訳ﾘｽﾄ(4～3月)'!I$26:I$973) -> 0 | G9: =SUMIF('内訳ﾘｽﾄ(4～3月)'!$D$26:$D$973,'採算表(VND)'!$B9,'内訳ﾘｽﾄ(4～3月)'!J$26:J$973) -> 0 | H9: =SUMIF('内訳ﾘｽﾄ(4～3月)'!$D$26:$D$973,'採算表(VND)'!$B9,'内訳ﾘｽﾄ(4～3月)'!K$26:K$973) -> 0 | I9: =SUMIF('内訳ﾘｽﾄ(4～3月)'!$D$26:$D$973,'採算表(VND)'!$B9,'内訳ﾘｽﾄ(4～3月)'!L$26:L$973) -> 0 | J9: =SUMIF('内訳ﾘｽﾄ(4～3月)'!$D$26:$D$973,'採算表(VND)'!$B9,'内訳ﾘｽﾄ(4～3月)'!M$26:M$973) -> 0 | ... N9: =SUMIF('内訳ﾘｽﾄ(4～3月)'!$D$26:$D$973,'採算表(VND)'!$B9,'内訳ﾘｽﾄ(4～3月)'!Q$26:Q$973) -> 0 | O9: =SUMIF('内訳ﾘｽﾄ(4～3月)'!$D$26:$D$772,'採算表(VND)'!$B9,'内訳ﾘｽﾄ(4～3月)'!R$26:R$772) -> 0
B10: 社内買 | C10: =SUMIF('内訳ﾘｽﾄ(4～3月)'!$D$26:$D$973,'採算表(VND)'!$B10,'内訳ﾘｽﾄ(4～3月)'!F$26:F$973) -> 0 | D10: =SUMIF('内訳ﾘｽﾄ(4～3月)'!$D$26:$D$973,'採算表(VND)'!$B10,'内訳ﾘｽﾄ(4～3月)'!G$26:G$973) -> 0 | E10: =SUMIF('内訳ﾘｽﾄ(4～3月)'!$D$26:$D$973,'採算表(VND)'!$B10,'内訳ﾘｽﾄ(4～3月)'!H$26:H$973) -> 0 | F10: =SUMIF('内訳ﾘｽﾄ(4～3月)'!$D$26:$D$973,'採算表(VND)'!$B10,'内訳ﾘｽﾄ(4～3月)'!I$26:I$973) -> 0 | G10: =SUMIF('内訳ﾘｽﾄ(4～3月)'!$D$26:$D$973,'採算表(VND)'!$B10,'内訳ﾘｽﾄ(4～3月)'!J$26:J$973) -> 0 | H10: =SUMIF('内訳ﾘｽﾄ(4～3月)'!$D$26:$D$973,'採算表(VND)'!$B10,'内訳ﾘｽﾄ(4～3月)'!K$26:K$973) -> 0 | I10: =SUMIF('内訳ﾘｽﾄ(4～3月)'!$D$26:$D$973,'採算表(VND)'!$B10,'内訳ﾘｽﾄ(4～3月)'!L$26:L$973) -> 0 | J10: =SUMIF('内訳ﾘｽﾄ(4～3月)'!$D$26:$D$973,'採算表(VND)'!$B10,'内訳ﾘｽﾄ(4～3月)'!M$26:M$973) -> 0 | ... N10: =SUMIF('内訳ﾘｽﾄ(4～3月)'!$D$26:$D$973,'採算表(VND)'!$B10,'内訳ﾘｽﾄ(4～3月)'!Q$26:Q$973) -> 0 | O10: =SUMIF('内訳ﾘｽﾄ(4～3月)'!$D$26:$D$772,'採算表(VND)'!$B10,'内訳ﾘｽﾄ(4～3月)'!R$26:R$772) -> 0
B12: 総生産 | C12: =C5-C10 -> 0 | D12: =D5-D10 -> 0 | E12: =E5-E10 -> 0 | F12: =F5-F10 -> 0 | G12: =G5-G10 -> 0 | H12: =H5-H10 -> 0 | I12: =I5-I10 -> 0 | J12: =J5-J10 -> 0 | ... O12: =O5-O10 -> 0
B13: 控除額 | C13: =SUM(C14:C65) -> 0 | D13: =SUM(D14:D65) -> 0 | E13: =SUM(E14:E65) -> 0 | F13: =SUM(F14:F65) -> 0 | G13: =SUM(G14:G65) -> 0 | H13: =SUM(H14:H65) -> 0 | I13: =SUM(I14:I65) -> 0 | J13: =SUM(J14:J65) -> 0 | ... O13: =SUM(O14:O65) -> 0
B14: 材料費 | C14: =SUMIF('内訳ﾘｽﾄ(4～3月)'!$D$26:$D$973,$B14,'内訳ﾘｽﾄ(4～3月)'!F$26:F$973) -> 0 | D14: =SUMIF('内訳ﾘｽﾄ(4～3月)'!$D$26:$D$973,$B14,'内訳ﾘｽﾄ(4～3月)'!G$26:G$973) -> 0 | E14: =SUMIF('内訳ﾘｽﾄ(4～3月)'!$D$26:$D$973,$B14,'内訳ﾘｽﾄ(4～3月)'!H$26:H$973) -> 0 | F14: =SUMIF('内訳ﾘｽﾄ(4～3月)'!$D$26:$D$973,$B14,'内訳ﾘｽﾄ(4～3月)'!I$26:I$973) -> 0 | G14: =SUMIF('内訳ﾘｽﾄ(4～3月)'!$D$26:$D$973,$B14,'内訳ﾘｽﾄ(4～3月)'!J$26:J$973) -> 0 | H14: =SUMIF('内訳ﾘｽﾄ(4～3月)'!$D$26:$D$973,$B14,'内訳ﾘｽﾄ(4～3月)'!K$26:K$973) -> 0 | I14: =SUMIF('内訳ﾘｽﾄ(4～3月)'!$D$26:$D$973,$B14,'内訳ﾘｽﾄ(4～3月)'!L$26:L$973) -> 0 | J14: =SUMIF('内訳ﾘｽﾄ(4～3月)'!$D$26:$D$973,$B14,'内訳ﾘｽﾄ(4～3月)'!M$26:M$973) -> 0 | ... N14: =SUMIF('内訳ﾘｽﾄ(4～3月)'!$D$26:$D$973,$B14,'内訳ﾘｽﾄ(4～3月)'!Q$26:Q$973) -> 0 | O14: =SUMIF('内訳ﾘｽﾄ(4～3月)'!$D$26:$D$772,'採算表(VND)'!$B14,'内訳ﾘｽﾄ(4～3月)'!R$26:R$772) -> 0
B15: 設計変更材料費 | C15: =SUMIF('内訳ﾘｽﾄ(4～3月)'!$D$26:$D$973,$B15,'内訳ﾘｽﾄ(4～3月)'!F$26:F$973) -> 0 | D15: =SUMIF('内訳ﾘｽﾄ(4～3月)'!$D$26:$D$973,$B15,'内訳ﾘｽﾄ(4～3月)'!G$26:G$973) -> 0 | E15: =SUMIF('内訳ﾘｽﾄ(4～3月)'!$D$26:$D$973,$B15,'内訳ﾘｽﾄ(4～3月)'!H$26:H$973) -> 0 | F15: =SUMIF('内訳ﾘｽﾄ(4～3月)'!$D$26:$D$973,$B15,'内訳ﾘｽﾄ(4～3月)'!I$26:I$973) -> 0 | G15: =SUMIF('内訳ﾘｽﾄ(4～3月)'!$D$26:$D$973,$B15,'内訳ﾘｽﾄ(4～3月)'!J$26:J$973) -> 0 | H15: =SUMIF('内訳ﾘｽﾄ(4～3月)'!$D$26:$D$973,$B15,'内訳ﾘｽﾄ(4～3月)'!K$26:K$973) -> 0 | I15: =SUMIF('内訳ﾘｽﾄ(4～3月)'!$D$26:$D$973,$B15,'内訳ﾘｽﾄ(4～3月)'!L$26:L$973) -> 0 | J15: =SUMIF('内訳ﾘｽﾄ(4～3月)'!$D$26:$D$973,$B15,'内訳ﾘｽﾄ(4～3月)'!M$26:M$973) -> 0 | ... N15: =SUMIF('内訳ﾘｽﾄ(4～3月)'!$D$26:$D$973,$B15,'内訳ﾘｽﾄ(4～3月)'!Q$26:Q$973) -> 0 | O15: =SUMIF('内訳ﾘｽﾄ(4～3月)'!$D$26:$D$772,'採算表(VND)'!$B15,'内訳ﾘｽﾄ(4～3月)'!R$26:R$772) -> 0
B16: 仕掛仕損 | C16: =SUMIF('内訳ﾘｽﾄ(4～3月)'!$D$26:$D$973,$B16,'内訳ﾘｽﾄ(4～3月)'!F$26:F$973) -> 0 | D16: =SUMIF('内訳ﾘｽﾄ(4～3月)'!$D$26:$D$973,$B16,'内訳ﾘｽﾄ(4～3月)'!G$26:G$973) -> 0 | E16: =SUMIF('内訳ﾘｽﾄ(4～3月)'!$D$26:$D$973,$B16,'内訳ﾘｽﾄ(4～3月)'!H$26:H$973) -> 0 | F16: =SUMIF('内訳ﾘｽﾄ(4～3月)'!$D$26:$D$973,$B16,'内訳ﾘｽﾄ(4～3月)'!I$26:I$973) -> 0 | G16: =SUMIF('内訳ﾘｽﾄ(4～3月)'!$D$26:$D$973,$B16,'内訳ﾘｽﾄ(4～3月)'!J$26:J$973) -> 0 | H16: =SUMIF('内訳ﾘｽﾄ(4～3月)'!$D$26:$D$973,$B16,'内訳ﾘｽﾄ(4～3月)'!K$26:K$973) -> 0 | I16: =SUMIF('内訳ﾘｽﾄ(4～3月)'!$D$26:$D$973,$B16,'内訳ﾘｽﾄ(4～3月)'!L$26:L$973) -> 0 | J16: =SUMIF('内訳ﾘｽﾄ(4～3月)'!$D$26:$D$973,$B16,'内訳ﾘｽﾄ(4～3月)'!M$26:M$973) -> 0 | ... N16: =SUMIF('内訳ﾘｽﾄ(4～3月)'!$D$26:$D$973,$B16,'内訳ﾘｽﾄ(4～3月)'!Q$26:Q$973) -> 0 | O16: =SUMIF('内訳ﾘｽﾄ(4～3月)'!$D$26:$D$772,'採算表(VND)'!$B16,'内訳ﾘｽﾄ(4～3月)'!R$26:R$772) -> 0
B17: 仕入製商品費 | C17: =SUMIF('内訳ﾘｽﾄ(4～3月)'!$D$26:$D$973,$B17,'内訳ﾘｽﾄ(4～3月)'!F$26:F$973) -> 0 | D17: =SUMIF('内訳ﾘｽﾄ(4～3月)'!$D$26:$D$973,$B17,'内訳ﾘｽﾄ(4～3月)'!G$26:G$973) -> 0 | E17: =SUMIF('内訳ﾘｽﾄ(4～3月)'!$D$26:$D$973,$B17,'内訳ﾘｽﾄ(4～3月)'!H$26:H$973) -> 0 | F17: =SUMIF('内訳ﾘｽﾄ(4～3月)'!$D$26:$D$973,$B17,'内訳ﾘｽﾄ(4～3月)'!I$26:I$973) -> 0 | G17: =SUMIF('内訳ﾘｽﾄ(4～3月)'!$D$26:$D$973,$B17,'内訳ﾘｽﾄ(4～3月)'!J$26:J$973) -> 0 | H17: =SUMIF('内訳ﾘｽﾄ(4～3月)'!$D$26:$D$973,$B17,'内訳ﾘｽﾄ(4～3月)'!K$26:K$973) -> 0 | I17: =SUMIF('内訳ﾘｽﾄ(4～3月)'!$D$26:$D$973,$B17,'内訳ﾘｽﾄ(4～3月)'!L$26:L$973) -> 0 | J17: =SUMIF('内訳ﾘｽﾄ(4～3月)'!$D$26:$D$973,$B17,'内訳ﾘｽﾄ(4～3月)'!M$26:M$973) -> 0 | ... N17: =SUMIF('内訳ﾘｽﾄ(4～3月)'!$D$26:$D$973,$B17,'内訳ﾘｽﾄ(4～3月)'!Q$26:Q$973) -> 0 | O17: =SUMIF('内訳ﾘｽﾄ(4～3月)'!$D$26:$D$772,'採算表(VND)'!$B17,'内訳ﾘｽﾄ(4～3月)'!R$26:R$772) -> 0
B18: 内製品有償支給原価 | C18: =SUMIF('内訳ﾘｽﾄ(4～3月)'!$D$26:$D$973,$B18,'内訳ﾘｽﾄ(4～3月)'!F$26:F$973) -> 0 | D18: =SUMIF('内訳ﾘｽﾄ(4～3月)'!$D$26:$D$973,$B18,'内訳ﾘｽﾄ(4～3月)'!G$26:G$973) -> 0 | E18: =SUMIF('内訳ﾘｽﾄ(4～3月)'!$D$26:$D$973,$B18,'内訳ﾘｽﾄ(4～3月)'!H$26:H$973) -> 0 | F18: =SUMIF('内訳ﾘｽﾄ(4～3月)'!$D$26:$D$973,$B18,'内訳ﾘｽﾄ(4～3月)'!I$26:I$973) -> 0 | G18: =SUMIF('内訳ﾘｽﾄ(4～3月)'!$D$26:$D$973,$B18,'内訳ﾘｽﾄ(4～3月)'!J$26:J$973) -> 0 | H18: =SUMIF('内訳ﾘｽﾄ(4～3月)'!$D$26:$D$973,$B18,'内訳ﾘｽﾄ(4～3月)'!K$26:K$973) -> 0 | I18: =SUMIF('内訳ﾘｽﾄ(4～3月)'!$D$26:$D$973,$B18,'内訳ﾘｽﾄ(4～3月)'!L$26:L$973) -> 0 | J18: =SUMIF('内訳ﾘｽﾄ(4～3月)'!$D$26:$D$973,$B18,'内訳ﾘｽﾄ(4～3月)'!M$26:M$973) -> 0 | ... N18: =SUMIF('内訳ﾘｽﾄ(4～3月)'!$D$26:$D$973,$B18,'内訳ﾘｽﾄ(4～3月)'!Q$26:Q$973) -> 0 | O18: =SUMIF('内訳ﾘｽﾄ(4～3月)'!$D$26:$D$772,'採算表(VND)'!$B18,'内訳ﾘｽﾄ(4～3月)'!R$26:R$772) -> 0
B19: 外注加工費 | C19: =SUMIF('内訳ﾘｽﾄ(4～3月)'!$D$26:$D$973,$B19,'内訳ﾘｽﾄ(4～3月)'!F$26:F$973) -> 0 | D19: =SUMIF('内訳ﾘｽﾄ(4～3月)'!$D$26:$D$973,$B19,'内訳ﾘｽﾄ(4～3月)'!G$26:G$973) -> 0 | E19: =SUMIF('内訳ﾘｽﾄ(4～3月)'!$D$26:$D$973,$B19,'内訳ﾘｽﾄ(4～3月)'!H$26:H$973) -> 0 | F19: =SUMIF('内訳ﾘｽﾄ(4～3月)'!$D$26:$D$973,$B19,'内訳ﾘｽﾄ(4～3月)'!I$26:I$973) -> 0 | G19: =SUMIF('内訳ﾘｽﾄ(4～3月)'!$D$26:$D$973,$B19,'内訳ﾘｽﾄ(4～3月)'!J$26:J$973) -> 0 | H19: =SUMIF('内訳ﾘｽﾄ(4～3月)'!$D$26:$D$973,$B19,'内訳ﾘｽﾄ(4～3月)'!K$26:K$973) -> 0 | I19: =SUMIF('内訳ﾘｽﾄ(4～3月)'!$D$26:$D$973,$B19,'内訳ﾘｽﾄ(4～3月)'!L$26:L$973) -> 0 | J19: =SUMIF('内訳ﾘｽﾄ(4～3月)'!$D$26:$D$973,$B19,'内訳ﾘｽﾄ(4～3月)'!M$26:M$973) -> 0 | ... N19: =SUMIF('内訳ﾘｽﾄ(4～3月)'!$D$26:$D$973,$B19,'内訳ﾘｽﾄ(4～3月)'!Q$26:Q$973) -> 0 | O19: =SUMIF('内訳ﾘｽﾄ(4～3月)'!$D$26:$D$772,'採算表(VND)'!$B19,'内訳ﾘｽﾄ(4～3月)'!R$26:R$772) -> 0
B20: 減価償却費 | C20: =SUMIF('内訳ﾘｽﾄ(4～3月)'!$D$26:$D$973,$B20,'内訳ﾘｽﾄ(4～3月)'!F$26:F$973) -> 532445568 | D20: =SUMIF('内訳ﾘｽﾄ(4～3月)'!$D$26:$D$973,$B20,'内訳ﾘｽﾄ(4～3月)'!G$26:G$973) -> 532908428 | E20: =SUMIF('内訳ﾘｽﾄ(4～3月)'!$D$26:$D$973,$B20,'内訳ﾘｽﾄ(4～3月)'!H$26:H$973) -> 532911221 | F20: =SUMIF('内訳ﾘｽﾄ(4～3月)'!$D$26:$D$973,$B20,'内訳ﾘｽﾄ(4～3月)'!I$26:I$973) -> 534570966 | G20: =SUMIF('内訳ﾘｽﾄ(4～3月)'!$D$26:$D$973,$B20,'内訳ﾘｽﾄ(4～3月)'!J$26:J$973) -> 534567919 | H20: =SUMIF('内訳ﾘｽﾄ(4～3月)'!$D$26:$D$973,$B20,'内訳ﾘｽﾄ(4～3月)'!K$26:K$973) -> 534426242 | I20: =SUMIF('内訳ﾘｽﾄ(4～3月)'!$D$26:$D$973,$B20,'内訳ﾘｽﾄ(4～3月)'!L$26:L$973) -> 538334779 | J20: =SUMIF('内訳ﾘｽﾄ(4～3月)'!$D$26:$D$973,$B20,'内訳ﾘｽﾄ(4～3月)'!M$26:M$973) -> 538333256 | ... N20: =SUMIF('内訳ﾘｽﾄ(4～3月)'!$D$26:$D$973,$B20,'内訳ﾘｽﾄ(4～3月)'!Q$26:Q$973) -> 538330718 | O20: =SUMIF('内訳ﾘｽﾄ(4～3月)'!$D$26:$D$772,'採算表(VND)'!$B20,'内訳ﾘｽﾄ(4～3月)'!R$26:R$772) -> 6431819219
B21: 金型償却費 | C21: =SUMIF('内訳ﾘｽﾄ(4～3月)'!$D$26:$D$973,$B21,'内訳ﾘｽﾄ(4～3月)'!F$26:F$973) -> 0 | D21: =SUMIF('内訳ﾘｽﾄ(4～3月)'!$D$26:$D$973,$B21,'内訳ﾘｽﾄ(4～3月)'!G$26:G$973) -> 0 | E21: =SUMIF('内訳ﾘｽﾄ(4～3月)'!$D$26:$D$973,$B21,'内訳ﾘｽﾄ(4～3月)'!H$26:H$973) -> 0 | F21: =SUMIF('内訳ﾘｽﾄ(4～3月)'!$D$26:$D$973,$B21,'内訳ﾘｽﾄ(4～3月)'!I$26:I$973) -> 0 | G21: =SUMIF('内訳ﾘｽﾄ(4～3月)'!$D$26:$D$973,$B21,'内訳ﾘｽﾄ(4～3月)'!J$26:J$973) -> 0 | H21: =SUMIF('内訳ﾘｽﾄ(4～3月)'!$D$26:$D$973,$B21,'内訳ﾘｽﾄ(4～3月)'!K$26:K$973) -> 0 | I21: =SUMIF('内訳ﾘｽﾄ(4～3月)'!$D$26:$D$973,$B21,'内訳ﾘｽﾄ(4～3月)'!L$26:L$973) -> 0 | J21: =SUMIF('内訳ﾘｽﾄ(4～3月)'!$D$26:$D$973,$B21,'内訳ﾘｽﾄ(4～3月)'!M$26:M$973) -> 0 | ... N21: =SUMIF('内訳ﾘｽﾄ(4～3月)'!$D$26:$D$973,$B21,'内訳ﾘｽﾄ(4～3月)'!Q$26:Q$973) -> 0 | O21: =SUMIF('内訳ﾘｽﾄ(4～3月)'!$D$26:$D$772,'採算表(VND)'!$B21,'内訳ﾘｽﾄ(4～3月)'!R$26:R$772) -> 0
B22: 賃借料 | C22: =SUMIF('内訳ﾘｽﾄ(4～3月)'!$D$26:$D$973,$B22,'内訳ﾘｽﾄ(4～3月)'!F$26:F$973) -> 0 | D22: =SUMIF('内訳ﾘｽﾄ(4～3月)'!$D$26:$D$973,$B22,'内訳ﾘｽﾄ(4～3月)'!G$26:G$973) -> 0 | E22: =SUMIF('内訳ﾘｽﾄ(4～3月)'!$D$26:$D$973,$B22,'内訳ﾘｽﾄ(4～3月)'!H$26:H$973) -> 0 | F22: =SUMIF('内訳ﾘｽﾄ(4～3月)'!$D$26:$D$973,$B22,'内訳ﾘｽﾄ(4～3月)'!I$26:I$973) -> 0 | G22: =SUMIF('内訳ﾘｽﾄ(4～3月)'!$D$26:$D$973,$B22,'内訳ﾘｽﾄ(4～3月)'!J$26:J$973) -> 0 | H22: =SUMIF('内訳ﾘｽﾄ(4～3月)'!$D$26:$D$973,$B22,'内訳ﾘｽﾄ(4～3月)'!K$26:K$973) -> 0 | I22: =SUMIF('内訳ﾘｽﾄ(4～3月)'!$D$26:$D$973,$B22,'内訳ﾘｽﾄ(4～3月)'!L$26:L$973) -> 0 | J22: =SUMIF('内訳ﾘｽﾄ(4～3月)'!$D$26:$D$973,$B22,'内訳ﾘｽﾄ(4～3月)'!M$26:M$973) -> 0 | ... N22: =SUMIF('内訳ﾘｽﾄ(4～3月)'!$D$26:$D$973,$B22,'内訳ﾘｽﾄ(4～3月)'!Q$26:Q$973) -> 0 | O22: =SUMIF('内訳ﾘｽﾄ(4～3月)'!$D$26:$D$772,'採算表(VND)'!$B22,'内訳ﾘｽﾄ(4～3月)'!R$26:R$772) -> 0
B23: 保険料 | C23: =SUMIF('内訳ﾘｽﾄ(4～3月)'!$D$26:$D$973,$B23,'内訳ﾘｽﾄ(4～3月)'!F$26:F$973) -> 0 | D23: =SUMIF('内訳ﾘｽﾄ(4～3月)'!$D$26:$D$973,$B23,'内訳ﾘｽﾄ(4～3月)'!G$26:G$973) -> 55000000 | E23: =SUMIF('内訳ﾘｽﾄ(4～3月)'!$D$26:$D$973,$B23,'内訳ﾘｽﾄ(4～3月)'!H$26:H$973) -> 0 | F23: =SUMIF('内訳ﾘｽﾄ(4～3月)'!$D$26:$D$973,$B23,'内訳ﾘｽﾄ(4～3月)'!I$26:I$973) -> 0 | G23: =SUMIF('内訳ﾘｽﾄ(4～3月)'!$D$26:$D$973,$B23,'内訳ﾘｽﾄ(4～3月)'!J$26:J$973) -> 0 | H23: =SUMIF('内訳ﾘｽﾄ(4～3月)'!$D$26:$D$973,$B23,'内訳ﾘｽﾄ(4～3月)'!K$26:K$973) -> 0 | I23: =SUMIF('内訳ﾘｽﾄ(4～3月)'!$D$26:$D$973,$B23,'内訳ﾘｽﾄ(4～3月)'!L$26:L$973) -> 0 | J23: =SUMIF('内訳ﾘｽﾄ(4～3月)'!$D$26:$D$973,$B23,'内訳ﾘｽﾄ(4～3月)'!M$26:M$973) -> 0 | ... N23: =SUMIF('内訳ﾘｽﾄ(4～3月)'!$D$26:$D$973,$B23,'内訳ﾘｽﾄ(4～3月)'!Q$26:Q$973) -> 0 | O23: =SUMIF('内訳ﾘｽﾄ(4～3月)'!$D$26:$D$772,'採算表(VND)'!$B23,'内訳ﾘｽﾄ(4～3月)'!R$26:R$772) -> 55000000
B24: 設計委託費 | C24: =SUMIF('内訳ﾘｽﾄ(4～3月)'!$D$26:$D$973,$B24,'内訳ﾘｽﾄ(4～3月)'!F$26:F$973) -> 0 | D24: =SUMIF('内訳ﾘｽﾄ(4～3月)'!$D$26:$D$973,$B24,'内訳ﾘｽﾄ(4～3月)'!G$26:G$973) -> 0 | E24: =SUMIF('内訳ﾘｽﾄ(4～3月)'!$D$26:$D$973,$B24,'内訳ﾘｽﾄ(4～3月)'!H$26:H$973) -> 0 | F24: =SUMIF('内訳ﾘｽﾄ(4～3月)'!$D$26:$D$973,$B24,'内訳ﾘｽﾄ(4～3月)'!I$26:I$973) -> 0 | G24: =SUMIF('内訳ﾘｽﾄ(4～3月)'!$D$26:$D$973,$B24,'内訳ﾘｽﾄ(4～3月)'!J$26:J$973) -> 0 | H24: =SUMIF('内訳ﾘｽﾄ(4～3月)'!$D$26:$D$973,$B24,'内訳ﾘｽﾄ(4～3月)'!K$26:K$973) -> 0 | I24: =SUMIF('内訳ﾘｽﾄ(4～3月)'!$D$26:$D$973,$B24,'内訳ﾘｽﾄ(4～3月)'!L$26:L$973) -> 0 | J24: =SUMIF('内訳ﾘｽﾄ(4～3月)'!$D$26:$D$973,$B24,'内訳ﾘｽﾄ(4～3月)'!M$26:M$973) -> 0 | ... N24: =SUMIF('内訳ﾘｽﾄ(4～3月)'!$D$26:$D$973,$B24,'内訳ﾘｽﾄ(4～3月)'!Q$26:Q$973) -> 0 | O24: =SUMIF('内訳ﾘｽﾄ(4～3月)'!$D$26:$D$772,'採算表(VND)'!$B24,'内訳ﾘｽﾄ(4～3月)'!R$26:R$772) -> 0
B25: 消耗品費 | C25: =SUMIF('内訳ﾘｽﾄ(4～3月)'!$D$26:$D$973,$B25,'内訳ﾘｽﾄ(4～3月)'!F$26:F$973) -> 3537120 | D25: =SUMIF('内訳ﾘｽﾄ(4～3月)'!$D$26:$D$973,$B25,'内訳ﾘｽﾄ(4～3月)'!G$26:G$973) -> 2466490 | E25: =SUMIF('内訳ﾘｽﾄ(4～3月)'!$D$26:$D$973,$B25,'内訳ﾘｽﾄ(4～3月)'!H$26:H$973) -> 3578200 | F25: =SUMIF('内訳ﾘｽﾄ(4～3月)'!$D$26:$D$973,$B25,'内訳ﾘｽﾄ(4～3月)'!I$26:I$973) -> 2524131 | G25: =SUMIF('内訳ﾘｽﾄ(4～3月)'!$D$26:$D$973,$B25,'内訳ﾘｽﾄ(4～3月)'!J$26:J$973) -> 3552412 | H25: =SUMIF('内訳ﾘｽﾄ(4～3月)'!$D$26:$D$973,$B25,'内訳ﾘｽﾄ(4～3月)'!K$26:K$973) -> 2636513 | I25: =SUMIF('内訳ﾘｽﾄ(4～3月)'!$D$26:$D$973,$B25,'内訳ﾘｽﾄ(4～3月)'!L$26:L$973) -> 3586803 | J25: =SUMIF('内訳ﾘｽﾄ(4～3月)'!$D$26:$D$973,$B25,'内訳ﾘｽﾄ(4～3月)'!M$26:M$973) -> 2481025 | ... N25: =SUMIF('内訳ﾘｽﾄ(4～3月)'!$D$26:$D$973,$B25,'内訳ﾘｽﾄ(4～3月)'!Q$26:Q$973) -> 2477000 | O25: =SUMIF('内訳ﾘｽﾄ(4～3月)'!$D$26:$D$772,'採算表(VND)'!$B25,'内訳ﾘｽﾄ(4～3月)'!R$26:R$772) -> 36385410
... B60: 内部技術料 | C60: =SUMIF('内訳ﾘｽﾄ(4～3月)'!$D$26:$D$973,$B60,'内訳ﾘｽﾄ(4～3月)'!F$26:F$973) -> 0 | D60: =SUMIF('内訳ﾘｽﾄ(4～3月)'!$D$26:$D$973,$B60,'内訳ﾘｽﾄ(4～3月)'!G$26:G$973) -> 0 | E60: =SUMIF('内訳ﾘｽﾄ(4～3月)'!$D$26:$D$973,$B60,'内訳ﾘｽﾄ(4～3月)'!H$26:H$973) -> 0 | F60: =SUMIF('内訳ﾘｽﾄ(4～3月)'!$D$26:$D$973,$B60,'内訳ﾘｽﾄ(4～3月)'!I$26:I$973) -> 0 | G60: =SUMIF('内訳ﾘｽﾄ(4～3月)'!$D$26:$D$973,$B60,'内訳ﾘｽﾄ(4～3月)'!J$26:J$973) -> 0 | H60: =SUMIF('内訳ﾘｽﾄ(4～3月)'!$D$26:$D$973,$B60,'内訳ﾘｽﾄ(4～3月)'!K$26:K$973) -> 0 | I60: =SUMIF('内訳ﾘｽﾄ(4～3月)'!$D$26:$D$973,$B60,'内訳ﾘｽﾄ(4～3月)'!L$26:L$973) -> 0 | J60: =SUMIF('内訳ﾘｽﾄ(4～3月)'!$D$26:$D$973,$B60,'内訳ﾘｽﾄ(4～3月)'!M$26:M$973) -> 0 | ... N60: =SUMIF('内訳ﾘｽﾄ(4～3月)'!$D$26:$D$973,$B60,'内訳ﾘｽﾄ(4～3月)'!Q$26:Q$973) -> 0 | O60: =SUMIF('内訳ﾘｽﾄ(4～3月)'!$D$26:$D$772,'採算表(VND)'!$B60,'内訳ﾘｽﾄ(4～3月)'!R$26:R$772) -> 0
B61: 部内間接経費 | C61: =IF('内訳ﾘｽﾄ(4～3月)'!$D$5="製造",SUMIF('内訳ﾘｽﾄ(4～3月)'!$D$26:$D$973,$B61,'内訳ﾘｽﾄ(4～3月)'!F$26:F$973),IF('内訳ﾘｽﾄ(4～3月)'!$D$5="部内間接",-SUM(C$14:C$60,C$65),0)) -> 0 | D61: =IF('内訳ﾘｽﾄ(4～3月)'!$D$5="製造",SUMIF('内訳ﾘｽﾄ(4～3月)'!$D$26:$D$973,$B61,'内訳ﾘｽﾄ(4～3月)'!G$26:G$973),IF('内訳ﾘｽﾄ(4～3月)'!$D$5="部内間接",-SUM(D$14:D$60,D$65),0)) -> 0 | E61: =IF('内訳ﾘｽﾄ(4～3月)'!$D$5="製造",SUMIF('内訳ﾘｽﾄ(4～3月)'!$D$26:$D$973,$B61,'内訳ﾘｽﾄ(4～3月)'!H$26:H$973),IF('内訳ﾘｽﾄ(4～3月)'!$D$5="部内間接",-SUM(E$14:E$60,E$65),0)) -> 0 | F61: =IF('内訳ﾘｽﾄ(4～3月)'!$D$5="製造",SUMIF('内訳ﾘｽﾄ(4～3月)'!$D$26:$D$973,$B61,'内訳ﾘｽﾄ(4～3月)'!I$26:I$973),IF('内訳ﾘｽﾄ(4～3月)'!$D$5="部内間接",-SUM(F$14:F$60,F$65),0)) -> 0 | G61: =IF('内訳ﾘｽﾄ(4～3月)'!$D$5="製造",SUMIF('内訳ﾘｽﾄ(4～3月)'!$D$26:$D$973,$B61,'内訳ﾘｽﾄ(4～3月)'!J$26:J$973),IF('内訳ﾘｽﾄ(4～3月)'!$D$5="部内間接",-SUM(G$14:G$60,G$65),0)) -> 0 | H61: =IF('内訳ﾘｽﾄ(4～3月)'!$D$5="製造",SUMIF('内訳ﾘｽﾄ(4～3月)'!$D$26:$D$973,$B61,'内訳ﾘｽﾄ(4～3月)'!K$26:K$973),IF('内訳ﾘｽﾄ(4～3月)'!$D$5="部内間接",-SUM(H$14:H$60,H$65),0)) -> 0 | I61: =IF('内訳ﾘｽﾄ(4～3月)'!$D$5="製造",SUMIF('内訳ﾘｽﾄ(4～3月)'!$D$26:$D$973,$B61,'内訳ﾘｽﾄ(4～3月)'!L$26:L$973),IF('内訳ﾘｽﾄ(4～3月)'!$D$5="部内間接",-SUM(I$14:I$60,I$65),0)) -> 0 | J61: =IF('内訳ﾘｽﾄ(4～3月)'!$D$5="製造",SUMIF('内訳ﾘｽﾄ(4～3月)'!$D$26:$D$973,$B61,'内訳ﾘｽﾄ(4～3月)'!M$26:M$973),IF('内訳ﾘｽﾄ(4～3月)'!$D$5="部内間接",-SUM(J$14:J$60,J$65),0)) -> 0 | ... N61: =IF('内訳ﾘｽﾄ(4～3月)'!$D$5="製造",SUMIF('内訳ﾘｽﾄ(4～3月)'!$D$26:$D$973,$B61,'内訳ﾘｽﾄ(4～3月)'!Q$26:Q$973),IF('内訳ﾘｽﾄ(4～3月)'!$D$5="部内間接",-SUM(N$14:N$60,N$65),0)) -> 0 | O61: =IF('内訳ﾘｽﾄ(4～3月)'!$D$5="部内間接",-SUM(O$65,O$14:O$60),IF('内訳ﾘｽﾄ(4～3月)'!$D$5="製造",SUMIF('内訳ﾘｽﾄ(4～3月)'!$D$26:$D$772,'採算表(VND)'!$B61,'内訳ﾘｽﾄ(4～3月)'!R$26:R$772),0)) -> 0
B62: 部外間接1経費 | C62: =IF('内訳ﾘｽﾄ(4～3月)'!$D$5="製造",SUMIF('内訳ﾘｽﾄ(4～3月)'!$D$26:$D$973,$B62,'内訳ﾘｽﾄ(4～3月)'!F$26:F$973),IF('内訳ﾘｽﾄ(4～3月)'!$D$5="部外間接1",-SUM(C$14:C$60,C$65),0)) -> 0 | D62: =IF('内訳ﾘｽﾄ(4～3月)'!$D$5="製造",SUMIF('内訳ﾘｽﾄ(4～3月)'!$D$26:$D$973,$B62,'内訳ﾘｽﾄ(4～3月)'!G$26:G$973),IF('内訳ﾘｽﾄ(4～3月)'!$D$5="部外間接1",-SUM(D$14:D$60,D$65),0)) -> 0 | E62: =IF('内訳ﾘｽﾄ(4～3月)'!$D$5="製造",SUMIF('内訳ﾘｽﾄ(4～3月)'!$D$26:$D$973,$B62,'内訳ﾘｽﾄ(4～3月)'!H$26:H$973),IF('内訳ﾘｽﾄ(4～3月)'!$D$5="部外間接1",-SUM(E$14:E$60,E$65),0)) -> 0 | F62: =IF('内訳ﾘｽﾄ(4～3月)'!$D$5="製造",SUMIF('内訳ﾘｽﾄ(4～3月)'!$D$26:$D$973,$B62,'内訳ﾘｽﾄ(4～3月)'!I$26:I$973),IF('内訳ﾘｽﾄ(4～3月)'!$D$5="部外間接1",-SUM(F$14:F$60,F$65),0)) -> 0 | G62: =IF('内訳ﾘｽﾄ(4～3月)'!$D$5="製造",SUMIF('内訳ﾘｽﾄ(4～3月)'!$D$26:$D$973,$B62,'内訳ﾘｽﾄ(4～3月)'!J$26:J$973),IF('内訳ﾘｽﾄ(4～3月)'!$D$5="部外間接1",-SUM(G$14:G$60,G$65),0)) -> 0 | H62: =IF('内訳ﾘｽﾄ(4～3月)'!$D$5="製造",SUMIF('内訳ﾘｽﾄ(4～3月)'!$D$26:$D$973,$B62,'内訳ﾘｽﾄ(4～3月)'!K$26:K$973),IF('内訳ﾘｽﾄ(4～3月)'!$D$5="部外間接1",-SUM(H$14:H$60,H$65),0)) -> 0 | I62: =IF('内訳ﾘｽﾄ(4～3月)'!$D$5="製造",SUMIF('内訳ﾘｽﾄ(4～3月)'!$D$26:$D$973,$B62,'内訳ﾘｽﾄ(4～3月)'!L$26:L$973),IF('内訳ﾘｽﾄ(4～3月)'!$D$5="部外間接1",-SUM(I$14:I$60,I$65),0)) -> 0 | J62: =IF('内訳ﾘｽﾄ(4～3月)'!$D$5="製造",SUMIF('内訳ﾘｽﾄ(4～3月)'!$D$26:$D$973,$B62,'内訳ﾘｽﾄ(4～3月)'!M$26:M$973),IF('内訳ﾘｽﾄ(4～3月)'!$D$5="部外間接1",-SUM(J$14:J$60,J$65),0)) -> 0 | ... N62: =IF('内訳ﾘｽﾄ(4～3月)'!$D$5="製造",SUMIF('内訳ﾘｽﾄ(4～3月)'!$D$26:$D$973,$B62,'内訳ﾘｽﾄ(4～3月)'!Q$26:Q$973),IF('内訳ﾘｽﾄ(4～3月)'!$D$5="部外間接1",-SUM(N$14:N$60,N$65),0)) -> 0 | O62: =IF('内訳ﾘｽﾄ(4～3月)'!$D$5="部外間接1",-SUM(O$65,O$14:O$60),IF('内訳ﾘｽﾄ(4～3月)'!$D$5="製造",SUMIF('内訳ﾘｽﾄ(4～3月)'!$D$26:$D$772,'採算表(VND)'!$B62,'内訳ﾘｽﾄ(4～3月)'!R$26:R$772),0)) -> 0
B63: 部外間接2経費 | C63: =IF('内訳ﾘｽﾄ(4～3月)'!$D$5="製造",SUMIF('内訳ﾘｽﾄ(4～3月)'!$D$26:$D$973,$B63,'内訳ﾘｽﾄ(4～3月)'!F$26:F$973),IF('内訳ﾘｽﾄ(4～3月)'!$D$5="部外間接2",-SUM(C$14:C$60,C$65),0)) -> 0 | D63: =IF('内訳ﾘｽﾄ(4～3月)'!$D$5="製造",SUMIF('内訳ﾘｽﾄ(4～3月)'!$D$26:$D$973,$B63,'内訳ﾘｽﾄ(4～3月)'!G$26:G$973),IF('内訳ﾘｽﾄ(4～3月)'!$D$5="部外間接2",-SUM(D$14:D$60,D$65),0)) -> 0 | E63: =IF('内訳ﾘｽﾄ(4～3月)'!$D$5="製造",SUMIF('内訳ﾘｽﾄ(4～3月)'!$D$26:$D$973,$B63,'内訳ﾘｽﾄ(4～3月)'!H$26:H$973),IF('内訳ﾘｽﾄ(4～3月)'!$D$5="部外間接2",-SUM(E$14:E$60,E$65),0)) -> 0 | F63: =IF('内訳ﾘｽﾄ(4～3月)'!$D$5="製造",SUMIF('内訳ﾘｽﾄ(4～3月)'!$D$26:$D$973,$B63,'内訳ﾘｽﾄ(4～3月)'!I$26:I$973),IF('内訳ﾘｽﾄ(4～3月)'!$D$5="部外間接2",-SUM(F$14:F$60,F$65),0)) -> 0 | G63: =IF('内訳ﾘｽﾄ(4～3月)'!$D$5="製造",SUMIF('内訳ﾘｽﾄ(4～3月)'!$D$26:$D$973,$B63,'内訳ﾘｽﾄ(4～3月)'!J$26:J$973),IF('内訳ﾘｽﾄ(4～3月)'!$D$5="部外間接2",-SUM(G$14:G$60,G$65),0)) -> 0 | H63: =IF('内訳ﾘｽﾄ(4～3月)'!$D$5="製造",SUMIF('内訳ﾘｽﾄ(4～3月)'!$D$26:$D$973,$B63,'内訳ﾘｽﾄ(4～3月)'!K$26:K$973),IF('内訳ﾘｽﾄ(4～3月)'!$D$5="部外間接2",-SUM(H$14:H$60,H$65),0)) -> 0 | I63: =IF('内訳ﾘｽﾄ(4～3月)'!$D$5="製造",SUMIF('内訳ﾘｽﾄ(4～3月)'!$D$26:$D$973,$B63,'内訳ﾘｽﾄ(4～3月)'!L$26:L$973),IF('内訳ﾘｽﾄ(4～3月)'!$D$5="部外間接2",-SUM(I$14:I$60,I$65),0)) -> 0 | J63: =IF('内訳ﾘｽﾄ(4～3月)'!$D$5="製造",SUMIF('内訳ﾘｽﾄ(4～3月)'!$D$26:$D$973,$B63,'内訳ﾘｽﾄ(4～3月)'!M$26:M$973),IF('内訳ﾘｽﾄ(4～3月)'!$D$5="部外間接2",-SUM(J$14:J$60,J$65),0)) -> 0 | ... N63: =IF('内訳ﾘｽﾄ(4～3月)'!$D$5="製造",SUMIF('内訳ﾘｽﾄ(4～3月)'!$D$26:$D$973,$B63,'内訳ﾘｽﾄ(4～3月)'!Q$26:Q$973),IF('内訳ﾘｽﾄ(4～3月)'!$D$5="部外間接2",-SUM(N$14:N$60,N$65),0)) -> 0 | O63: =IF('内訳ﾘｽﾄ(4～3月)'!$D$5="部外間接2",-SUM(O$65,O$14:O$60),IF('内訳ﾘｽﾄ(4～3月)'!$D$5="製造",SUMIF('内訳ﾘｽﾄ(4～3月)'!$D$26:$D$772,'採算表(VND)'!$B63,'内訳ﾘｽﾄ(4～3月)'!R$26:R$772),0)) -> 0
B64: 工場間接経費 | C64: =IF('内訳ﾘｽﾄ(4～3月)'!$D$5="製造",SUMIF('内訳ﾘｽﾄ(4～3月)'!$D$26:$D$973,$B64,'内訳ﾘｽﾄ(4～3月)'!F$26:F$973),IF('内訳ﾘｽﾄ(4～3月)'!$D$5="工場間接",-SUM(C$14:C$60,C$65),0)) -> -3232448531 | D64: =IF('内訳ﾘｽﾄ(4～3月)'!$D$5="製造",SUMIF('内訳ﾘｽﾄ(4～3月)'!$D$26:$D$973,$B64,'内訳ﾘｽﾄ(4～3月)'!G$26:G$973),IF('内訳ﾘｽﾄ(4～3月)'!$D$5="工場間接",-SUM(D$14:D$60,D$65),0)) -> -1191581278 | E64: =IF('内訳ﾘｽﾄ(4～3月)'!$D$5="製造",SUMIF('内訳ﾘｽﾄ(4～3月)'!$D$26:$D$973,$B64,'内訳ﾘｽﾄ(4～3月)'!H$26:H$973),IF('内訳ﾘｽﾄ(4～3月)'!$D$5="工場間接",-SUM(E$14:E$60,E$65),0)) -> -1137648047 | F64: =IF('内訳ﾘｽﾄ(4～3月)'!$D$5="製造",SUMIF('内訳ﾘｽﾄ(4～3月)'!$D$26:$D$973,$B64,'内訳ﾘｽﾄ(4～3月)'!I$26:I$973),IF('内訳ﾘｽﾄ(4～3月)'!$D$5="工場間接",-SUM(F$14:F$60,F$65),0)) -> -1140451181 | G64: =IF('内訳ﾘｽﾄ(4～3月)'!$D$5="製造",SUMIF('内訳ﾘｽﾄ(4～3月)'!$D$26:$D$973,$B64,'内訳ﾘｽﾄ(4～3月)'!J$26:J$973),IF('内訳ﾘｽﾄ(4～3月)'!$D$5="工場間接",-SUM(G$14:G$60,G$65),0)) -> -1223940850 | H64: =IF('内訳ﾘｽﾄ(4～3月)'!$D$5="製造",SUMIF('内訳ﾘｽﾄ(4～3月)'!$D$26:$D$973,$B64,'内訳ﾘｽﾄ(4～3月)'!K$26:K$973),IF('内訳ﾘｽﾄ(4～3月)'!$D$5="工場間接",-SUM(H$14:H$60,H$65),0)) -> -1245870347 | I64: =IF('内訳ﾘｽﾄ(4～3月)'!$D$5="製造",SUMIF('内訳ﾘｽﾄ(4～3月)'!$D$26:$D$973,$B64,'内訳ﾘｽﾄ(4～3月)'!L$26:L$973),IF('内訳ﾘｽﾄ(4～3月)'!$D$5="工場間接",-SUM(I$14:I$60,I$65),0)) -> -1039609847 | J64: =IF('内訳ﾘｽﾄ(4～3月)'!$D$5="製造",SUMIF('内訳ﾘｽﾄ(4～3月)'!$D$26:$D$973,$B64,'内訳ﾘｽﾄ(4～3月)'!M$26:M$973),IF('内訳ﾘｽﾄ(4～3月)'!$D$5="工場間接",-SUM(J$14:J$60,J$65),0)) -> -1245812344 | ... N64: =IF('内訳ﾘｽﾄ(4～3月)'!$D$5="製造",SUMIF('内訳ﾘｽﾄ(4～3月)'!$D$26:$D$973,$B64,'内訳ﾘｽﾄ(4～3月)'!Q$26:Q$973),IF('内訳ﾘｽﾄ(4～3月)'!$D$5="工場間接",-SUM(N$14:N$60,N$65),0)) -> -1095461921 | O64: =IF('内訳ﾘｽﾄ(4～3月)'!$D$5="工場間接",-SUM(O$65,O$14:O$60),IF('内訳ﾘｽﾄ(4～3月)'!$D$5="製造",SUMIF('内訳ﾘｽﾄ(4～3月)'!$D$26:$D$772,'採算表(VND)'!$B64,'内訳ﾘｽﾄ(4～3月)'!R$26:R$772),0)) -> -16318790325
B65: 本社機構経費 | C65: =SUMIF('内訳ﾘｽﾄ(4～3月)'!$D$26:$D$973,$B65,'内訳ﾘｽﾄ(4～3月)'!F$26:F$973) -> 0 | D65: =SUMIF('内訳ﾘｽﾄ(4～3月)'!$D$26:$D$973,$B65,'内訳ﾘｽﾄ(4～3月)'!G$26:G$973) -> 0 | E65: =SUMIF('内訳ﾘｽﾄ(4～3月)'!$D$26:$D$973,$B65,'内訳ﾘｽﾄ(4～3月)'!H$26:H$973) -> 0 | F65: =SUMIF('内訳ﾘｽﾄ(4～3月)'!$D$26:$D$973,$B65,'内訳ﾘｽﾄ(4～3月)'!I$26:I$973) -> 0 | G65: =SUMIF('内訳ﾘｽﾄ(4～3月)'!$D$26:$D$973,$B65,'内訳ﾘｽﾄ(4～3月)'!J$26:J$973) -> 0 | H65: =SUMIF('内訳ﾘｽﾄ(4～3月)'!$D$26:$D$973,$B65,'内訳ﾘｽﾄ(4～3月)'!K$26:K$973) -> 0 | I65: =SUMIF('内訳ﾘｽﾄ(4～3月)'!$D$26:$D$973,$B65,'内訳ﾘｽﾄ(4～3月)'!L$26:L$973) -> 0 | J65: =SUMIF('内訳ﾘｽﾄ(4～3月)'!$D$26:$D$973,$B65,'内訳ﾘｽﾄ(4～3月)'!M$26:M$973) -> 0 | ... N65: =SUMIF('内訳ﾘｽﾄ(4～3月)'!$D$26:$D$973,$B65,'内訳ﾘｽﾄ(4～3月)'!Q$26:Q$973) -> 0 | O65: =SUMIF('内訳ﾘｽﾄ(4～3月)'!$D$26:$D$772,'採算表(VND)'!$B65,'内訳ﾘｽﾄ(4～3月)'!R$26:R$772) -> 0
B66: 差引収益 | C66: =C12-C13 -> 0 | D66: =D12-D13 -> 0 | E66: =E12-E13 -> 0 | F66: =F12-F13 -> 0 | G66: =G12-G13 -> 0 | H66: =H12-H13 -> 0 | I66: =I12-I13 -> 0 | J66: =J12-J13 -> 0 | ... N66: =N12-N13 -> 0 | O66: =IF(ISBLANK(O4),"",O12-O13) -> 0
B67: 総時間 | C67: =C73+C79 -> 0 | D67: =D73+D79 -> 0 | E67: =E73+E79 -> 0 | F67: =F73+F79 -> 0 | G67: =G73+G79 -> 0 | H67: =H73+H79 -> 0 | I67: =I73+I79 -> 0 | J67: =J73+J79 -> 0 | ... N67: =N73+N79 -> 0 | O67: =IF(ISBLANK(O4),"",O73+O79) -> 0
B68: 直接部門 | C68: =SUMIF('内訳ﾘｽﾄ(4～3月)'!$D$8:$D$15,'採算表(VND)'!$B68,'内訳ﾘｽﾄ(4～3月)'!F$8:F$15) -> 2767 | D68: =SUMIF('内訳ﾘｽﾄ(4～3月)'!$D$8:$D$15,'採算表(VND)'!$B68,'内訳ﾘｽﾄ(4～3月)'!G$8:G$15) -> 2709.5 | E68: =SUMIF('内訳ﾘｽﾄ(4～3月)'!$D$8:$D$15,'採算表(VND)'!$B68,'内訳ﾘｽﾄ(4～3月)'!H$8:H$15) -> 2979.5 | F68: =SUMIF('内訳ﾘｽﾄ(4～3月)'!$D$8:$D$15,'採算表(VND)'!$B68,'内訳ﾘｽﾄ(4～3月)'!I$8:I$15) -> 3190 | G68: =SUMIF('内訳ﾘｽﾄ(4～3月)'!$D$8:$D$15,'採算表(VND)'!$B68,'内訳ﾘｽﾄ(4～3月)'!J$8:J$15) -> 2767 | H68: =SUMIF('内訳ﾘｽﾄ(4～3月)'!$D$8:$D$15,'採算表(VND)'!$B68,'内訳ﾘｽﾄ(4～3月)'!K$8:K$15) -> 2616 | I68: =SUMIF('内訳ﾘｽﾄ(4～3月)'!$D$8:$D$15,'採算表(VND)'!$B68,'内訳ﾘｽﾄ(4～3月)'!L$8:L$15) -> 3190 | J68: =SUMIF('内訳ﾘｽﾄ(4～3月)'!$D$8:$D$15,'採算表(VND)'!$B68,'内訳ﾘｽﾄ(4～3月)'!M$8:M$15) -> 2767 | ... N68: =SUMIF('内訳ﾘｽﾄ(4～3月)'!$D$8:$D$15,'採算表(VND)'!$B68,'内訳ﾘｽﾄ(4～3月)'!Q$8:Q$15) -> 2902 | O68: =SUMIF('内訳ﾘｽﾄ(4～3月)'!$D$8:$D$15,'採算表(VND)'!$B68,'内訳ﾘｽﾄ(4～3月)'!$R$8:$R$15) -> 34066
B69: 部内間接部門 | C69: =IF('内訳ﾘｽﾄ(4～3月)'!$D$5="製造",SUMIF('内訳ﾘｽﾄ(4～3月)'!$D$8:$D$15,$B69,'内訳ﾘｽﾄ(4～3月)'!F$8:F$15),IF('内訳ﾘｽﾄ(4～3月)'!$D$5="部内間接",-C$68,0)) -> 0 | D69: =IF('内訳ﾘｽﾄ(4～3月)'!$D$5="製造",SUMIF('内訳ﾘｽﾄ(4～3月)'!$D$8:$D$15,$B69,'内訳ﾘｽﾄ(4～3月)'!G$8:G$15),IF('内訳ﾘｽﾄ(4～3月)'!$D$5="部内間接",-D$68,0)) -> 0 | E69: =IF('内訳ﾘｽﾄ(4～3月)'!$D$5="製造",SUMIF('内訳ﾘｽﾄ(4～3月)'!$D$8:$D$15,$B69,'内訳ﾘｽﾄ(4～3月)'!H$8:H$15),IF('内訳ﾘｽﾄ(4～3月)'!$D$5="部内間接",-E$68,0)) -> 0 | F69: =IF('内訳ﾘｽﾄ(4～3月)'!$D$5="製造",SUMIF('内訳ﾘｽﾄ(4～3月)'!$D$8:$D$15,$B69,'内訳ﾘｽﾄ(4～3月)'!I$8:I$15),IF('内訳ﾘｽﾄ(4～3月)'!$D$5="部内間接",-F$68,0)) -> 0 | G69: =IF('内訳ﾘｽﾄ(4～3月)'!$D$5="製造",SUMIF('内訳ﾘｽﾄ(4～3月)'!$D$8:$D$15,$B69,'内訳ﾘｽﾄ(4～3月)'!J$8:J$15),IF('内訳ﾘｽﾄ(4～3月)'!$D$5="部内間接",-G$68,0)) -> 0 | H69: =IF('内訳ﾘｽﾄ(4～3月)'!$D$5="製造",SUMIF('内訳ﾘｽﾄ(4～3月)'!$D$8:$D$15,$B69,'内訳ﾘｽﾄ(4～3月)'!K$8:K$15),IF('内訳ﾘｽﾄ(4～3月)'!$D$5="部内間接",-H$68,0)) -> 0 | I69: =IF('内訳ﾘｽﾄ(4～3月)'!$D$5="製造",SUMIF('内訳ﾘｽﾄ(4～3月)'!$D$8:$D$15,$B69,'内訳ﾘｽﾄ(4～3月)'!L$8:L$15),IF('内訳ﾘｽﾄ(4～3月)'!$D$5="部内間接",-I$68,0)) -> 0 | J69: =IF('内訳ﾘｽﾄ(4～3月)'!$D$5="製造",SUMIF('内訳ﾘｽﾄ(4～3月)'!$D$8:$D$15,$B69,'内訳ﾘｽﾄ(4～3月)'!M$8:M$15),IF('内訳ﾘｽﾄ(4～3月)'!$D$5="部内間接",-J$68,0)) -> 0 | ... N69: =IF('内訳ﾘｽﾄ(4～3月)'!$D$5="製造",SUMIF('内訳ﾘｽﾄ(4～3月)'!$D$8:$D$15,$B69,'内訳ﾘｽﾄ(4～3月)'!Q$8:Q$15),IF('内訳ﾘｽﾄ(4～3月)'!$D$5="部内間接",-N$68,0)) -> 0 | O69: =IF('内訳ﾘｽﾄ(4～3月)'!$D$5="部内間接",-SUM(O$68),IF('内訳ﾘｽﾄ(4～3月)'!$D$5="製造",SUMIF('内訳ﾘｽﾄ(4～3月)'!$D$8:$D$15,'採算表(VND)'!$B69,'内訳ﾘｽﾄ(4～3月)'!$R$8:$R$15),0)) -> 0
B70: 部外間接部門1 | C70: =IF('内訳ﾘｽﾄ(4～3月)'!$D$5="製造",SUMIF('内訳ﾘｽﾄ(4～3月)'!$D$8:$D$15,$B70,'内訳ﾘｽﾄ(4～3月)'!F$8:F$15),IF('内訳ﾘｽﾄ(4～3月)'!$D$5="部外間接1",-C$68,0)) -> 0 | D70: =IF('内訳ﾘｽﾄ(4～3月)'!$D$5="製造",SUMIF('内訳ﾘｽﾄ(4～3月)'!$D$8:$D$15,$B70,'内訳ﾘｽﾄ(4～3月)'!G$8:G$15),IF('内訳ﾘｽﾄ(4～3月)'!$D$5="部外間接1",-D$68,0)) -> 0 | E70: =IF('内訳ﾘｽﾄ(4～3月)'!$D$5="製造",SUMIF('内訳ﾘｽﾄ(4～3月)'!$D$8:$D$15,$B70,'内訳ﾘｽﾄ(4～3月)'!H$8:H$15),IF('内訳ﾘｽﾄ(4～3月)'!$D$5="部外間接1",-E$68,0)) -> 0 | F70: =IF('内訳ﾘｽﾄ(4～3月)'!$D$5="製造",SUMIF('内訳ﾘｽﾄ(4～3月)'!$D$8:$D$15,$B70,'内訳ﾘｽﾄ(4～3月)'!I$8:I$15),IF('内訳ﾘｽﾄ(4～3月)'!$D$5="部外間接1",-F$68,0)) -> 0 | G70: =IF('内訳ﾘｽﾄ(4～3月)'!$D$5="製造",SUMIF('内訳ﾘｽﾄ(4～3月)'!$D$8:$D$15,$B70,'内訳ﾘｽﾄ(4～3月)'!J$8:J$15),IF('内訳ﾘｽﾄ(4～3月)'!$D$5="部外間接1",-G$68,0)) -> 0 | H70: =IF('内訳ﾘｽﾄ(4～3月)'!$D$5="製造",SUMIF('内訳ﾘｽﾄ(4～3月)'!$D$8:$D$15,$B70,'内訳ﾘｽﾄ(4～3月)'!K$8:K$15),IF('内訳ﾘｽﾄ(4～3月)'!$D$5="部外間接1",-H$68,0)) -> 0 | I70: =IF('内訳ﾘｽﾄ(4～3月)'!$D$5="製造",SUMIF('内訳ﾘｽﾄ(4～3月)'!$D$8:$D$15,$B70,'内訳ﾘｽﾄ(4～3月)'!L$8:L$15),IF('内訳ﾘｽﾄ(4～3月)'!$D$5="部外間接1",-I$68,0)) -> 0 | J70: =IF('内訳ﾘｽﾄ(4～3月)'!$D$5="製造",SUMIF('内訳ﾘｽﾄ(4～3月)'!$D$8:$D$15,$B70,'内訳ﾘｽﾄ(4～3月)'!M$8:M$15),IF('内訳ﾘｽﾄ(4～3月)'!$D$5="部外間接1",-J$68,0)) -> 0 | ... N70: =IF('内訳ﾘｽﾄ(4～3月)'!$D$5="製造",SUMIF('内訳ﾘｽﾄ(4～3月)'!$D$8:$D$15,$B70,'内訳ﾘｽﾄ(4～3月)'!Q$8:Q$15),IF('内訳ﾘｽﾄ(4～3月)'!$D$5="部外間接1",-N$68,0)) -> 0 | O70: =IF('内訳ﾘｽﾄ(4～3月)'!$D$5="部外間接1",-SUM(O$68),IF('内訳ﾘｽﾄ(4～3月)'!$D$5="製造",SUMIF('内訳ﾘｽﾄ(4～3月)'!$D$8:$D$15,'採算表(VND)'!$B70,'内訳ﾘｽﾄ(4～3月)'!$R$8:$R$15),0)) -> 0
B71: 部外間接部門2 | C71: =IF('内訳ﾘｽﾄ(4～3月)'!$D$5="製造",SUMIF('内訳ﾘｽﾄ(4～3月)'!$D$8:$D$15,$B71,'内訳ﾘｽﾄ(4～3月)'!F$8:F$15),IF('内訳ﾘｽﾄ(4～3月)'!$D$5="部外間接2",-C$68,0)) -> 0 | D71: =IF('内訳ﾘｽﾄ(4～3月)'!$D$5="製造",SUMIF('内訳ﾘｽﾄ(4～3月)'!$D$8:$D$15,$B71,'内訳ﾘｽﾄ(4～3月)'!G$8:G$15),IF('内訳ﾘｽﾄ(4～3月)'!$D$5="部外間接2",-D$68,0)) -> 0 | E71: =IF('内訳ﾘｽﾄ(4～3月)'!$D$5="製造",SUMIF('内訳ﾘｽﾄ(4～3月)'!$D$8:$D$15,$B71,'内訳ﾘｽﾄ(4～3月)'!H$8:H$15),IF('内訳ﾘｽﾄ(4～3月)'!$D$5="部外間接2",-E$68,0)) -> 0 | F71: =IF('内訳ﾘｽﾄ(4～3月)'!$D$5="製造",SUMIF('内訳ﾘｽﾄ(4～3月)'!$D$8:$D$15,$B71,'内訳ﾘｽﾄ(4～3月)'!I$8:I$15),IF('内訳ﾘｽﾄ(4～3月)'!$D$5="部外間接2",-F$68,0)) -> 0 | G71: =IF('内訳ﾘｽﾄ(4～3月)'!$D$5="製造",SUMIF('内訳ﾘｽﾄ(4～3月)'!$D$8:$D$15,$B71,'内訳ﾘｽﾄ(4～3月)'!J$8:J$15),IF('内訳ﾘｽﾄ(4～3月)'!$D$5="部外間接2",-G$68,0)) -> 0 | H71: =IF('内訳ﾘｽﾄ(4～3月)'!$D$5="製造",SUMIF('内訳ﾘｽﾄ(4～3月)'!$D$8:$D$15,$B71,'内訳ﾘｽﾄ(4～3月)'!K$8:K$15),IF('内訳ﾘｽﾄ(4～3月)'!$D$5="部外間接2",-H$68,0)) -> 0 | I71: =IF('内訳ﾘｽﾄ(4～3月)'!$D$5="製造",SUMIF('内訳ﾘｽﾄ(4～3月)'!$D$8:$D$15,$B71,'内訳ﾘｽﾄ(4～3月)'!L$8:L$15),IF('内訳ﾘｽﾄ(4～3月)'!$D$5="部外間接2",-I$68,0)) -> 0 | J71: =IF('内訳ﾘｽﾄ(4～3月)'!$D$5="製造",SUMIF('内訳ﾘｽﾄ(4～3月)'!$D$8:$D$15,$B71,'内訳ﾘｽﾄ(4～3月)'!M$8:M$15),IF('内訳ﾘｽﾄ(4～3月)'!$D$5="部外間接2",-J$68,0)) -> 0 | ... N71: =IF('内訳ﾘｽﾄ(4～3月)'!$D$5="製造",SUMIF('内訳ﾘｽﾄ(4～3月)'!$D$8:$D$15,$B71,'内訳ﾘｽﾄ(4～3月)'!Q$8:Q$15),IF('内訳ﾘｽﾄ(4～3月)'!$D$5="部外間接2",-N$68,0)) -> 0 | O71: =IF('内訳ﾘｽﾄ(4～3月)'!$D$5="部外間接2",-SUM(O$68),IF('内訳ﾘｽﾄ(4～3月)'!$D$5="製造",SUMIF('内訳ﾘｽﾄ(4～3月)'!$D$8:$D$15,'採算表(VND)'!$B71,'内訳ﾘｽﾄ(4～3月)'!$R$8:$R$15),0)) -> 0
B72: 工場間接部門 | C72: =IF('内訳ﾘｽﾄ(4～3月)'!$D$5="製造",SUMIF('内訳ﾘｽﾄ(4～3月)'!$D$8:$D$15,$B72,'内訳ﾘｽﾄ(4～3月)'!F$8:F$15),IF('内訳ﾘｽﾄ(4～3月)'!$D$5="工場間接",-C$68,0)) -> -2767 | D72: =IF('内訳ﾘｽﾄ(4～3月)'!$D$5="製造",SUMIF('内訳ﾘｽﾄ(4～3月)'!$D$8:$D$15,$B72,'内訳ﾘｽﾄ(4～3月)'!G$8:G$15),IF('内訳ﾘｽﾄ(4～3月)'!$D$5="工場間接",-D$68,0)) -> -2709.5 | E72: =IF('内訳ﾘｽﾄ(4～3月)'!$D$5="製造",SUMIF('内訳ﾘｽﾄ(4～3月)'!$D$8:$D$15,$B72,'内訳ﾘｽﾄ(4～3月)'!H$8:H$15),IF('内訳ﾘｽﾄ(4～3月)'!$D$5="工場間接",-E$68,0)) -> -2979.5 | F72: =IF('内訳ﾘｽﾄ(4～3月)'!$D$5="製造",SUMIF('内訳ﾘｽﾄ(4～3月)'!$D$8:$D$15,$B72,'内訳ﾘｽﾄ(4～3月)'!I$8:I$15),IF('内訳ﾘｽﾄ(4～3月)'!$D$5="工場間接",-F$68,0)) -> -3190 | G72: =IF('内訳ﾘｽﾄ(4～3月)'!$D$5="製造",SUMIF('内訳ﾘｽﾄ(4～3月)'!$D$8:$D$15,$B72,'内訳ﾘｽﾄ(4～3月)'!J$8:J$15),IF('内訳ﾘｽﾄ(4～3月)'!$D$5="工場間接",-G$68,0)) -> -2767 | H72: =IF('内訳ﾘｽﾄ(4～3月)'!$D$5="製造",SUMIF('内訳ﾘｽﾄ(4～3月)'!$D$8:$D$15,$B72,'内訳ﾘｽﾄ(4～3月)'!K$8:K$15),IF('内訳ﾘｽﾄ(4～3月)'!$D$5="工場間接",-H$68,0)) -> -2616 | I72: =IF('内訳ﾘｽﾄ(4～3月)'!$D$5="製造",SUMIF('内訳ﾘｽﾄ(4～3月)'!$D$8:$D$15,$B72,'内訳ﾘｽﾄ(4～3月)'!L$8:L$15),IF('内訳ﾘｽﾄ(4～3月)'!$D$5="工場間接",-I$68,0)) -> -3190 | J72: =IF('内訳ﾘｽﾄ(4～3月)'!$D$5="製造",SUMIF('内訳ﾘｽﾄ(4～3月)'!$D$8:$D$15,$B72,'内訳ﾘｽﾄ(4～3月)'!M$8:M$15),IF('内訳ﾘｽﾄ(4～3月)'!$D$5="工場間接",-J$68,0)) -> -2767 | ... N72: =IF('内訳ﾘｽﾄ(4～3月)'!$D$5="製造",SUMIF('内訳ﾘｽﾄ(4～3月)'!$D$8:$D$15,$B72,'内訳ﾘｽﾄ(4～3月)'!Q$8:Q$15),IF('内訳ﾘｽﾄ(4～3月)'!$D$5="工場間接",-N$68,0)) -> -2902 | O72: =IF('内訳ﾘｽﾄ(4～3月)'!$D$5="工場間接",-SUM(O$68),IF('内訳ﾘｽﾄ(4～3月)'!$D$5="製造",SUMIF('内訳ﾘｽﾄ(4～3月)'!$D$8:$D$15,'採算表(VND)'!$B72,'内訳ﾘｽﾄ(4～3月)'!$R$8:$R$15),0)) -> -34066
B73: 定時間合計 | C73: =SUM(C68:C72) -> 0 | D73: =SUM(D68:D72) -> 0 | E73: =SUM(E68:E72) -> 0 | F73: =SUM(F68:F72) -> 0 | G73: =SUM(G68:G72) -> 0 | H73: =SUM(H68:H72) -> 0 | I73: =SUM(I68:I72) -> 0 | J73: =SUM(J68:J72) -> 0 | ... N73: =SUM(N68:N72) -> 0 | O73: =IF(ISBLANK(O4),"",SUM(O68:O72)) -> 0
B74: 直接部門 | C74: =SUMIF('内訳ﾘｽﾄ(4～3月)'!$D$16:$D$23,'採算表(VND)'!$B74,'内訳ﾘｽﾄ(4～3月)'!F$16:F$23) -> 176.5 | D74: =SUMIF('内訳ﾘｽﾄ(4～3月)'!$D$16:$D$23,'採算表(VND)'!$B74,'内訳ﾘｽﾄ(4～3月)'!G$16:G$23) -> 193.5 | E74: =SUMIF('内訳ﾘｽﾄ(4～3月)'!$D$16:$D$23,'採算表(VND)'!$B74,'内訳ﾘｽﾄ(4～3月)'!H$16:H$23) -> 185.5 | F74: =SUMIF('内訳ﾘｽﾄ(4～3月)'!$D$16:$D$23,'採算表(VND)'!$B74,'内訳ﾘｽﾄ(4～3月)'!I$16:I$23) -> 203.5 | G74: =SUMIF('内訳ﾘｽﾄ(4～3月)'!$D$16:$D$23,'採算表(VND)'!$B74,'内訳ﾘｽﾄ(4～3月)'!J$16:J$23) -> 176.5 | H74: =SUMIF('内訳ﾘｽﾄ(4～3月)'!$D$16:$D$23,'採算表(VND)'!$B74,'内訳ﾘｽﾄ(4～3月)'!K$16:K$23) -> 251.5 | I74: =SUMIF('内訳ﾘｽﾄ(4～3月)'!$D$16:$D$23,'採算表(VND)'!$B74,'内訳ﾘｽﾄ(4～3月)'!L$16:L$23) -> 203.5 | J74: =SUMIF('内訳ﾘｽﾄ(4～3月)'!$D$16:$D$23,'採算表(VND)'!$B74,'内訳ﾘｽﾄ(4～3月)'!M$16:M$23) -> 246.5 | ... N74: =SUMIF('内訳ﾘｽﾄ(4～3月)'!$D$16:$D$23,'採算表(VND)'!$B74,'内訳ﾘｽﾄ(4～3月)'!Q$16:Q$23) -> 176.5 | O74: =SUMIF('内訳ﾘｽﾄ(4～3月)'!$D$16:$D$23,'採算表(VND)'!$B74,'内訳ﾘｽﾄ(4～3月)'!$R$16:$R$23) -> 2316
B75: 部内間接部門 | C75: =IF('内訳ﾘｽﾄ(4～3月)'!$D$5="製造",SUMIF('内訳ﾘｽﾄ(4～3月)'!$D$16:$D$23,$B75,'内訳ﾘｽﾄ(4～3月)'!F$16:F$23),IF('内訳ﾘｽﾄ(4～3月)'!$D$5="部内間接",-C$74,0)) -> 0 | D75: =IF('内訳ﾘｽﾄ(4～3月)'!$D$5="製造",SUMIF('内訳ﾘｽﾄ(4～3月)'!$D$16:$D$23,$B75,'内訳ﾘｽﾄ(4～3月)'!G$16:G$23),IF('内訳ﾘｽﾄ(4～3月)'!$D$5="部内間接",-D$74,0)) -> 0 | E75: =IF('内訳ﾘｽﾄ(4～3月)'!$D$5="製造",SUMIF('内訳ﾘｽﾄ(4～3月)'!$D$16:$D$23,$B75,'内訳ﾘｽﾄ(4～3月)'!H$16:H$23),IF('内訳ﾘｽﾄ(4～3月)'!$D$5="部内間接",-E$74,0)) -> 0 | F75: =IF('内訳ﾘｽﾄ(4～3月)'!$D$5="製造",SUMIF('内訳ﾘｽﾄ(4～3月)'!$D$16:$D$23,$B75,'内訳ﾘｽﾄ(4～3月)'!I$16:I$23),IF('内訳ﾘｽﾄ(4～3月)'!$D$5="部内間接",-F$74,0)) -> 0 | G75: =IF('内訳ﾘｽﾄ(4～3月)'!$D$5="製造",SUMIF('内訳ﾘｽﾄ(4～3月)'!$D$16:$D$23,$B75,'内訳ﾘｽﾄ(4～3月)'!J$16:J$23),IF('内訳ﾘｽﾄ(4～3月)'!$D$5="部内間接",-G$74,0)) -> 0 | H75: =IF('内訳ﾘｽﾄ(4～3月)'!$D$5="製造",SUMIF('内訳ﾘｽﾄ(4～3月)'!$D$16:$D$23,$B75,'内訳ﾘｽﾄ(4～3月)'!K$16:K$23),IF('内訳ﾘｽﾄ(4～3月)'!$D$5="部内間接",-H$74,0)) -> 0 | I75: =IF('内訳ﾘｽﾄ(4～3月)'!$D$5="製造",SUMIF('内訳ﾘｽﾄ(4～3月)'!$D$16:$D$23,$B75,'内訳ﾘｽﾄ(4～3月)'!L$16:L$23),IF('内訳ﾘｽﾄ(4～3月)'!$D$5="部内間接",-I$74,0)) -> 0 | J75: =IF('内訳ﾘｽﾄ(4～3月)'!$D$5="製造",SUMIF('内訳ﾘｽﾄ(4～3月)'!$D$16:$D$23,$B75,'内訳ﾘｽﾄ(4～3月)'!M$16:M$23),IF('内訳ﾘｽﾄ(4～3月)'!$D$5="部内間接",-J$74,0)) -> 0 | ... N75: =IF('内訳ﾘｽﾄ(4～3月)'!$D$5="製造",SUMIF('内訳ﾘｽﾄ(4～3月)'!$D$16:$D$23,$B75,'内訳ﾘｽﾄ(4～3月)'!Q$16:Q$23),IF('内訳ﾘｽﾄ(4～3月)'!$D$5="部内間接",-N$74,0)) -> 0 | O75: =IF('内訳ﾘｽﾄ(4～3月)'!$D$5="部内間接",-SUM(O$74),IF('内訳ﾘｽﾄ(4～3月)'!$D$5="製造",SUMIF('内訳ﾘｽﾄ(4～3月)'!$D$16:$D$23,'採算表(VND)'!$B75,'内訳ﾘｽﾄ(4～3月)'!$R$16:$R$23),0)) -> 0
...

Sheet 内訳ﾘｽﾄ(4～3月)
A1: MP FY2026_各予定 | F1: 5797 | G1: 5753 | H1: 5618 | I1: 6137 | J1: 6325 | K1: 6547 | L1: 6897 | M1: 7003 | N1: 6941 | O1: 7207 | P1: 7661 | Q1: 7193
B2: 25390 | E2: 稼働日数 | F2: =OFFSET(稼働日!$B$2,MATCH('内訳ﾘｽﾄ(4～3月)'!F4,稼働日!$A$3:$A$14,0),0) -> 20 | G2: =OFFSET(稼働日!$B$2,MATCH('内訳ﾘｽﾄ(4～3月)'!G4,稼働日!$A$3:$A$14,0),0) -> 19 | H2: =OFFSET(稼働日!$B$2,MATCH('内訳ﾘｽﾄ(4～3月)'!H4,稼働日!$A$3:$A$14,0),0) -> 21 | I2: =OFFSET(稼働日!$B$2,MATCH('内訳ﾘｽﾄ(4～3月)'!I4,稼働日!$A$3:$A$14,0),0) -> 23 | J2: =OFFSET(稼働日!$B$2,MATCH('内訳ﾘｽﾄ(4～3月)'!J4,稼働日!$A$3:$A$14,0),0) -> 20 | K2: =OFFSET(稼働日!$B$2,MATCH('内訳ﾘｽﾄ(4～3月)'!K4,稼働日!$A$3:$A$14,0),0) -> 19 | L2: =OFFSET(稼働日!$B$2,MATCH('内訳ﾘｽﾄ(4～3月)'!L4,稼働日!$A$3:$A$14,0),0) -> 23 | M2: =OFFSET(稼働日!$B$2,MATCH('内訳ﾘｽﾄ(4～3月)'!M4,稼働日!$A$3:$A$14,0),0) -> 20 | ... Q2: =OFFSET(稼働日!$B$2,MATCH('内訳ﾘｽﾄ(4～3月)'!Q4,稼働日!$A$3:$A$14,0),0) -> 20
E3: CHECK | F3: {=IF(SUM((F8:F25)-ROUNDDOWN((F8:F25)*4,0)/4)<>0,"時間➝0.25の倍数では無い",IF(SUM(ROUND((F26:F973),0)-ROUND((F26:F973),4))<>0,"経費➝小数点",IF(F5<>IF($D$5="製造",'採算表(VND)'!C13,-VLOOKUP($D$5&"経費",'採算表(VND)'!$B:$N,'採算表(VND)'!C3,0)),"経費➝NG","OK")))} -> OK | G3: {=IF(SUM((G8:G25)-ROUNDDOWN((G8:G25)*4,0)/4)<>0,"時間➝0.25の倍数では無い",IF(SUM(ROUND((G26:G973),0)-ROUND((G26:G973),4))<>0,"経費➝小数点",IF(G5<>IF($D$5="製造",'採算表(VND)'!D13,-VLOOKUP($D$5&"経費",'採算表(VND)'!$B:$N,'採算表(VND)'!D3,0)),"経費➝NG","OK")))} -> OK | H3: {=IF(SUM((H8:H25)-ROUNDDOWN((H8:H25)*4,0)/4)<>0,"時間➝0.25の倍数では無い",IF(SUM(ROUND((H26:H973),0)-ROUND((H26:H973),4))<>0,"経費➝小数点",IF(H5<>IF($D$5="製造",'採算表(VND)'!E13,-VLOOKUP($D$5&"経費",'採算表(VND)'!$B:$N,'採算表(VND)'!E3,0)),"経費➝NG","OK")))} -> OK | I3: {=IF(SUM((I8:I25)-ROUNDDOWN((I8:I25)*4,0)/4)<>0,"時間➝0.25の倍数では無い",IF(SUM(ROUND((I26:I973),0)-ROUND((I26:I973),4))<>0,"経費➝小数点",IF(I5<>IF($D$5="製造",'採算表(VND)'!F13,-VLOOKUP($D$5&"経費",'採算表(VND)'!$B:$N,'採算表(VND)'!F3,0)),"経費➝NG","OK")))} -> OK | J3: {=IF(SUM((J8:J25)-ROUNDDOWN((J8:J25)*4,0)/4)<>0,"時間➝0.25の倍数では無い",IF(SUM(ROUND((J26:J973),0)-ROUND((J26:J973),4))<>0,"経費➝小数点",IF(J5<>IF($D$5="製造",'採算表(VND)'!G13,-VLOOKUP($D$5&"経費",'採算表(VND)'!$B:$N,'採算表(VND)'!G3,0)),"経費➝NG","OK")))} -> OK | K3: {=IF(SUM((K8:K25)-ROUNDDOWN((K8:K25)*4,0)/4)<>0,"時間➝0.25の倍数では無い",IF(SUM(ROUND((K26:K973),0)-ROUND((K26:K973),4))<>0,"経費➝小数点",IF(K5<>IF($D$5="製造",'採算表(VND)'!H13,-VLOOKUP($D$5&"経費",'採算表(VND)'!$B:$N,'採算表(VND)'!H3,0)),"経費➝NG","OK")))} -> OK | L3: {=IF(SUM((L8:L25)-ROUNDDOWN((L8:L25)*4,0)/4)<>0,"時間➝0.25の倍数では無い",IF(SUM(ROUND((L26:L973),0)-ROUND((L26:L973),4))<>0,"経費➝小数点",IF(L5<>IF($D$5="製造",'採算表(VND)'!I13,-VLOOKUP($D$5&"経費",'採算表(VND)'!$B:$N,'採算表(VND)'!I3,0)),"経費➝NG","OK")))} -> OK | M3: {=IF(SUM((M8:M25)-ROUNDDOWN((M8:M25)*4,0)/4)<>0,"時間➝0.25の倍数では無い",IF(SUM(ROUND((M26:M973),0)-ROUND((M26:M973),4))<>0,"経費➝小数点",IF(M5<>IF($D$5="製造",'採算表(VND)'!J13,-VLOOKUP($D$5&"経費",'採算表(VND)'!$B:$N,'採算表(VND)'!J3,0)),"経費➝NG","OK")))} -> OK | ... Q3: {=IF(SUM((Q8:Q25)-ROUNDDOWN((Q8:Q25)*4,0)/4)<>0,"時間➝0.25の倍数では無い",IF(SUM(ROUND((Q26:Q973),0)-ROUND((Q26:Q973),4))<>0,"経費➝小数点",IF(Q5<>IF($D$5="製造",'採算表(VND)'!N13,-VLOOKUP($D$5&"経費",'採算表(VND)'!$B:$N,'採算表(VND)'!N3,0)),"経費➝NG","OK")))} -> OK
B4: 原価センター | C4: 組織名 | D4: 採算区分 | E4: 原価区分 | F4: 4 | G4: 5 | H4: 6 | I4: 7 | J4: 8 | K4: 9 | L4: 10 | M4: 11 | N4: 12 | O4: 1 | P4: 2 | Q4: 3 | R4: 合計
B5: 1412000024 | C5: =VLOOKUP($B$5,原価センタ!$A:$E,2,0) -> 総務課 | D5: =VLOOKUP($B$5,原価センタ!$A:$E,4,0) -> 工場間接 | E5: =VLOOKUP($B$5,原価センタ!$A:$E,5,0) -> 一般 | F5: =SUM(F29:F973) -> 3232448531 | G5: =SUM(G29:G973) -> 1191581278 | H5: =SUM(H29:H973) -> 1137648047 | I5: =SUM(I29:I973) -> 1140451181 | J5: =SUM(J29:J973) -> 1223940850 | K5: =SUM(K29:K973) -> 1245870347 | L5: =SUM(L29:L973) -> 1039609847 | M5: =SUM(M29:M973) -> 1245812344 | ... R5: =SUM(R29:R973) -> 16318790325
C7: 勘定科目名称 | D7: 採算科目 | E7: ﾃｰﾏｺｰﾄﾞ | F7: MP | G7: MP | H7: MP | I7: MP | J7: MP | K7: MP | L7: MP | M7: MP | N7: MP | O7: MP | P7: MP | Q7: MP | R7: MP | S7: 備考 | T7: WBS | BC7: WBS
B8: 出向社員定時 | C8: 定時間（日本社員） | D8: 直接部門 | F8: 170 | G8: 161.5 | H8: 178.5 | I8: 195.5 | J8: 170 | K8: 161.5 | L8: 195.5 | M8: 170 | N8: 187 | O8: 170 | P8: 127.5 | Q8: 170 | R8: =SUM(F8:Q8) -> 2057
B9: ローカル社員定時 | C9: 定時間（ベトナム社員） | D9: 直接部門 | F9: 2597 | G9: 2548 | H9: 2801 | I9: 2994.5 | J9: 2597 | K9: 2454.5 | L9: 2994.5 | M9: 2597 | N9: 2934.5 | O9: 2739.5 | P9: 2019.5 | Q9: 2732 | R9: =SUM(F9:Q9) -> 32009
B10: 出向社員定時 | C10: 定時間（移動分日本社員） | D10: 直接部門 | R10: =SUM(F10:Q10) -> 0
B11: ローカル社員定時 | C11: 定時間（移動分ベトナム社員） | D11: 直接部門 | R11: =SUM(F11:Q11) -> 0
C12: 定時間（部内間接部門） | D12: 部内間接部門 | R12: =SUM(F12:Q12) -> 0 | S12: この分には間接部門から直接部門に配賦された数字
C13: 定時間（部外間接部門1） | D13: 部外間接部門1 | R13: =SUM(F13:Q13) -> 0 | S13: この分には間接部門から直接部門に配賦された数字
C14: 定時間（部外間接部門2） | D14: 部外間接部門2 | R14: =SUM(F14:Q14) -> 0 | S14: この分には間接部門から直接部門に配賦された数字
C15: 定時間（工場間接部門） | D15: 工場間接部門 | R15: =SUM(F15:Q15) -> 0 | S15: この分には間接部門から直接部門に配賦された数字
B16: 出向社員残業 | C16: 残業時間（日本社員） | D16: 直接部門 | F16: 40 | G16: 38 | H16: 42 | I16: 46 | J16: 40 | K16: 38 | L16: 46 | M16: 40 | N16: 44 | O16: 40 | P16: 30 | Q16: 40 | R16: =SUM(F16:Q16) -> 484
B17: ローカル社員残業 | C17: 残業時間（ベトナム社員） | D17: 直接部門 | F17: 136.5 | G17: 155.5 | H17: 143.5 | I17: 157.5 | J17: 136.5 | K17: 213.5 | L17: 157.5 | M17: 206.5 | N17: 150.5 | O17: 136.5 | P17: 101.5 | Q17: 136.5 | R17: =SUM(F17:Q17) -> 1832
B18: 出向社員残業 | C18: 残業時間（移動分日本社員） | D18: 直接部門 | R18: =SUM(F18:Q18) -> 0
B19: ローカル社員残業 | C19: 残業時間（移動分ベトナム社員） | D19: 直接部門 | R19: =SUM(F19:Q19) -> 0
C20: 残業時間（部内間接部門） | D20: 部内間接部門 | R20: =SUM(F20:Q20) -> 0 | S20: この分には間接部門から直接部門に配賦された数字
C21: 残業時間（部外間接部門1） | D21: 部外間接部門1 | R21: =SUM(F21:Q21) -> 0 | S21: この分には間接部門から直接部門に配賦された数字
C22: 残業時間（部外間接部門2） | D22: 部外間接部門2 | R22: =SUM(F22:Q22) -> 0 | S22: この分には間接部門から直接部門に配賦された数字
C23: 残業時間（工場間接部門） | D23: 工場間接部門 | R23: =SUM(F23:Q23) -> 0 | S23: この分には間接部門から直接部門に配賦された数字
B24: 出向社員(人) | C24: 出向社員(人) | D24: 出向社員(人) | F24: 1 | G24: 1 | H24: 1 | I24: 1 | J24: 1 | K24: 1 | L24: 1 | M24: 1 | N24: 1 | O24: 1 | P24: 1 | Q24: 1 | R24: =Q24 -> 1
B25: ローカル社員(人) | C25: ローカル社員(人) | D25: ローカル社員(人) | F25: 16 | G25: 17 | H25: 17 | I25: 17 | J25: 17 | K25: 17 | L25: 17 | M25: 17 | N25: 17 | O25: 17 | P25: 17 | Q25: 17 | R25: =Q25 -> 17 | V25: 4 | W25: 5 | X25: 6 | Y25: 7 | Z25: 8 | AA25: 9 | AB25: 10 | AC25: 11 | AD25: 12 | AE25: 1 | AF25: 2 | AG25: 3
B26: 9114120002 | C26: =IFERROR(IF(VLOOKUP($B26,勘定科目!$A:$H,HLOOKUP($E$5,勘定科目!$F$1:$H$2,2,0),0)="","",VLOOKUP($B26,勘定科目!$A:$E,2,0)),"") -> 社外出荷 | D26: =IF(C26="","",VLOOKUP($B26,勘定科目!$A:$E,4,0)) -> 社外出荷 | F26: =ROUNDDOWN(V26*$B$2,0) -> 0 | G26: =ROUNDDOWN(W26*$B$2,0) -> 0 | H26: =ROUNDDOWN(X26*$B$2,0) -> 0 | I26: =ROUNDDOWN(Y26*$B$2,0) -> 0 | J26: =ROUNDDOWN(Z26*$B$2,0) -> 0 | K26: =ROUNDDOWN(AA26*$B$2,0) -> 0 | L26: =ROUNDDOWN(AB26*$B$2,0) -> 0 | M26: =ROUNDDOWN(AC26*$B$2,0) -> 0 | ... Q26: =ROUNDDOWN(AG26*$B$2,0) -> 0 | R26: =SUM(F26:Q26) -> 0 | S26: 総生産
B27: 9114120004 | C27: =IFERROR(IF(VLOOKUP($B27,勘定科目!$A:$H,HLOOKUP($E$5,勘定科目!$F$1:$H$2,2,0),0)="","",VLOOKUP($B27,勘定科目!$A:$E,2,0)),"") -> 社内売 | D27: =IF(C27="","",VLOOKUP($B27,勘定科目!$A:$E,4,0)) -> 社内売 | F27: =ROUNDDOWN(V27*$B$2,0) -> 0 | G27: =ROUNDDOWN(W27*$B$2,0) -> 0 | H27: =ROUNDDOWN(X27*$B$2,0) -> 0 | I27: =ROUNDDOWN(Y27*$B$2,0) -> 0 | J27: =ROUNDDOWN(Z27*$B$2,0) -> 0 | K27: =ROUNDDOWN(AA27*$B$2,0) -> 0 | L27: =ROUNDDOWN(AB27*$B$2,0) -> 0 | M27: =ROUNDDOWN(AC27*$B$2,0) -> 0 | ... Q27: =ROUNDDOWN(AG27*$B$2,0) -> 0 | R27: =SUM(F27:Q27) -> 0 | S27: 総生産
B28: 9114120014 | C28: =IFERROR(IF(VLOOKUP($B28,勘定科目!$A:$H,HLOOKUP($E$5,勘定科目!$F$1:$H$2,2,0),0)="","",VLOOKUP($B28,勘定科目!$A:$E,2,0)),"") -> 社内買 | D28: =IF(C28="","",VLOOKUP($B28,勘定科目!$A:$E,4,0)) -> 社内買 | F28: =ROUNDDOWN(V28*$B$2,0) -> 0 | G28: =ROUNDDOWN(W28*$B$2,0) -> 0 | H28: =ROUNDDOWN(X28*$B$2,0) -> 0 | I28: =ROUNDDOWN(Y28*$B$2,0) -> 0 | J28: =ROUNDDOWN(Z28*$B$2,0) -> 0 | K28: =ROUNDDOWN(AA28*$B$2,0) -> 0 | L28: =ROUNDDOWN(AB28*$B$2,0) -> 0 | M28: =ROUNDDOWN(AC28*$B$2,0) -> 0 | ... Q28: =ROUNDDOWN(AG28*$B$2,0) -> 0 | R28: =SUM(F28:Q28) -> 0 | S28: 総生産
B29: 9114120006 | C29: =IFERROR(IF(VLOOKUP($B29,勘定科目!$A:$H,HLOOKUP($E$5,勘定科目!$F$1:$H$2,2,0),0)="","",VLOOKUP($B29,勘定科目!$A:$E,2,0)),"") -> 材料費(指図出庫） | D29: =IF(C29="","",VLOOKUP($B29,勘定科目!$A:$E,4,0)) -> 材料費 | F29: =ROUNDUP(V29*$B$2,0) -> 0 | G29: =ROUNDUP(W29*$B$2,0) -> 0 | H29: =ROUNDUP(X29*$B$2,0) -> 0 | I29: =ROUNDUP(Y29*$B$2,0) -> 0 | J29: =ROUNDUP(Z29*$B$2,0) -> 0 | K29: =ROUNDUP(AA29*$B$2,0) -> 0 | L29: =ROUNDUP(AB29*$B$2,0) -> 0 | M29: =ROUNDUP(AC29*$B$2,0) -> 0 | ... Q29: =ROUNDUP(AG29*$B$2,0) -> 0 | R29: =SUM(F29:Q29) -> 0 | S29: 総生産
C30: =IFERROR(IF(VLOOKUP($B30,勘定科目!$A:$H,HLOOKUP($E$5,勘定科目!$F$1:$H$2,2,0),0)="","",VLOOKUP($B30,勘定科目!$A:$E,2,0)),"") | D30: =IF(C30="","",VLOOKUP($B30,勘定科目!$A:$E,4,0)) | R30: =SUM(F30:Q30) -> 0
B31: 9114120018 | C31: =IFERROR(IF(VLOOKUP($B31,勘定科目!$A:$H,HLOOKUP($E$5,勘定科目!$F$1:$H$2,2,0),0)="","",VLOOKUP($B31,勘定科目!$A:$E,2,0)),"") -> 部内間接経費 | D31: =IF(C31="","",VLOOKUP($B31,勘定科目!$A:$E,4,0)) -> 部内間接経費 | R31: =SUM(F31:Q31) -> 0 | S31: この分には間接部門から直接部門に配賦された数字
B32: 9114120029 | C32: =IFERROR(IF(VLOOKUP($B32,勘定科目!$A:$H,HLOOKUP($E$5,勘定科目!$F$1:$H$2,2,0),0)="","",VLOOKUP($B32,勘定科目!$A:$E,2,0)),"") -> 部外間接経費1 | D32: =IF(C32="","",VLOOKUP($B32,勘定科目!$A:$E,4,0)) -> 部外間接経費1 | R32: =SUM(F32:Q32) -> 0 | S32: この分には間接部門から直接部門に配賦された数字
B33: 9114120030 | C33: =IFERROR(IF(VLOOKUP($B33,勘定科目!$A:$H,HLOOKUP($E$5,勘定科目!$F$1:$H$2,2,0),0)="","",VLOOKUP($B33,勘定科目!$A:$E,2,0)),"") -> 部外間接経費2 | D33: =IF(C33="","",VLOOKUP($B33,勘定科目!$A:$E,4,0)) -> 部外間接経費2 | R33: =SUM(F33:Q33) -> 0 | S33: この分には間接部門から直接部門に配賦された数字
B34: 9114120021 | C34: =IFERROR(IF(VLOOKUP($B34,勘定科目!$A:$H,HLOOKUP($E$5,勘定科目!$F$1:$H$2,2,0),0)="","",VLOOKUP($B34,勘定科目!$A:$E,2,0)),"") -> 工場間接経費 | D34: =IF(C34="","",VLOOKUP($B34,勘定科目!$A:$E,4,0)) -> 工場間接経費 | R34: =SUM(F34:Q34) -> 0 | S34: この分には間接部門から直接部門に配賦された数字
C35: =IFERROR(IF(VLOOKUP($B35,勘定科目!$A:$H,HLOOKUP($E$5,勘定科目!$F$1:$H$2,2,0),0)="","",VLOOKUP($B35,勘定科目!$A:$E,2,0)),"") | D35: =IF(C35="","",VLOOKUP($B35,勘定科目!$A:$E,4,0)) | R35: =SUM(F35:Q35) -> 0
B36: 9114120009 | C36: =IFERROR(IF(VLOOKUP($B36,勘定科目!$A:$H,HLOOKUP($E$5,勘定科目!$F$1:$H$2,2,0),0)="","",VLOOKUP($B36,勘定科目!$A:$E,2,0)),"") -> 社内金利（在庫） | D36: =IF(C36="","",VLOOKUP($B36,勘定科目!$A:$E,4,0)) -> 在庫金利 | R36: =SUM(F36:Q36) -> 0
C37: =IFERROR(IF(VLOOKUP($B37,勘定科目!$A:$H,HLOOKUP($E$5,勘定科目!$F$1:$H$2,2,0),0)="","",VLOOKUP($B37,勘定科目!$A:$E,2,0)),"") | D37: =IF(C37="","",VLOOKUP($B37,勘定科目!$A:$E,4,0)) | R37: =SUM(F37:Q37) -> 0
B38: 6006016628 | C38: =IFERROR(IF(VLOOKUP($B38,勘定科目!$A:$H,HLOOKUP($E$5,勘定科目!$F$1:$H$2,2,0),0)="","",VLOOKUP($B38,勘定科目!$A:$E,2,0)),"") -> 減価償却費配賦（一般） 建物 | D38: =IF(C38="","",VLOOKUP($B38,勘定科目!$A:$E,4,0)) -> 減価償却費 | E38: 施設 | F38: =ROUNDUP(18247.45*$B$2,0) -> 463302756 | G38: =ROUNDUP(18264.53*$B$2,0) -> 463736417 | H38: =ROUNDUP(18264.63*$B$2,0) -> 463738956 | I38: =ROUNDUP(18264.27*$B$2,0) -> 463729816 | J38: =ROUNDUP(18264.16*$B$2,0) -> 463727023 | K38: =ROUNDUP(18258.93*$B$2,0) -> 463594233 | L38: =ROUNDUP(18257.42*$B$2,0) -> 463555894 | M38: =ROUNDUP(18257.36*$B$2,0) -> 463554371 | N38: =ROUNDUP(18257.39*$B$2,0) -> 463555133 | O38: =ROUNDUP(18257.27*$B$2,0) -> 463552086 | P38: =ROUNDUP(18257.07*$B$2,0) -> 463547008 | Q38: =ROUNDUP(18257.27*$B$2,0) -> 463552086 | R38: =SUM(F38:Q38) -> 5563145779 | S38: 建屋償却費 Khấu hao nhà xưởng
B39: 6006016629 | C39: =IFERROR(IF(VLOOKUP($B39,勘定科目!$A:$H,HLOOKUP($E$5,勘定科目!$F$1:$H$2,2,0),0)="","",VLOOKUP($B39,勘定科目!$A:$E,2,0)),"") -> 減価償却費配賦（一般） 土地使用権 | D39: =IF(C39="","",VLOOKUP($B39,勘定科目!$A:$E,4,0)) -> 減価償却費 | E39: 施設 | F39: =ROUNDUP(1231.63*$B$2,0) -> 31271086 | G39: =ROUNDUP(1232.78*$B$2,0) -> 31300285 | H39: =ROUNDUP(1232.79*$B$2,0) -> 31300539 | I39: =ROUNDUP(1232.77*$B$2,0) -> 31300031 | J39: =ROUNDUP(1232.76*$B$2,0) -> 31299777 | K39: =ROUNDUP(1232.41*$B$2,0) -> 31290890 | L39: =ROUNDUP(1232.3*$B$2,0) -> 31288097 | M39: =ROUNDUP(1232.3*$B$2,0) -> 31288097 | N39: =ROUNDUP(1232.3*$B$2,0) -> 31288097 | O39: =ROUNDUP(1232.29*$B$2,0) -> 31287844 | P39: =ROUNDUP(1232.28*$B$2,0) -> 31287590 | Q39: =ROUNDUP(1232.29*$B$2,0) -> 31287844 | R39: =SUM(F39:Q39) -> 375490177 | S39: 土地使用権償却費 Khấu hao đất sử dụng
B40: 9114120007 | C40: =IFERROR(IF(VLOOKUP($B40,勘定科目!$A:$H,HLOOKUP($E$5,勘定科目!$F$1:$H$2,2,0),0)="","",VLOOKUP($B40,勘定科目!$A:$E,2,0)),"") -> 社内金利（固定資産） | D40: =IF(C40="","",VLOOKUP($B40,勘定科目!$A:$E,4,0)) -> 固定資産金利 | E40: 施設 | F40: =ROUNDUP(12386.05*$B$2,0) -> 314481810 | G40: =ROUNDUP(11740.13*$B$2,0) -> 298081901 | H40: =ROUNDUP(11740.19*$B$2,0) -> 298083425 | I40: =ROUNDUP(11739.96*$B$2,0) -> 298077585 | J40: =ROUNDUP(11739.89*$B$2,0) -> 298075808 | K40: =ROUNDUP(11736.53*$B$2,0) -> 297990497 | L40: =ROUNDUP(11735.55*$B$2,0) -> 297965615 | M40: =ROUNDUP(11735.52*$B$2,0) -> 297964853 | N40: =ROUNDUP(11735.54*$B$2,0) -> 297965361 | O40: =ROUNDUP(11735.46*$B$2,0) -> 297963330 | P40: =ROUNDUP(11735.336*$B$2,0) -> 297960182 | Q40: =ROUNDUP(11735.46*$B$2,0) -> 297963330 | R40: =SUM(F40:Q40) -> 3592573697 | S40: 建物利益 Lãi nhà xưởng
