Workbook
Name WBS: 原価センタ!$G$2:$G$3

Sheet 採算表(USD)
B1: 組織名 | C1: ='採算表(VND)'!C1 -> MP FY2026_各予定 | N1: ='内訳ﾘｽﾄ(4～3月)'!B2 -> 25390
B2: ='採算表(VND)'!B2 -> MD3課
B4: 項目 ＼ 部門 | C4: ='採算表(VND)'!C4 -> 4 | D4: ='採算表(VND)'!D4 -> 5 | E4: ='採算表(VND)'!E4 -> 6 | F4: ='採算表(VND)'!F4 -> 7 | G4: ='採算表(VND)'!G4 -> 8 | H4: ='採算表(VND)'!H4 -> 9 | I4: ='採算表(VND)'!I4 -> 10 | J4: ='採算表(VND)'!J4 -> 11 | ... O4: ='採算表(VND)'!O4 -> 合計
B5: 総出荷 | C5: =C8+C9 -> 29803.37 | D5: =D8+D9 -> 43553.32 | E5: =E8+E9 -> 40419.06 | F5: =F8+F9 -> 41786.85 | G5: =G8+G9 -> 45272.7 | H5: =H8+H9 -> 45438.09 | I5: =I8+I9 -> 57256.11 | J5: =J8+J9 -> 46122.27 | ... O5: =O8+O9 -> 529556.24
B6: 社外出荷 | C6: =ROUNDDOWN('採算表(VND)'!C6/$N$1,2) -> 29803.37 | D6: =ROUNDDOWN('採算表(VND)'!D6/$N$1,2) -> 43553.32 | E6: =ROUNDDOWN('採算表(VND)'!E6/$N$1,2) -> 40419.06 | F6: =ROUNDDOWN('採算表(VND)'!F6/$N$1,2) -> 41786.85 | G6: =ROUNDDOWN('採算表(VND)'!G6/$N$1,2) -> 45272.7 | H6: =ROUNDDOWN('採算表(VND)'!H6/$N$1,2) -> 45438.09 | I6: =ROUNDDOWN('採算表(VND)'!I6/$N$1,2) -> 57256.11 | J6: =ROUNDDOWN('採算表(VND)'!J6/$N$1,2) -> 46122.27 | ... N6: =ROUNDDOWN('採算表(VND)'!N6/$N$1,2) -> 44490.33 | O6: =SUM(C6:N6) -> 529556.24
B7: 販売支援 | C7: =ROUNDDOWN('採算表(VND)'!C7/$N$1,2) -> 0 | D7: =ROUNDDOWN('採算表(VND)'!D7/$N$1,2) -> 0 | E7: =ROUNDDOWN('採算表(VND)'!E7/$N$1,2) -> 0 | F7: =ROUNDDOWN('採算表(VND)'!F7/$N$1,2) -> 0 | G7: =ROUNDDOWN('採算表(VND)'!G7/$N$1,2) -> 0 | H7: =ROUNDDOWN('採算表(VND)'!H7/$N$1,2) -> 0 | I7: =ROUNDDOWN('採算表(VND)'!I7/$N$1,2) -> 0 | J7: =ROUNDDOWN('採算表(VND)'!J7/$N$1,2) -> 0 | ... N7: =ROUNDDOWN('採算表(VND)'!N7/$N$1,2) -> 0 | O7: =SUM(C7:N7) -> 0
B8: 社外出荷合計 | C8: =C6+C7 -> 29803.37 | D8: =D6+D7 -> 43553.32 | E8: =E6+E7 -> 40419.06 | F8: =F6+F7 -> 41786.85 | G8: =G6+G7 -> 45272.7 | H8: =H6+H7 -> 45438.09 | I8: =I6+I7 -> 57256.11 | J8: =J6+J7 -> 46122.27 | ... O8: =O6+O7 -> 529556.24
B9: 社内売 | C9: =ROUNDDOWN('採算表(VND)'!C9/$N$1,2) -> 0 | D9: =ROUNDDOWN('採算表(VND)'!D9/$N$1,2) -> 0 | E9: =ROUNDDOWN('採算表(VND)'!E9/$N$1,2) -> 0 | F9: =ROUNDDOWN('採算表(VND)'!F9/$N$1,2) -> 0 | G9: =ROUNDDOWN('採算表(VND)'!G9/$N$1,2) -> 0 | H9: =ROUNDDOWN('採算表(VND)'!H9/$N$1,2) -> 0 | I9: =ROUNDDOWN('採算表(VND)'!I9/$N$1,2) -> 0 | J9: =ROUNDDOWN('採算表(VND)'!J9/$N$1,2) -> 0 | ... N9: =ROUNDDOWN('採算表(VND)'!N9/$N$1,2) -> 0 | O9: =SUM(C9:N9) -> 0
B10: 社内買 | C10: =ROUNDDOWN('採算表(VND)'!C10/$N$1,2) -> 0 | D10: =ROUNDDOWN('採算表(VND)'!D10/$N$1,2) -> 0 | E10: =ROUNDDOWN('採算表(VND)'!E10/$N$1,2) -> 0 | F10: =ROUNDDOWN('採算表(VND)'!F10/$N$1,2) -> 0 | G10: =ROUNDDOWN('採算表(VND)'!G10/$N$1,2) -> 0 | H10: =ROUNDDOWN('採算表(VND)'!H10/$N$1,2) -> 0 | I10: =ROUNDDOWN('採算表(VND)'!I10/$N$1,2) -> 0 | J10: =ROUNDDOWN('採算表(VND)'!J10/$N$1,2) -> 0 | ... N10: =ROUNDDOWN('採算表(VND)'!N10/$N$1,2) -> 0 | O10: =SUM(C10:N10) -> 0
B12: 総生産 | C12: =C5-C10 -> 29803.37 | D12: =D5-D10 -> 43553.32 | E12: =E5-E10 -> 40419.06 | F12: =F5-F10 -> 41786.85 | G12: =G5-G10 -> 45272.7 | H12: =H5-H10 -> 45438.09 | I12: =I5-I10 -> 57256.11 | J12: =J5-J10 -> 46122.27 | ... O12: =O5-O10 -> 529556.24
B13: 控除額 | C13: =SUM(C14:C65) -> 15786.73 | D13: =SUM(D14:D65) -> 17904.1 | E13: =SUM(E14:E65) -> 16382.29 | F13: =SUM(F14:F65) -> 18303.13 | G13: =SUM(G14:G65) -> 18206.71 | H13: =SUM(H14:H65) -> 30694.92 | I13: =SUM(I14:I65) -> 18556.05 | J13: =SUM(J14:J65) -> 17609.38 | ... O13: =SUM(O14:O65) -> 224210.84
B14: 材料費 | C14: =ROUNDUP('採算表(VND)'!C14/$N$1,2) -> 0 | D14: =ROUNDUP('採算表(VND)'!D14/$N$1,2) -> 0 | E14: =ROUNDUP('採算表(VND)'!E14/$N$1,2) -> 0 | F14: =ROUNDUP('採算表(VND)'!F14/$N$1,2) -> 0 | G14: =ROUNDUP('採算表(VND)'!G14/$N$1,2) -> 0 | H14: =ROUNDUP('採算表(VND)'!H14/$N$1,2) -> 0 | I14: =ROUNDUP('採算表(VND)'!I14/$N$1,2) -> 0 | J14: =ROUNDUP('採算表(VND)'!J14/$N$1,2) -> 0 | ... N14: =ROUNDUP('採算表(VND)'!N14/$N$1,2) -> 0 | O14: =SUM(C14:N14) -> 0
B15: 設計変更材料費 | C15: =ROUNDUP('採算表(VND)'!C15/$N$1,2) -> 0 | D15: =ROUNDUP('採算表(VND)'!D15/$N$1,2) -> 0 | E15: =ROUNDUP('採算表(VND)'!E15/$N$1,2) -> 0 | F15: =ROUNDUP('採算表(VND)'!F15/$N$1,2) -> 0 | G15: =ROUNDUP('採算表(VND)'!G15/$N$1,2) -> 0 | H15: =ROUNDUP('採算表(VND)'!H15/$N$1,2) -> 0 | I15: =ROUNDUP('採算表(VND)'!I15/$N$1,2) -> 0 | J15: =ROUNDUP('採算表(VND)'!J15/$N$1,2) -> 0 | ... N15: =ROUNDUP('採算表(VND)'!N15/$N$1,2) -> 0 | O15: =SUM(C15:N15) -> 0
B16: 仕掛仕損 | C16: =ROUNDUP('採算表(VND)'!C16/$N$1,2) -> 0 | D16: =ROUNDUP('採算表(VND)'!D16/$N$1,2) -> 0 | E16: =ROUNDUP('採算表(VND)'!E16/$N$1,2) -> 0 | F16: =ROUNDUP('採算表(VND)'!F16/$N$1,2) -> 0 | G16: =ROUNDUP('採算表(VND)'!G16/$N$1,2) -> 0 | H16: =ROUNDUP('採算表(VND)'!H16/$N$1,2) -> 0 | I16: =ROUNDUP('採算表(VND)'!I16/$N$1,2) -> 0 | J16: =ROUNDUP('採算表(VND)'!J16/$N$1,2) -> 0 | ... N16: =ROUNDUP('採算表(VND)'!N16/$N$1,2) -> 0 | O16: =SUM(C16:N16) -> 0
B17: 仕入製商品費 | C17: =ROUNDUP('採算表(VND)'!C17/$N$1,2) -> 0 | D17: =ROUNDUP('採算表(VND)'!D17/$N$1,2) -> 0 | E17: =ROUNDUP('採算表(VND)'!E17/$N$1,2) -> 0 | F17: =ROUNDUP('採算表(VND)'!F17/$N$1,2) -> 0 | G17: =ROUNDUP('採算表(VND)'!G17/$N$1,2) -> 0 | H17: =ROUNDUP('採算表(VND)'!H17/$N$1,2) -> 0 | I17: =ROUNDUP('採算表(VND)'!I17/$N$1,2) -> 0 | J17: =ROUNDUP('採算表(VND)'!J17/$N$1,2) -> 0 | ... N17: =ROUNDUP('採算表(VND)'!N17/$N$1,2) -> 0 | O17: =SUM(C17:N17) -> 0
B18: 内製品有償支給原価 | C18: =ROUNDUP('採算表(VND)'!C18/$N$1,2) -> 0 | D18: =ROUNDUP('採算表(VND)'!D18/$N$1,2) -> 0 | E18: =ROUNDUP('採算表(VND)'!E18/$N$1,2) -> 0 | F18: =ROUNDUP('採算表(VND)'!F18/$N$1,2) -> 0 | G18: =ROUNDUP('採算表(VND)'!G18/$N$1,2) -> 0 | H18: =ROUNDUP('採算表(VND)'!H18/$N$1,2) -> 0 | I18: =ROUNDUP('採算表(VND)'!I18/$N$1,2) -> 0 | J18: =ROUNDUP('採算表(VND)'!J18/$N$1,2) -> 0 | ... N18: =ROUNDUP('採算表(VND)'!N18/$N$1,2) -> 0 | O18: =SUM(C18:N18) -> 0
B19: 外注加工費 | C19: =ROUNDUP('採算表(VND)'!C19/$N$1,2) -> 0 | D19: =ROUNDUP('採算表(VND)'!D19/$N$1,2) -> 0 | E19: =ROUNDUP('採算表(VND)'!E19/$N$1,2) -> 0 | F19: =ROUNDUP('採算表(VND)'!F19/$N$1,2) -> 0 | G19: =ROUNDUP('採算表(VND)'!G19/$N$1,2) -> 0 | H19: =ROUNDUP('採算表(VND)'!H19/$N$1,2) -> 0 | I19: =ROUNDUP('採算表(VND)'!I19/$N$1,2) -> 0 | J19: =ROUNDUP('採算表(VND)'!J19/$N$1,2) -> 0 | ... N19: =ROUNDUP('採算表(VND)'!N19/$N$1,2) -> 0 | O19: =SUM(C19:N19) -> 0
B20: 減価償却費 | C20: =ROUNDUP('採算表(VND)'!C20/$N$1,2) -> 10862.61 | D20: =ROUNDUP('採算表(VND)'!D20/$N$1,2) -> 10789.26 | E20: =ROUNDUP('採算表(VND)'!E20/$N$1,2) -> 10790.77 | F20: =ROUNDUP('採算表(VND)'!F20/$N$1,2) -> 11982 | G20: =ROUNDUP('採算表(VND)'!G20/$N$1,2) -> 12864.18 | H20: =ROUNDUP('採算表(VND)'!H20/$N$1,2) -> 12847.1 | I20: =ROUNDUP('採算表(VND)'!I20/$N$1,2) -> 12847.1 | J20: =ROUNDUP('採算表(VND)'!J20/$N$1,2) -> 12832.58 | ... N20: =ROUNDUP('採算表(VND)'!N20/$N$1,2) -> 12830.48 | O20: =SUM(C20:N20) -> 147168.35
B21: 金型償却費 | C21: =ROUNDUP('採算表(VND)'!C21/$N$1,2) -> 0 | D21: =ROUNDUP('採算表(VND)'!D21/$N$1,2) -> 0 | E21: =ROUNDUP('採算表(VND)'!E21/$N$1,2) -> 0 | F21: =ROUNDUP('採算表(VND)'!F21/$N$1,2) -> 0 | G21: =ROUNDUP('採算表(VND)'!G21/$N$1,2) -> 0 | H21: =ROUNDUP('採算表(VND)'!H21/$N$1,2) -> 0 | I21: =ROUNDUP('採算表(VND)'!I21/$N$1,2) -> 0 | J21: =ROUNDUP('採算表(VND)'!J21/$N$1,2) -> 0 | ... N21: =ROUNDUP('採算表(VND)'!N21/$N$1,2) -> 0 | O21: =SUM(C21:N21) -> 0
B22: 賃借料 | C22: =ROUNDUP('採算表(VND)'!C22/$N$1,2) -> 0 | D22: =ROUNDUP('採算表(VND)'!D22/$N$1,2) -> 0 | E22: =ROUNDUP('採算表(VND)'!E22/$N$1,2) -> 0 | F22: =ROUNDUP('採算表(VND)'!F22/$N$1,2) -> 0 | G22: =ROUNDUP('採算表(VND)'!G22/$N$1,2) -> 0 | H22: =ROUNDUP('採算表(VND)'!H22/$N$1,2) -> 0 | I22: =ROUNDUP('採算表(VND)'!I22/$N$1,2) -> 0 | J22: =ROUNDUP('採算表(VND)'!J22/$N$1,2) -> 0 | ... N22: =ROUNDUP('採算表(VND)'!N22/$N$1,2) -> 0 | O22: =SUM(C22:N22) -> 0
B23: 保険料 | C23: =ROUNDUP('採算表(VND)'!C23/$N$1,2) -> 0 | D23: =ROUNDUP('採算表(VND)'!D23/$N$1,2) -> 0 | E23: =ROUNDUP('採算表(VND)'!E23/$N$1,2) -> 0 | F23: =ROUNDUP('採算表(VND)'!F23/$N$1,2) -> 0 | G23: =ROUNDUP('採算表(VND)'!G23/$N$1,2) -> 0 | H23: =ROUNDUP('採算表(VND)'!H23/$N$1,2) -> 0 | I23: =ROUNDUP('採算表(VND)'!I23/$N$1,2) -> 0 | J23: =ROUNDUP('採算表(VND)'!J23/$N$1,2) -> 0 | ... N23: =ROUNDUP('採算表(VND)'!N23/$N$1,2) -> 0 | O23: =SUM(C23:N23) -> 0
B24: 設計委託費 | C24: =ROUNDUP('採算表(VND)'!C24/$N$1,2) -> 0 | D24: =ROUNDUP('採算表(VND)'!D24/$N$1,2) -> 0 | E24: =ROUNDUP('採算表(VND)'!E24/$N$1,2) -> 0 | F24: =ROUNDUP('採算表(VND)'!F24/$N$1,2) -> 0 | G24: =ROUNDUP('採算表(VND)'!G24/$N$1,2) -> 0 | H24: =ROUNDUP('採算表(VND)'!H24/$N$1,2) -> 0 | I24: =ROUNDUP('採算表(VND)'!I24/$N$1,2) -> 0 | J24: =ROUNDUP('採算表(VND)'!J24/$N$1,2) -> 0 | ... N24: =ROUNDUP('採算表(VND)'!N24/$N$1,2) -> 0 | O24: =SUM(C24:N24) -> 0
B25: 消耗品費 | C25: =ROUNDUP('採算表(VND)'!C25/$N$1,2) -> 33.15 | D25: =ROUNDUP('採算表(VND)'!D25/$N$1,2) -> 33.15 | E25: =ROUNDUP('採算表(VND)'!E25/$N$1,2) -> 33.15 | F25: =ROUNDUP('採算表(VND)'!F25/$N$1,2) -> 33.15 | G25: =ROUNDUP('採算表(VND)'!G25/$N$1,2) -> 33.15 | H25: =ROUNDUP('採算表(VND)'!H25/$N$1,2) -> 33.15 | I25: =ROUNDUP('採算表(VND)'!I25/$N$1,2) -> 33.15 | J25: =ROUNDUP('採算表(VND)'!J25/$N$1,2) -> 33.15 | ... N25: =ROUNDUP('採算表(VND)'!N25/$N$1,2) -> 33.15 | O25: =SUM(C25:N25) -> 397.8
... B65: 本社機構経費 | C65: =ROUNDUP('採算表(VND)'!C65/$N$1,2) -> 0 | D65: =ROUNDUP('採算表(VND)'!D65/$N$1,2) -> 0 | E65: =ROUNDUP('採算表(VND)'!E65/$N$1,2) -> 0 | F65: =ROUNDUP('採算表(VND)'!F65/$N$1,2) -> 0 | G65: =ROUNDUP('採算表(VND)'!G65/$N$1,2) -> 0 | H65: =ROUNDUP('採算表(VND)'!H65/$N$1,2) -> 0 | I65: =ROUNDUP('採算表(VND)'!I65/$N$1,2) -> 0 | J65: =ROUNDUP('採算表(VND)'!J65/$N$1,2) -> 0 | ... N65: =ROUNDUP('採算表(VND)'!N65/$N$1,2) -> 0 | O65: =SUM(C65:N65) -> 0
B66: 差引収益 | C66: =C12-C13 -> 14016.64 | D66: =IF(ISBLANK(D4),"",D12-D13) -> 25649.22 | E66: =IF(ISBLANK(E4),"",E12-E13) -> 24036.77 | F66: =IF(ISBLANK(F4),"",F12-F13) -> 23483.72 | G66: =IF(ISBLANK(G4),"",G12-G13) -> 27065.99 | H66: =IF(ISBLANK(H4),"",H12-H13) -> 14743.17 | I66: =IF(ISBLANK(I4),"",I12-I13) -> 38700.06 | J66: =IF(ISBLANK(J4),"",J12-J13) -> 28512.89 | K66: =IF(ISBLANK(K4),"",K12-K13) -> 27062.68 | ... O66: =IF(ISBLANK(O4),"",O12-O13) -> 305345.4
B67: 総時間 | C67: =C73+C79 -> 2247 | D67: =IF(ISBLANK(D4),"",D73+D79) -> 2097.5 | E67: =IF(ISBLANK(E4),"",E73+E79) -> 2315.25 | F67: =IF(ISBLANK(F4),"",F73+F79) -> 2579.5 | G67: =IF(ISBLANK(G4),"",G73+G79) -> 2257.5 | H67: =IF(ISBLANK(H4),"",H73+H79) -> 2146.25 | I67: =IF(ISBLANK(I4),"",I73+I79) -> 2545.25 | J67: =IF(ISBLANK(J4),"",J73+J79) -> 2228.75 | K67: =IF(ISBLANK(K4),"",K73+K79) -> 2447.5 | ... O67: =IF(ISBLANK(O4),"",O73+O79) -> 27004.5
B68: 直接部門 | C68: ='採算表(VND)'!C68 -> 1997.5 | D68: ='採算表(VND)'!D68 -> 1853 | E68: ='採算表(VND)'!E68 -> 2057 | F68: ='採算表(VND)'!F68 -> 2261 | G68: ='採算表(VND)'!G68 -> 1955 | H68: ='採算表(VND)'!H68 -> 1853 | I68: ='採算表(VND)'!I68 -> 2261 | J68: ='採算表(VND)'!J68 -> 1963.5 | ... N68: ='採算表(VND)'!N68 -> 1963.5 | O68: =SUM(C68:N68) -> 23749
B69: 部内間接部門 | C69: ='採算表(VND)'!C69 -> 0 | D69: ='採算表(VND)'!D69 -> 0 | E69: ='採算表(VND)'!E69 -> 0 | F69: ='採算表(VND)'!F69 -> 0 | G69: ='採算表(VND)'!G69 -> 0 | H69: ='採算表(VND)'!H69 -> 0 | I69: ='採算表(VND)'!I69 -> 0 | J69: ='採算表(VND)'!J69 -> 0 | ... N69: ='採算表(VND)'!N69 -> 0 | O69: =SUM(C69:N69) -> 0
B70: 部外間接部門1 | C70: ='採算表(VND)'!C70 -> 6.75 | D70: ='採算表(VND)'!D70 -> 7 | E70: ='採算表(VND)'!E70 -> 7.75 | F70: ='採算表(VND)'!F70 -> 12 | G70: ='採算表(VND)'!G70 -> 10.75 | H70: ='採算表(VND)'!H70 -> 10 | I70: ='採算表(VND)'!I70 -> 8.25 | J70: ='採算表(VND)'!J70 -> 7.25 | ... N70: ='採算表(VND)'!N70 -> 7.5 | O70: =SUM(C70:N70) -> 98.25
B71: 部外間接部門2 | C71: ='採算表(VND)'!C71 -> 12.75 | D71: ='採算表(VND)'!D71 -> 12.25 | E71: ='採算表(VND)'!E71 -> 14 | F71: ='採算表(VND)'!F71 -> 23.25 | G71: ='採算表(VND)'!G71 -> 20.25 | H71: ='採算表(VND)'!H71 -> 19.75 | I71: ='採算表(VND)'!I71 -> 16.25 | J71: ='採算表(VND)'!J71 -> 14 | ... N71: ='採算表(VND)'!N71 -> 14 | O71: =SUM(C71:N71) -> 187
B72: 工場間接部門 | C72: ='採算表(VND)'!C72 -> 57 | D72: ='採算表(VND)'!D72 -> 56.5 | E72: ='採算表(VND)'!E72 -> 60 | F72: ='採算表(VND)'!F72 -> 96 | G72: ='採算表(VND)'!G72 -> 88.25 | H72: ='採算表(VND)'!H72 -> 82.5 | I72: ='採算表(VND)'!I72 -> 65 | J72: ='採算表(VND)'!J72 -> 59.25 | ... N72: ='採算表(VND)'!N72 -> 60.5 | O72: =SUM(C72:N72) -> 794.25
B73: 定時間合計 | C73: =SUM(C68:C72) -> 2074 | D73: =IF(ISBLANK(D4),"",SUM(D68:D72)) -> 1928.75 | E73: =IF(ISBLANK(E4),"",SUM(E68:E72)) -> 2138.75 | F73: =IF(ISBLANK(F4),"",SUM(F68:F72)) -> 2392.25 | G73: =IF(ISBLANK(G4),"",SUM(G68:G72)) -> 2074.25 | H73: =IF(ISBLANK(H4),"",SUM(H68:H72)) -> 1965.25 | I73: =IF(ISBLANK(I4),"",SUM(I68:I72)) -> 2350.5 | J73: =IF(ISBLANK(J4),"",SUM(J68:J72)) -> 2044 | K73: =IF(ISBLANK(K4),"",SUM(K68:K72)) -> 2254.75 | ... O73: =IF(ISBLANK(O4),"",SUM(O68:O72)) -> 24828.5
B74: 直接部門 | C74: ='採算表(VND)'!C74 -> 168 | D74: ='採算表(VND)'!D74 -> 164 | E74: ='採算表(VND)'!E74 -> 172 | F74: ='採算表(VND)'!F74 -> 180 | G74: ='採算表(VND)'!G74 -> 178 | H74: ='採算表(VND)'!H74 -> 174 | I74: ='採算表(VND)'!I74 -> 190 | J74: ='採算表(VND)'!J74 -> 180 | ... N74: ='採算表(VND)'!N74 -> 180 | O74: =SUM(C74:N74) -> 2114
B75: 部内間接部門 | C75: ='採算表(VND)'!C75 -> 0 | D75: ='採算表(VND)'!D75 -> 0 | E75: ='採算表(VND)'!E75 -> 0 | F75: ='採算表(VND)'!F75 -> 0 | G75: ='採算表(VND)'!G75 -> 0 | H75: ='採算表(VND)'!H75 -> 0 | I75: ='採算表(VND)'!I75 -> 0 | J75: ='採算表(VND)'!J75 -> 0 | ... N75: ='採算表(VND)'!N75 -> 0 | O75: =SUM(C75:N75) -> 0
B76: 部外間接部門1 | C76: ='採算表(VND)'!C76 -> 0.5 | D76: ='採算表(VND)'!D76 -> 0.5 | E76: ='採算表(VND)'!E76 -> 0.5 | F76: ='採算表(VND)'!F76 -> 0.75 | G76: ='採算表(VND)'!G76 -> 0.75 | H76: ='採算表(VND)'!H76 -> 0.75 | I76: ='採算表(VND)'!I76 -> 0.5 | J76: ='採算表(VND)'!J76 -> 0.5 | ... N76: ='採算表(VND)'!N76 -> 0.5 | O76: =SUM(C76:N76) -> 6.5
B77: 部外間接部門2 | C77: ='採算表(VND)'!C77 -> 1.25 | D77: ='採算表(VND)'!D77 -> 1 | E77: ='採算表(VND)'!E77 -> 1.25 | F77: ='採算表(VND)'!F77 -> 2 | G77: ='採算表(VND)'!G77 -> 1.25 | H77: ='採算表(VND)'!H77 -> 1.25 | I77: ='採算表(VND)'!I77 -> 1.25 | J77: ='採算表(VND)'!J77 -> 1.25 | ... N77: ='採算表(VND)'!N77 -> 1.5 | O77: =SUM(C77:N77) -> 15.25
B78: 工場間接部門 | C78: ='採算表(VND)'!C78 -> 3.25 | D78: ='採算表(VND)'!D78 -> 3.25 | E78: ='採算表(VND)'!E78 -> 2.75 | F78: ='採算表(VND)'!F78 -> 4.5 | G78: ='採算表(VND)'!G78 -> 3.25 | H78: ='採算表(VND)'!H78 -> 5 | I78: ='採算表(VND)'!I78 -> 3 | J78: ='採算表(VND)'!J78 -> 3 | ... N78: ='採算表(VND)'!N78 -> 2.75 | O78: =SUM(C78:N78) -> 40.25
B79: 残業時間合計 | C79: =SUM(C74:C78) -> 173 | D79: =IF(ISBLANK(D4),"",SUM(D74:D78)) -> 168.75 | E79: =IF(ISBLANK(E4),"",SUM(E74:E78)) -> 176.5 | F79: =IF(ISBLANK(F4),"",SUM(F74:F78)) -> 187.25 | G79: =IF(ISBLANK(G4),"",SUM(G74:G78)) -> 183.25 | H79: =IF(ISBLANK(H4),"",SUM(H74:H78)) -> 181 | I79: =IF(ISBLANK(I4),"",SUM(I74:I78)) -> 194.75 | J79: =IF(ISBLANK(J4),"",SUM(J74:J78)) -> 184.75 | K79: =IF(ISBLANK(K4),"",SUM(K74:K78)) -> 192.75 | ... O79: =IF(ISBLANK(O4),"",SUM(O74:O78)) -> 2176
B80: 当月時間当り | C80: =IFERROR(ROUNDDOWN(C66/C67,0),0) -> 6 | D80: =IFERROR(ROUNDDOWN(D66/D67,0),0) -> 12 | E80: =IFERROR(ROUNDDOWN(E66/E67,0),0) -> 10 | F80: =IFERROR(ROUNDDOWN(F66/F67,0),0) -> 9 | G80: =IFERROR(ROUNDDOWN(G66/G67,0),0) -> 11 | H80: =IFERROR(ROUNDDOWN(H66/H67,0),0) -> 6 | I80: =IFERROR(ROUNDDOWN(I66/I67,0),0) -> 15 | J80: =IFERROR(ROUNDDOWN(J66/J67,0),0) -> 12 | ... O80: =IFERROR(ROUNDDOWN(O66/O67,0),0) -> 11
B81: 時間当り生産高 | C81: =IFERROR(ROUNDDOWN(C12/C67,0),0) -> 13 | D81: =IFERROR(ROUNDDOWN(D12/D67,0),0) -> 20 | E81: =IFERROR(ROUNDDOWN(E12/E67,0),0) -> 17 | F81: =IFERROR(ROUNDDOWN(F12/F67,0),0) -> 16 | G81: =IFERROR(ROUNDDOWN(G12/G67,0),0) -> 20 | H81: =IFERROR(ROUNDDOWN(H12/H67,0),0) -> 21 | I81: =IFERROR(ROUNDDOWN(I12/I67,0),0) -> 22 | J81: =IFERROR(ROUNDDOWN(J12/J67,0),0) -> 20 | ... O81: =IFERROR(ROUNDDOWN(O12/O67,0),0) -> 19
...

Sheet 採算表(VND)
B1: 組織名 | C1: ='内訳ﾘｽﾄ(4～3月)'!A1 -> MP FY2026_各予定
B2: ='内訳ﾘｽﾄ(4～3月)'!C5 -> MD3課
C3: 2 | D3: 3 | E3: 4 | F3: 5 | G3: 6 | H3: 7 | I3: 8 | J3: 9 | K3: 10 | L3: 11 | M3: 12 | N3: 13
B4: 項目 ＼ 部門 | C4: ='内訳ﾘｽﾄ(4～3月)'!F4 -> 4 | D4: 5 | E4: 6 | F4: 7 | G4: 8 | H4: 9 | I4: 10 | J4: 11 | K4: 12 | L4: 1 | M4: 2 | N4: 3 | O4: 合計
B5: 総出荷 | C5: =C8+C9 -> 756707565 | D5: =D8+D9 -> 1105818795 | E5: =E8+E9 -> 1026239934 | F5: =F8+F9 -> 1060968122 | G5: =G8+G9 -> 1149473853 | H5: =H8+H9 -> 1153673106 | I5: =I8+I9 -> 1453732633 | J5: =J8+J9 -> 1171044436 | ... O5: =O8+O9 -> 13445432939
B6: 社外出荷 | C6: =SUMIF('内訳ﾘｽﾄ(4～3月)'!$D$26:$D$595,'採算表(VND)'!$B6,'内訳ﾘｽﾄ(4～3月)'!F$26:F$595) -> 756707565 | D6: =SUMIF('内訳ﾘｽﾄ(4～3月)'!$D$26:$D$595,'採算表(VND)'!$B6,'内訳ﾘｽﾄ(4～3月)'!G$26:G$595) -> 1105818795 | E6: =SUMIF('内訳ﾘｽﾄ(4～3月)'!$D$26:$D$595,'採算表(VND)'!$B6,'内訳ﾘｽﾄ(4～3月)'!H$26:H$595) -> 1026239934 | F6: =SUMIF('内訳ﾘｽﾄ(4～3月)'!$D$26:$D$595,'採算表(VND)'!$B6,'内訳ﾘｽﾄ(4～3月)'!I$26:I$595) -> 1060968122 | G6: =SUMIF('内訳ﾘｽﾄ(4～3月)'!$D$26:$D$595,'採算表(VND)'!$B6,'内訳ﾘｽﾄ(4～3月)'!J$26:J$595) -> 1149473853 | H6: =SUMIF('内訳ﾘｽﾄ(4～3月)'!$D$26:$D$595,'採算表(VND)'!$B6,'内訳ﾘｽﾄ(4～3月)'!K$26:K$595) -> 1153673106 | I6: =SUMIF('内訳ﾘｽﾄ(4～3月)'!$D$26:$D$595,'採算表(VND)'!$B6,'内訳ﾘｽﾄ(4～3月)'!L$26:L$595) -> 1453732633 | J6: =SUMIF('内訳ﾘｽﾄ(4～3月)'!$D$26:$D$595,'採算表(VND)'!$B6,'内訳ﾘｽﾄ(4～3月)'!M$26:M$595) -> 1171044436 | ... N6: =SUMIF('内訳ﾘｽﾄ(4～3月)'!$D$26:$D$595,'採算表(VND)'!$B6,'内訳ﾘｽﾄ(4～3月)'!Q$26:Q$595) -> 1129609479 | O6: =SUMIF('内訳ﾘｽﾄ(4～3月)'!$D$26:$D$394,'採算表(VND)'!$B6,'内訳ﾘｽﾄ(4～3月)'!R$26:R$394) -> 13445432939
B7: 販売支援 | C7: =SUMIF('内訳ﾘｽﾄ(4～3月)'!$D$26:$D$595,'採算表(VND)'!$B7,'内訳ﾘｽﾄ(4～3月)'!F$26:F$595) -> 0 | D7: =SUMIF('内訳ﾘｽﾄ(4～3月)'!$D$26:$D$595,'採算表(VND)'!$B7,'内訳ﾘｽﾄ(4～3月)'!G$26:G$595) -> 0 | E7: =SUMIF('内訳ﾘｽﾄ(4～3月)'!$D$26:$D$595,'採算表(VND)'!$B7,'内訳ﾘｽﾄ(4～3月)'!H$26:H$595) -> 0 | F7: =SUMIF('内訳ﾘｽﾄ(4～3月)'!$D$26:$D$595,'採算表(VND)'!$B7,'内訳ﾘｽﾄ(4～3月)'!I$26:I$595) -> 0 | G7: =SUMIF('内訳ﾘｽﾄ(4～3月)'!$D$26:$D$595,'採算表(VND)'!$B7,'内訳ﾘｽﾄ(4～3月)'!J$26:J$595) -> 0 | H7: =SUMIF('内訳ﾘｽﾄ(4～3月)'!$D$26:$D$595,'採算表(VND)'!$B7,'内訳ﾘｽﾄ(4～3月)'!K$26:K$595) -> 0 | I7: =SUMIF('内訳ﾘｽﾄ(4～3月)'!$D$26:$D$595,'採算表(VND)'!$B7,'内訳ﾘｽﾄ(4～3月)'!L$26:L$595) -> 0 | J7: =SUMIF('内訳ﾘｽﾄ(4～3月)'!$D$26:$D$595,'採算表(VND)'!$B7,'内訳ﾘｽﾄ(4～3月)'!M$26:M$595) -> 0 | ... N7: =SUMIF('内訳ﾘｽﾄ(4～3月)'!$D$26:$D$595,'採算表(VND)'!$B7,'内訳ﾘｽﾄ(4～3月)'!Q$26:Q$595) -> 0 | O7: =SUMIF('内訳ﾘｽﾄ(4～3月)'!$D$26:$D$394,'採算表(VND)'!$B7,'内訳ﾘｽﾄ(4～3月)'!R$26:R$394) -> 0
B8: 社外出荷合計 | C8: =C6+C7 -> 756707565 | D8: =D6+D7 -> 1105818795 | E8: =E6+E7 -> 1026239934 | F8: =F6+F7 -> 1060968122 | G8: =G6+G7 -> 1149473853 | H8: =H6+H7 -> 1153673106 | I8: =I6+I7 -> 1453732633 | J8: =J6+J7 -> 1171044436 | ... O8: =O6+O7 -> 13445432939
B9: 社内売 | C9: =SUMIF('内訳ﾘｽﾄ(4～3月)'!$D$26:$D$595,'採算表(VND)'!$B9,'内訳ﾘｽﾄ(4～3月)'!F$26:F$595) -> 0 | D9: =SUMIF('内訳ﾘｽﾄ(4～3月)'!$D$26:$D$595,'採算表(VND)'!$B9,'内訳ﾘｽﾄ(4～3月)'!G$26:G$595) -> 0 | E9: =SUMIF('内訳ﾘｽﾄ(4～3月)'!$D$26:$D$595,'採算表(VND)'!$B9,'内訳ﾘｽﾄ(4～3月)'!H$26:H$595) -> 0 | F9: =SUMIF('内訳ﾘｽﾄ(4～3月)'!$D$26:$D$595,'採算表(VND)'!$B9,'内訳ﾘｽﾄ(4～3月)'!I$26:I$595) -> 0 | G9: =SUMIF('内訳ﾘｽﾄ(4～3月)'!$D$26:$D$595,'採算表(VND)'!$B9,'内訳ﾘｽﾄ(4～3月)'!J$26:J$595) -> 0 | H9: =SUMIF('内訳ﾘｽﾄ(4～3月)'!$D$26:$D$595,'採算表(VND)'!$B9,'内訳ﾘｽﾄ(4～3月)'!K$26:K$595) -> 0 | I9: =SUMIF('内訳ﾘｽﾄ(4～3月)'!$D$26:$D$595,'採算表(VND)'!$B9,'内訳ﾘｽﾄ(4～3月)'!L$26:L$595) -> 0 | J9: =SUMIF('内訳ﾘｽﾄ(4～3月)'!$D$26:$D$595,'採算表(VND)'!$B9,'内訳ﾘｽﾄ(4～3月)'!M$26:M$595) -> 0 | ... N9: =SUMIF('内訳ﾘｽﾄ(4～3月)'!$D$26:$D$595,'採算表(VND)'!$B9,'内訳ﾘｽﾄ(4～3月)'!Q$26:Q$595) -> 0 | O9: =SUMIF('内訳ﾘｽﾄ(4～3月)'!$D$26:$D$394,'採算表(VND)'!$B9,'内訳ﾘｽﾄ(4～3月)'!R$26:R$394) -> 0
B10: 社内買 | C10: =SUMIF('内訳ﾘｽﾄ(4～3月)'!$D$26:$D$595,'採算表(VND)'!$B10,'内訳ﾘｽﾄ(4～3月)'!F$26:F$595) -> 0 | D10: =SUMIF('内訳ﾘｽﾄ(4～3月)'!$D$26:$D$595,'採算表(VND)'!$B10,'内訳ﾘｽﾄ(4～3月)'!G$26:G$595) -> 0 | E10: =SUMIF('内訳ﾘｽﾄ(4～3月)'!$D$26:$D$595,'採算表(VND)'!$B10,'内訳ﾘｽﾄ(4～3月)'!H$26:H$595) -> 0 | F10: =SUMIF('内訳ﾘｽﾄ(4～3月)'!$D$26:$D$595,'採算表(VND)'!$B10,'内訳ﾘｽﾄ(4～3月)'!I$26:I$595) -> 0 | G10: =SUMIF('内訳ﾘｽﾄ(4～3月)'!$D$26:$D$595,'採算表(VND)'!$B10,'内訳ﾘｽﾄ(4～3月)'!J$26:J$595) -> 0 | H10: =SUMIF('内訳ﾘｽﾄ(4～3月)'!$D$26:$D$595,'採算表(VND)'!$B10,'内訳ﾘｽﾄ(4～3月)'!K$26:K$595) -> 0 | I10: =SUMIF('内訳ﾘｽﾄ(4～3月)'!$D$26:$D$595,'採算表(VND)'!$B10,'内訳ﾘｽﾄ(4～3月)'!L$26:L$595) -> 0 | J10: =SUMIF('内訳ﾘｽﾄ(4～3月)'!$D$26:$D$595,'採算表(VND)'!$B10,'内訳ﾘｽﾄ(4～3月)'!M$26:M$595) -> 0 | ... N10: =SUMIF('内訳ﾘｽﾄ(4～3月)'!$D$26:$D$595,'採算表(VND)'!$B10,'内訳ﾘｽﾄ(4～3月)'!Q$26:Q$595) -> 0 | O10: =SUMIF('内訳ﾘｽﾄ(4～3月)'!$D$26:$D$394,'採算表(VND)'!$B10,'内訳ﾘｽﾄ(4～3月)'!R$26:R$394) -> 0
B12: 総生産 | C12: =C5-C10 -> 756707565 | D12: =D5-D10 -> 1105818795 | E12: =E5-E10 -> 1026239934 | F12: =F5-F10 -> 1060968122 | G12: =G5-G10 -> 1149473853 | H12: =H5-H10 -> 1153673106 | I12: =I5-I10 -> 1453732633 | J12: =J5-J10 -> 1171044436 | ... O12: =O5-O10 -> 13445432939
B13: 控除額 | C13: =SUM(C14:C65) -> 400823203 | D13: =SUM(D14:D65) -> 454583044 | E13: =SUM(E14:E65) -> 415944472 | F13: =SUM(F14:F65) -> 464714882 | G13: =SUM(G14:G65) -> 462266346 | H13: =SUM(H14:H65) -> 779341928 | I13: =SUM(I14:I65) -> 471136190 | J13: =SUM(J14:J65) -> 447100639 | ... O13: =SUM(O14:O65) -> 5692691901
B14: 材料費 | C14: =SUMIF('内訳ﾘｽﾄ(4～3月)'!$D$26:$D$595,$B14,'内訳ﾘｽﾄ(4～3月)'!F$26:F$595) -> 0 | D14: =SUMIF('内訳ﾘｽﾄ(4～3月)'!$D$26:$D$595,$B14,'内訳ﾘｽﾄ(4～3月)'!G$26:G$595) -> 0 | E14: =SUMIF('内訳ﾘｽﾄ(4～3月)'!$D$26:$D$595,$B14,'内訳ﾘｽﾄ(4～3月)'!H$26:H$595) -> 0 | F14: =SUMIF('内訳ﾘｽﾄ(4～3月)'!$D$26:$D$595,$B14,'内訳ﾘｽﾄ(4～3月)'!I$26:I$595) -> 0 | G14: =SUMIF('内訳ﾘｽﾄ(4～3月)'!$D$26:$D$595,$B14,'内訳ﾘｽﾄ(4～3月)'!J$26:J$595) -> 0 | H14: =SUMIF('内訳ﾘｽﾄ(4～3月)'!$D$26:$D$595,$B14,'内訳ﾘｽﾄ(4～3月)'!K$26:K$595) -> 0 | I14: =SUMIF('内訳ﾘｽﾄ(4～3月)'!$D$26:$D$595,$B14,'内訳ﾘｽﾄ(4～3月)'!L$26:L$595) -> 0 | J14: =SUMIF('内訳ﾘｽﾄ(4～3月)'!$D$26:$D$595,$B14,'内訳ﾘｽﾄ(4～3月)'!M$26:M$595) -> 0 | ... N14: =SUMIF('内訳ﾘｽﾄ(4～3月)'!$D$26:$D$595,$B14,'内訳ﾘｽﾄ(4～3月)'!Q$26:Q$595) -> 0 | O14: =SUMIF('内訳ﾘｽﾄ(4～3月)'!$D$26:$D$394,'採算表(VND)'!$B14,'内訳ﾘｽﾄ(4～3月)'!R$26:R$394) -> 0
B15: 設計変更材料費 | C15: =SUMIF('内訳ﾘｽﾄ(4～3月)'!$D$26:$D$595,$B15,'内訳ﾘｽﾄ(4～3月)'!F$26:F$595) -> 0 | D15: =SUMIF('内訳ﾘｽﾄ(4～3月)'!$D$26:$D$595,$B15,'内訳ﾘｽﾄ(4～3月)'!G$26:G$595) -> 0 | E15: =SUMIF('内訳ﾘｽﾄ(4～3月)'!$D$26:$D$595,$B15,'内訳ﾘｽﾄ(4～3月)'!H$26:H$595) -> 0 | F15: =SUMIF('内訳ﾘｽﾄ(4～3月)'!$D$26:$D$595,$B15,'内訳ﾘｽﾄ(4～3月)'!I$26:I$595) -> 0 | G15: =SUMIF('内訳ﾘｽﾄ(4～3月)'!$D$26:$D$595,$B15,'内訳ﾘｽﾄ(4～3月)'!J$26:J$595) -> 0 | H15: =SUMIF('内訳ﾘｽﾄ(4～3月)'!$D$26:$D$595,$B15,'内訳ﾘｽﾄ(4～3月)'!K$26:K$595) -> 0 | I15: =SUMIF('内訳ﾘｽﾄ(4～3月)'!$D$26:$D$595,$B15,'内訳ﾘｽﾄ(4～3月)'!L$26:L$595) -> 0 | J15: =SUMIF('内訳ﾘｽﾄ(4～3月)'!$D$26:$D$595,$B15,'内訳ﾘｽﾄ(4～3月)'!M$26:M$595) -> 0 | ... N15: =SUMIF('内訳ﾘｽﾄ(4～3月)'!$D$26:$D$595,$B15,'内訳ﾘｽﾄ(4～3月)'!Q$26:Q$595) -> 0 | O15: =SUMIF('内訳ﾘｽﾄ(4～3月)'!$D$26:$D$394,'採算表(VND)'!$B15,'内訳ﾘｽﾄ(4～3月)'!R$26:R$394) -> 0
B16: 仕掛仕損 | C16: =SUMIF('内訳ﾘｽﾄ(4～3月)'!$D$26:$D$595,$B16,'内訳ﾘｽﾄ(4～3月)'!F$26:F$595) -> 0 | D16: =SUMIF('内訳ﾘｽﾄ(4～3月)'!$D$26:$D$595,$B16,'内訳ﾘｽﾄ(4～3月)'!G$26:G$595) -> 0 | E16: =SUMIF('内訳ﾘｽﾄ(4～3月)'!$D$26:$D$595,$B16,'内訳ﾘｽﾄ(4～3月)'!H$26:H$595) -> 0 | F16: =SUMIF('内訳ﾘｽﾄ(4～3月)'!$D$26:$D$595,$B16,'内訳ﾘｽﾄ(4～3月)'!I$26:I$595) -> 0 | G16: =SUMIF('内訳ﾘｽﾄ(4～3月)'!$D$26:$D$595,$B16,'内訳ﾘｽﾄ(4～3月)'!J$26:J$595) -> 0 | H16: =SUMIF('内訳ﾘｽﾄ(4～3月)'!$D$26:$D$595,$B16,'内訳ﾘｽﾄ(4～3月)'!K$26:K$595) -> 0 | I16: =SUMIF('内訳ﾘｽﾄ(4～3月)'!$D$26:$D$595,$B16,'内訳ﾘｽﾄ(4～3月)'!L$26:L$595) -> 0 | J16: =SUMIF('内訳ﾘｽﾄ(4～3月)'!$D$26:$D$595,$B16,'内訳ﾘｽﾄ(4～3月)'!M$26:M$595) -> 0 | ... N16: =SUMIF('内訳ﾘｽﾄ(4～3月)'!$D$26:$D$595,$B16,'内訳ﾘｽﾄ(4～3月)'!Q$26:Q$595) -> 0 | O16: =SUMIF('内訳ﾘｽﾄ(4～3月)'!$D$26:$D$394,'採算表(VND)'!$B16,'内訳ﾘｽﾄ(4～3月)'!R$26:R$394) -> 0
B17: 仕入製商品費 | C17: =SUMIF('内訳ﾘｽﾄ(4～3月)'!$D$26:$D$595,$B17,'内訳ﾘｽﾄ(4～3月)'!F$26:F$595) -> 0 | D17: =SUMIF('内訳ﾘｽﾄ(4～3月)'!$D$26:$D$595,$B17,'内訳ﾘｽﾄ(4～3月)'!G$26:G$595) -> 0 | E17: =SUMIF('内訳ﾘｽﾄ(4～3月)'!$D$26:$D$595,$B17,'内訳ﾘｽﾄ(4～3月)'!H$26:H$595) -> 0 | F17: =SUMIF('内訳ﾘｽﾄ(4～3月)'!$D$26:$D$595,$B17,'内訳ﾘｽﾄ(4～3月)'!I$26:I$595) -> 0 | G17: =SUMIF('内訳ﾘｽﾄ(4～3月)'!$D$26:$D$595,$B17,'内訳ﾘｽﾄ(4～3月)'!J$26:J$595) -> 0 | H17: =SUMIF('内訳ﾘｽﾄ(4～3月)'!$D$26:$D$595,$B17,'内訳ﾘｽﾄ(4～3月)'!K$26:K$595) -> 0 | I17: =SUMIF('内訳ﾘｽﾄ(4～3月)'!$D$26:$D$595,$B17,'内訳ﾘｽﾄ(4～3月)'!L$26:L$595) -> 0 | J17: =SUMIF('内訳ﾘｽﾄ(4～3月)'!$D$26:$D$595,$B17,'内訳ﾘｽﾄ(4～3月)'!M$26:M$595) -> 0 | ... N17: =SUMIF('内訳ﾘｽﾄ(4～3月)'!$D$26:$D$595,$B17,'内訳ﾘｽﾄ(4～3月)'!Q$26:Q$595) -> 0 | O17: =SUMIF('内訳ﾘｽﾄ(4～3月)'!$D$26:$D$394,'採算表(VND)'!$B17,'内訳ﾘｽﾄ(4～3月)'!R$26:R$394) -> 0
B18: 内製品有償支給原価 | C18: =SUMIF('内訳ﾘｽﾄ(4～3月)'!$D$26:$D$595,$B18,'内訳ﾘｽﾄ(4～3月)'!F$26:F$595) -> 0 | D18: =SUMIF('内訳ﾘｽﾄ(4～3月)'!$D$26:$D$595,$B18,'内訳ﾘｽﾄ(4～3月)'!G$26:G$595) -> 0 | E18: =SUMIF('内訳ﾘｽﾄ(4～3月)'!$D$26:$D$595,$B18,'内訳ﾘｽﾄ(4～3月)'!H$26:H$595) -> 0 | F18: =SUMIF('内訳ﾘｽﾄ(4～3月)'!$D$26:$D$595,$B18,'内訳ﾘｽﾄ(4～3月)'!I$26:I$595) -> 0 | G18: =SUMIF('内訳ﾘｽﾄ(4～3月)'!$D$26:$D$595,$B18,'内訳ﾘｽﾄ(4～3月)'!J$26:J$595) -> 0 | H18: =SUMIF('内訳ﾘｽﾄ(4～3月)'!$D$26:$D$595,$B18,'内訳ﾘｽﾄ(4～3月)'!K$26:K$595) -> 0 | I18: =SUMIF('内訳ﾘｽﾄ(4～3月)'!$D$26:$D$595,$B18,'内訳ﾘｽﾄ(4～3月)'!L$26:L$595) -> 0 | J18: =SUMIF('内訳ﾘｽﾄ(4～3月)'!$D$26:$D$595,$B18,'内訳ﾘｽﾄ(4～3月)'!M$26:M$595) -> 0 | ... N18: =SUMIF('内訳ﾘｽﾄ(4～3月)'!$D$26:$D$595,$B18,'内訳ﾘｽﾄ(4～3月)'!Q$26:Q$595) -> 0 | O18: =SUMIF('内訳ﾘｽﾄ(4～3月)'!$D$26:$D$394,'採算表(VND)'!$B18,'内訳ﾘｽﾄ(4～3月)'!R$26:R$394) -> 0
B19: 外注加工費 | C19: =SUMIF('内訳ﾘｽﾄ(4～3月)'!$D$26:$D$595,$B19,'内訳ﾘｽﾄ(4～3月)'!F$26:F$595) -> 0 | D19: =SUMIF('内訳ﾘｽﾄ(4～3月)'!$D$26:$D$595,$B19,'内訳ﾘｽﾄ(4～3月)'!G$26:G$595) -> 0 | E19: =SUMIF('内訳ﾘｽﾄ(4～3月)'!$D$26:$D$595,$B19,'内訳ﾘｽﾄ(4～3月)'!H$26:H$595) -> 0 | F19: =SUMIF('内訳ﾘｽﾄ(4～3月)'!$D$26:$D$595,$B19,'内訳ﾘｽﾄ(4～3月)'!I$26:I$595) -> 0 | G19: =SUMIF('内訳ﾘｽﾄ(4～3月)'!$D$26:$D$595,$B19,'内訳ﾘｽﾄ(4～3月)'!J$26:J$595) -> 0 | H19: =SUMIF('内訳ﾘｽﾄ(4～3月)'!$D$26:$D$595,$B19,'内訳ﾘｽﾄ(4～3月)'!K$26:K$595) -> 0 | I19: =SUMIF('内訳ﾘｽﾄ(4～3月)'!$D$26:$D$595,$B19,'内訳ﾘｽﾄ(4～3月)'!L$26:L$595) -> 0 | J19: =SUMIF('内訳ﾘｽﾄ(4～3月)'!$D$26:$D$595,$B19,'内訳ﾘｽﾄ(4～3月)'!M$26:M$595) -> 0 | ... N19: =SUMIF('内訳ﾘｽﾄ(4～3月)'!$D$26:$D$595,$B19,'内訳ﾘｽﾄ(4～3月)'!Q$26:Q$595) -> 0 | O19: =SUMIF('内訳ﾘｽﾄ(4～3月)'!$D$26:$D$394,'採算表(VND)'!$B19,'内訳ﾘｽﾄ(4～3月)'!R$26:R$394) -> 0
B20: 減価償却費 | C20: =SUMIF('内訳ﾘｽﾄ(4～3月)'!$D$26:$D$595,$B20,'内訳ﾘｽﾄ(4～3月)'!F$26:F$595) -> 275801558 | D20: =SUMIF('内訳ﾘｽﾄ(4～3月)'!$D$26:$D$595,$B20,'内訳ﾘｽﾄ(4～3月)'!G$26:G$595) -> 273939202 | E20: =SUMIF('内訳ﾘｽﾄ(4～3月)'!$D$26:$D$595,$B20,'内訳ﾘｽﾄ(4～3月)'!H$26:H$595) -> 273977541 | F20: =SUMIF('内訳ﾘｽﾄ(4～3月)'!$D$26:$D$595,$B20,'内訳ﾘｽﾄ(4～3月)'!I$26:I$595) -> 304222824 | G20: =SUMIF('内訳ﾘｽﾄ(4～3月)'!$D$26:$D$595,$B20,'内訳ﾘｽﾄ(4～3月)'!J$26:J$595) -> 326621516 | H20: =SUMIF('内訳ﾘｽﾄ(4～3月)'!$D$26:$D$595,$B20,'内訳ﾘｽﾄ(4～3月)'!K$26:K$595) -> 326187855 | I20: =SUMIF('内訳ﾘｽﾄ(4～3月)'!$D$26:$D$595,$B20,'内訳ﾘｽﾄ(4～3月)'!L$26:L$595) -> 326187855 | J20: =SUMIF('内訳ﾘｽﾄ(4～3月)'!$D$26:$D$595,$B20,'内訳ﾘｽﾄ(4～3月)'!M$26:M$595) -> 325819192 | ... N20: =SUMIF('内訳ﾘｽﾄ(4～3月)'!$D$26:$D$595,$B20,'内訳ﾘｽﾄ(4～3月)'!Q$26:Q$595) -> 325765873 | O20: =SUMIF('内訳ﾘｽﾄ(4～3月)'!$D$26:$D$394,'採算表(VND)'!$B20,'内訳ﾘｽﾄ(4～3月)'!R$26:R$394) -> 3736603808
B21: 金型償却費 | C21: =SUMIF('内訳ﾘｽﾄ(4～3月)'!$D$26:$D$595,$B21,'内訳ﾘｽﾄ(4～3月)'!F$26:F$595) -> 0 | D21: =SUMIF('内訳ﾘｽﾄ(4～3月)'!$D$26:$D$595,$B21,'内訳ﾘｽﾄ(4～3月)'!G$26:G$595) -> 0 | E21: =SUMIF('内訳ﾘｽﾄ(4～3月)'!$D$26:$D$595,$B21,'内訳ﾘｽﾄ(4～3月)'!H$26:H$595) -> 0 | F21: =SUMIF('内訳ﾘｽﾄ(4～3月)'!$D$26:$D$595,$B21,'内訳ﾘｽﾄ(4～3月)'!I$26:I$595) -> 0 | G21: =SUMIF('内訳ﾘｽﾄ(4～3月)'!$D$26:$D$595,$B21,'内訳ﾘｽﾄ(4～3月)'!J$26:J$595) -> 0 | H21: =SUMIF('内訳ﾘｽﾄ(4～3月)'!$D$26:$D$595,$B21,'内訳ﾘｽﾄ(4～3月)'!K$26:K$595) -> 0 | I21: =SUMIF('内訳ﾘｽﾄ(4～3月)'!$D$26:$D$595,$B21,'内訳ﾘｽﾄ(4～3月)'!L$26:L$595) -> 0 | J21: =SUMIF('内訳ﾘｽﾄ(4～3月)'!$D$26:$D$595,$B21,'内訳ﾘｽﾄ(4～3月)'!M$26:M$595) -> 0 | ... N21: =SUMIF('内訳ﾘｽﾄ(4～3月)'!$D$26:$D$595,$B21,'内訳ﾘｽﾄ(4～3月)'!Q$26:Q$595) -> 0 | O21: =SUMIF('内訳ﾘｽﾄ(4～3月)'!$D$26:$D$394,'採算表(VND)'!$B21,'内訳ﾘｽﾄ(4～3月)'!R$26:R$394) -> 0
B22: 賃借料 | C22: =SUMIF('内訳ﾘｽﾄ(4～3月)'!$D$26:$D$595,$B22,'内訳ﾘｽﾄ(4～3月)'!F$26:F$595) -> 0 | D22: =SUMIF('内訳ﾘｽﾄ(4～3月)'!$D$26:$D$595,$B22,'内訳ﾘｽﾄ(4～3月)'!G$26:G$595) -> 0 | E22: =SUMIF('内訳ﾘｽﾄ(4～3月)'!$D$26:$D$595,$B22,'内訳ﾘｽﾄ(4～3月)'!H$26:H$595) -> 0 | F22: =SUMIF('内訳ﾘｽﾄ(4～3月)'!$D$26:$D$595,$B22,'内訳ﾘｽﾄ(4～3月)'!I$26:I$595) -> 0 | G22: =SUMIF('内訳ﾘｽﾄ(4～3月)'!$D$26:$D$595,$B22,'内訳ﾘｽﾄ(4～3月)'!J$26:J$595) -> 0 | H22: =SUMIF('内訳ﾘｽﾄ(4～3月)'!$D$26:$D$595,$B22,'内訳ﾘｽﾄ(4～3月)'!K$26:K$595) -> 0 | I22: =SUMIF('内訳ﾘｽﾄ(4～3月)'!$D$26:$D$595,$B22,'内訳ﾘｽﾄ(4～3月)'!L$26:L$595) -> 0 | J22: =SUMIF('内訳ﾘｽﾄ(4～3月)'!$D$26:$D$595,$B22,'内訳ﾘｽﾄ(4～3月)'!M$26:M$595) -> 0 | ... N22: =SUMIF('内訳ﾘｽﾄ(4～3月)'!$D$26:$D$595,$B22,'内訳ﾘｽﾄ(4～3月)'!Q$26:Q$595) -> 0 | O22: =SUMIF('内訳ﾘｽﾄ(4～3月)'!$D$26:$D$394,'採算表(VND)'!$B22,'内訳ﾘｽﾄ(4～3月)'!R$26:R$394) -> 0
B23: 保険料 | C23: =SUMIF('内訳ﾘｽﾄ(4～3月)'!$D$26:$D$595,$B23,'内訳ﾘｽﾄ(4～3月)'!F$26:F$595) -> 0 | D23: =SUMIF('内訳ﾘｽﾄ(4～3月)'!$D$26:$D$595,$B23,'内訳ﾘｽﾄ(4～3月)'!G$26:G$595) -> 0 | E23: =SUMIF('内訳ﾘｽﾄ(4～3月)'!$D$26:$D$595,$B23,'内訳ﾘｽﾄ(4～3月)'!H$26:H$595) -> 0 | F23: =SUMIF('内訳ﾘｽﾄ(4～3月)'!$D$26:$D$595,$B23,'内訳ﾘｽﾄ(4～3月)'!I$26:I$595) -> 0 | G23: =SUMIF('内訳ﾘｽﾄ(4～3月)'!$D$26:$D$595,$B23,'内訳ﾘｽﾄ(4～3月)'!J$26:J$595) -> 0 | H23: =SUMIF('内訳ﾘｽﾄ(4～3月)'!$D$26:$D$595,$B23,'内訳ﾘｽﾄ(4～3月)'!K$26:K$595) -> 0 | I23: =SUMIF('内訳ﾘｽﾄ(4～3月)'!$D$26:$D$595,$B23,'内訳ﾘｽﾄ(4～3月)'!L$26:L$595) -> 0 | J23: =SUMIF('内訳ﾘｽﾄ(4～3月)'!$D$26:$D$595,$B23,'内訳ﾘｽﾄ(4～3月)'!M$26:M$595) -> 0 | ... N23: =SUMIF('内訳ﾘｽﾄ(4～3月)'!$D$26:$D$595,$B23,'内訳ﾘｽﾄ(4～3月)'!Q$26:Q$595) -> 0 | O23: =SUMIF('内訳ﾘｽﾄ(4～3月)'!$D$26:$D$394,'採算表(VND)'!$B23,'内訳ﾘｽﾄ(4～3月)'!R$26:R$394) -> 0
B24: 設計委託費 | C24: =SUMIF('内訳ﾘｽﾄ(4～3月)'!$D$26:$D$595,$B24,'内訳ﾘｽﾄ(4～3月)'!F$26:F$595) -> 0 | D24: =SUMIF('内訳ﾘｽﾄ(4～3月)'!$D$26:$D$595,$B24,'内訳ﾘｽﾄ(4～3月)'!G$26:G$595) -> 0 | E24: =SUMIF('内訳ﾘｽﾄ(4～3月)'!$D$26:$D$595,$B24,'内訳ﾘｽﾄ(4～3月)'!H$26:H$595) -> 0 | F24: =SUMIF('内訳ﾘｽﾄ(4～3月)'!$D$26:$D$595,$B24,'内訳ﾘｽﾄ(4～3月)'!I$26:I$595) -> 0 | G24: =SUMIF('内訳ﾘｽﾄ(4～3月)'!$D$26:$D$595,$B24,'内訳ﾘｽﾄ(4～3月)'!J$26:J$595) -> 0 | H24: =SUMIF('内訳ﾘｽﾄ(4～3月)'!$D$26:$D$595,$B24,'内訳ﾘｽﾄ(4～3月)'!K$26:K$595) -> 0 | I24: =SUMIF('内訳ﾘｽﾄ(4～3月)'!$D$26:$D$595,$B24,'内訳ﾘｽﾄ(4～3月)'!L$26:L$595) -> 0 | J24: =SUMIF('内訳ﾘｽﾄ(4～3月)'!$D$26:$D$595,$B24,'内訳ﾘｽﾄ(4～3月)'!M$26:M$595) -> 0 | ... N24: =SUMIF('内訳ﾘｽﾄ(4～3月)'!$D$26:$D$595,$B24,'内訳ﾘｽﾄ(4～3月)'!Q$26:Q$595) -> 0 | O24: =SUMIF('内訳ﾘｽﾄ(4～3月)'!$D$26:$D$394,'採算表(VND)'!$B24,'内訳ﾘｽﾄ(4～3月)'!R$26:R$394) -> 0
B25: 消耗品費 | C25: =SUMIF('内訳ﾘｽﾄ(4～3月)'!$D$26:$D$595,$B25,'内訳ﾘｽﾄ(4～3月)'!F$26:F$595) -> 841440 | D25: =SUMIF('内訳ﾘｽﾄ(4～3月)'!$D$26:$D$595,$B25,'内訳ﾘｽﾄ(4～3月)'!G$26:G$595) -> 841440 | E25: =SUMIF('内訳ﾘｽﾄ(4～3月)'!$D$26:$D$595,$B25,'内訳ﾘｽﾄ(4～3月)'!H$26:H$595) -> 841440 | F25: =SUMIF('内訳ﾘｽﾄ(4～3月)'!$D$26:$D$595,$B25,'内訳ﾘｽﾄ(4～3月)'!I$26:I$595) -> 841440 | G25: =SUMIF('内訳ﾘｽﾄ(4～3月)'!$D$26:$D$595,$B25,'内訳ﾘｽﾄ(4～3月)'!J$26:J$595) -> 841440 | H25: =SUMIF('内訳ﾘｽﾄ(4～3月)'!$D$26:$D$595,$B25,'内訳ﾘｽﾄ(4～3月)'!K$26:K$595) -> 841440 | I25: =SUMIF('内訳ﾘｽﾄ(4～3月)'!$D$26:$D$595,$B25,'内訳ﾘｽﾄ(4～3月)'!L$26:L$595) -> 841440 | J25: =SUMIF('内訳ﾘｽﾄ(4～3月)'!$D$26:$D$595,$B25,'内訳ﾘｽﾄ(4～3月)'!M$26:M$595) -> 841440 | ... N25: =SUMIF('内訳ﾘｽﾄ(4～3月)'!$D$26:$D$595,$B25,'内訳ﾘｽﾄ(4～3月)'!Q$26:Q$595) -> 841440 | O25: =SUMIF('内訳ﾘｽﾄ(4～3月)'!$D$26:$D$394,'採算表(VND)'!$B25,'内訳ﾘｽﾄ(4～3月)'!R$26:R$394) -> 10097280
... B65: 本社機構経費 | C65: =SUMIF('内訳ﾘｽﾄ(4～3月)'!$D$26:$D$595,$B65,'内訳ﾘｽﾄ(4～3月)'!F$26:F$595) -> 0 | D65: =SUMIF('内訳ﾘｽﾄ(4～3月)'!$D$26:$D$595,$B65,'内訳ﾘｽﾄ(4～3月)'!G$26:G$595) -> 0 | E65: =SUMIF('内訳ﾘｽﾄ(4～3月)'!$D$26:$D$595,$B65,'内訳ﾘｽﾄ(4～3月)'!H$26:H$595) -> 0 | F65: =SUMIF('内訳ﾘｽﾄ(4～3月)'!$D$26:$D$595,$B65,'内訳ﾘｽﾄ(4～3月)'!I$26:I$595) -> 0 | G65: =SUMIF('内訳ﾘｽﾄ(4～3月)'!$D$26:$D$595,$B65,'内訳ﾘｽﾄ(4～3月)'!J$26:J$595) -> 0 | H65: =SUMIF('内訳ﾘｽﾄ(4～3月)'!$D$26:$D$595,$B65,'内訳ﾘｽﾄ(4～3月)'!K$26:K$595) -> 0 | I65: =SUMIF('内訳ﾘｽﾄ(4～3月)'!$D$26:$D$595,$B65,'内訳ﾘｽﾄ(4～3月)'!L$26:L$595) -> 0 | J65: =SUMIF('内訳ﾘｽﾄ(4～3月)'!$D$26:$D$595,$B65,'内訳ﾘｽﾄ(4～3月)'!M$26:M$595) -> 0 | ... N65: =SUMIF('内訳ﾘｽﾄ(4～3月)'!$D$26:$D$595,$B65,'内訳ﾘｽﾄ(4～3月)'!Q$26:Q$595) -> 0 | O65: =SUMIF('内訳ﾘｽﾄ(4～3月)'!$D$26:$D$394,'採算表(VND)'!$B65,'内訳ﾘｽﾄ(4～3月)'!R$26:R$394) -> 0
B66: 差引収益 | C66: =C12-C13 -> 355884362 | D66: =D12-D13 -> 651235751 | E66: =E12-E13 -> 610295462 | F66: =F12-F13 -> 596253240 | G66: =G12-G13 -> 687207507 | H66: =H12-H13 -> 374331178 | I66: =I12-I13 -> 982596443 | J66: =J12-J13 -> 723943797 | ... N66: =N12-N13 -> 690651260 | O66: =IF(ISBLANK(O4),"",O12-O13) -> 7752741038
B67: 総時間 | C67: =C73+C79 -> 2247 | D67: =D73+D79 -> 2097.5 | E67: =E73+E79 -> 2315.25 | F67: =F73+F79 -> 2579.5 | G67: =G73+G79 -> 2257.5 | H67: =H73+H79 -> 2146.25 | I67: =I73+I79 -> 2545.25 | J67: =J73+J79 -> 2228.75 | ... N67: =N73+N79 -> 2230.25 | O67: =IF(ISBLANK(O4),"",O73+O79) -> 27004.5
B68: 直接部門 | C68: =SUMIF('内訳ﾘｽﾄ(4～3月)'!$D$8:$D$15,'採算表(VND)'!$B68,'内訳ﾘｽﾄ(4～3月)'!F$8:F$15) -> 1997.5 | D68: =SUMIF('内訳ﾘｽﾄ(4～3月)'!$D$8:$D$15,'採算表(VND)'!$B68,'内訳ﾘｽﾄ(4～3月)'!G$8:G$15) -> 1853 | E68: =SUMIF('内訳ﾘｽﾄ(4～3月)'!$D$8:$D$15,'採算表(VND)'!$B68,'内訳ﾘｽﾄ(4～3月)'!H$8:H$15) -> 2057 | F68: =SUMIF('内訳ﾘｽﾄ(4～3月)'!$D$8:$D$15,'採算表(VND)'!$B68,'内訳ﾘｽﾄ(4～3月)'!I$8:I$15) -> 2261 | G68: =SUMIF('内訳ﾘｽﾄ(4～3月)'!$D$8:$D$15,'採算表(VND)'!$B68,'内訳ﾘｽﾄ(4～3月)'!J$8:J$15) -> 1955 | H68: =SUMIF('内訳ﾘｽﾄ(4～3月)'!$D$8:$D$15,'採算表(VND)'!$B68,'内訳ﾘｽﾄ(4～3月)'!K$8:K$15) -> 1853 | I68: =SUMIF('内訳ﾘｽﾄ(4～3月)'!$D$8:$D$15,'採算表(VND)'!$B68,'内訳ﾘｽﾄ(4～3月)'!L$8:L$15) -> 2261 | J68: =SUMIF('内訳ﾘｽﾄ(4～3月)'!$D$8:$D$15,'採算表(VND)'!$B68,'内訳ﾘｽﾄ(4～3月)'!M$8:M$15) -> 1963.5 | ... N68: =SUMIF('内訳ﾘｽﾄ(4～3月)'!$D$8:$D$15,'採算表(VND)'!$B68,'内訳ﾘｽﾄ(4～3月)'!Q$8:Q$15) -> 1963.5 | O68: =SUMIF('内訳ﾘｽﾄ(4～3月)'!$D$8:$D$15,'採算表(VND)'!$B68,'内訳ﾘｽﾄ(4～3月)'!$R$8:$R$15) -> 23749
B69: 部内間接部門 | C69: =IF('内訳ﾘｽﾄ(4～3月)'!$D$5="製造",SUMIF('内訳ﾘｽﾄ(4～3月)'!$D$8:$D$15,$B69,'内訳ﾘｽﾄ(4～3月)'!F$8:F$15),IF('内訳ﾘｽﾄ(4～3月)'!$D$5="部内間接",-C$68,0)) -> 0 | D69: =IF('内訳ﾘｽﾄ(4～3月)'!$D$5="製造",SUMIF('内訳ﾘｽﾄ(4～3月)'!$D$8:$D$15,$B69,'内訳ﾘｽﾄ(4～3月)'!G$8:G$15),IF('内訳ﾘｽﾄ(4～3月)'!$D$5="部内間接",-D$68,0)) -> 0 | E69: =IF('内訳ﾘｽﾄ(4～3月)'!$D$5="製造",SUMIF('内訳ﾘｽﾄ(4～3月)'!$D$8:$D$15,$B69,'内訳ﾘｽﾄ(4～3月)'!H$8:H$15),IF('内訳ﾘｽﾄ(4～3月)'!$D$5="部内間接",-E$68,0)) -> 0 | F69: =IF('内訳ﾘｽﾄ(4～3月)'!$D$5="製造",SUMIF('内訳ﾘｽﾄ(4～3月)'!$D$8:$D$15,$B69,'内訳ﾘｽﾄ(4～3月)'!I$8:I$15),IF('内訳ﾘｽﾄ(4～3月)'!$D$5="部内間接",-F$68,0)) -> 0 | G69: =IF('内訳ﾘｽﾄ(4～3月)'!$D$5="製造",SUMIF('内訳ﾘｽﾄ(4～3月)'!$D$8:$D$15,$B69,'内訳ﾘｽﾄ(4～3月)'!J$8:J$15),IF('内訳ﾘｽﾄ(4～3月)'!$D$5="部内間接",-G$68,0)) -> 0 | H69: =IF('内訳ﾘｽﾄ(4～3月)'!$D$5="製造",SUMIF('内訳ﾘｽﾄ(4～3月)'!$D$8:$D$15,$B69,'内訳ﾘｽﾄ(4～3月)'!K$8:K$15),IF('内訳ﾘｽﾄ(4～3月)'!$D$5="部内間接",-H$68,0)) -> 0 | I69: =IF('内訳ﾘｽﾄ(4～3月)'!$D$5="製造",SUMIF('内訳ﾘｽﾄ(4～3月)'!$D$8:$D$15,$B69,'内訳ﾘｽﾄ(4～3月)'!L$8:L$15),IF('内訳ﾘｽﾄ(4～3月)'!$D$5="部内間接",-I$68,0)) -> 0 | J69: =IF('内訳ﾘｽﾄ(4～3月)'!$D$5="製造",SUMIF('内訳ﾘｽﾄ(4～3月)'!$D$8:$D$15,$B69,'内訳ﾘｽﾄ(4～3月)'!M$8:M$15),IF('内訳ﾘｽﾄ(4～3月)'!$D$5="部内間接",-J$68,0)) -> 0 | ... N69: =IF('内訳ﾘｽﾄ(4～3月)'!$D$5="製造",SUMIF('内訳ﾘｽﾄ(4～3月)'!$D$8:$D$15,$B69,'内訳ﾘｽﾄ(4～3月)'!Q$8:Q$15),IF('内訳ﾘｽﾄ(4～3月)'!$D$5="部内間接",-N$68,0)) -> 0 | O69: =IF('内訳ﾘｽﾄ(4～3月)'!$D$5="部内間接",-SUM(O$68),IF('内訳ﾘｽﾄ(4～3月)'!$D$5="製造",SUMIF('内訳ﾘｽﾄ(4～3月)'!$D$8:$D$15,'採算表(VND)'!$B69,'内訳ﾘｽﾄ(4～3月)'!$R$8:$R$15),0)) -> 0
B70: 部外間接部門1 | C70: =IF('内訳ﾘｽﾄ(4～3月)'!$D$5="製造",SUMIF('内訳ﾘｽﾄ(4～3月)'!$D$8:$D$15,$B70,'内訳ﾘｽﾄ(4～3月)'!F$8:F$15),IF('内訳ﾘｽﾄ(4～3月)'!$D$5="部外間接1",-C$68,0)) -> 6.75 | D70: =IF('内訳ﾘｽﾄ(4～3月)'!$D$5="製造",SUMIF('内訳ﾘｽﾄ(4～3月)'!$D$8:$D$15,$B70,'内訳ﾘｽﾄ(4～3月)'!G$8:G$15),IF('内訳ﾘｽﾄ(4～3月)'!$D$5="部外間接1",-D$68,0)) -> 7 | E70: =IF('内訳ﾘｽﾄ(4～3月)'!$D$5="製造",SUMIF('内訳ﾘｽﾄ(4～3月)'!$D$8:$D$15,$B70,'内訳ﾘｽﾄ(4～3月)'!H$8:H$15),IF('内訳ﾘｽﾄ(4～3月)'!$D$5="部外間接1",-E$68,0)) -> 7.75 | F70: =IF('内訳ﾘｽﾄ(4～3月)'!$D$5="製造",SUMIF('内訳ﾘｽﾄ(4～3月)'!$D$8:$D$15,$B70,'内訳ﾘｽﾄ(4～3月)'!I$8:I$15),IF('内訳ﾘｽﾄ(4～3月)'!$D$5="部外間接1",-F$68,0)) -> 12 | G70: =IF('内訳ﾘｽﾄ(4～3月)'!$D$5="製造",SUMIF('内訳ﾘｽﾄ(4～3月)'!$D$8:$D$15,$B70,'内訳ﾘｽﾄ(4～3月)'!J$8:J$15),IF('内訳ﾘｽﾄ(4～3月)'!$D$5="部外間接1",-G$68,0)) -> 10.75 | H70: =IF('内訳ﾘｽﾄ(4～3月)'!$D$5="製造",SUMIF('内訳ﾘｽﾄ(4～3月)'!$D$8:$D$15,$B70,'内訳ﾘｽﾄ(4～3月)'!K$8:K$15),IF('内訳ﾘｽﾄ(4～3月)'!$D$5="部外間接1",-H$68,0)) -> 10 | I70: =IF('内訳ﾘｽﾄ(4～3月)'!$D$5="製造",SUMIF('内訳ﾘｽﾄ(4～3月)'!$D$8:$D$15,$B70,'内訳ﾘｽﾄ(4～3月)'!L$8:L$15),IF('内訳ﾘｽﾄ(4～3月)'!$D$5="部外間接1",-I$68,0)) -> 8.25 | J70: =IF('内訳ﾘｽﾄ(4～3月)'!$D$5="製造",SUMIF('内訳ﾘｽﾄ(4～3月)'!$D$8:$D$15,$B70,'内訳ﾘｽﾄ(4～3月)'!M$8:M$15),IF('内訳ﾘｽﾄ(4～3月)'!$D$5="部外間接1",-J$68,0)) -> 7.25 | ... N70: =IF('内訳ﾘｽﾄ(4～3月)'!$D$5="製造",SUMIF('内訳ﾘｽﾄ(4～3月)'!$D$8:$D$15,$B70,'内訳ﾘｽﾄ(4～3月)'!Q$8:Q$15),IF('内訳ﾘｽﾄ(4～3月)'!$D$5="部外間接1",-N$68,0)) -> 7.5 | O70: =IF('内訳ﾘｽﾄ(4～3月)'!$D$5="部外間接1",-SUM(O$68),IF('内訳ﾘｽﾄ(4～3月)'!$D$5="製造",SUMIF('内訳ﾘｽﾄ(4～3月)'!$D$8:$D$15,'採算表(VND)'!$B70,'内訳ﾘｽﾄ(4～3月)'!$R$8:$R$15),0)) -> 98.25
B71: 部外間接部門2 | C71: =IF('内訳ﾘｽﾄ(4～3月)'!$D$5="製造",SUMIF('内訳ﾘｽﾄ(4～3月)'!$D$8:$D$15,$B71,'内訳ﾘｽﾄ(4～3月)'!F$8:F$15),IF('内訳ﾘｽﾄ(4～3月)'!$D$5="部外間接2",-C$68,0)) -> 12.75 | D71: =IF('内訳ﾘｽﾄ(4～3月)'!$D$5="製造",SUMIF('内訳ﾘｽﾄ(4～3月)'!$D$8:$D$15,$B71,'内訳ﾘｽﾄ(4～3月)'!G$8:G$15),IF('内訳ﾘｽﾄ(4～3月)'!$D$5="部外間接2",-D$68,0)) -> 12.25 | E71: =IF('内訳ﾘｽﾄ(4～3月)'!$D$5="製造",SUMIF('内訳ﾘｽﾄ(4～3月)'!$D$8:$D$15,$B71,'内訳ﾘｽﾄ(4～3月)'!H$8:H$15),IF('内訳ﾘｽﾄ(4～3月)'!$D$5="部外間接2",-E$68,0)) -> 14 | F71: =IF('内訳ﾘｽﾄ(4～3月)'!$D$5="製造",SUMIF('内訳ﾘｽﾄ(4～3月)'!$D$8:$D$15,$B71,'内訳ﾘｽﾄ(4～3月)'!I$8:I$15),IF('内訳ﾘｽﾄ(4～3月)'!$D$5="部外間接2",-F$68,0)) -> 23.25 | G71: =IF('内訳ﾘｽﾄ(4～3月)'!$D$5="製造",SUMIF('内訳ﾘｽﾄ(4～3月)'!$D$8:$D$15,$B71,'内訳ﾘｽﾄ(4～3月)'!J$8:J$15),IF('内訳ﾘｽﾄ(4～3月)'!$D$5="部外間接2",-G$68,0)) -> 20.25 | H71: =IF('内訳ﾘｽﾄ(4～3月)'!$D$5="製造",SUMIF('内訳ﾘｽﾄ(4～3月)'!$D$8:$D$15,$B71,'内訳ﾘｽﾄ(4～3月)'!K$8:K$15),IF('内訳ﾘｽﾄ(4～3月)'!$D$5="部外間接2",-H$68,0)) -> 19.75 | I71: =IF('内訳ﾘｽﾄ(4～3月)'!$D$5="製造",SUMIF('内訳ﾘｽﾄ(4～3月)'!$D$8:$D$15,$B71,'内訳ﾘｽﾄ(4～3月)'!L$8:L$15),IF('内訳ﾘｽﾄ(4～3月)'!$D$5="部外間接2",-I$68,0)) -> 16.25 | J71: =IF('内訳ﾘｽﾄ(4～3月)'!$D$5="製造",SUMIF('内訳ﾘｽﾄ(4～3月)'!$D$8:$D$15,$B71,'内訳ﾘｽﾄ(4～3月)'!M$8:M$15),IF('内訳ﾘｽﾄ(4～3月)'!$D$5="部外間接2",-J$68,0)) -> 14 | ... N71: =IF('内訳ﾘｽﾄ(4～3月)'!$D$5="製造",SUMIF('内訳ﾘｽﾄ(4～3月)'!$D$8:$D$15,$B71,'内訳ﾘｽﾄ(4～3月)'!Q$8:Q$15),IF('内訳ﾘｽﾄ(4～3月)'!$D$5="部外間接2",-N$68,0)) -> 14 | O71: =IF('内訳ﾘｽﾄ(4～3月)'!$D$5="部外間接2",-SUM(O$68),IF('内訳ﾘｽﾄ(4～3月)'!$D$5="製造",SUMIF('内訳ﾘｽﾄ(4～3月)'!$D$8:$D$15,'採算表(VND)'!$B71,'内訳ﾘｽﾄ(4～3月)'!$R$8:$R$15),0)) -> 187
B72: 工場間接部門 | C72: =IF('内訳ﾘｽﾄ(4～3月)'!$D$5="製造",SUMIF('内訳ﾘｽﾄ(4～3月)'!$D$8:$D$15,$B72,'内訳ﾘｽﾄ(4～3月)'!F$8:F$15),IF('内訳ﾘｽﾄ(4～3月)'!$D$5="工場間接",-C$68,0)) -> 57 | D72: =IF('内訳ﾘｽﾄ(4～3月)'!$D$5="製造",SUMIF('内訳ﾘｽﾄ(4～3月)'!$D$8:$D$15,$B72,'内訳ﾘｽﾄ(4～3月)'!G$8:G$15),IF('内訳ﾘｽﾄ(4～3月)'!$D$5="工場間接",-D$68,0)) -> 56.5 | E72: =IF('内訳ﾘｽﾄ(4～3月)'!$D$5="製造",SUMIF('内訳ﾘｽﾄ(4～3月)'!$D$8:$D$15,$B72,'内訳ﾘｽﾄ(4～3月)'!H$8:H$15),IF('内訳ﾘｽﾄ(4～3月)'!$D$5="工場間接",-E$68,0)) -> 60 | F72: =IF('内訳ﾘｽﾄ(4～3月)'!$D$5="製造",SUMIF('内訳ﾘｽﾄ(4～3月)'!$D$8:$D$15,$B72,'内訳ﾘｽﾄ(4～3月)'!I$8:I$15),IF('内訳ﾘｽﾄ(4～3月)'!$D$5="工場間接",-F$68,0)) -> 96 | G72: =IF('内訳ﾘｽﾄ(4～3月)'!$D$5="製造",SUMIF('内訳ﾘｽﾄ(4～3月)'!$D$8:$D$15,$B72,'内訳ﾘｽﾄ(4～3月)'!J$8:J$15),IF('内訳ﾘｽﾄ(4～3月)'!$D$5="工場間接",-G$68,0)) -> 88.25 | H72: =IF('内訳ﾘｽﾄ(4～3月)'!$D$5="製造",SUMIF('内訳ﾘｽﾄ(4～3月)'!$D$8:$D$15,$B72,'内訳ﾘｽﾄ(4～3月)'!K$8:K$15),IF('内訳ﾘｽﾄ(4～3月)'!$D$5="工場間接",-H$68,0)) -> 82.5 | I72: =IF('内訳ﾘｽﾄ(4～3月)'!$D$5="製造",SUMIF('内訳ﾘｽﾄ(4～3月)'!$D$8:$D$15,$B72,'内訳ﾘｽﾄ(4～3月)'!L$8:L$15),IF('内訳ﾘｽﾄ(4～3月)'!$D$5="工場間接",-I$68,0)) -> 65 | J72: =IF('内訳ﾘｽﾄ(4～3月)'!$D$5="製造",SUMIF('内訳ﾘｽﾄ(4～3月)'!$D$8:$D$15,$B72,'内訳ﾘｽﾄ(4～3月)'!M$8:M$15),IF('内訳ﾘｽﾄ(4～3月)'!$D$5="工場間接",-J$68,0)) -> 59.25 | ... N72: =IF('内訳ﾘｽﾄ(4～3月)'!$D$5="製造",SUMIF('内訳ﾘｽﾄ(4～3月)'!$D$8:$D$15,$B72,'内訳ﾘｽﾄ(4～3月)'!Q$8:Q$15),IF('内訳ﾘｽﾄ(4～3月)'!$D$5="工場間接",-N$68,0)) -> 60.5 | O72: =IF('内訳ﾘｽﾄ(4～3月)'!$D$5="工場間接",-SUM(O$68),IF('内訳ﾘｽﾄ(4～3月)'!$D$5="製造",SUMIF('内訳ﾘｽﾄ(4～3月)'!$D$8:$D$15,'採算表(VND)'!$B72,'内訳ﾘｽﾄ(4～3月)'!$R$8:$R$15),0)) -> 794.25
B73: 定時間合計 | C73: =SUM(C68:C72) -> 2074 | D73: =SUM(D68:D72) -> 1928.75 | E73: =SUM(E68:E72) -> 2138.75 | F73: =SUM(F68:F72) -> 2392.25 | G73: =SUM(G68:G72) -> 2074.25 | H73: =SUM(H68:H72) -> 1965.25 | I73: =SUM(I68:I72) -> 2350.5 | J73: =SUM(J68:J72) -> 2044 | ... N73: =SUM(N68:N72) -> 2045.5 | O73: =IF(ISBLANK(O4),"",SUM(O68:O72)) -> 24828.5
B74: 直接部門 | C74: =SUMIF('内訳ﾘｽﾄ(4～3月)'!$D$16:$D$23,'採算表(VND)'!$B74,'内訳ﾘｽﾄ(4～3月)'!F$16:F$23) -> 168 | D74: =SUMIF('内訳ﾘｽﾄ(4～3月)'!$D$16:$D$23,'採算表(VND)'!$B74,'内訳ﾘｽﾄ(4～3月)'!G$16:G$23) -> 164 | E74: =SUMIF('内訳ﾘｽﾄ(4～3月)'!$D$16:$D$23,'採算表(VND)'!$B74,'内訳ﾘｽﾄ(4～3月)'!H$16:H$23) -> 172 | F74: =SUMIF('内訳ﾘｽﾄ(4～3月)'!$D$16:$D$23,'採算表(VND)'!$B74,'内訳ﾘｽﾄ(4～3月)'!I$16:I$23) -> 180 | G74: =SUMIF('内訳ﾘｽﾄ(4～3月)'!$D$16:$D$23,'採算表(VND)'!$B74,'内訳ﾘｽﾄ(4～3月)'!J$16:J$23) -> 178 | H74: =SUMIF('内訳ﾘｽﾄ(4～3月)'!$D$16:$D$23,'採算表(VND)'!$B74,'内訳ﾘｽﾄ(4～3月)'!K$16:K$23) -> 174 | I74: =SUMIF('内訳ﾘｽﾄ(4～3月)'!$D$16:$D$23,'採算表(VND)'!$B74,'内訳ﾘｽﾄ(4～3月)'!L$16:L$23) -> 190 | J74: =SUMIF('内訳ﾘｽﾄ(4～3月)'!$D$16:$D$23,'採算表(VND)'!$B74,'内訳ﾘｽﾄ(4～3月)'!M$16:M$23) -> 180 | ... N74: =SUMIF('内訳ﾘｽﾄ(4～3月)'!$D$16:$D$23,'採算表(VND)'!$B74,'内訳ﾘｽﾄ(4～3月)'!Q$16:Q$23) -> 180 | O74: =SUMIF('内訳ﾘｽﾄ(4～3月)'!$D$16:$D$23,'採算表(VND)'!$B74,'内訳ﾘｽﾄ(4～3月)'!$R$16:$R$23) -> 2114
B75: 部内間接部門 | C75: =IF('内訳ﾘｽﾄ(4～3月)'!$D$5="製造",SUMIF('内訳ﾘｽﾄ(4～3月)'!$D$16:$D$23,$B75,'内訳ﾘｽﾄ(4～3月)'!F$16:F$23),IF('内訳ﾘｽﾄ(4～3月)'!$D$5="部内間接",-C$74,0)) -> 0 | D75: =IF('内訳ﾘｽﾄ(4～3月)'!$D$5="製造",SUMIF('内訳ﾘｽﾄ(4～3月)'!$D$16:$D$23,$B75,'内訳ﾘｽﾄ(4～3月)'!G$16:G$23),IF('内訳ﾘｽﾄ(4～3月)'!$D$5="部内間接",-D$74,0)) -> 0 | E75: =IF('内訳ﾘｽﾄ(4～3月)'!$D$5="製造",SUMIF('内訳ﾘｽﾄ(4～3月)'!$D$16:$D$23,$B75,'内訳ﾘｽﾄ(4～3月)'!H$16:H$23),IF('内訳ﾘｽﾄ(4～3月)'!$D$5="部内間接",-E$74,0)) -> 0 | F75: =IF('内訳ﾘｽﾄ(4～3月)'!$D$5="製造",SUMIF('内訳ﾘｽﾄ(4～3月)'!$D$16:$D$23,$B75,'内訳ﾘｽﾄ(4～3月)'!I$16:I$23),IF('内訳ﾘｽﾄ(4～3月)'!$D$5="部内間接",-F$74,0)) -> 0 | G75: =IF('内訳ﾘｽﾄ(4～3月)'!$D$5="製造",SUMIF('内訳ﾘｽﾄ(4～3月)'!$D$16:$D$23,$B75,'内訳ﾘｽﾄ(4～3月)'!J$16:J$23),IF('内訳ﾘｽﾄ(4～3月)'!$D$5="部内間接",-G$74,0)) -> 0 | H75: =IF('内訳ﾘｽﾄ(4～3月)'!$D$5="製造",SUMIF('内訳ﾘｽﾄ(4～3月)'!$D$16:$D$23,$B75,'内訳ﾘｽﾄ(4～3月)'!K$16:K$23),IF('内訳ﾘｽﾄ(4～3月)'!$D$5="部内間接",-H$74,0)) -> 0 | I75: =IF('内訳ﾘｽﾄ(4～3月)'!$D$5="製造",SUMIF('内訳ﾘｽﾄ(4～3月)'!$D$16:$D$23,$B75,'内訳ﾘｽﾄ(4～3月)'!L$16:L$23),IF('内訳ﾘｽﾄ(4～3月)'!$D$5="部内間接",-I$74,0)) -> 0 | J75: =IF('内訳ﾘｽﾄ(4～3月)'!$D$5="製造",SUMIF('内訳ﾘｽﾄ(4～3月)'!$D$16:$D$23,$B75,'内訳ﾘｽﾄ(4～3月)'!M$16:M$23),IF('内訳ﾘｽﾄ(4～3月)'!$D$5="部内間接",-J$74,0)) -> 0 | ... N75: =IF('内訳ﾘｽﾄ(4～3月)'!$D$5="製造",SUMIF('内訳ﾘｽﾄ(4～3月)'!$D$16:$D$23,$B75,'内訳ﾘｽﾄ(4～3月)'!Q$16:Q$23),IF('内訳ﾘｽﾄ(4～3月)'!$D$5="部内間接",-N$74,0)) -> 0 | O75: =IF('内訳ﾘｽﾄ(4～3月)'!$D$5="部内間接",-SUM(O$74),IF('内訳ﾘｽﾄ(4～3月)'!$D$5="製造",SUMIF('内訳ﾘｽﾄ(4～3月)'!$D$16:$D$23,'採算表(VND)'!$B75,'内訳ﾘｽﾄ(4～3月)'!$R$16:$R$23),0)) -> 0
B76: 部外間接部門1 | C76: =IF('内訳ﾘｽﾄ(4～3月)'!$D$5="製造",SUMIF('内訳ﾘｽﾄ(4～3月)'!$D$16:$D$23,$B76,'内訳ﾘｽﾄ(4～3月)'!F$16:F$23),IF('内訳ﾘｽﾄ(4～3月)'!$D$5="部外間接1",-C$74,0)) -> 0.5 | D76: =IF('内訳ﾘｽﾄ(4～3月)'!$D$5="製造",SUMIF('内訳ﾘｽﾄ(4～3月)'!$D$16:$D$23,$B76,'内訳ﾘｽﾄ(4～3月)'!G$16:G$23),IF('内訳ﾘｽﾄ(4～3月)'!$D$5="部外間接1",-D$74,0)) -> 0.5 | E76: =IF('内訳ﾘｽﾄ(4～3月)'!$D$5="製造",SUMIF('内訳ﾘｽﾄ(4～3月)'!$D$16:$D$23,$B76,'内訳ﾘｽﾄ(4～3月)'!H$16:H$23),IF('内訳ﾘｽﾄ(4～3月)'!$D$5="部外間接1",-E$74,0)) -> 0.5 | F76: =IF('内訳ﾘｽﾄ(4～3月)'!$D$5="製造",SUMIF('内訳ﾘｽﾄ(4～3月)'!$D$16:$D$23,$B76,'内訳ﾘｽﾄ(4～3月)'!I$16:I$23),IF('内訳ﾘｽﾄ(4～3月)'!$D$5="部外間接1",-F$74,0)) -> 0.75 | G76: =IF('内訳ﾘｽﾄ(4～3月)'!$D$5="製造",SUMIF('内訳ﾘｽﾄ(4～3月)'!$D$16:$D$23,$B76,'内訳ﾘｽﾄ(4～3月)'!J$16:J$23),IF('内訳ﾘｽﾄ(4～3月)'!$D$5="部外間接1",-G$74,0)) -> 0.75 | H76: =IF('内訳ﾘｽﾄ(4～3月)'!$D$5="製造",SUMIF('内訳ﾘｽﾄ(4～3月)'!$D$16:$D$23,$B76,'内訳ﾘｽﾄ(4～3月)'!K$16:K$23),IF('内訳ﾘｽﾄ(4～3月)'!$D$5="部外間接1",-H$74,0)) -> 0.75 | I76: =IF('内訳ﾘｽﾄ(4～3月)'!$D$5="製造",SUMIF('内訳ﾘｽﾄ(4～3月)'!$D$16:$D$23,$B76,'内訳ﾘｽﾄ(4～3月)'!L$16:L$23),IF('内訳ﾘｽﾄ(4～3月)'!$D$5="部外間接1",-I$74,0)) -> 0.5 | J76: =IF('内訳ﾘｽﾄ(4～3月)'!$D$5="製造",SUMIF('内訳ﾘｽﾄ(4～3月)'!$D$16:$D$23,$B76,'内訳ﾘｽﾄ(4～3月)'!M$16:M$23),IF('内訳ﾘｽﾄ(4～3月)'!$D$5="部外間接1",-J$74,0)) -> 0.5 | ... N76: =IF('内訳ﾘｽﾄ(4～3月)'!$D$5="製造",SUMIF('内訳ﾘｽﾄ(4～3月)'!$D$16:$D$23,$B76,'内訳ﾘｽﾄ(4～3月)'!Q$16:Q$23),IF('内訳ﾘｽﾄ(4～3月)'!$D$5="部外間接1",-N$74,0)) -> 0.5 | O76: =IF('内訳ﾘｽﾄ(4～3月)'!$D$5="部外間接1",-SUM(O$74),IF('内訳ﾘｽﾄ(4～3月)'!$D$5="製造",SUMIF('内訳ﾘｽﾄ(4～3月)'!$D$16:$D$23,'採算表(VND)'!$B76,'内訳ﾘｽﾄ(4～3月)'!$R$16:$R$23),0)) -> 6.5
B77: 部外間接部門2 | C77: =IF('内訳ﾘｽﾄ(4～3月)'!$D$5="製造",SUMIF('内訳ﾘｽﾄ(4～3月)'!$D$16:$D$23,$B77,'内訳ﾘｽﾄ(4～3月)'!F$16:F$23),IF('内訳ﾘｽﾄ(4～3月)'!$D$5="部外間接2",-C$74,0)) -> 1.25 | D77: =IF('内訳ﾘｽﾄ(4～3月)'!$D$5="製造",SUMIF('内訳ﾘｽﾄ(4～3月)'!$D$16:$D$23,$B77,'内訳ﾘｽﾄ(4～3月)'!G$16:G$23),IF('内訳ﾘｽﾄ(4～3月)'!$D$5="部外間接2",-D$74,0)) -> 1 | E77: =IF('内訳ﾘｽﾄ(4～3月)'!$D$5="製造",SUMIF('内訳ﾘｽﾄ(4～3月)'!$D$16:$D$23,$B77,'内訳ﾘｽﾄ(4～3月)'!H$16:H$23),IF('内訳ﾘｽﾄ(4～3月)'!$D$5="部外間接2",-E$74,0)) -> 1.25 | F77: =IF('内訳ﾘｽﾄ(4～3月)'!$D$5="製造",SUMIF('内訳ﾘｽﾄ(4～3月)'!$D$16:$D$23,$B77,'内訳ﾘｽﾄ(4～3月)'!I$16:I$23),IF('内訳ﾘｽﾄ(4～3月)'!$D$5="部外間接2",-F$74,0)) -> 2 | G77: =IF('内訳ﾘｽﾄ(4～3月)'!$D$5="製造",SUMIF('内訳ﾘｽﾄ(4～3月)'!$D$16:$D$23,$B77,'内訳ﾘｽﾄ(4～3月)'!J$16:J$23),IF('内訳ﾘｽﾄ(4～3月)'!$D$5="部外間接2",-G$74,0)) -> 1.25 | H77: =IF('内訳ﾘｽﾄ(4～3月)'!$D$5="製造",SUMIF('内訳ﾘｽﾄ(4～3月)'!$D$16:$D$23,$B77,'内訳ﾘｽﾄ(4～3月)'!K$16:K$23),IF('内訳ﾘｽﾄ(4～3月)'!$D$5="部外間接2",-H$74,0)) -> 1.25 | I77: =IF('内訳ﾘｽﾄ(4～3月)'!$D$5="製造",SUMIF('内訳ﾘｽﾄ(4～3月)'!$D$16:$D$23,$B77,'内訳ﾘｽﾄ(4～3月)'!L$16:L$23),IF('内訳ﾘｽﾄ(4～3月)'!$D$5="部外間接2",-I$74,0)) -> 1.25 | J77: =IF('内訳ﾘｽﾄ(4～3月)'!$D$5="製造",SUMIF('内訳ﾘｽﾄ(4～3月)'!$D$16:$D$23,$B77,'内訳ﾘｽﾄ(4～3月)'!M$16:M$23),IF('内訳ﾘｽﾄ(4～3月)'!$D$5="部外間接2",-J$74,0)) -> 1.25 | ... N77: =IF('内訳ﾘｽﾄ(4～3月)'!$D$5="製造",SUMIF('内訳ﾘｽﾄ(4～3月)'!$D$16:$D$23,$B77,'内訳ﾘｽﾄ(4～3月)'!Q$16:Q$23),IF('内訳ﾘｽﾄ(4～3月)'!$D$5="部外間接2",-N$74,0)) -> 1.5 | O77: =IF('内訳ﾘｽﾄ(4～3月)'!$D$5="部外間接2",-SUM(O$74),IF('内訳ﾘｽﾄ(4～3月)'!$D$5="製造",SUMIF('内訳ﾘｽﾄ(4～3月)'!$D$16:$D$23,'採算表(VND)'!$B77,'内訳ﾘｽﾄ(4～3月)'!$R$16:$R$23),0)) -> 15.25
B78: 工場間接部門 | C78: =IF('内訳ﾘｽﾄ(4～3月)'!$D$5="製造",SUMIF('内訳ﾘｽﾄ(4～3月)'!$D$16:$D$23,$B78,'内訳ﾘｽﾄ(4～3月)'!F$16:F$23),IF('内訳ﾘｽﾄ(4～3月)'!$D$5="工場間接",-C$74,0)) -> 3.25 | D78: =IF('内訳ﾘｽﾄ(4～3月)'!$D$5="製造",SUMIF('内訳ﾘｽﾄ(4～3月)'!$D$16:$D$23,$B78,'内訳ﾘｽﾄ(4～3月)'!G$16:G$23),IF('内訳ﾘｽﾄ(4～3月)'!$D$5="工場間接",-D$74,0)) -> 3.25 | E78: =IF('内訳ﾘｽﾄ(4～3月)'!$D$5="製造",SUMIF('内訳ﾘｽﾄ(4～3月)'!$D$16:$D$23,$B78,'内訳ﾘｽﾄ(4～3月)'!H$16:H$23),IF('内訳ﾘｽﾄ(4～3月)'!$D$5="工場間接",-E$74,0)) -> 2.75 | F78: =IF('内訳ﾘｽﾄ(4～3月)'!$D$5="製造",SUMIF('内訳ﾘｽﾄ(4～3月)'!$D$16:$D$23,$B78,'内訳ﾘｽﾄ(4～3月)'!I$16:I$23),IF('内訳ﾘｽﾄ(4～3月)'!$D$5="工場間接",-F$74,0)) -> 4.5 | G78: =IF('内訳ﾘｽﾄ(4～3月)'!$D$5="製造",SUMIF('内訳ﾘｽﾄ(4～3月)'!$D$16:$D$23,$B78,'内訳ﾘｽﾄ(4～3月)'!J$16:J$23),IF('内訳ﾘｽﾄ(4～3月)'!$D$5="工場間接",-G$74,0)) -> 3.25 | H78: =IF('内訳ﾘｽﾄ(4～3月)'!$D$5="製造",SUMIF('内訳ﾘｽﾄ(4～3月)'!$D$16:$D$23,$B78,'内訳ﾘｽﾄ(4～3月)'!K$16:K$23),IF('内訳ﾘｽﾄ(4～3月)'!$D$5="工場間接",-H$74,0)) -> 5 | I78: =IF('内訳ﾘｽﾄ(4～3月)'!$D$5="製造",SUMIF('内訳ﾘｽﾄ(4～3月)'!$D$16:$D$23,$B78,'内訳ﾘｽﾄ(4～3月)'!L$16:L$23),IF('内訳ﾘｽﾄ(4～3月)'!$D$5="工場間接",-I$74,0)) -> 3 | J78: =IF('内訳ﾘｽﾄ(4～3月)'!$D$5="製造",SUMIF('内訳ﾘｽﾄ(4～3月)'!$D$16:$D$23,$B78,'内訳ﾘｽﾄ(4～3月)'!M$16:M$23),IF('内訳ﾘｽﾄ(4～3月)'!$D$5="工場間接",-J$74,0)) -> 3 | ... N78: =IF('内訳ﾘｽﾄ(4～3月)'!$D$5="製造",SUMIF('内訳ﾘｽﾄ(4～3月)'!$D$16:$D$23,$B78,'内訳ﾘｽﾄ(4～3月)'!Q$16:Q$23),IF('内訳ﾘｽﾄ(4～3月)'!$D$5="工場間接",-N$74,0)) -> 2.75 | O78: =IF('内訳ﾘｽﾄ(4～3月)'!$D$5="工場間接",-SUM(O$74),IF('内訳ﾘｽﾄ(4～3月)'!$D$5="製造",SUMIF('内訳ﾘｽﾄ(4～3月)'!$D$16:$D$23,'採算表(VND)'!$B78,'内訳ﾘｽﾄ(4～3月)'!$R$16:$R$23),0)) -> 40.25
B79: 残業時間合計 | C79: =SUM(C74:C78) -> 173 | D79: =SUM(D74:D78) -> 168.75 | E79: =SUM(E74:E78) -> 176.5 | F79: =SUM(F74:F78) -> 187.25 | G79: =SUM(G74:G78) -> 183.25 | H79: =SUM(H74:H78) -> 181 | I79: =SUM(I74:I78) -> 194.75 | J79: =SUM(J74:J78) -> 184.75 | ... N79: =SUM(N74:N78) -> 184.75 | O79: =IF(ISBLANK(O10),"",SUM(O74:O78)) -> 2176
B80: 当月時間当り | C80: =IFERROR(ROUNDDOWN(C66/C67,0),0) -> 158382 | D80: =IFERROR(ROUNDDOWN(D66/D67,0),0) -> 310481 | E80: =IFERROR(ROUNDDOWN(E66/E67,0),0) -> 263598 | F80: =IFERROR(ROUNDDOWN(F66/F67,0),0) -> 231150 | G80: =IFERROR(ROUNDDOWN(G66/G67,0),0) -> 304410 | H80: =IFERROR(ROUNDDOWN(H66/H67,0),0) -> 174411 | I80: =IFERROR(ROUNDDOWN(I66/I67,0),0) -> 386051 | J80: =IFERROR(ROUNDDOWN(J66/J67,0),0) -> 324820 | ... O80: =IFERROR(ROUNDDOWN(O66/O67,0),0) -> 287090
...

Sheet 内訳ﾘｽﾄ(4～3月)
A1: MP FY2026_各予定
B2: 25390 | E2: 稼働日数 | F2: =OFFSET(稼働日!$B$2,MATCH('内訳ﾘｽﾄ(4～3月)'!F4,稼働日!$A$3:$A$14,0),0) -> 20 | G2: =OFFSET(稼働日!$B$2,MATCH('内訳ﾘｽﾄ(4～3月)'!G4,稼働日!$A$3:$A$14,0),0) -> 19 | H2: =OFFSET(稼働日!$B$2,MATCH('内訳ﾘｽﾄ(4～3月)'!H4,稼働日!$A$3:$A$14,0),0) -> 21 | I2: =OFFSET(稼働日!$B$2,MATCH('内訳ﾘｽﾄ(4～3月)'!I4,稼働日!$A$3:$A$14,0),0) -> 23 | J2: =OFFSET(稼働日!$B$2,MATCH('内訳ﾘｽﾄ(4～3月)'!J4,稼働日!$A$3:$A$14,0),0) -> 20 | K2: =OFFSET(稼働日!$B$2,MATCH('内訳ﾘｽﾄ(4～3月)'!K4,稼働日!$A$3:$A$14,0),0) -> 19 | L2: =OFFSET(稼働日!$B$2,MATCH('内訳ﾘｽﾄ(4～3月)'!L4,稼働日!$A$3:$A$14,0),0) -> 23 | M2: =OFFSET(稼働日!$B$2,MATCH('内訳ﾘｽﾄ(4～3月)'!M4,稼働日!$A$3:$A$14,0),0) -> 20 | ... Q2: =OFFSET(稼働日!$B$2,MATCH('内訳ﾘｽﾄ(4～3月)'!Q4,稼働日!$A$3:$A$14,0),0) -> 20
E3: CHECK | F3: {=IF(SUM((F8:F25)-ROUNDDOWN((F8:F25)*4,0)/4)<>0,"時間➝0.25の倍数では無い",IF(SUM(ROUND((F26:F1001),0)-ROUND((F26:F1001),4))<>0,"経費➝小数点",IF(F5<>IF($D$5="製造",'採算表(VND)'!C13,-VLOOKUP($D$5&"経費",'採算表(VND)'!$B:$N,'採算表(VND)'!C3,0)),"経費➝NG","OK")))} -> OK | G3: {=IF(SUM((G8:G25)-ROUNDDOWN((G8:G25)*4,0)/4)<>0,"時間➝0.25の倍数では無い",IF(SUM(ROUND((G26:G1001),0)-ROUND((G26:G1001),4))<>0,"経費➝小数点",IF(G5<>IF($D$5="製造",'採算表(VND)'!D13,-VLOOKUP($D$5&"経費",'採算表(VND)'!$B:$N,'採算表(VND)'!D3,0)),"経費➝NG","OK")))} -> OK | H3: {=IF(SUM((H8:H25)-ROUNDDOWN((H8:H25)*4,0)/4)<>0,"時間➝0.25の倍数では無い",IF(SUM(ROUND((H26:H1001),0)-ROUND((H26:H1001),4))<>0,"経費➝小数点",IF(H5<>IF($D$5="製造",'採算表(VND)'!E13,-VLOOKUP($D$5&"経費",'採算表(VND)'!$B:$N,'採算表(VND)'!E3,0)),"経費➝NG","OK")))} -> OK | I3: {=IF(SUM((I8:I25)-ROUNDDOWN((I8:I25)*4,0)/4)<>0,"時間➝0.25の倍数では無い",IF(SUM(ROUND((I26:I1001),0)-ROUND((I26:I1001),4))<>0,"経費➝小数点",IF(I5<>IF($D$5="製造",'採算表(VND)'!F13,-VLOOKUP($D$5&"経費",'採算表(VND)'!$B:$N,'採算表(VND)'!F3,0)),"経費➝NG","OK")))} -> OK | J3: {=IF(SUM((J8:J25)-ROUNDDOWN((J8:J25)*4,0)/4)<>0,"時間➝0.25の倍数では無い",IF(SUM(ROUND((J26:J1001),0)-ROUND((J26:J1001),4))<>0,"経費➝小数点",IF(J5<>IF($D$5="製造",'採算表(VND)'!G13,-VLOOKUP($D$5&"経費",'採算表(VND)'!$B:$N,'採算表(VND)'!G3,0)),"経費➝NG","OK")))} -> OK | K3: {=IF(SUM((K8:K25)-ROUNDDOWN((K8:K25)*4,0)/4)<>0,"時間➝0.25の倍数では無い",IF(SUM(ROUND((K26:K1001),0)-ROUND((K26:K1001),4))<>0,"経費➝小数点",IF(K5<>IF($D$5="製造",'採算表(VND)'!H13,-VLOOKUP($D$5&"経費",'採算表(VND)'!$B:$N,'採算表(VND)'!H3,0)),"経費➝NG","OK")))} -> OK | L3: {=IF(SUM((L8:L25)-ROUNDDOWN((L8:L25)*4,0)/4)<>0,"時間➝0.25の倍数では無い",IF(SUM(ROUND((L26:L1001),0)-ROUND((L26:L1001),4))<>0,"経費➝小数点",IF(L5<>IF($D$5="製造",'採算表(VND)'!I13,-VLOOKUP($D$5&"経費",'採算表(VND)'!$B:$N,'採算表(VND)'!I3,0)),"経費➝NG","OK")))} -> OK | M3: {=IF(SUM((M8:M25)-ROUNDDOWN((M8:M25)*4,0)/4)<>0,"時間➝0.25の倍数では無い",IF(SUM(ROUND((M26:M1001),0)-ROUND((M26:M1001),4))<>0,"経費➝小数点",IF(M5<>IF($D$5="製造",'採算表(VND)'!J13,-VLOOKUP($D$5&"経費",'採算表(VND)'!$B:$N,'採算表(VND)'!J3,0)),"経費➝NG","OK")))} -> OK | ... Q3: {=IF(SUM((Q8:Q25)-ROUNDDOWN((Q8:Q25)*4,0)/4)<>0,"時間➝0.25の倍数では無い",IF(SUM(ROUND((Q26:Q1001),0)-ROUND((Q26:Q1001),4))<>0,"経費➝小数点",IF(Q5<>IF($D$5="製造",'採算表(VND)'!N13,-VLOOKUP($D$5&"経費",'採算表(VND)'!$B:$N,'採算表(VND)'!N3,0)),"経費➝NG","OK")))} -> OK
B4: 原価センター | C4: 組織名 | D4: 採算区分 | E4: 原価区分 | F4: 4 | G4: 5 | H4: 6 | I4: 7 | J4: 8 | K4: 9 | L4: 10 | M4: 11 | N4: 12 | O4: 1 | P4: 2 | Q4: 3 | R4: 合計 | S4: ※MEBIUS経費になると "V02V0800" は T列に 反映お願いします
B5: 1412000083 | C5: =VLOOKUP($B$5,原価センタ!$A:$E,2,0) -> MD3課 | D5: =VLOOKUP($B$5,原価センタ!$A:$E,4,0) -> 製造 | E5: =VLOOKUP($B$5,原価センタ!$A:$E,5,0) -> 製造 | F5: =SUM(F29:F1000) -> 400823203 | G5: =SUM(G29:G1000) -> 454583044 | H5: =SUM(H29:H1000) -> 415944472 | I5: =SUM(I29:I1000) -> 464714882 | J5: =SUM(J29:J1000) -> 462266346 | K5: =SUM(K29:K1000) -> 779341928 | L5: =SUM(L29:L1000) -> 471136190 | M5: =SUM(M29:M1000) -> 447100639 | ... Q5: =SUM(Q29:Q1000) -> 438958219 | R5: =SUM(R29:R595) -> 5692691901
C7: 勘定科目名称 | D7: 採算科目 | E7: ﾃｰﾏｺｰﾄﾞ | F7: MP | G7: MP | H7: MP | I7: MP | J7: MP | K7: MP | L7: MP | M7: MP | N7: MP | O7: MP | P7: MP | Q7: MP | R7: MP | S7: 備考 | T7: WBS | BC7: WBS | BG7: 12 | BH7: 12 | BI7: 12 | BJ7: 1 | BK7: 2 | BL7: 3 | BM7: 4
B8: 出向社員定時 | C8: 定時間（日本社員） | D8: 直接部門 | F8: 161.5 | G8: 153 | H8: 170 | I8: 187 | J8: 161.5 | K8: 153 | L8: 187 | M8: 170 | N8: 187 | O8: 170 | P8: 127.5 | Q8: 170 | R8: =SUM(F8:Q8) -> 1997.5 | BE8: USD換算Rate (VND/USD) | BG8: 25359 | BH8: 25359 | BI8: 25359 | BJ8: 25359 | BK8: 25359 | BL8: 25359 | BM8: 25359
B9: ローカル社員定時 | C9: 定時間（ベトナム社員） | D9: 直接部門 | F9: 1836 | G9: 1700 | H9: 1887 | I9: 2074 | J9: 1793.5 | K9: 1700 | L9: 2074 | M9: 1793.5 | N9: 1980.5 | O9: 1793.5 | P9: 1326 | Q9: 1793.5 | R9: =SUM(F9:Q9) -> 21751.5 | BE9: JPY換算Rate (VND/JPY) | BG9: 164.27 | BH9: 164.27 | BI9: 164.27 | BJ9: 164.27 | BK9: 164.27 | BL9: 164.27 | BM9: 164.27
B10: 出向社員定時 | C10: 定時間（移動分日本社員） | D10: 直接部門 | R10: =SUM(F10:Q10) -> 0 | BE10: 【システム課金金額】 Mail | BF10: 7.05 | BG10: 1966590 | BH10: 1966590 | BI10: 1966590 | BJ10: 1966590 | BK10: 1966590 | BL10: 1966590 | BM10: 1966590
B11: ローカル社員定時 | C11: 定時間（移動分ベトナム社員） | D11: 直接部門 | R11: =SUM(F11:Q11) -> 0 | BE11: 【システム課金金額】 R3 | BF11: 0
C12: 定時間（部内間接部門） | D12: 部内間接部門 | F12: 0 | G12: 0 | H12: 0 | I12: 0 | J12: 0 | K12: 0 | L12: 0 | M12: 0 | N12: 0 | O12: 0 | P12: 0 | Q12: 0 | R12: =SUM(F12:Q12) -> 0 | S12: この分には間接部門から直接部門に配賦された数字 | BE12: 【システム課金金額】 VPS | BF12: 0
C13: 定時間（部外間接部門1） | D13: 部外間接部門1 | F13: 6.75 | G13: 7 | H13: 7.75 | I13: 12 | J13: 10.75 | K13: 10 | L13: 8.25 | M13: 7.25 | N13: 8 | O13: 7.5 | P13: 5.5 | Q13: 7.5 | R13: =SUM(F13:Q13) -> 98.25 | S13: この分には間接部門から直接部門に配賦された数字 | BE13: 【システム課金金額】 VPN | BF13: 3.52 | BG13: 89264 | BH13: 89264 | BI13: 89264 | BJ13: 89264 | BK13: 89264 | BL13: 89264 | BM13: 89264
C14: 定時間（部外間接部門2） | D14: 部外間接部門2 | F14: 12.75 | G14: 12.25 | H14: 14 | I14: 23.25 | J14: 20.25 | K14: 19.75 | L14: 16.25 | M14: 14 | N14: 15.5 | O14: 14.25 | P14: 10.75 | Q14: 14 | R14: =SUM(F14:Q14) -> 187 | S14: この分には間接部門から直接部門に配賦された数字 | BE14: [減価償却費] 建物 | BF14: (USD) | BG14: 182.06 | BH14: 182.06 | BI14: 182.06 | BJ14: 182.01 | BK14: 182.01 | BL14: 182.01 | BM14: 182.01
C15: 定時間（工場間接部門） | D15: 工場間接部門 | F15: 57 | G15: 56.5 | H15: 60 | I15: 96 | J15: 88.25 | K15: 82.5 | L15: 65 | M15: 59.25 | N15: 63.75 | O15: 60.25 | P15: 45.25 | Q15: 60.5 | R15: =SUM(F15:Q15) -> 794.25 | S15: この分には間接部門から直接部門に配賦された数字 | BE15: [減価償却費] 土地使用権 | BF15: (USD) | BG15: 12.29 | BH15: 12.29 | BI15: 12.29 | BJ15: 12.29 | BK15: 12.29 | BL15: 12.29 | BM15: 12.29
B16: 出向社員残業 | C16: 残業時間（日本社員） | D16: 直接部門 | F16: 38 | G16: 36 | H16: 40 | I16: 44 | J16: 38 | K16: 36 | L16: 44 | M16: 40 | N16: 44 | O16: 40 | P16: 30 | Q16: 40 | R16: =SUM(F16:Q16) -> 470 | BE16: [固定資産金利] 建物 | BF16: (USD) | BG16: 123.58 | BH16: 123.58 | BI16: 123.58 | BJ16: 123.55 | BK16: 123.55 | BL16: 123.55 | BM16: 123.55
B17: ローカル社員残業 | C17: 残業時間（ベトナム社員） | D17: 直接部門 | F17: 130 | G17: 128 | H17: 132 | I17: 136 | J17: 140 | K17: 138 | L17: 146 | M17: 140 | N17: 144 | O17: 140 | P17: 130 | Q17: 140 | R17: =SUM(F17:Q17) -> 1644 | S17: 13時間/人・月(1-12期生)で計算 係責任者は2時間のみなし残業 | BE17: [固定資産金利] 土地使用権 | BF17: (USD) | BG17: 15.28 | BH17: 15.28 | BI17: 15.28 | BJ17: 15.28 | BK17: 15.28 | BL17: 15.28 | BM17: 15.28
B18: 出向社員残業 | C18: 残業時間（移動分日本社員） | D18: 直接部門 | R18: =SUM(F18:Q18) -> 0 | BE18: 電気代 | BF18: (VND) | BG18: 1278721 | BH18: 1323787 | BI18: 1323787 | BJ18: 1226674 | BK18: 858672 | BL18: 1104007 | BM18: 1300274
B19: ローカル社員残業 | C19: 残業時間（移動分ベトナム社員） | D19: 直接部門 | R19: =SUM(F19:Q19) -> 0 | BE19: 水道代 | BF19: (VND) | BG19: 424631 | BH19: 424631 | BI19: 424631 | BJ19: 295783 | BK19: 235769 | BL19: 257202 | BM19: 300069
C20: 残業時間（部内間接部門） | D20: 部内間接部門 | F20: 0 | G20: 0 | H20: 0 | I20: 0 | J20: 0 | K20: 0 | L20: 0 | M20: 0 | N20: 0 | O20: 0 | P20: 0 | Q20: 0 | R20: =SUM(F20:Q20) -> 0 | S20: この分には間接部門から直接部門に配賦された数字 | BE20: ガス | BF20: (USD) | BG20: 39585 | BH20: 39585 | BI20: 39585 | BJ20: 35606 | BK20: 38435 | BL20: 38435 | BM20: 38435
C21: 残業時間（部外間接部門1） | D21: 部外間接部門1 | F21: 0.5 | G21: 0.5 | H21: 0.5 | I21: 0.75 | J21: 0.75 | K21: 0.75 | L21: 0.5 | M21: 0.5 | N21: 0.5 | O21: 0.5 | P21: 0.25 | Q21: 0.5 | R21: =SUM(F21:Q21) -> 6.5 | S21: この分には間接部門から直接部門に配賦された数字 | BE21: 手洗い洗剤 | BF21: (USD) | BG21: 1079 | BH21: 1079 | BI21: 1079 | BJ21: 1028 | BK21: 1126 | BL21: 1174 | BM21: 1174
C22: 残業時間（部外間接部門2） | D22: 部外間接部門2 | F22: 1.25 | G22: 1 | H22: 1.25 | I22: 2 | J22: 1.25 | K22: 1.25 | L22: 1.25 | M22: 1.25 | N22: 1.25 | O22: 1.5 | P22: 0.5 | Q22: 1.5 | R22: =SUM(F22:Q22) -> 15.25 | S22: この分には間接部門から直接部門に配賦された数字 | BE22: トイレットペーパー | BF22: (USD) | BG22: 17105 | BH22: 17105 | BI22: 17105 | BJ22: 15443 | BK22: 16391 | BL22: 17520 | BM22: 17520
C23: 残業時間（工場間接部門） | D23: 工場間接部門 | F23: 3.25 | G23: 3.25 | H23: 2.75 | I23: 4.5 | J23: 3.25 | K23: 5 | L23: 3 | M23: 3 | N23: 3 | O23: 2.75 | P23: 3.75 | Q23: 2.75 | R23: =SUM(F23:Q23) -> 40.25 | S23: この分には間接部門から直接部門に配賦された数字 | BE23: 清掃費 | BF23: (USD) | BG23: 49155 | BH23: 49155 | BI23: 49155 | BJ23: 49027 | BK23: 48431 | BL23: 48915 | BM23: 49077
B24: 出向社員(人) | C24: 出向社員(人) | D24: 出向社員(人) | F24: 1 | G24: 1 | H24: 1 | I24: 1 | J24: 1 | K24: 1 | L24: 1 | M24: 1 | N24: 1 | O24: 1 | P24: 1 | Q24: 1 | R24: =Q24 -> 1 | BE24: 出向者送迎費 | BF24: (USD) | BG24: 727642 | BH24: 727642 | BI24: 727642 | BJ24: 585189 | BK24: 546296 | BL24: 803438 | BM24: 803438
B25: ローカル社員(人) | C25: ローカル社員(人) | D25: ローカル社員(人) | F25: 11 | G25: 11 | H25: 11 | I25: 11 | J25: 11 | K25: 11 | L25: 11 | M25: 11 | N25: 11 | O25: 11 | P25: 11 | Q25: 11 | R25: =Q25 -> 11 | V25: 4 | W25: 5 | X25: 6 | Y25: 7 | Z25: 8 | AA25: 9 | AB25: 10 | AC25: 11 | AD25: 12 | AE25: 1 | AF25: 2 | AG25: 3 | BE25: Local社員送迎費 | BF25: (USD) | BG25: 1620318 | BH25: 1620318 | BI25: 1620318 | BJ25: 1505412 | BK25: 1488121 | BL25: 1167909 | BM25: 1259044
B26: 9114120002 | C26: 社外出荷 | D26: 社外出荷 | F26: =ROUNDDOWN(V26*$B$2,0)+1 -> 756707565 | G26: =ROUNDDOWN(W26*$B$2,0)+1 -> 1105818795 | H26: =ROUNDDOWN(X26*$B$2,0)+1 -> 1026239934 | I26: =ROUNDDOWN(Y26*$B$2,0)+1 -> 1060968122 | J26: =ROUNDDOWN(Z26*$B$2,0) -> 1149473853 | K26: =ROUNDDOWN(AA26*$B$2,0)+1 -> 1153673106 | L26: =ROUNDDOWN(AB26*$B$2,0)+1 -> 1453732633 | M26: =ROUNDDOWN(AC26*$B$2,0)+1 -> 1171044436 | N26: =ROUNDDOWN(AD26*$B$2,0)+1 -> 1135944792 | O26: =ROUNDDOWN(AE26*$B$2,0)+1 -> 1161632363 | P26: =ROUNDDOWN(AF26*$B$2,0)+1 -> 1140587861 | Q26: =ROUNDDOWN(AG26*$B$2,0)+1 -> 1129609479 | R26: =SUM(F26:Q26) -> 13445432939 | S26: 総生産情報 | V26: 29803.37 | W26: 43553.32 | X26: 40419.06 | Y26: 41786.85 | Z26: 45272.7 | AA26: 45438.09 | AB26: 57256.11 | AC26: 46122.27 | AD26: 44739.85 | AE26: 45751.57 | AF26: 44922.72 | AG26: 44490.33 | BE26: 休(出向) 人日 | BG26: 1 | BH26: 1 | BI26: 1 | BJ26: 1 | BK26: 1 | BL26: 1 | BM26: 1
B27: 9114120004 | C27: 社内売 | D27: 社内売 | F27: 0 | G27: 0 | H27: 0 | I27: 0 | J27: 0 | K27: 0 | L27: 0 | M27: 0 | N27: 0 | O27: 0 | P27: 0 | Q27: 0 | R27: =SUM(F27:Q27) -> 0 | S27: 総生産情報 | BE27: 休(Local) 人日 | BG27: 7 | BH27: 7 | BI27: 7 | BJ27: 5 | BK27: 5 | BL27: 5 | BM27: 6
B28: 9114120014 | C28: 社内買 | D28: 社内買 | F28: 0 | G28: 0 | H28: 0 | I28: 0 | J28: 0 | K28: 0 | L28: 0 | M28: 0 | N28: 0 | O28: 0 | P28: 0 | Q28: 0 | R28: =SUM(F28:Q28) -> 0 | S28: 総生産情報 | BE28: 残(Local) 時間 | BG28: 10 | BH28: 10 | BI28: 10 | BJ28: 10 | BK28: 100 | BL28: 100 | BM28: 100
B29: 9114120006 | C29: 材料費(指図出庫） | D29: 材料費 | F29: 0 | G29: 0 | H29: 0 | I29: 0 | J29: 0 | K29: 0 | L29: 0 | M29: 0 | N29: 0 | O29: 0 | P29: 0 | Q29: 0 | R29: =SUM(F29:Q29) -> 0 | S29: 総生産情報 | BE29: 誕生会人数 | BG29: 0 | BH29: 0 | BI29: 0 | BJ29: 2 | BK29: 2 | BL29: 2 | BM29: 1
C30: =IFERROR(IF(VLOOKUP($B30,[1]勘定科目!$A:$H,HLOOKUP($E$5,[1]勘定科目!$F$1:$H$2,2,0),0)="","",VLOOKUP($B30,[1]勘定科目!$A:$E,2,0)),"") | D30: =IF(C30="","",VLOOKUP($B30,[1]勘定科目!$A:$E,4,0)) | R30: =SUM(F30:Q30) -> 0 | BE30: CHI さん産休 ( 9/5~9/11) | BG30: 20 | BH30: 20 | BI30: 20 | BJ30: 17 | BK30: 19 | BL30: 20 | BM30: 19
B31: 9114120018 | C31: =IFERROR(IF(VLOOKUP($B31,[1]勘定科目!$A:$H,HLOOKUP($E$5,[1]勘定科目!$F$1:$H$2,2,0),0)="","",VLOOKUP($B31,[1]勘定科目!$A:$E,2,0)),"") -> 部内間接経費 | D31: =IF(C31="","",VLOOKUP($B31,[1]勘定科目!$A:$E,4,0)) -> 部内間接経費 | F31: 0 | G31: 0 | H31: 0 | I31: 0 | J31: 0 | K31: 0 | L31: 0 | M31: 0 | N31: 0 | O31: 0 | P31: 0 | Q31: 0 | R31: =SUM(F31:Q31) -> 0 | S31: この分には間接部門から直接部門に配賦された数字
B32: 9114120029 | C32: =IFERROR(IF(VLOOKUP($B32,[1]勘定科目!$A:$H,HLOOKUP($E$5,[1]勘定科目!$F$1:$H$2,2,0),0)="","",VLOOKUP($B32,[1]勘定科目!$A:$E,2,0)),"") -> 部外間接経費1 | D32: =IF(C32="","",VLOOKUP($B32,[1]勘定科目!$A:$E,4,0)) -> 部外間接経費1 | F32: 397748 | G32: 456535 | H32: 380026 | I32: 628019 | J32: 564637 | K32: 617936 | L32: 371560 | M32: 373979 | N32: 377736 | O32: 363367 | P32: 384655 | Q32: 367742 | R32: =SUM(F32:Q32) -> 5283940 | S32: この分には間接部門から直接部門に配賦された数字
B33: 9114120030 | C33: =IFERROR(IF(VLOOKUP($B33,[1]勘定科目!$A:$H,HLOOKUP($E$5,[1]勘定科目!$F$1:$H$2,2,0),0)="","",VLOOKUP($B33,[1]勘定科目!$A:$E,2,0)),"") -> 部外間接経費2 | D33: =IF(C33="","",VLOOKUP($B33,[1]勘定科目!$A:$E,4,0)) -> 部外間接経費2 | F33: 2428308 | G33: 829829 | H33: 594132 | I33: 960180 | J33: 862028 | K33: 775164 | L33: 646360 | M33: 664785 | N33: 642063 | O33: 502068 | P33: 525403 | Q33: 516391 | R33: =SUM(F33:Q33) -> 9946711 | S33: この分には間接部門から直接部門に配賦された数字
B34: 9114120021 | C34: =IFERROR(IF(VLOOKUP($B34,[1]勘定科目!$A:$H,HLOOKUP($E$5,[1]勘定科目!$F$1:$H$2,2,0),0)="","",VLOOKUP($B34,[1]勘定科目!$A:$E,2,0)),"") -> 工場間接経費 | D34: =IF(C34="","",VLOOKUP($B34,[1]勘定科目!$A:$E,4,0)) -> 工場間接経費 | F34: 28869303 | G34: 36883360 | H34: 27306721 | I34: 59003732 | J34: 32875220 | K34: 32133504 | L34: 27208202 | M34: 22922178 | N34: 22670432 | O34: 25237009 | P34: 17427497 | Q34: 17985042 | R34: =SUM(F34:Q34) -> 350522200 | S34: この分には間接部門から直接部門に配賦された数字
C35: =IFERROR(IF(VLOOKUP($B35,[1]勘定科目!$A:$H,HLOOKUP($E$5,[1]勘定科目!$F$1:$H$2,2,0),0)="","",VLOOKUP($B35,[1]勘定科目!$A:$E,2,0)),"") | D35: =IF(C35="","",VLOOKUP($B35,[1]勘定科目!$A:$E,4,0)) | R35: =SUM(F35:Q35) -> 0
C36: =IFERROR(IF(VLOOKUP($B36,[1]勘定科目!$A:$H,HLOOKUP($E$5,[1]勘定科目!$F$1:$H$2,2,0),0)="","",VLOOKUP($B36,[1]勘定科目!$A:$E,2,0)),"") | D36: =IF(C36="","",VLOOKUP($B36,[1]勘定科目!$A:$E,4,0)) | R36: =SUM(F36:Q36) -> 0
C37: =IFERROR(IF(VLOOKUP($B37,[1]勘定科目!$A:$H,HLOOKUP($E$5,[1]勘定科目!$F$1:$H$2,2,0),0)="","",VLOOKUP($B37,[1]勘定科目!$A:$E,2,0)),"") | D37: =IF(C37="","",VLOOKUP($B37,[1]勘定科目!$A:$E,4,0)) | R37: =SUM(F37:Q37) -> 0
C38: =IFERROR(IF(VLOOKUP($B38,[1]勘定科目!$A:$H,HLOOKUP($E$5,[1]勘定科目!$F$1:$H$2,2,0),0)="","",VLOOKUP($B38,[1]勘定科目!$A:$E,2,0)),"") | D38: =IF(C38="","",VLOOKUP($B38,[1]勘定科目!$A:$E,4,0)) | R38: =SUM(F38:Q38) -> 0
